Workbook

Sheet Overview_KRONE
B2: 재고 | C2: Jan | D2: Feb | E2: Mar | F2: Apr | G2: May | H2: Jun | I2: Jul | J2: Aug | K2: Sep | L2: Oct | M2: Nov | N2: Dec
B3: 재고수량 | C3: =KRONE!C19 -> 226894 | D3: =KRONE!D19 -> 224748.29 | E3: =KRONE!E19 -> 245291.23 | F3: =KRONE!F19 -> 260357.3 | G3: =KRONE!G19 -> 251982.36 | H3: =KRONE!H19 -> 246532 | I3: =KRONE!I19 -> 235150.27 | J3: =KRONE!J19 -> 215770.89 | ... N3: =KRONE!N19 -> 217026.51
B4: 재고 수준(월) | C4: =KRONE!C81 -> 5.0582766 | D4: =KRONE!D81 -> 4.5497056 | E4: =KRONE!E81 -> 4.4312347 | F4: =KRONE!F81 -> 4.9958079 | G4: =KRONE!G81 -> 4.8229608 | H4: =KRONE!H81 -> 3.9619104 | I4: =KRONE!I81 -> 3.6590465 | J4: =KRONE!J81 -> 2.9702119 | ... N4: =KRONE!N81 -> 1.6789351
B5: 재고 금액 | C5: =KRONE!C20 -> 7.4443203e+09 | D5: =KRONE!D20 -> 7.4033816e+09 | E5: =KRONE!E20 -> 8.0703097e+09 | F5: =KRONE!F20 -> 8.4301076e+09 | G5: =KRONE!G20 -> 8.0578349e+09 | H5: =KRONE!H20 -> 8.062808e+09 | I5: =KRONE!I20 -> 7.6780599e+09 | J5: =KRONE!J20 -> 7.0743153e+09 | ... N5: =KRONE!N20 -> 7.2832754e+09
B7: 매출 | C7: Jan | D7: Feb | E7: Mar | F7: Apr | G7: May | H7: Jun | I7: Jul | J7: Aug | K7: Sep | L7: Oct | M7: Nov | N7: Dec
A8: 33000 | B8: 크로네 판매량 | C8: =KRONE!C39 -> 60763 | D8: =KRONE!D39 -> 64885.71 | E8: =KRONE!E39 -> 61057.061 | F8: =KRONE!F39 -> 70253.931 | G8: =KRONE!G39 -> 71458.937 | H8: =KRONE!H39 -> 72650.357 | I8: =KRONE!I39 -> 65177.736 | J8: =KRONE!J39 -> 72227.375 | ... N8: =KRONE!N39 -> 73973.376
B9: 몰테일 판매량 | C9: 0 | D9: 0 | E9: 0 | F9: 0 | G9: 0 | H9: 0 | I9: 0 | J9: 0 | K9: 0 | L9: 0 | M9: 0 | N9: 0
B10: 총 판매량 | C10: =SUM(C8:C9) -> 60763 | D10: =SUM(D8:D9) -> 64885.71 | E10: =SUM(E8:E9) -> 61057.061 | F10: =SUM(F8:F9) -> 70253.931 | G10: =SUM(G8:G9) -> 71458.937 | H10: =SUM(H8:H9) -> 72650.357 | I10: =SUM(I8:I9) -> 65177.736 | J10: =SUM(J8:J9) -> 72227.375 | ... N10: =SUM(N8:N9) -> 73973.376
A11: 1500000000 | B11: 정산 금액 | C11: =C10*$A$8 -> 2005179000 | D11: =D10*$A$8 -> 2.1412284e+09 | E11: =E10*$A$8 -> 2.014883e+09 | F11: =F10*$A$8 -> 2.3183797e+09 | G11: =G10*$A$8 -> 2.3581449e+09 | H11: =H10*$A$8 -> 2.3974618e+09 | I11: =I10*$A$8 -> 2.1508653e+09 | J11: =J10*$A$8 -> 2.3835034e+09 | ... N11: =N10*$A$8 -> 2.4411214e+09
B13: 결제 | C13: Jan | D13: Feb | E13: Mar | F13: Apr | G13: May | H13: Jun | I13: Jul | J13: Aug | K13: Sep | L13: Oct | M13: Nov | N13: Dec
B14: 발주 결제 | C14: =KRONE!C61 -> 563753925 | D14: =KRONE!D61 -> 2180222100 | E14: =KRONE!E61 -> 2709084000 | F14: =KRONE!F61 -> 2718456300 | G14: =KRONE!G61 -> 2026879890 | H14: =KRONE!H61 -> 2377872000 | I14: =KRONE!I61 -> 1826075790 | J14: =KRONE!J61 -> 1849599360 | ... N14: =KRONE!N61 -> 2466032310
B15: 물류비 | C15: =C10*4500 -> 273433500 | D15: =D10*4500 -> 2.9198569e+08 | E15: =E10*4500 -> 2.7475678e+08 | F15: =F10*4500 -> 3.1614269e+08 | G15: =G10*4500 -> 3.2156522e+08 | H15: =H10*4500 -> 3.269266e+08 | I15: =I10*4500 -> 2.9329981e+08 | J15: =J10*4500 -> 3.2502319e+08 | ... N15: =N10*4500 -> 3.3288019e+08
B16: 전체 비용 | C16: =SUM(C14:C15) -> 837187425 | D16: =SUM(D14:D15) -> 2472207795 | E16: =SUM(E14:E15) -> 2.9838408e+09 | F16: =SUM(F14:F15) -> 3.034599e+09 | G16: =SUM(G14:G15) -> 2.3484451e+09 | H16: =SUM(H14:H15) -> 2.7047986e+09 | I16: =SUM(I14:I15) -> 2.1193756e+09 | J16: =SUM(J14:J15) -> 2.1746225e+09 | ... N16: =SUM(N14:N15) -> 2.7989125e+09
B18: 서포트 | C18: Jan | D18: Feb | E18: Mar | F18: Apr | G18: May | H18: Jun | I18: Jul | J18: Aug | K18: Sep | L18: Oct | M18: Nov | N18: Dec
A19: 3925 | B19: Trade support | C19: 0 | D19: 425748000 | E19: 732371057 | F19: 0 | G19: 0 | H19: =$A$19*SUM(F10:H10) -> 8.4137566e+08 | I19: 0 | J19: 0 | K19: =$A$19*SUM(I10:K10) -> 7.8317007e+08 | L19: 0 | M19: 0 | N19: =$A$19*SUM(L10:N10) -> 8.5458131e+08
B21: Cash +/- | C21: =A11-C16+C19 -> 662812575 | D21: =C11-D16+D19 -> -41280795 | E21: =D11-E16+E19 -> -1.1024129e+08 | F21: =E11-F16+F19 -> -1.019716e+09 | G21: =F11-G16+G19 -> -30065394 | H21: =G11-H16+H19 -> 4.9472198e+08 | I21: =H21+H11-I16+I19 -> 7.7280814e+08 | J21: =I21+I11-J16+J19 -> 7.490509e+08 | K21: =J21+J11-K16+K19 -> 1.7050189e+09 | L21: =K21+K11-L16+L19 -> 7.1031934e+08 | M21: =L21+L11-M16+M19 -> 1.2742849e+08 | N21: =M21+M11-N16+N19 -> 5.74866e+08

Sheet KRONE
B2: Stock
B3: SKU | C3: Jan | D3: Feb | E3: Mar | F3: Apr | G3: May | H3: Jun | I3: Jul | J3: Aug | K3: Sep | L3: Oct | M3: Nov | N3: Dec
A4: 3043 | B4: PN PRE | C4: =A4-C24+C45 -> 3460 | D4: =C4+D45-D24-1700 -> 1471.16 | E4: =D4+E45-E24 -> 1381.2308 | F4: =E4+F45-F24 -> 1303.6602 | G4: =F4+G45-G24 -> 1784.2567 | H4: =G4+H45-H24 -> 1196.6013 | I4: =H4+I45-I24 -> 1453.4852 | J4: =I4+J45-J24 -> 911.19138 | K4: =J4+K45-K24 -> 395.41229 | L4: =K4+L45-L24 -> 944.51982 | ... N4: =M4+N45-N24 -> 931.39379
A5: 4934 | B5: PN 1 | C5: =A5-C25+C46 -> 6439 | D5: =C5+D46-D25 -> 6756.94 | E5: =D5+E46-E25 -> 7526.5198 | F5: =E5+F46-F25 -> 9754.0428 | G5: =F5+G46-G25 -> 8229.6753 | H5: =G5+H46-H25 -> 6746.6289 | I5: =H5+I46-I25 -> 5425.0243 | J5: =I5+J46-J25 -> 4008.2458 | K5: =J5+K46-K25 -> 2813.7473 | ... N5: =M5+N46-N25 -> 4358.2618
A6: 2605 | B6: PN 2 | C6: =A6-C26+C47 -> 2680 | D6: =C6+D47-D26 -> 2215.4 | E6: =D6+E47-E26 -> 1725.848 | F6: =E6+F47-F26 -> 4086.9194 | G6: =F6+G47-G26 -> 6162.4116 | H6: =G6+H47-H26 -> 4473.6388 | I6: =H6+I47-I26 -> 6670.0215 | J6: =I6+J47-J26 -> 5042.9365 | K6: =J6+K47-K26 -> 3549.695 | ... N6: =M6+N47-N26 -> 4749.8448
A7: 857 | B7: PN 3 | C7: =A7-C27+C48 -> 256 | D7: =C7+D48-D27 -> -10.54 | E7: =D7+E48-E27 -> -85.3226 | F7: =E7+F48-F27 -> 2788.8809 | G7: =F7+G48-G27 -> 2159.1423 | H7: =G7+H48-H27 -> 1535.4012 | I7: =H7+I48-I27 -> 2291.5348 | J7: =I7+J48-J27 -> 1697.1245 | K7: =J7+K48-K27 -> 1165.867 | ... N7: =M7+N48-N27 -> 1355.6473
A8: 4162 | B8: PN VP 1 | C8: =A8-C28+C49 -> 3357 | D8: =C8+D49-D28 -> 2552 | E8: =D8+E49-E28 -> 1747 | F8: =E8+F49-F28 -> 942 | G8: =F8+G49-G28 -> 137 | H8: =G8+H49-H28 -> -668 | I8: =H8+I49-I28 -> -1473 | J8: =I8+J49-J28 -> -2278 | K8: =J8+K49-K28 -> -3083 | ... N8: =M8+N49-N28 -> -5498
A9: 6281 | B9: PN VP 2 | C9: =A9-C29+C50 -> 5694 | D9: =C9+D50-D29 -> 5107 | E9: =D9+E50-E29 -> 4520 | F9: =E9+F50-F29 -> 3933 | G9: =F9+G50-G29 -> 3346 | H9: =G9+H50-H29 -> 2759 | I9: =H9+I50-I29 -> 2172 | J9: =I9+J50-J29 -> 1585 | K9: =J9+K50-K29 -> 998 | ... N9: =M9+N50-N29 -> -763
A10: 31891 | B10: PF PRE | C10: =A10-C30+C51 -> 21116.191 | D10: =C10+D51-D30 -> 19900.061 | E10: =D10+E51-E30 -> 20760.522 | F10: =E10+F51-F30 -> 38142.681 | G10: =F10+G51-G30 -> 26236.02 | H10: =G10+H51-H30 -> 26021.622 | I10: =H10+I51-I30 -> 31192.182 | J10: =I10+J51-J30 -> 28823.234 | K10: =J10+K51-K30 -> 29903.24 | ... N10: =M10+N51-N30 -> 33690.215
A11: 90234 | B11: PF 1 | C11: =A11-C31+C52 -> 70891.957 | D11: =C11+D52-D31 -> 70969.513 | E11: =D11+E52-E31 -> 76231.9 | F11: =E11+F52-F31 -> 61530.752 | G11: =F11+G52-G31 -> 60622.602 | H11: =G11+H52-H31 -> 67143.499 | I11: =H11+I52-I31 -> 69465.397 | J11: =I11+J52-J31 -> 65797.374 | K11: =J11+K52-K31 -> 63754.898 | ... N11: =M11+N52-N31 -> 72852.293
A12: 85815 | B12: PF 2 | C12: =A12-C32+C53 -> 68511.853 | D12: =C12+D53-D32 -> 73791.796 | E12: =D12+E53-E32 -> 83074.443 | F12: =E12+F53-F32 -> 75697.286 | G12: =F12+G53-G32 -> 77784.199 | H12: =G12+H53-H32 -> 80076.602 | I12: =H12+I53-I32 -> 61187.889 | J12: =I12+J53-J32 -> 58820.061 | K12: =J12+K53-K32 -> 61745.644 | ... N12: =M12+N53-N32 -> 71748.71
A13: 13264 | B13: PF K1+ | C13: =A13-C33+C54 -> 10255 | D13: =C13+D54-D33 -> 8689.66 | E13: =D13+E54-E33 -> 9493.5598 | F13: =E13+F54-F33 -> 12009.258 | G13: =F13+G54-G33 -> 8750.1139 | H13: =G13+H54-H33 -> 5520.8016 | I13: =H13+I54-I33 -> 9412.5556 | J13: =I13+J54-J33 -> 8988.1945 | K13: =J13+K54-K33 -> 9894.197 | ... N13: =M13+N54-N33 -> 9589.0495
A14: 1704 | B14: PF K2+ | C14: =A14-C34+C55 -> 1271 | D14: =C14+D55-D34 -> 838.18 | E14: =D14+E55-E34 -> 410.419 | F14: =E14+F55-F34 -> -49.29722 | G14: =F14+G55-G34 -> -513.0706 | H14: =G14+H55-H34 -> -974.79512 | I14: =H14+I55-I34 -> -1404.3651 | J14: =I14+J55-J34 -> -1853.9395 | K14: =J14+K55-K34 -> -2267.6466 | ... N14: =M14+N55-N34 -> -3611.7725
A15: 8377 | B15: TAB IF | C15: =A15-C35+C56 -> 16221 | D15: =C15+D56-D35 -> 16559.56 | E15: =D15+E56-E35 -> 19804.309 | F15: =E15+F56-F35 -> 25543.393 | G15: =F15+G56-G35 -> 25457.031 | H15: =G15+H56-H35 -> 23820.72 | I15: =H15+I56-I35 -> 22035.977 | J15: =I15+J56-J35 -> 19989.997 | K15: =J15+K56-K35 -> 18019.775 | ... N15: =M15+N56-N35 -> 12487.075
A16: 8444 | B16: TAB FO | C16: =A16-C36+C57 -> 13309 | D16: =C16+D57-D36 -> 13188.87 | E16: =D16+E57-E36 -> 16704.223 | F16: =E16+F57-F36 -> 23407.416 | G16: =F16+G57-G36 -> 29283.161 | H16: =G16+H57-H36 -> 27087.045 | I16: =H16+I57-I36 -> 24685.918 | J16: =I16+J57-J36 -> 21969.073 | K16: =J16+K57-K36 -> 19380.77 | ... N16: =M16+N57-N36 -> 12785.617
... A18: 2131 | B18: COMF | C18: =A18-C38+C59 -> 1976 | D18: =C18+D59-D38 -> 1845.8 | E18: =D18+E59-E38 -> 1703.882 | F18: =E18+F59-F38 -> 1557.7065 | G18: =F18+G59-G38 -> 1407.1457 | H18: =G18+H59-H38 -> 1254.3264 | I18: =H18+I59-I38 -> 1098.4508 | J18: =I18+J59-J38 -> 941.01647 | K18: =J18+K59-K38 -> 783.58212 | ... N18: =M18+N59-N38 -> 322.2053
B19: Total(CU) | C19: =SUM(C4:C18) -> 226894 | D19: =SUM(D4:D18) -> 224748.29 | E19: =SUM(E4:E18) -> 245291.23 | F19: =SUM(F4:F18) -> 260357.3 | G19: =SUM(G4:G18) -> 251982.36 | H19: =SUM(H4:H18) -> 246532 | I19: =SUM(I4:I18) -> 235150.27 | J19: =SUM(J4:J18) -> 215770.89 | ... N19: =SUM(N4:N18) -> 217026.51
B20: Total(KRW) | C20: =SUM(C4:C7)*$R$46+SUM(C8:C9)*$R$48+SUM(C10:C14)*$R$47+SUM(C15:C16)*$R$49+SUM(C17:C18)*$R$50 -> 7.4443203e+09 | D20: =SUM(D4:D7)*$R$46+SUM(D8:D9)*$R$48+SUM(D10:D14)*$R$47+SUM(D15:D16)*$R$49+SUM(D17:D18)*$R$50 -> 7.4033816e+09 | E20: =SUM(E4:E7)*$R$46+SUM(E8:E9)*$R$48+SUM(E10:E14)*$R$47+SUM(E15:E16)*$R$49+SUM(E17:E18)*$R$50 -> 8.0703097e+09 | F20: =SUM(F4:F7)*$R$46+SUM(F8:F9)*$R$48+SUM(F10:F14)*$R$47+SUM(F15:F16)*$R$49+SUM(F17:F18)*$R$50 -> 8.4301076e+09 | G20: =SUM(G4:G7)*$R$46+SUM(G8:G9)*$R$48+SUM(G10:G14)*$R$47+SUM(G15:G16)*$R$49+SUM(G17:G18)*$R$50 -> 8.0578349e+09 | H20: =SUM(H4:H7)*$R$46+SUM(H8:H9)*$R$48+SUM(H10:H14)*$R$54+SUM(H15:H16)*$R$49+SUM(H17:H18)*$R$50 -> 8.062808e+09 | I20: =SUM(I4:I7)*$R$46+SUM(I8:I9)*$R$48+SUM(I10:I14)*$R$54+SUM(I15:I16)*$R$49+SUM(I17:I18)*$R$50 -> 7.6780599e+09 | J20: =SUM(J4:J7)*$R$46+SUM(J8:J9)*$R$48+SUM(J10:J14)*$R$54+SUM(J15:J16)*$R$49+SUM(J17:J18)*$R$50 -> 7.0743153e+09 | K20: =SUM(K4:K7)*$R$46+SUM(K8:K9)*$R$48+SUM(K10:K14)*$R$54+SUM(K15:K16)*$R$49+SUM(K17:K18)*$R$50 -> 6.9028205e+09 | L20: =SUM(L4:L7)*$R$46+SUM(L8:L9)*$R$48+SUM(L10:L14)*$R$54+SUM(L15:L16)*$R$49+SUM(L17:L18)*$R$50 -> 7.2031403e+09 | M20: =SUM(M4:M7)*$R$46+SUM(M8:M9)*$R$48+SUM(M10:M14)*$R$54+SUM(M15:M16)*$R$49+SUM(M17:M18)*$R$50 -> 7.3428917e+09 | N20: =SUM(N4:N7)*$R$46+SUM(N8:N9)*$R$48+SUM(N10:N14)*$R$54+SUM(N15:N16)*$R$49+SUM(N17:N18)*$R$50 -> 7.2832754e+09
B22: Sales Fcst | R22: 44
B23: SKU | C23: Jan | D23: Feb | E23: Mar | F23: Apr | G23: May | H23: Jun | I23: Jul | J23: Aug | K23: Sep | L23: Oct | M23: Nov | N23: Dec | R23: 54
B24: PN PRE | C24: 663 | D24: =Sheet2!L5+Sheet2!L22+Sheet2!L39 -> 558.84 | E24: =Sheet2!M5+Sheet2!M22+Sheet2!M39 -> 629.9292 | F24: =Sheet2!N5+Sheet2!N22+Sheet2!N39 -> 617.57062 | G24: =Sheet2!O5+Sheet2!O22+Sheet2!O39 -> 599.4035 | H24: =Sheet2!P5+Sheet2!P22+Sheet2!P39 -> 587.65543 | I24: =Sheet2!Q5+Sheet2!Q22+Sheet2!Q39 -> 553.1161 | J24: =Sheet2!R5+Sheet2!R22+Sheet2!R39 -> 542.29378 | K24: =Sheet2!S5+Sheet2!S22+Sheet2!S39 -> 515.77909 | ... N24: =Sheet2!V5+Sheet2!V22+Sheet2!V39 -> 551.85572
B25: PN 1 | C25: 1465 | D25: =Sheet2!L6+Sheet2!L23+Sheet2!L40 -> 1302.06 | E25: =Sheet2!M6+Sheet2!M23+Sheet2!M40 -> 1390.4202 | F25: =Sheet2!N6+Sheet2!N23+Sheet2!N40 -> 1552.477 | G25: =Sheet2!O6+Sheet2!O23+Sheet2!O40 -> 1524.3675 | H25: =Sheet2!P6+Sheet2!P23+Sheet2!P40 -> 1483.0464 | I25: =Sheet2!Q6+Sheet2!Q23+Sheet2!Q40 -> 1321.6046 | J25: =Sheet2!R6+Sheet2!R23+Sheet2!R40 -> 1416.7785 | K25: =Sheet2!S6+Sheet2!S23+Sheet2!S40 -> 1194.4985 | ... N25: =Sheet2!V6+Sheet2!V23+Sheet2!V40 -> 1508.547
B26: PN 2 | C26: 1545 | D26: =Sheet2!L7+Sheet2!L24+Sheet2!L41 -> 1544.6 | E26: =Sheet2!M7+Sheet2!M24+Sheet2!M41 -> 1569.552 | F26: =Sheet2!N7+Sheet2!N24+Sheet2!N41 -> 1688.9286 | G26: =Sheet2!O7+Sheet2!O24+Sheet2!O41 -> 1704.5078 | H26: =Sheet2!P7+Sheet2!P24+Sheet2!P41 -> 1688.7728 | I26: =Sheet2!Q7+Sheet2!Q24+Sheet2!Q41 -> 1583.6173 | J26: =Sheet2!R7+Sheet2!R24+Sheet2!R41 -> 1627.085 | K26: =Sheet2!S7+Sheet2!S24+Sheet2!S41 -> 1493.2416 | ... N26: =Sheet2!V7+Sheet2!V24+Sheet2!V41 -> 1715.657
B27: PN 3 | C27: 601 | D27: =Sheet2!L8+Sheet2!L25+Sheet2!L42 -> 536.54 | E27: =Sheet2!M8+Sheet2!M25+Sheet2!M42 -> 614.7826 | F27: =Sheet2!N8+Sheet2!N25+Sheet2!N42 -> 635.79651 | G27: =Sheet2!O8+Sheet2!O25+Sheet2!O42 -> 629.73855 | H27: =Sheet2!P8+Sheet2!P25+Sheet2!P42 -> 623.74116 | I27: =Sheet2!Q8+Sheet2!Q25+Sheet2!Q42 -> 593.86634 | J27: =Sheet2!R8+Sheet2!R25+Sheet2!R42 -> 594.41035 | K27: =Sheet2!S8+Sheet2!S25+Sheet2!S42 -> 531.25752 | ... N27: =Sheet2!V8+Sheet2!V25+Sheet2!V42 -> 575.63788
B28: PN VP 1 | C28: 805 | D28: =Sheet2!L9+Sheet2!L26+Sheet2!L43 -> 805 | E28: =Sheet2!M9+Sheet2!M26+Sheet2!M43 -> 805 | F28: =Sheet2!N9+Sheet2!N26+Sheet2!N43 -> 805 | G28: =Sheet2!O9+Sheet2!O26+Sheet2!O43 -> 805 | H28: =Sheet2!P9+Sheet2!P26+Sheet2!P43 -> 805 | I28: =Sheet2!Q9+Sheet2!Q26+Sheet2!Q43 -> 805 | J28: =Sheet2!R9+Sheet2!R26+Sheet2!R43 -> 805 | K28: =Sheet2!S9+Sheet2!S26+Sheet2!S43 -> 805 | ... N28: =Sheet2!V9+Sheet2!V26+Sheet2!V43 -> 805
B29: PN VP 2 | C29: 587 | D29: =Sheet2!L10+Sheet2!L27+Sheet2!L44 -> 587 | E29: =Sheet2!M10+Sheet2!M27+Sheet2!M44 -> 587 | F29: =Sheet2!N10+Sheet2!N27+Sheet2!N44 -> 587 | G29: =Sheet2!O10+Sheet2!O27+Sheet2!O44 -> 587 | H29: =Sheet2!P10+Sheet2!P27+Sheet2!P44 -> 587 | I29: =Sheet2!Q10+Sheet2!Q27+Sheet2!Q44 -> 587 | J29: =Sheet2!R10+Sheet2!R27+Sheet2!R44 -> 587 | K29: =Sheet2!S10+Sheet2!S27+Sheet2!S44 -> 587 | ... N29: =Sheet2!V10+Sheet2!V27+Sheet2!V44 -> 587
B30: PF PRE | C30: 10774.809 | D30: =Sheet2!L11+Sheet2!L28+Sheet2!L45 -> 11200.129 | E30: =Sheet2!M11+Sheet2!M28+Sheet2!M45 -> 10659.539 | F30: =Sheet2!N11+Sheet2!N28+Sheet2!N45 -> 11801.841 | G30: =Sheet2!O11+Sheet2!O28+Sheet2!O45 -> 11906.661 | H30: =Sheet2!P11+Sheet2!P28+Sheet2!P45 -> 12118.398 | I30: =Sheet2!Q11+Sheet2!Q28+Sheet2!Q45 -> 10957.441 | J30: =Sheet2!R11+Sheet2!R28+Sheet2!R45 -> 11584.948 | K30: =Sheet2!S11+Sheet2!S28+Sheet2!S45 -> 10439.994 | ... N30: =Sheet2!V11+Sheet2!V28+Sheet2!V45 -> 12305.929
B31: PF 1 | C31: 19342.043 | D31: =Sheet2!L12+Sheet2!L29+Sheet2!L46 -> 21042.443 | E31: =Sheet2!M12+Sheet2!M29+Sheet2!M46 -> 19697.613 | F31: =Sheet2!N12+Sheet2!N29+Sheet2!N46 -> 23149.148 | G31: =Sheet2!O12+Sheet2!O29+Sheet2!O46 -> 23564.15 | H31: =Sheet2!P12+Sheet2!P29+Sheet2!P46 -> 24199.103 | I31: =Sheet2!Q12+Sheet2!Q29+Sheet2!Q46 -> 21486.102 | J31: =Sheet2!R12+Sheet2!R29+Sheet2!R46 -> 24404.024 | K31: =Sheet2!S12+Sheet2!S29+Sheet2!S46 -> 19706.476 | ... N31: =Sheet2!V12+Sheet2!V29+Sheet2!V46 -> 24414.726
B32: PF 2 | C32: 17303.147 | D32: =Sheet2!L13+Sheet2!L30+Sheet2!L47 -> 19680.057 | E32: =Sheet2!M13+Sheet2!M30+Sheet2!M47 -> 17597.353 | F32: =Sheet2!N13+Sheet2!N30+Sheet2!N47 -> 21585.157 | G32: =Sheet2!O13+Sheet2!O30+Sheet2!O47 -> 22105.087 | H32: =Sheet2!P13+Sheet2!P30+Sheet2!P47 -> 22283.597 | I32: =Sheet2!Q13+Sheet2!Q30+Sheet2!Q47 -> 18888.713 | J32: =Sheet2!R13+Sheet2!R30+Sheet2!R47 -> 21567.828 | K32: =Sheet2!S13+Sheet2!S30+Sheet2!S47 -> 18194.417 | ... N32: =Sheet2!V13+Sheet2!V30+Sheet2!V47 -> 23508.711
B33: PF K1+ | C33: 3009 | D33: =Sheet2!L14+Sheet2!L31+Sheet2!L48 -> 3101.34 | E33: =Sheet2!M14+Sheet2!M31+Sheet2!M48 -> 3036.1002 | F33: =Sheet2!N14+Sheet2!N31+Sheet2!N48 -> 3244.3022 | G33: =Sheet2!O14+Sheet2!O31+Sheet2!O48 -> 3259.1437 | H33: =Sheet2!P14+Sheet2!P31+Sheet2!P48 -> 3229.3123 | I33: =Sheet2!Q14+Sheet2!Q31+Sheet2!Q48 -> 3020.246 | J33: =Sheet2!R14+Sheet2!R31+Sheet2!R48 -> 3112.3611 | K33: =Sheet2!S14+Sheet2!S31+Sheet2!S48 -> 2933.9975 | ... N33: =Sheet2!V14+Sheet2!V31+Sheet2!V48 -> 3212.191
B34: PF K2+ | C34: 433 | D34: =Sheet2!L15+Sheet2!L32+Sheet2!L49 -> 432.82 | E34: =Sheet2!M15+Sheet2!M32+Sheet2!M49 -> 427.761 | F34: =Sheet2!N15+Sheet2!N32+Sheet2!N49 -> 459.71622 | G34: =Sheet2!O15+Sheet2!O32+Sheet2!O49 -> 463.77338 | H34: =Sheet2!P15+Sheet2!P32+Sheet2!P49 -> 461.72452 | I34: =Sheet2!Q15+Sheet2!Q32+Sheet2!Q49 -> 429.57002 | J34: =Sheet2!R15+Sheet2!R32+Sheet2!R49 -> 449.57432 | K34: =Sheet2!S15+Sheet2!S32+Sheet2!S49 -> 413.70709 | ... N34: =Sheet2!V15+Sheet2!V32+Sheet2!V49 -> 455.22447
B35: TAB IF | C35: 1516 | D35: =Sheet2!L16+Sheet2!L33+Sheet2!L50 -> 1461.44 | E35: =Sheet2!M16+Sheet2!M33+Sheet2!M50 -> 1435.2512 | F35: =Sheet2!N16+Sheet2!N33+Sheet2!N50 -> 1460.9162 | G35: =Sheet2!O16+Sheet2!O33+Sheet2!O50 -> 1526.362 | H35: =Sheet2!P16+Sheet2!P33+Sheet2!P50 -> 1636.311 | I35: =Sheet2!Q16+Sheet2!Q33+Sheet2!Q50 -> 1784.7421 | J35: =Sheet2!R16+Sheet2!R33+Sheet2!R50 -> 2045.9808 | K35: =Sheet2!S16+Sheet2!S33+Sheet2!S50 -> 1970.2216 | ... N35: =Sheet2!V16+Sheet2!V33+Sheet2!V50 -> 1651.7128
... B38: COMF | C38: 155 | D38: =Sheet2!L19+Sheet2!L36+Sheet2!L53 -> 130.2 | E38: =Sheet2!M19+Sheet2!M36+Sheet2!M53 -> 141.918 | F38: =Sheet2!N19+Sheet2!N36+Sheet2!N53 -> 146.17554 | G38: =Sheet2!O19+Sheet2!O36+Sheet2!O53 -> 150.56081 | H38: =Sheet2!P19+Sheet2!P36+Sheet2!P53 -> 152.81922 | I38: =Sheet2!Q19+Sheet2!Q36+Sheet2!Q53 -> 155.8756 | J38: =Sheet2!R19+Sheet2!R36+Sheet2!R53 -> 157.43436 | K38: =Sheet2!S19+Sheet2!S36+Sheet2!S53 -> 157.43436 | ... N38: =Sheet2!V19+Sheet2!V36+Sheet2!V53 -> 151.21539
B39: Total(CU) | C39: =SUM(C24:C38) -> 60763 | D39: =SUM(D24:D38) -> 64885.71 | E39: =SUM(E24:E38) -> 61057.061 | F39: =SUM(F24:F38) -> 70253.931 | G39: =SUM(G24:G38) -> 71458.937 | H39: =SUM(H24:H38) -> 72650.357 | I39: =SUM(I24:I38) -> 65177.736 | J39: =SUM(J24:J38) -> 72227.375 | ... N39: =SUM(N24:N38) -> 73973.376 | O39: =AVERAGE(C39:N39) -> 68194.208
D40: =(D39-C39)/C39 -> 0.06784902 | E40: =(E39-D39)/D39 -> -0.059006038 | F40: =(F39-E39)/E39 -> 0.15062745 | G40: =(G39-F39)/F39 -> 0.017152157 | H40: =(H39-G39)/G39 -> 0.016672784 | I40: =(I39-H39)/H39 -> -0.10285731 | J40: =(J39-I39)/I39 -> 0.10816022 | K40: =(K39-J39)/J39 -> -0.13981832 | ... N40: =(N39-M39)/M39 -> 0.0206344
B41: TON | C41: =C39*0.8/1000 -> 48.6104 | D41: =D39*0.8/1000 -> 51.908568 | E41: =E39*0.8/1000 -> 48.845649 | F41: =F39*0.8/1000 -> 56.203145 | G41: =G39*0.8/1000 -> 57.16715 | H41: =H39*0.8/1000 -> 58.120285 | I41: =I39*0.8/1000 -> 52.142189 | J41: =J39*0.8/1000 -> 57.7819 | ... N41: =N39*0.8/1000 -> 59.178701
B42: Stock-in
B43: Production | C43: Oct | D43: Nov | E43: Dec | F43: Jan | G43: Feb | H43: Mar | I43: Apr | J43: May | K43: Jun | L43: Jul | M43: Aug | N43: Sep
B44: Stock-in | C44: Jan | D44: Feb | E44: Mar | F44: Apr | G44: May | H44: Jun | I44: Jul | J44: Aug | K44: Sep | L44: Oct | M44: Nov | N44: Dec | R44: 1750
B45: PN PRE | C45: 1080 | D45: 270 | E45: 540 | F45: 540 | G45: 1080 | H45: 0 | I45: 810 | J45: 0 | K45: 0 | L45: 1080 | M45: 0 | N45: 1080 | P45: SKU | Q45: SP(EURO) | R45: SP(KRW)
...

Sheet Sheet3
E8: PN PRE | F8: 663 | G8: 558.84 | H8: 629.9292 | I8: 617.57062 | J8: 599.4035 | K8: 587.65543 | L8: 553.1161 | M8: 542.29378 | N8: 515.77909 | O8: 530.89246 | P8: 541.27031 | Q8: 551.85572
E9: PN 1 | F9: 1465 | G9: 1302.06 | H9: 1390.4202 | I9: 1498.477 | J9: 1470.3675 | K9: 1429.0464 | L9: 1321.6046 | M9: 1362.7785 | N9: 1194.4985 | O9: 1364.0483 | P9: 1414.8903 | Q9: 1454.547
E10: PN VP 1 | F10: 805 | G10: 805 | H10: 805 | I10: 805 | J10: 805 | K10: 805 | L10: 805 | M10: 805 | N10: 805 | O10: 805 | P10: 805 | Q10: 805
E11: TAB IF | F11: 1516 | G11: 1461.44 | H11: 1435.2512 | I11: 1460.9162 | J11: 1526.362 | K11: 1636.311 | L11: 1784.7421 | M11: 2045.9808 | N11: 1970.2216 | O11: 2024.7682 | P11: 1856.2191 | Q11: 1651.7128
E12: PN 2 | F12: 1545 | G12: 1544.6 | H12: 1569.552 | I12: 1638.9286 | J12: 1654.5078 | K12: 1638.7728 | L12: 1583.6173 | M12: 1577.085 | N12: 1493.2416 | O12: 1574.6912 | P12: 1619.502 | Q12: 1665.657
E13: PN VP 2 | F13: 587 | G13: 587 | H13: 587 | I13: 587 | J13: 587 | K13: 587 | L13: 587 | M13: 587 | N13: 587 | O13: 587 | P13: 587 | Q13: 587
E14: TAB FO | F14: 1975 | G14: 1920.13 | H14: 1884.6474 | I14: 1936.8068 | J14: 2044.2552 | K14: 2196.1156 | L14: 2401.1272 | M14: 2716.845 | N14: 2588.3028 | O14: 2417.3416 | P14: 2212.9208 | Q14: 1964.8903
E15: PN 3 | F15: 601 | G15: 536.54 | H15: 614.7826 | I15: 635.79651 | J15: 629.73855 | K15: 623.74116 | L15: 593.86634 | M15: 594.41035 | N15: 531.25752 | O15: 559.64267 | P15: 564.9391 | Q15: 575.63788
E16: PF PRE | F16: 10774.809 | G16: 11200.129 | H16: 10659.539 | I16: 11762.841 | J16: 11867.661 | K16: 12079.398 | L16: 10957.441 | M16: 11545.948 | N16: 10439.994 | O16: 11536.709 | P16: 11844.386 | Q16: 12266.929
E17: PF 1 | F17: 19342.043 | G17: 21042.443 | H17: 19697.613 | I17: 23026.148 | J17: 23441.15 | K17: 24076.103 | L17: 21486.102 | M17: 24281.024 | N17: 19706.476 | O17: 23231.386 | P17: 23650.493 | Q17: 24291.726
E18: PF 2 | F18: 17303.147 | G18: 19680.057 | H18: 17597.353 | I18: 21425.157 | J18: 21945.087 | K18: 22123.597 | L18: 18888.713 | M18: 21407.828 | N18: 18194.417 | O18: 21896.073 | P18: 22608.15 | Q18: 23348.711
E19: PF K1+ | F19: 3009 | G19: 3101.34 | H19: 3036.1002 | I19: 3244.3022 | J19: 3259.1437 | K19: 3229.3123 | L19: 3020.246 | M19: 3112.3611 | N19: 2933.9975 | O19: 3140.1575 | P19: 3168.799 | Q19: 3212.191
... E22: COMF | F22: 155 | G22: 130.2 | H22: 141.918 | I22: 146.17554 | J22: 150.56081 | K22: 152.81922 | L22: 155.8756 | M22: 157.43436 | N22: 157.43436 | O22: 155.86002 | P22: 154.30141 | Q22: 151.21539

Sheet Sheet2
K3: 상시
C4: 일 매출 | D4: 월 예상 | E4: 예상 CRM | F4: 1월예상 | H4: 예상 외부채널 | K4: Jan | L4: Feb | M4: Mar | N4: Apr | O4: May | P4: Jun | Q4: Jul | R4: Aug | S4: Sep | T4: Oct | U4: Nov | V4: Dec
B5: PN PRE | C5: 21 | D5: =C5*31 -> 651 | E5: 12 | F5: =D5+E5 -> 663 | H5: 0 | K5: 651 | L5: =Sheet1!C3 -> 546.84 | M5: =Sheet1!D3 -> 617.9292 | N5: =Sheet1!E3 -> 605.57062 | O5: =Sheet1!F3 -> 587.4035 | P5: =Sheet1!G3 -> 575.65543 | Q5: =Sheet1!H3 -> 541.1161 | R5: =Sheet1!I3 -> 530.29378 | S5: =Sheet1!J3 -> 503.77909 | ... V5: =Sheet1!M3 -> 539.85572
B6: PN 1 | C6: 46 | D6: =C6*31 -> 1426 | E6: 39 | F6: =D6+E6 -> 1465 | H6: 54 | K6: 1426 | L6: =Sheet1!C5 -> 1155.06 | M6: =Sheet1!D5 -> 1351.4202 | N6: =Sheet1!E5 -> 1405.477 | O6: =Sheet1!F5 -> 1377.3675 | P6: =Sheet1!G5 -> 1336.0464 | Q6: =Sheet1!H5 -> 1282.6046 | R6: =Sheet1!I5 -> 1269.7785 | S6: =Sheet1!J5 -> 1155.4985 | ... V6: =Sheet1!M5 -> 1361.547
B7: PN 2 | C7: 48 | D7: =C7*31 -> 1488 | E7: 57 | F7: =D7+E7 -> 1545 | H7: 24 | K7: 1488 | L7: =Sheet1!C7 -> 1413.6 | M7: =Sheet1!D7 -> 1512.552 | N7: =Sheet1!E7 -> 1557.9286 | O7: =Sheet1!F7 -> 1573.5078 | P7: =Sheet1!G7 -> 1557.7728 | Q7: =Sheet1!H7 -> 1526.6173 | R7: =Sheet1!I7 -> 1496.085 | S7: =Sheet1!J7 -> 1436.2416 | ... V7: =Sheet1!M7 -> 1584.657 | X7: 2218005000
B8: PN 3 | C8: 19 | D8: =C8*31 -> 589 | E8: 12 | F8: =D8+E8 -> 601 | H8: 18 | K8: 589 | L8: =Sheet1!C9 -> 506.54 | M8: =Sheet1!D9 -> 602.7826 | N8: =Sheet1!E9 -> 605.79651 | O8: =Sheet1!F9 -> 599.73855 | P8: =Sheet1!G9 -> 593.74116 | Q8: =Sheet1!H9 -> 581.86634 | R8: =Sheet1!I9 -> 564.41035 | S8: =Sheet1!J9 -> 519.25752 | ... V8: =Sheet1!M9 -> 545.63788 | X8: =X7*10% -> 221800500
B9: PN VP 1 | C9: 23 | D9: =C9*31 -> 713 | E9: 92 | F9: =D9+E9 -> 805 | H9: 0 | K9: 713 | L9: =Sheet1!C11 -> 713 | M9: =Sheet1!D11 -> 713 | N9: =Sheet1!E11 -> 713 | O9: =Sheet1!F11 -> 713 | P9: =Sheet1!G11 -> 713 | Q9: =Sheet1!H11 -> 713 | R9: =Sheet1!I11 -> 713 | S9: =Sheet1!J11 -> 713 | ... V9: =Sheet1!M11 -> 713
B10: PN VP 2 | C10: 17 | D10: =C10*31 -> 527 | E10: 60 | F10: =D10+E10 -> 587 | H10: 0 | K10: 527 | L10: =Sheet1!C13 -> 527 | M10: =Sheet1!D13 -> 527 | N10: =Sheet1!E13 -> 527 | O10: =Sheet1!F13 -> 527 | P10: =Sheet1!G13 -> 527 | Q10: =Sheet1!H13 -> 527 | R10: =Sheet1!I13 -> 527 | S10: =Sheet1!J13 -> 527 | ... V10: =Sheet1!M13 -> 527
B11: PF PRE | C11: 332 | D11: =C11*31 -> 10292 | E11: 482.80936 | F11: =D11+E11 -> 10774.809 | H11: 798 | K11: 10292 | L11: =Sheet1!C15 -> 9880.32 | M11: =Sheet1!D15 -> 10176.73 | N11: =Sheet1!E15 -> 10482.031 | O11: =Sheet1!F15 -> 10586.852 | P11: =Sheet1!G15 -> 10798.589 | Q11: =Sheet1!H15 -> 10474.631 | R11: =Sheet1!I15 -> 10265.139 | S11: =Sheet1!J15 -> 9957.1844 | ... V11: =Sheet1!M15 -> 10986.12
B12: PF 1 | C12: 620 | D12: =C12*31 -> 19220 | E12: 122.04348 | F12: =D12+E12 -> 19342.043 | H12: 2154 | K12: 19220 | L12: =Sheet1!C17 -> 18643.4 | M12: =Sheet1!D17 -> 19575.57 | N12: =Sheet1!E17 -> 20750.104 | O12: =Sheet1!F17 -> 21165.106 | P12: =Sheet1!G17 -> 21800.059 | Q12: =Sheet1!H17 -> 21364.058 | R12: =Sheet1!I17 -> 22004.98 | S12: =Sheet1!J17 -> 19584.432 | ... V12: =Sheet1!M17 -> 22015.683
B13: PF 2 | C13: 513 | D13: =C13*31 -> 15903 | E13: 1400.1472 | F13: =D13+E13 -> 17303.147 | H13: 2694 | K13: 15903 | L13: =Sheet1!C19 -> 15425.91 | M13: =Sheet1!D19 -> 16197.206 | N13: =Sheet1!E19 -> 17331.01 | O13: =Sheet1!F19 -> 17850.94 | P13: =Sheet1!G19 -> 18029.45 | Q13: =Sheet1!H19 -> 17488.566 | R13: =Sheet1!I19 -> 17313.68 | S13: =Sheet1!J19 -> 16794.27 | ... V13: =Sheet1!M19 -> 19254.563
B14: PF K1+ | C14: 93 | D14: =C14*31 -> 2883 | E14: 126 | F14: =D14+E14 -> 3009 | H14: 150 | K14: 2883 | L14: =Sheet1!C21 -> 2825.34 | M14: =Sheet1!D21 -> 2910.1002 | N14: =Sheet1!E21 -> 2968.3022 | O14: =Sheet1!F21 -> 2983.1437 | P14: =Sheet1!G21 -> 2953.3123 | Q14: =Sheet1!H21 -> 2894.246 | R14: =Sheet1!I21 -> 2836.3611 | S14: =Sheet1!J21 -> 2807.9975 | ... V14: =Sheet1!M21 -> 2936.191
B15: PF K2+ | C15: 13 | D15: =C15*31 -> 403 | E15: 30 | F15: =D15+E15 -> 433 | H15: 24 | K15: 403 | L15: =Sheet1!C23 -> 378.82 | M15: =Sheet1!D23 -> 397.761 | N15: =Sheet1!E23 -> 405.71622 | O15: =Sheet1!F23 -> 409.77338 | P15: =Sheet1!G23 -> 407.72452 | Q15: =Sheet1!H23 -> 399.57002 | R15: =Sheet1!I23 -> 395.57432 | S15: =Sheet1!J23 -> 383.70709 | ... V15: =Sheet1!M23 -> 401.22447
B16: TAB IF | C16: 44 | D16: =C16*31 -> 1364 | E16: 152 | F16: =D16+E16 -> 1516 | H16: 0 | K16: 1364 | L16: =Sheet1!C25 -> 1309.44 | M16: =Sheet1!D25 -> 1283.2512 | N16: =Sheet1!E25 -> 1308.9162 | O16: =Sheet1!F25 -> 1374.362 | P16: =Sheet1!G25 -> 1484.311 | Q16: =Sheet1!H25 -> 1632.7421 | R16: =Sheet1!I25 -> 1893.9808 | S16: =Sheet1!J25 -> 1818.2216 | ... V16: =Sheet1!M25 -> 1499.7128
B17: TAB FO | C17: 59 | D17: =C17*31 -> 1829 | E17: 146 | F17: =D17+E17 -> 1975 | H17: 0 | K17: 1829 | L17: =Sheet1!C27 -> 1774.13 | M17: =Sheet1!D27 -> 1738.6474 | N17: =Sheet1!E27 -> 1790.8068 | O17: =Sheet1!F27 -> 1898.2552 | P17: =Sheet1!G27 -> 2050.1156 | Q17: =Sheet1!H27 -> 2255.1272 | R17: =Sheet1!I27 -> 2570.845 | S17: =Sheet1!J27 -> 2442.3028 | ... V17: =Sheet1!M27 -> 1818.8903
B18: AR | C18: 19 | D18: =C18*31 -> 589 | E18: 0 | F18: =D18+E18 -> 589 | H18: 0 | K18: 589 | L18: =Sheet1!C29 -> 583.11 | M18: =Sheet1!D29 -> 580.19445 | N18: =Sheet1!E29 -> 583.09542 | O18: =Sheet1!F29 -> 588.92638 | P18: =Sheet1!G29 -> 597.76027 | Q18: =Sheet1!H29 -> 609.71548 | R18: =Sheet1!I29 -> 615.81263 | S18: =Sheet1!J29 -> 597.33825 | ... V18: =Sheet1!M29 -> 565.0784
B19: COMF | C19: 5 | D19: =C19*31 -> 155 | E19: 0 | F19: =D19+E19 -> 155 | H19: 0 | K19: 155 | L19: =Sheet1!C31 -> 130.2 | M19: =Sheet1!D31 -> 141.918 | N19: =Sheet1!E31 -> 146.17554 | O19: =Sheet1!F31 -> 150.56081 | P19: =Sheet1!G31 -> 152.81922 | Q19: =Sheet1!H31 -> 155.8756 | R19: =Sheet1!I31 -> 157.43436 | S19: =Sheet1!J31 -> 157.43436 | ... V19: =Sheet1!M31 -> 151.21539
D20: =SUM(D5:D19) -> 58032 | F20: =SUM(F5:F19) -> 60763 | H20: =SUM(H5:H19) -> 5916 | K20: CRM | L20: =SUM(L5:L19) -> 55812.71 | M20: =SUM(M5:M19) -> 58326.061 | N20: =SUM(N5:N19) -> 61180.931 | O20: =SUM(O5:O19) -> 62385.937 | P20: =SUM(P5:P19) -> 63577.357 | Q20: =SUM(Q5:Q19) -> 62446.736 | R20: =SUM(R5:R19) -> 63154.375 | S20: =SUM(S5:S19) -> 59397.665 | ... V20: =SUM(V5:V19) -> 64900.376
K21: Jan | L21: Feb | M21: Mar | N21: Apr | O21: May | P21: Jun | Q21: Jul | R21: Aug | S21: Sep | T21: Oct | U21: Nov | V21: Dec
K22: 12 | L22: 12 | M22: 12 | N22: 12 | O22: 12 | P22: 12 | Q22: 12 | R22: 12 | S22: 12 | T22: 12 | U22: 12 | V22: 12
K23: 39 | L23: 39 | M23: 39 | N23: 39 | O23: 39 | P23: 39 | Q23: 39 | R23: 39 | S23: 39 | T23: 39 | U23: 39 | V23: 39
K24: 57 | L24: 57 | M24: 57 | N24: 57 | O24: 57 | P24: 57 | Q24: 57 | R24: 57 | S24: 57 | T24: 57 | U24: 57 | V24: 57
K25: 12 | L25: 12 | M25: 12 | N25: 12 | O25: 12 | P25: 12 | Q25: 12 | R25: 12 | S25: 12 | T25: 12 | U25: 12 | V25: 12
K26: 92 | L26: 92 | M26: 92 | N26: 92 | O26: 92 | P26: 92 | Q26: 92 | R26: 92 | S26: 92 | T26: 92 | U26: 92 | V26: 92
K27: 60 | L27: 60 | M27: 60 | N27: 60 | O27: 60 | P27: 60 | Q27: 60 | R27: 60 | S27: 60 | T27: 60 | U27: 60 | V27: 60
K28: 482.80936 | L28: 482.80936 | M28: 482.80936 | N28: 482.80936 | O28: 482.80936 | P28: 482.80936 | Q28: 482.80936 | R28: 482.80936 | S28: 482.80936 | T28: 482.80936 | U28: 482.80936 | V28: 482.80936
K29: 122.04348 | L29: 122.04348 | M29: 122.04348 | N29: 122.04348 | O29: 122.04348 | P29: 122.04348 | Q29: 122.04348 | R29: 122.04348 | S29: 122.04348 | T29: 122.04348 | U29: 122.04348 | V29: 122.04348
K30: 1400.1472 | L30: 1400.1472 | M30: 1400.1472 | N30: 1400.1472 | O30: 1400.1472 | P30: 1400.1472 | Q30: 1400.1472 | R30: 1400.1472 | S30: 1400.1472 | T30: 1400.1472 | U30: 1400.1472 | V30: 1400.1472
K31: 126 | L31: 126 | M31: 126 | N31: 126 | O31: 126 | P31: 126 | Q31: 126 | R31: 126 | S31: 126 | T31: 126 | U31: 126 | V31: 126
K32: 30 | L32: 30 | M32: 30 | N32: 30 | O32: 30 | P32: 30 | Q32: 30 | R32: 30 | S32: 30 | T32: 30 | U32: 30 | V32: 30
K33: 152 | L33: 152 | M33: 152 | N33: 152 | O33: 152 | P33: 152 | Q33: 152 | R33: 152 | S33: 152 | T33: 152 | U33: 152 | V33: 152
... K36: 0 | L36: 0 | M36: 0 | N36: 0 | O36: 0 | P36: 0 | Q36: 0 | R36: 0 | S36: 0 | T36: 0 | U36: 0 | V36: 0
K37: 타채널 | L37: (매출 3억기준)
K38: Jan | L38: Feb | M38: Mar | N38: Apr | O38: May | P38: Jun | Q38: Jul | R38: Aug | S38: Sep | T38: Oct | U38: Nov | V38: Dec
L39: 0 | N39: 0 | O39: 0 | P39: 0 | R39: 0 | T39: 0 | U39: 0 | V39: 0
L40: 108 | N40: 108 | O40: 108 | P40: 108 | R40: 108 | T40: 108 | U40: 108 | V40: 108
L41: 74 | N41: 74 | O41: 74 | P41: 74 | R41: 74 | T41: 74 | U41: 74 | V41: 74
L42: 18 | N42: 18 | O42: 18 | P42: 18 | R42: 18 | T42: 18 | U42: 18 | V42: 18
L43: 0 | N43: 0 | O43: 0 | P43: 0 | R43: 0 | T43: 0 | U43: 0 | V43: 0
L44: 0 | N44: 0 | O44: 0 | P44: 0 | R44: 0 | T44: 0 | U44: 0 | V44: 0
...

Sheet Sheet1
B1: 상시
B2: Jan | C2: Feb | D2: Mar | E2: Apr | F2: May | G2: Jun | H2: Jul | I2: Aug | J2: Sep | K2: Oct | L2: Nov | M2: Dec
A3: PN PRE | B3: 651 | C3: =B3+B3*C4 -> 546.84 | D3: =C3+C3*D4 -> 617.9292 | E3: =D3+D3*E4 -> 605.57062 | F3: =E3+E3*F4 -> 587.4035 | G3: =F3+F3*G4 -> 575.65543 | H3: =G3+G3*H4 -> 541.1161 | I3: =H3+H3*I4 -> 530.29378 | J3: =I3+I3*J4 -> 503.77909 | ... M3: =L3+L3*M4 -> 539.85572
C4: -0.16 | D4: 0.13 | E4: -0.02 | F4: -0.03 | G4: -0.02 | H4: -0.06 | I4: -0.02 | J4: -0.05 | K4: 0.03 | L4: 0.02 | M4: 0.02
A5: PN 1 | B5: 1426 | C5: =B5+B5*C6 -> 1155.06 | D5: =C5+C5*D6 -> 1351.4202 | E5: =D5+D5*E6 -> 1405.477 | F5: =E5+E5*F6 -> 1377.3675 | G5: =F5+F5*G6 -> 1336.0464 | H5: =G5+G5*H6 -> 1282.6046 | I5: =H5+H5*I6 -> 1269.7785 | J5: =I5+I5*J6 -> 1155.4985 | ... M5: =L5+L5*M6 -> 1361.547
C6: -0.19 | D6: 0.17 | E6: 0.04 | F6: -0.02 | G6: -0.03 | H6: -0.04 | I6: -0.01 | J6: -0.09 | K6: 0.1 | L6: 0.04 | M6: 0.03
A7: PN 2 | B7: 1488 | C7: =B7+B7*C8 -> 1413.6 | D7: =C7+C7*D8 -> 1512.552 | E7: =D7+D7*E8 -> 1557.9286 | F7: =E7+E7*F8 -> 1573.5078 | G7: =F7+F7*G8 -> 1557.7728 | H7: =G7+G7*H8 -> 1526.6173 | I7: =H7+H7*I8 -> 1496.085 | J7: =I7+I7*J8 -> 1436.2416 | ... M7: =L7+L7*M8 -> 1584.657
C8: -0.05 | D8: 0.07 | E8: 0.03 | F8: 0.01 | G8: -0.01 | H8: -0.02 | I8: -0.02 | J8: -0.04 | K8: 0.04 | L8: 0.03 | M8: 0.03
A9: PN 3 | B9: 589 | C9: =B9+B9*C10 -> 506.54 | D9: =C9+C9*D10 -> 602.7826 | E9: =D9+D9*E10 -> 605.79651 | F9: =E9+E9*F10 -> 599.73855 | G9: =F9+F9*G10 -> 593.74116 | H9: =G9+G9*H10 -> 581.86634 | I9: =H9+H9*I10 -> 564.41035 | J9: =I9+I9*J10 -> 519.25752 | ... M9: =L9+L9*M10 -> 545.63788
C10: -0.14 | D10: 0.19 | E10: 0.005 | F10: -0.01 | G10: -0.01 | H10: -0.02 | I10: -0.03 | J10: -0.08 | K10: 0.02 | L10: 0.01 | M10: 0.02
A11: PN VP 1 | B11: 713 | C11: =B11+B11*C12 -> 713 | D11: =C11+C11*D12 -> 713 | E11: =D11+D11*E12 -> 713 | F11: =E11+E11*F12 -> 713 | G11: =F11+F11*G12 -> 713 | H11: =G11+G11*H12 -> 713 | I11: =H11+H11*I12 -> 713 | J11: =I11+I11*J12 -> 713 | ... M11: =L11+L11*M12 -> 713
A13: PN VP 2 | B13: 527 | C13: =B13+B13*C14 -> 527 | D13: =C13+C13*D14 -> 527 | E13: =D13+D13*E14 -> 527 | F13: =E13+E13*F14 -> 527 | G13: =F13+F13*G14 -> 527 | H13: =G13+G13*H14 -> 527 | I13: =H13+H13*I14 -> 527 | J13: =I13+I13*J14 -> 527 | ... M13: =L13+L13*M14 -> 527
A15: PF PRE | B15: 10292 | C15: =B15+B15*C16 -> 9880.32 | D15: =C15+C15*D16 -> 10176.73 | E15: =D15+D15*E16 -> 10482.031 | F15: =E15+E15*F16 -> 10586.852 | G15: =F15+F15*G16 -> 10798.589 | H15: =G15+G15*H16 -> 10474.631 | I15: =H15+H15*I16 -> 10265.139 | J15: =I15+I15*J16 -> 9957.1844 | ... M15: =L15+L15*M16 -> 10986.12
C16: -0.04 | D16: 0.03 | E16: 0.03 | F16: 0.01 | G16: 0.02 | H16: -0.03 | I16: -0.02 | J16: -0.03 | K16: 0.03 | L16: 0.03 | M16: 0.04
A17: PF 1 | B17: 19220 | C17: =B17+B17*C18 -> 18643.4 | D17: =C17+C17*D18 -> 19575.57 | E17: =D17+D17*E18 -> 20750.104 | F17: =E17+E17*F18 -> 21165.106 | G17: =F17+F17*G18 -> 21800.059 | H17: =G17+G17*H18 -> 21364.058 | I17: =H17+H17*I18 -> 22004.98 | J17: =I17+I17*J18 -> 19584.432 | ... M17: =L17+L17*M18 -> 22015.683
C18: -0.03 | D18: 0.05 | E18: 0.06 | F18: 0.02 | G18: 0.03 | H18: -0.02 | I18: 0.03 | J18: -0.11 | K18: 0.07 | L18: 0.02 | M18: 0.03
A19: PF 2 | B19: 15903 | C19: =B19+B19*C20 -> 15425.91 | D19: =C19+C19*D20 -> 16197.206 | E19: =D19+D19*E20 -> 17331.01 | F19: =E19+E19*F20 -> 17850.94 | G19: =F19+F19*G20 -> 18029.45 | H19: =G19+G19*H20 -> 17488.566 | I19: =H19+H19*I20 -> 17313.68 | J19: =I19+I19*J20 -> 16794.27 | ... M19: =L19+L19*M20 -> 19254.563
C20: -0.03 | D20: 0.05 | E20: 0.07 | F20: 0.03 | G20: 0.01 | H20: -0.03 | I20: -0.01 | J20: -0.03 | K20: 0.06 | L20: 0.04 | M20: 0.04
A21: PF K1+ | B21: 2883 | C21: =B21+B21*C22 -> 2825.34 | D21: =C21+C21*D22 -> 2910.1002 | E21: =D21+D21*E22 -> 2968.3022 | F21: =E21+E21*F22 -> 2983.1437 | G21: =F21+F21*G22 -> 2953.3123 | H21: =G21+G21*H22 -> 2894.246 | I21: =H21+H21*I22 -> 2836.3611 | J21: =I21+I21*J22 -> 2807.9975 | ... M21: =L21+L21*M22 -> 2936.191
C22: -0.02 | D22: 0.03 | E22: 0.02 | F22: 0.005 | G22: -0.01 | H22: -0.02 | I22: -0.02 | J22: -0.01 | K22: 0.02 | L22: 0.01 | M22: 0.015
A23: PF K2+ | B23: 403 | C23: =B23+B23*C24 -> 378.82 | D23: =C23+C23*D24 -> 397.761 | E23: =D23+D23*E24 -> 405.71622 | F23: =E23+E23*F24 -> 409.77338 | G23: =F23+F23*G24 -> 407.72452 | H23: =G23+G23*H24 -> 399.57002 | I23: =H23+H23*I24 -> 395.57432 | J23: =I23+I23*J24 -> 383.70709 | ... M23: =L23+L23*M24 -> 401.22447
C24: -0.06 | D24: 0.05 | E24: 0.02 | F24: 0.01 | G24: -0.005 | H24: -0.02 | I24: -0.01 | J24: -0.03 | K24: 0.01 | L24: 0.015 | M24: 0.02
A25: TAB IF | B25: 1364 | C25: =B25+B25*C26 -> 1309.44 | D25: =C25+C25*D26 -> 1283.2512 | E25: =D25+D25*E26 -> 1308.9162 | F25: =E25+E25*F26 -> 1374.362 | G25: =F25+F25*G26 -> 1484.311 | H25: =G25+G25*H26 -> 1632.7421 | I25: =H25+H25*I26 -> 1893.9808 | J25: =I25+I25*J26 -> 1818.2216 | ... M25: =L25+L25*M26 -> 1499.7128
C26: -0.04 | D26: -0.02 | E26: 0.02 | F26: 0.05 | G26: 0.08 | H26: 0.1 | I26: 0.16 | J26: -0.04 | K26: 0.03 | L26: -0.09 | M26: -0.12
A27: TAB FO | B27: 1829 | C27: =B27+B27*C28 -> 1774.13 | D27: =C27+C27*D28 -> 1738.6474 | E27: =D27+D27*E28 -> 1790.8068 | F27: =E27+E27*F28 -> 1898.2552 | G27: =F27+F27*G28 -> 2050.1156 | H27: =G27+G27*H28 -> 2255.1272 | I27: =H27+H27*I28 -> 2570.845 | J27: =I27+I27*J28 -> 2442.3028 | ... M27: =L27+L27*M28 -> 1818.8903
C28: -0.03 | D28: -0.02 | E28: 0.03 | F28: 0.06 | G28: 0.08 | H28: 0.1 | I28: 0.14 | J28: -0.05 | K28: -0.07 | L28: -0.09 | M28: -0.12
A29: AR | B29: 589 | C29: =B29+B29*C30 -> 583.11 | D29: =C29+C29*D30 -> 580.19445 | E29: =D29+D29*E30 -> 583.09542 | F29: =E29+E29*F30 -> 588.92638 | G29: =F29+F29*G30 -> 597.76027 | H29: =G29+G29*H30 -> 609.71548 | I29: =H29+H29*I30 -> 615.81263 | J29: =I29+I29*J30 -> 597.33825 | ... M29: =L29+L29*M30 -> 565.0784
C30: -0.01 | D30: -0.005 | E30: 0.005 | F30: 0.01 | G30: 0.015 | H30: 0.02 | I30: 0.01 | J30: -0.03 | K30: -0.02 | L30: -0.015 | M30: -0.02
A31: COMF | B31: 155 | C31: =B31+B31*C32 -> 130.2 | D31: =C31+C31*D32 -> 141.918 | E31: =D31+D31*E32 -> 146.17554 | F31: =E31+E31*F32 -> 150.56081 | G31: =F31+F31*G32 -> 152.81922 | H31: =G31+G31*H32 -> 155.8756 | I31: =H31+H31*I32 -> 157.43436 | J31: =I31+I31*J32 -> 157.43436 | ... M31: =L31+L31*M32 -> 151.21539
C32: -0.16 | D32: 0.09 | E32: 0.03 | F32: 0.03 | G32: 0.015 | H32: 0.02 | I32: 0.01 | J32: 0 | K32: -0.01 | L32: -0.01 | M32: -0.02

Sheet  original
B1: 상시
B2: Jan | C2: Feb | D2: Mar | E2: Apr | F2: May | G2: Jun | H2: Jul | I2: Aug | J2: Sep | K2: Oct | L2: Nov | M2: Dec
A3: PN PRE | B3: 651 | C3: =B3+B3*C4 -> 670.53 | D3: =C3+C3*D4 -> 677.2353 | E3: =D3+D3*E4 -> 663.69059 | F3: =E3+E3*F4 -> 643.77988 | G3: =F3+F3*G4 -> 630.90428 | H3: =G3+G3*H4 -> 599.35906 | I3: =H3+H3*I4 -> 575.3847 | J3: =I3+I3*J4 -> 558.12316 | ... M3: =L3+L3*M4 -> 586.47805
C4: 0.03 | D4: 0.01 | E4: -0.02 | F4: -0.03 | G4: -0.02 | H4: -0.05 | I4: -0.04 | J4: -0.03 | K4: 0.01 | L4: 0.02 | M4: 0.02
A5: PN 1 | B5: 1426 | C5: =B5+B5*C6 -> 1468.78 | D5: =C5+C5*D6 -> 1498.1556 | E5: =D5+D5*E6 -> 1513.1372 | F5: =E5+E5*F6 -> 1482.8744 | G5: =F5+F5*G6 -> 1423.5594 | H5: =G5+G5*H6 -> 1352.3815 | I5: =H5+H5*I6 -> 1325.3338 | J5: =I5+I5*J6 -> 1338.5872 | ... M5: =L5+L5*M6 -> 1462.5725
C6: 0.03 | D6: 0.02 | E6: 0.01 | F6: -0.02 | G6: -0.04 | H6: -0.05 | I6: -0.02 | J6: 0.01 | K6: 0.02 | L6: 0.03 | M6: 0.04
A7: PN 2 | B7: 1488 | C7: =B7+B7*C8 -> 1532.64 | D7: =C7+C7*D8 -> 1563.2928 | E7: =D7+D7*E8 -> 1594.5587 | F7: =E7+E7*F8 -> 1610.5042 | G7: =F7+F7*G8 -> 1594.3992 | H7: =G7+G7*H8 -> 1562.5112 | I7: =H7+H7*I8 -> 1531.261 | J7: =I7+I7*J8 -> 1515.9484 | ... M7: =L7+L7*M8 -> 1624.5085
C8: 0.03 | D8: 0.02 | E8: 0.02 | F8: 0.01 | G8: -0.01 | H8: -0.02 | I8: -0.02 | J8: -0.01 | K8: 0.02 | L8: 0.02 | M8: 0.03
A9: PN 3 | B9: 589 | C9: =B9+B9*C10 -> 594.89 | D9: =C9+C9*D10 -> 603.81335 | E9: =D9+D9*E10 -> 606.83242 | F9: =E9+E9*F10 -> 600.76409 | G9: =F9+F9*G10 -> 594.75645 | H9: =G9+G9*H10 -> 582.86132 | I9: =H9+H9*I10 -> 565.37548 | J9: =I9+I9*J10 -> 559.72173 | ... M9: =L9+L9*M10 -> 573.7422
C10: 0.01 | D10: 0.015 | E10: 0.005 | F10: -0.01 | G10: -0.01 | H10: -0.02 | I10: -0.03 | J10: -0.01 | K10: -0.005 | L10: 0.01 | M10: 0.02
A11: PN VP 1 | B11: 713 | C11: =B11+B11*C12 -> 713 | D11: =C11+C11*D12 -> 713 | E11: =D11+D11*E12 -> 713 | F11: =E11+E11*F12 -> 713 | G11: =F11+F11*G12 -> 713 | H11: =G11+G11*H12 -> 713 | I11: =H11+H11*I12 -> 713 | J11: =I11+I11*J12 -> 713 | ... M11: =L11+L11*M12 -> 713
A13: PN VP 2 | B13: 527 | C13: =B13+B13*C14 -> 527 | D13: =C13+C13*D14 -> 527 | E13: =D13+D13*E14 -> 527 | F13: =E13+E13*F14 -> 527 | G13: =F13+F13*G14 -> 527 | H13: =G13+G13*H14 -> 527 | I13: =H13+H13*I14 -> 527 | J13: =I13+I13*J14 -> 527 | ... M13: =L13+L13*M14 -> 527
A15: PF PRE | B15: 10292 | C15: =B15+B15*C16 -> 10497.84 | D15: =C15+C15*D16 -> 10655.308 | E15: =D15+D15*E16 -> 10761.861 | F15: =E15+E15*F16 -> 10815.67 | G15: =F15+F15*G16 -> 10707.513 | H15: =G15+G15*H16 -> 10493.363 | I15: =H15+H15*I16 -> 10283.496 | J15: =I15+I15*J16 -> 10180.661 | ... M15: =L15+L15*M16 -> 11016.676
C16: 0.02 | D16: 0.015 | E16: 0.01 | F16: 0.005 | G16: -0.01 | H16: -0.02 | I16: -0.02 | J16: -0.01 | K16: 0.02 | L16: 0.03 | M16: 0.03
A17: PF 1 | B17: 19220 | C17: =B17+B17*C18 -> 19988.8 | D17: =C17+C17*D18 -> 20988.24 | E17: =D17+D17*E18 -> 21827.77 | F17: =E17+E17*F18 -> 22264.325 | G17: =F17+F17*G18 -> 22709.611 | H17: =G17+G17*H18 -> 22482.515 | I17: =H17+H17*I18 -> 21808.04 | J17: =I17+I17*J18 -> 21589.96 | ... M17: =L17+L17*M18 -> 23136.06
C18: 0.04 | D18: 0.05 | E18: 0.04 | F18: 0.02 | G18: 0.02 | H18: -0.01 | I18: -0.03 | J18: -0.01 | K18: 0.02 | L18: 0.02 | M18: 0.03
A19: PF 2 | B19: 15903 | C19: =B19+B19*C20 -> 16857.18 | D19: =C19+C19*D20 -> 17700.039 | E19: =D19+D19*E20 -> 18054.04 | F19: =E19+E19*F20 -> 18234.58 | G19: =F19+F19*G20 -> 18052.234 | H19: =G19+G19*H20 -> 17510.667 | I19: =H19+H19*I20 -> 17160.454 | J19: =I19+I19*J20 -> 16817.245 | ... M19: =L19+L19*M20 -> 19466.297
C20: 0.06 | D20: 0.05 | E20: 0.02 | F20: 0.01 | G20: -0.01 | H20: -0.03 | I20: -0.02 | J20: -0.02 | K20: 0.04 | L20: 0.05 | M20: 0.06
A21: PF K1+ | B21: 2883 | C21: =B21+B21*C22 -> 2911.83 | D21: =C21+C21*D22 -> 2970.0666 | E21: =D21+D21*E22 -> 2999.7673 | F21: =E21+E21*F22 -> 3014.7661 | G21: =F21+F21*G22 -> 2984.6184 | H21: =G21+G21*H22 -> 2924.9261 | I21: =H21+H21*I22 -> 2866.4276 | J21: =I21+I21*J22 -> 2880.7597 | ... M21: =L21+L21*M22 -> 3012.275
C22: 0.01 | D22: 0.02 | E22: 0.01 | F22: 0.005 | G22: -0.01 | H22: -0.02 | I22: -0.02 | J22: 0.005 | K22: 0.01 | L22: 0.02 | M22: 0.015
A23: PF K2+ | B23: 403 | C23: =B23+B23*C24 -> 407.03 | D23: =C23+C23*D24 -> 411.1003 | E23: =D23+D23*E24 -> 413.1558 | F23: =E23+E23*F24 -> 417.28736 | G23: =F23+F23*G24 -> 415.20092 | H23: =G23+G23*H24 -> 406.8969 | I23: =H23+H23*I24 -> 394.69 | J23: =I23+I23*J24 -> 396.66345 | ... M23: =L23+L23*M24 -> 414.77232
C24: 0.01 | D24: 0.01 | E24: 0.005 | F24: 0.01 | G24: -0.005 | H24: -0.02 | I24: -0.03 | J24: 0.005 | K24: 0.01 | L24: 0.015 | M24: 0.02
A25: TAB IF | B25: 1364 | C25: =B25+B25*C26 -> 1336.72 | D25: =C25+C25*D26 -> 1309.9856 | E25: =D25+D25*E26 -> 1323.0855 | F25: =E25+E25*F26 -> 1389.2397 | G25: =F25+F25*G26 -> 1500.3789 | H25: =G25+G25*H26 -> 1650.4168 | I25: =H25+H25*I26 -> 1897.9793 | J25: =I25+I25*J26 -> 1992.8783 | ... M25: =L25+L25*M26 -> 1452.0908
C26: -0.02 | D26: -0.02 | E26: 0.01 | F26: 0.05 | G26: 0.08 | H26: 0.1 | I26: 0.15 | J26: 0.05 | K26: -0.08 | L26: -0.1 | M26: -0.12
A27: TAB FO | B27: 1829 | C27: =B27+B27*C28 -> 1792.42 | D27: =C27+C27*D28 -> 1756.5716 | E27: =D27+D27*E28 -> 1774.1373 | F27: =E27+E27*F28 -> 1862.8442 | G27: =F27+F27*G28 -> 2011.8717 | H27: =G27+G27*H28 -> 2213.0589 | I27: =H27+H27*I28 -> 2545.0177 | J27: =I27+I27*J28 -> 2672.2686 | ... M27: =L27+L27*M28 -> 1947.1218
C28: -0.02 | D28: -0.02 | E28: 0.01 | F28: 0.05 | G28: 0.08 | H28: 0.1 | I28: 0.15 | J28: 0.05 | K28: -0.08 | L28: -0.1 | M28: -0.12
A29: AR | B29: 589 | C29: =B29+B29*C30 -> 583.11 | D29: =C29+C29*D30 -> 580.19445 | E29: =D29+D29*E30 -> 583.09542 | F29: =E29+E29*F30 -> 588.92638 | G29: =F29+F29*G30 -> 597.76027 | H29: =G29+G29*H30 -> 609.71548 | I29: =H29+H29*I30 -> 615.81263 | J29: =I29+I29*J30 -> 621.97076 | ... M29: =L29+L29*M30 -> 594.38449
C30: -0.01 | D30: -0.005 | E30: 0.005 | F30: 0.01 | G30: 0.015 | H30: 0.02 | I30: 0.01 | J30: 0.01 | K30: -0.01 | L30: -0.015 | M30: -0.02
A31: COMF | B31: 155 | C31: =B31+B31*C32 -> 153.45 | D31: =C31+C31*D32 -> 152.68275 | E31: =D31+D31*E32 -> 153.44616 | F31: =E31+E31*F32 -> 154.98063 | G31: =F31+F31*G32 -> 157.30533 | H31: =G31+G31*H32 -> 160.45144 | I31: =H31+H31*I32 -> 162.05596 | J31: =I31+I31*J32 -> 163.67652 | ... M31: =L31+L31*M32 -> 156.41697
C32: -0.01 | D32: -0.005 | E32: 0.005 | F32: 0.01 | G32: 0.015 | H32: 0.02 | I32: 0.01 | J32: 0.01 | K32: -0.01 | L32: -0.015 | M32: -0.02
