Workbook
Name Report1.Header: 'Lookup info'!$A$4:$B$4
Name Report1.Range: 'Lookup info'!$A$5:$B$45
Name Report2.Header: 'Lookup info'!$E$4:$H$4
Name Report2.Range: 'Lookup info'!$E$5:$H$20
Name Report3.Header: 'Lookup info'!#REF!
Name Report3.Range: 'Lookup info'!#REF!
Name Report4.Header: 'Lookup info'!#REF!
Name Report4.Range: 'Lookup info'!#REF!

Sheet Order
A1: EIBE - South Korea
A2: Initials | B2: FS
A3: Debtor number | B3: 72851
A4: Pre-payment customer | B4: No
A5: PO/SO fulfillment date | B5: 29
A6: PO/SO fulfillment Month | B6: 5
A7: PO/SO fulfillment Year | B7: 2026
A8: Order Proposal | B8: May
A9: Order / PF number | B9: W/H/05/2026
A10: Loading | B10: Palletized
A11: Size / Type | B11: 40FT
A12: Transport | B12: Sea
A13: Combined with | B13: no
A14: Planned utilization | B14: 1 | P14: =22-14 -> 8
A15: Target utilization | B15: 1
A18: CORPORATE CODE | B18: PRODUCT DESCRIPTION | C18: Grams | D18: Supply Point | E18: WAREHOUSE CODE | F18: Supply Point disc. Letter | G18: Tu's per pallet | H18: SUGGESTED ORDER QUANTITY IN PALLETS | I18: SUGGESTED ORDER QUANTITY IN TU | J18: CONFIRMED ORDER QUANTITY IN PALLETS | K18: CONFIRMED ORDER QUANTITY IN TU | L18: Comments: | M18: Cus | N18: MOQ
A19: 676366 | B19: APTAMIL 1 KOR 4X800G | C19: 800 | D19: Wexford | E19: =VLOOKUP($D19,'Lookup info'!$D:$H,2,FALSE) -> 0023 | F19: =VLOOKUP($D19,'Lookup info'!$D:$H,5,FALSE) -> W | G19: 144 | I19: =H19*G19 -> 0 | J19: =IF(G19="","",K19/G19) -> 0 | M19: =K19*24 -> 0 | N19: 1500 TU | O19: If ordered below MOQ - leftover has to be ordered next cycle
A20: 676367 | B20: APTAMIL 2 KOR 4X800G | C20: 800 | D20: Wexford | E20: =VLOOKUP($D20,'Lookup info'!$D:$H,2,FALSE) -> 0023 | F20: =VLOOKUP($D20,'Lookup info'!$D:$H,5,FALSE) -> W | G20: 144 | I20: =H20*G20 -> 0 | J20: =IF(G20="","",K20/G20) -> 12 | K20: 1728 | M20: =K20*24 -> 41472 | N20: 1500 TU | O20: If ordered below MOQ - leftover has to be ordered next cycle
A21: 676369 | B21: APTAMIL 3 KOR 4X800G | C21: 800 | D21: Wexford | E21: =VLOOKUP($D21,'Lookup info'!$D:$H,2,FALSE) -> 0023 | F21: =VLOOKUP($D21,'Lookup info'!$D:$H,5,FALSE) -> W | G21: 144 | I21: =H21*G21 -> 0 | J21: =IF(G21="","",K21/G21) -> 10 | K21: 1440 | M21: =K21*24 -> 34560 | N21: 1500 TU | O21: If ordered below MOQ - leftover has to be ordered next cycle
A22: 677211 | B22: APTAMIL PROFUTURA 1 4X800G KOR | C22: 800 | D22: Haps | E22: =VLOOKUP($D22,'Lookup info'!$D:$H,2,FALSE) -> 0002 | F22: =VLOOKUP($D22,'Lookup info'!$D:$H,5,FALSE) -> C | G22: 96 | I22: =H22*G22 -> 0 | J22: =IF(G22="","",K22/G22) -> 24 | K22: 2304 | M22: =K22*7 -> 16128 | N22: 1413 TU | O22: If ordered below MOQ - leftover has to be ordered next cycle
A23: 677200 | B23: APTAMIL PROFUTURA 2 4X800G KOR | C23: 800 | D23: Haps | E23: =VLOOKUP($D23,'Lookup info'!$D:$H,2,FALSE) -> 0002 | F23: =VLOOKUP($D23,'Lookup info'!$D:$H,5,FALSE) -> C | G23: 96 | I23: =H23*G23 -> 0 | J23: =IF(G23="","",K23/G23) -> 0 | K23: 0 | M23: =K23*7 -> 0 | N23: 1520 TU | O23: If ordered below MOQ - leftover has to be ordered next cycle
A24: 677281 | B24: APTAMIL PROFUTURA 3 4X800G KOR | C24: 800 | D24: Haps | E24: =VLOOKUP($D24,'Lookup info'!$D:$H,2,FALSE) -> 0002 | F24: =VLOOKUP($D24,'Lookup info'!$D:$H,5,FALSE) -> C | G24: 96 | I24: =H24*G24 -> 0 | J24: =IF(G24="","",K24/G24) -> 6.5833333 | K24: 632 | M24: =K24*7 -> 4424 | N24: 1253 TU | O24: If ordered below MOQ - leftover has to be ordered next cycle
A25: 702466 | B25: FORTIFIT VANILLA 12X280G A | C25: 280 | D25: Fulda | E25: =VLOOKUP($D25,'Lookup info'!$D:$H,2,FALSE) -> 0120 | F25: =VLOOKUP($D25,'Lookup info'!$D:$H,5,FALSE) -> F | G25: 72 | I25: =H25*G25 -> 0 | J25: =IF(G25="","",K25/G25) -> 0 | N25: 12000 CU | O25: Already confirmed
A26: 552897 | B26: ELEMENTAL 028 EXTRA ORANGE 10X100G | C26: 100 | D26: Liverpool | E26: 0091 | F26: L | G26: 245 | I26: =H26*G26 -> 0 | J26: =IF(G26="","",K26/G26) -> 0 | M26: =K26*24 -> 0 | N26: 1500 TU | O26: If ordered below MOQ - leftover has to be ordered next cycle
A27: 701775 | B27: NEOCATE LCP UPGRADE3 6X400G UK IE | C27: 400 | D27: Liverpool | E27: 0091 | F27: L | G27: 108 | I27: =H27*G27 -> 0 | J27: =IF(G27="","",K27/G27) -> 6 | K27: 648 | M27: =K27*24 -> 15552 | O27: Already confirmed
A28: 691217 | B28: NUTRICIA LORENZO'S OIL 12X500ML GB/DE | C28: 500 | D28: Medical Logistics (3PS) | E28: 0991 | F28: 3P | G28: 78 | I28: =H28*G28 -> 0 | J28: =IF(G28="","",K28/G28) -> 0.051282051 | K28: 4 | M28: =K28*24 -> 96 | O28: Already confirmed
A29: 117771 | B29: PK AID 4 3X500G UK | C29: 500 | D29: Liverpool | E29: 0091 | F29: L | G29: 200 | I29: =H29*G29 -> 0 | J29: =IF(G29="","",K29/G29) -> 0 | M29: =K29*7 -> 0 | O29: Already confirmed
A30: 611174 | B30: INFATRINI 12X400G KOR | C30: 400 | D30: Fulda | E30: 0120 | F30: F | G30: 72 | I30: =H30*G30 -> 0 | J30: =IF(G30="","",K30/G30) -> 14 | K30: 1008 | M30: =K30*7 -> 7056 | N30: 1008 TU | O30: Already confirmed
A31: 117547 | B31: SS DUOCAL 6X400G MULTI | C31: 400 | D31: Liverpool | E31: 0091 | F31: L | G31: 108 | I31: =H31*G31 -> 0 | J31: =IF(G31="","",K31/G31) -> 0.37037037 | K31: 40 | M31: =K31*7 -> 280 | O31: Already confirmed
A32: 646546 | B32: TYR ANAMIX INF+MET 3X400G MLL1 | C32: 400 | D32: Liverpool | E32: 0091 | F32: L | G32: 225 | I32: =H32*G32 -> 0 | J32: =IF(G32="","",K32/G32) -> 0 | M32: =K32*4 -> 0 | O32: Already confirmed
A33: 646567 | B33: NKH ANAMIX INFANT 3X400G MLL1 | C33: 400 | D33: Liverpool | E33: 0091 | F33: L | G33: 225 | I33: =H33*G33 -> 0 | J33: =IF(G33="","",K33/G33) -> 0 | M33: =K33*7 -> 0 | O33: Already confirmed
A34: 116180 | B34: MSUD Maxamum 3x500g | C34: 500 | D34: Liverpool | E34: 0091 | F34: L | G34: 200 | I34: =H34*G34 -> 0 | J34: =IF(G34="","",K34/G34) -> 0 | M34: =K34*5 -> 0 | O34: Already confirmed
A35: 552896 | B35: ELEMENTAL 028 EXTRA/100GX10 Unflavored | C35: 100 | D35: Liverpool | E35: 0091 | F35: L | G35: 245 | I35: =H35*G35 -> 0 | J35: =IF(G35="","",K35/G35) -> 0 | M35: =K35*4 -> 0 | N35: 1500 TU | O35: Already confirmed
A36: 578785 | B36: ELEMENTAL 028 EXTRA BANANA 10X100G UK | C36: 100 | D36: Liverpool | E36: 0091 | F36: L | G36: 245 | I36: =H36*G36 -> 0 | J36: =IF(G36="","",K36/G36) -> 1.3510204 | K36: 331 | M36: =K36*4 -> 1324 | N36: 331 TU | O36: Already confirmed
A37: 589462 | B37: GA 1 Anamix Junior 6x400g | C37: 400 | D37: Liverpool | E37: 0091 | F37: L | G37: 108 | I37: =H37*G37 -> 0 | J37: =IF(G37="","",K37/G37) -> 0 | M37: =K37*4 -> 0 | O37: Already confirmed
A38: 589466 | B38: MSUD Anamix Junior 6x400g | C38: 400 | D38: Liverpool | E38: 0091 | F38: L | G38: 108 | I38: =H38*G38 -> 0 | J38: =IF(G38="","",K38/G38) -> 0 | M38: =K38*4 -> 0 | O38: Already confirmed
A39: 646548 | B39: GA 1 Anamix Infant 3x400g | C39: 400 | D39: Liverpool | E39: 0091 | F39: L | G39: 225 | I39: =H39*G39 -> 0 | J39: =IF(G39="","",K39/G39) -> 0 | M39: =K39*4 -> 0 | O39: Already confirmed
A40: 699883 | B40: Basic-F 6x300g | C40: 300 | D40: Fulda | E40: 0120 | F40: F | G40: 144 | I40: =H40*G40 -> 0 | J40: =IF(G40="","",K40/G40) -> 0 | O40: Already confirmed
A41: 695413 | B41: Locasol 6x400g | C41: 400 | D41: Fulda | E41: 0120 | F41: F | G41: 132 | I41: =H41*G41 -> 0 | J41: =IF(G41="","",K41/G41) -> 0 | M41: =K41*7 -> 0 | O41: Already confirmed
A42: 645380 | B42: APTAMIL PEPTI SYNEO 1, DE 12X400G | C42: 400 | D42: Haps | E42: 0002 | F42: C | G42: 72 | I42: =H42*G42 -> 0 | J42: =IF(G42="","",K42/G42) -> 2.0833333 | K42: 150 | M42: =K42*5 -> 750 | O42: Already confirmed
...

Sheet Sheet1
B3: Jun. | C3: July. | D3: Aug. | E3: Sep. | F3: Oct. | G3: Nov. | H3: Dec. | I3: Jan. | J3: Feb.
B4: 309 | C4: 315 | D4: 318 | E4: 324 | F4: 334 | G4: 347 | H4: 365 | I4: 390 | J4: 406
B5: 1369 | C5: 1355 | D5: 1328 | E5: 1368 | F5: 1436 | G5: 1537 | H5: 1675 | I5: 1842 | J5: 1953
B6: 423 | C6: 435 | D6: 422 | E6: 405 | F6: 426 | G6: 456 | H6: 501 | I6: 576 | J6: 628
B7: 1247 | C7: 298 | D7: 192 | E7: 209 | F7: 276 | G7: 169 | H7: 125 | I7: 173 | J7: 333
B8: 779 | C8: 794 | D8: 723 | E8: 687 | F8: 639 | G8: 658 | H8: 691 | I8: 725 | J8: 754
B9: 401 | C9: 413 | D9: 417 | E9: 355 | F9: 319 | G9: 351 | H9: 393 | I9: 452 | J9: 475
B10: 1150 | C10: 396 | D10: 330 | E10: 488 | F10: 564 | G10: 296 | H10: 137 | I10: 105 | J10: 123
B11: 377 | C11: 339 | D11: 322 | E11: 319 | F11: 329 | G11: 342 | H11: 362 | I11: 388 | J11: 407
B12: 6544 | C12: 5889 | D12: 6007 | E12: 6187 | F12: 6435 | G12: 6756 | H12: 7094 | I12: 7520 | J12: 7821
B13: 13691 | C13: 13144 | D13: 12749 | E13: 13004 | F13: 13395 | G13: 13930 | H13: 14906 | I13: 16098 | J13: 16742
B14: 11583 | C14: 10425 | D14: 10320 | E14: 10527 | F14: 10843 | G14: 11493 | H14: 11953 | I14: 12670 | J14: 13304
B15: 1565 | C15: 1486 | D15: 1442 | E15: 1485 | F15: 1515 | G15: 1560 | H15: 1669 | I15: 1803 | J15: 1839
... B18: 203 | C18: 195 | D18: 201 | E18: 203 | F18: 207 | G18: 211 | H18: 218 | I18: 222 | J18: 229
B20: =B4 -> 309 | C20: =C4*1.05 -> 330.75 | D20: =D4*1.05 -> 333.9 | E20: =E4*1.05 -> 340.2 | F20: =F4*1.05 -> 350.7 | G20: =G4*1.05 -> 364.35 | H20: =H4*1.05 -> 383.25 | I20: =I4*1.05 -> 409.5 | J20: =J4*1.05 -> 426.3
B21: =B5 -> 1369 | C21: =C5*1.05 -> 1422.75 | D21: =D5*1.05 -> 1394.4 | E21: =E5*1.05 -> 1436.4 | F21: =F5*1.05 -> 1507.8 | G21: =G5*1.05 -> 1613.85 | H21: =H5*1.05 -> 1758.75 | I21: =I5*1.05 -> 1934.1 | J21: =J5*1.05 -> 2050.65
B22: =B6 -> 423 | C22: =C6*1.05 -> 456.75 | D22: =D6*1.05 -> 443.1 | E22: =E6*1.05 -> 425.25 | F22: =F6*1.05 -> 447.3 | G22: =G6*1.05 -> 478.8 | H22: =H6*1.05 -> 526.05 | I22: =I6*1.05 -> 604.8 | J22: =J6*1.05 -> 659.4
B23: =B7 -> 1247 | C23: =C7*1.05 -> 312.9 | D23: =D7*1.05 -> 201.6 | E23: =E7*1.05 -> 219.45 | F23: =F7*1.05 -> 289.8 | G23: =G7*1.05 -> 177.45 | H23: =H7*1.05 -> 131.25 | I23: =I7*1.05 -> 181.65 | J23: =J7*1.05 -> 349.65
B24: =B8 -> 779 | C24: =C8*1.05 -> 833.7 | D24: =D8*1.05 -> 759.15 | E24: =E8*1.05 -> 721.35 | F24: =F8*1.05 -> 670.95 | G24: =G8*1.05 -> 690.9 | H24: =H8*1.05 -> 725.55 | I24: =I8*1.05 -> 761.25 | J24: =J8*1.05 -> 791.7
B25: =B9 -> 401 | C25: =C9*1.05 -> 433.65 | D25: =D9*1.05 -> 437.85 | E25: =E9*1.05 -> 372.75 | F25: =F9*1.05 -> 334.95 | G25: =G9*1.05 -> 368.55 | H25: =H9*1.05 -> 412.65 | I25: =I9*1.05 -> 474.6 | J25: =J9*1.05 -> 498.75
B26: =B10 -> 1150 | C26: =C10*1.05 -> 415.8 | D26: =D10*1.05 -> 346.5 | E26: =E10*1.05 -> 512.4 | F26: =F10*1.05 -> 592.2 | G26: =G10*1.05 -> 310.8 | H26: =H10*1.05 -> 143.85 | I26: =I10*1.05 -> 110.25 | J26: =J10*1.05 -> 129.15
B27: =B11 -> 377 | C27: =C11*1.05 -> 355.95 | D27: =D11*1.05 -> 338.1 | E27: =E11*1.05 -> 334.95 | F27: =F11*1.05 -> 345.45 | G27: =G11*1.05 -> 359.1 | H27: =H11*1.05 -> 380.1 | I27: =I11*1.05 -> 407.4 | J27: =J11*1.05 -> 427.35
B28: =B12 -> 6544 | C28: =C12*1.05 -> 6183.45 | D28: =D12*1.05 -> 6307.35 | E28: =E12*1.05 -> 6496.35 | F28: =F12*1.05 -> 6756.75 | G28: =G12*1.05 -> 7093.8 | H28: =H12*1.05 -> 7448.7 | I28: =I12*1.05 -> 7896 | J28: =J12*1.05 -> 8212.05
B29: =B13 -> 13691 | C29: =C13*1.05 -> 13801.2 | D29: =D13*1.05 -> 13386.45 | E29: =E13*1.05 -> 13654.2 | F29: =F13*1.05 -> 14064.75 | G29: =G13*1.05 -> 14626.5 | H29: =H13*1.05 -> 15651.3 | I29: =I13*1.05 -> 16902.9 | J29: =J13*1.05 -> 17579.1
B30: =B14 -> 11583 | C30: =C14*1.05 -> 10946.25 | D30: =D14*1.05 -> 10836 | E30: =E14*1.05 -> 11053.35 | F30: =F14*1.05 -> 11385.15 | G30: =G14*1.05 -> 12067.65 | H30: =H14*1.05 -> 12550.65 | I30: =I14*1.05 -> 13303.5 | J30: =J14*1.05 -> 13969.2
B31: =B15 -> 1565 | C31: =C15*1.05 -> 1560.3 | D31: =D15*1.05 -> 1514.1 | E31: =E15*1.05 -> 1559.25 | F31: =F15*1.05 -> 1590.75 | G31: =G15*1.05 -> 1638 | H31: =H15*1.05 -> 1752.45 | I31: =I15*1.05 -> 1893.15 | J31: =J15*1.05 -> 1930.95
... B34: =B18 -> 203 | C34: =C18*1.05 -> 204.75 | D34: =D18*1.05 -> 211.05 | E34: =E18*1.05 -> 213.15 | F34: =F18*1.05 -> 217.35 | G34: =G18*1.05 -> 221.55 | H34: =H18*1.05 -> 228.9 | I34: =I18*1.05 -> 233.1 | J34: =J18*1.05 -> 240.45

Sheet Lookup info
A1: Note, these schedules are downloads from exact, don't change them manually
A3: Initials | D3: Warehouse information
A4: Selection code | B4: Description (1) | D4: Planner name | E4: Warehouse code | F4: Name | G4: Address line 2 | H4: Address line 3
A5: AA | B5: ANNA ALEKSANDROVA | D5: =IF(G5="","",G5) -> Zoetermeer | E5: 0001 | F5: NV NUTRICIA | G5: Zoetermeer | H5: Z
A6: AG | B6: AGUSTINA GABIOUD | D6: =IF(G6="","",G6) -> Haps | E6: 0002 | F6: NUTRICIA CUIJK B.V. | G6: Haps | H6: C
A7: AP | B7: ANTON PRYKHODKO | D7: =IF(G7="","",G7) -> Wexford | E7: 0023 | F7: NUTRICIA INFANT NUTRITION LTD | G7: Wexford | H7: W
A8: BA | B8: BALKAN COUNTRIES | D8: =IF(G8="","",G8) -> PTNIS | E8: 0057 | F8: P.T. NUTRICIA INDONESIA | G8: PTNIS | H8: P
A9: BC | B9: BARBARA CANGA RICARTE | D9: =IF(G9="","",G9) -> Opole | E9: 0074 | F9: NUTRICIA POLSKA | G9: Opole | H9: O
A10: BK | B10: BOTAKUZI AKEERBIEKE | D10: =IF(G10="","",G10) -> Istra | E10: 0089 | F10: NUTRICIA LLC | G10: Istra | H10: I
A11: BM | B11: Bob Minion | D11: =IF(G11="","",G11) -> Liverpool | E11: 0091 | F11: SHS INTERNATIONAL LTD | G11: Liverpool | H11: L
A12: CA | B12: CAROLINA ROTGERS | D12: =IF(G12="","",G12) -> Fulda | E12: 0120 | F12: MILUPA GMBH & CO | G12: Fulda | H12: F
A13: CN | B13: CAROLINE NAUTA | D13: =IF(G13="","",G13) -> Kasdorf | E13: 0146 | F13: KASDORF S.A. | G13: Kasdorf | H13: K
A14: DN | B14: DINA NURMAGAMBETOVA | D14: =IF(G14="","",G14) -> Wuxi (Nutricia Pharmaceutical) | E14: 0190 | F14: Nutricia Pharmaceutical (Wuxi) | G14: Wuxi (Nutricia Pharmaceutical) | H14: WX
A15: EN | B15: ELINA NIKOLOVA | D15: =IF(G15="","",G15) -> Steenvoorde | E15: 0510 | F15: BLEDINA - STEENVOORDE | G15: Steenvoorde | H15: S
A16: EP | B16: EVELIEN PARDOEN | D16: =IF(G16="","",G16) -> Villefranche | E16: 0518 | F16: BLEDINA - VILLEFRANCHE | G16: Villefranche | H16: V
... A20: IO | B20: ITSASO ORTIGOSA ARRAIAGO | D20: =IF(G20="","",G20) -> Wuxi | E20: 0994 | F20: WUXI | G20: Wuxi | H20: WX
A21: IS | B21: IRINA STRIZHEVSKA | D21: =IF(G21="","",G21)
A22: JC | B22: JULIJA CARJOVA | D22: =IF(G22="","",G22)
A23: JE | B23: JANAIKA ELDERS | D23: =IF(G23="","",G23)
A24: JK | B24: JANA KAUMANN | D24: =IF(G24="","",G24)
A25: JN | B25: JACK NIAMA | D25: =IF(G25="","",G25)
A26: KP | B26: KATERINA PALMOU | D26: =IF(G26="","",G26)
A27: KS | B27: KSENIA SANINOVA | D27: =IF(G27="","",G27)
A28: LB | B28: LUBA BISCHOT | D28: =IF(G28="","",G28)
A29: MB | B29: MARCELLA BUERGER | D29: =IF(G29="","",G29)
A30: ME | B30: MIRJAM EKDOM | D30: =IF(G30="","",G30)
A31: MJ | B31: MIRIAM JIMENEZ RUBIA | D31: =IF(G31="","",G31)
A32: MM | B32: MAXIM MURASHKOV | D32: =IF(G32="","",G32)
... A40: TB | B40: TAL VAN DE BERG | D40: =IF(G40="","",G40)
A41: TK | B41: TATIANA KARAZHAKOVA
A42: VG | B42: VALENTINA GURINOVICH
A43: VS | B43: VIVIANE STORM
A44: XX | B44: NOT USED
A45: YC | B45: YARELI CONTRERAS
A46: FS | B46: FABIANA DE SANCTIS
A47: OD | B47: OLENA DIDKIVSKA
