Workbook

Sheet 아이베
B2: *판매량
B3: Sales | E3: Jun. | F3: July | G3: Aug. | H3: Sep. | I3: Oct. | J3: Nov. | K3: Dec. | L3: Jan. | M3: Feb. | N3: Mar. | O3: Apr. | P3: May. | Q3: Jun.
C4: PN | D4: 1 | E4: 8839 | F4: 7757 | G4: 7424 | H4: 7808 | I4: 8086 | J4: 8259 | K4: 8672 | L4: 8456.762 | M4: 8246.8662 | N4: 8217.6289 | O4: 8153.031 | P4: 8311.102 | Q4: 8571.5585
D5: 2 | E5: 9769 | F5: 9878 | G5: 9386 | H5: 9667 | I5: 9859 | J5: 9958 | K5: 10256 | L5: 9917.5116 | M5: 9590.1947 | N5: 9362.7272 | O5: 9013.9181 | P5: 8354.3424 | Q5: 7639.4043
D6: 3 | E6: 3523 | F6: 3014 | G6: 2883 | H6: 3034 | I6: 3142 | J6: 3210 | K6: 3370 | L6: 3318.5943 | M6: 3267.9728 | N6: 3406.3503 | O6: 3156.0839 | P6: 3245.5062 | Q6: 3174.5713
C7: PF | D7: 1 | E7: 11979 | F7: 11038 | G7: 10485 | H7: 11214 | I7: 11923 | J7: 12932 | K7: 13756 | L7: 13868.882 | M7: 13982.69 | N7: 13960.097 | O7: 13480.645 | P7: 13189.489 | Q7: 13481.268
D8: 2 | E8: 11355 | F8: 10680 | G8: 10790 | H8: 11327 | I8: 12042 | J8: 13061 | K8: 13895 | L8: 14208.725 | M8: 14529.534 | N8: 14654.245 | O8: 15371.97 | P8: 15490.756 | Q8: 16328.389
D9: 3 | E9: 3866 | F9: 3458 | G9: 3354 | H9: 3588 | I9: 3814 | J9: 4139 | K9: 4402 | L9: 4385.0558 | M9: 4368.1769 | N9: 4728.9702 | O9: 4123.7782 | P9: 4157.2794 | Q9: 4078.7792
C10: Total | E10: =SUM(E4:E9) -> 49331 | F10: =SUM(F4:F9) -> 45825 | G10: =SUM(G4:G9) -> 44322 | H10: =SUM(H4:H9) -> 46638 | I10: =SUM(I4:I9) -> 48866 | J10: =SUM(J4:J9) -> 51559 | K10: =SUM(K4:K9) -> 54351 | L10: =SUM(L4:L9) -> 54155.531 | ... Q10: =SUM(Q4:Q9) -> 53273.97
B12: *재고
B13: Stock(CU) | E13: Jun. | F13: July | G13: Aug. | H13: Sep. | I13: Oct. | J13: Nov. | K13: Dec. | L13: Jan. | M13: Feb. | N13: Mar. | O13: Apr. | P13: May. | Q13: Jun.
C14: PN | D14: 1 | E14: 63467 | F14: =E14+F36-F4 -> 55710 | G14: =F14+G36-G4 -> 48286 | H14: =G14+H36-H4 -> 40478 | I14: =H14+I36-I4 -> 35272 | J14: =I14+J36-J4 -> 27013 | K14: =J14+K36-K4 -> 18341 | L14: =K14+L36-L4 -> 25884.238 | M14: =L14+M36-M4 -> 25637.372 | ... Q14: =P14+Q36-Q4 -> 27384.051
D15: 2 | E15: 76603 | F15: =E15+F37-F5 -> 66725 | G15: =F15+G37-G5 -> 57339 | H15: =G15+H37-H5 -> 47672 | I15: =H15+I37-I5 -> 47605 | J15: =I15+J37-J5 -> 37647 | K15: =J15+K37-K5 -> 27391 | L15: =K15+L37-L5 -> 31473.488 | M15: =L15+M37-M5 -> 29883.294 | ... Q15: =P15+Q37-Q5 -> 24512.902
D16: 3 | E16: 31876 | F16: =E16+F38-F6 -> 28862 | G16: =F16+G38-G6 -> 25979 | H16: =G16+H38-H6 -> 22945 | I16: =H16+I38-I6 -> 19803 | J16: =I16+J38-J6 -> 16593 | K16: =J16+K38-K6 -> 13223 | L16: =K16+L38-L6 -> 9904.4057 | M16: =L16+M38-M6 -> 10136.433 | ... Q16: =P16+Q38-Q6 -> 10653.921
C17: PF | D17: 1 | E17: 54162 | F17: =E17+F39-F7 -> 53492 | G17: =F17+G39-G7 -> 44497 | H17: =G17+H39-H7 -> 65151 | I17: =H17+I39-I7 -> 53228 | J17: =I17+J39-J7 -> 40296 | K17: =J17+K39-K7 -> 30380 | L17: =K17+L39-L7 -> 42511.118 | M17: =L17+M39-M7 -> 43528.428 | ... Q17: =P17+Q39-Q7 -> 43416.929
D18: 2 | E18: 47776 | F18: =E18+F40-F8 -> 57064 | G18: =F18+G40-G8 -> 47638 | H18: =G18+H40-H8 -> 53975 | I18: =H18+I40-I8 -> 51149 | J18: =I18+J40-J8 -> 38088 | K18: =J18+K40-K8 -> 29569 | L18: =K18+L40-L8 -> 42360.275 | M18: =L18+M40-M8 -> 43830.74 | ... Q18: =P18+Q40-Q8 -> 53985.38
D19: 3 | E19: 14633 | F19: =E19+F41-F9 -> 20391 | G19: =F19+G41-G9 -> 23777 | H19: =G19+H41-H9 -> 25949 | I19: =H19+I41-I9 -> 22135 | J19: =I19+J41-J9 -> 17996 | K19: =J19+K41-K9 -> 13594 | L19: =K19+L41-L9 -> 14208.944 | M19: =L19+M41-M9 -> 13840.767 | ... Q19: =P19+Q41-Q9 -> 12751.96
C20: Total | E20: =SUM(E14:E19) -> 288517 | F20: =SUM(F14:F19) -> 282244 | G20: =SUM(G14:G19) -> 247516 | H20: =SUM(H14:H19) -> 256170 | I20: =SUM(I14:I19) -> 229192 | J20: =SUM(J14:J19) -> 177633 | K20: =SUM(K14:K19) -> 132498 | L20: =SUM(L14:L19) -> 166342.47 | ... Q20: =SUM(Q14:Q19) -> 172705.14
B22: *발주 | F22: 3Q | I22: 4Q
B23: Supply (arrival) | E23: Jun. | F23: July. | G23: Aug. | H23: Sep. | I23: Oct. | J23: Nov. | K23: Dec.
C24: PN | D24: 1 | F24: 16000 | G24: 8000 | H24: 10000 | I24: 8000 | J24: 9000 | K24: 8000
D25: 2 | F25: 14000 | G25: 8000 | H25: 9000 | I25: 9000 | J25: 6000 | K25: 5000
D26: 3 | G26: 3500 | H26: 3500 | I26: 3000 | J26: 5000 | K26: 2000
C27: PF | D27: 1 | E27: 3840 | F27: 26000 | G27: 15000 | H27: 12000 | I27: 15000 | J27: 12000 | K27: 15000
D28: 2 | E28: 5376 | F28: 27000 | G28: 16000 | H28: 16000 | I28: 19000 | J28: 19000 | K28: 18000
D29: 3 | F29: 5000 | G29: 4000 | H29: 5000 | I29: 5000 | J29: 4000 | K29: 2000
C30: Total | E30: =SUM(E24:E29) -> 9216 | F30: =SUM(F24:F29) -> 88000 | G30: =SUM(G24:G29) -> 54500 | H30: =SUM(H24:H29) -> 55500 | I30: =SUM(I24:I29) -> 59000 | J30: =SUM(J24:J29) -> 55000 | K30: =SUM(K24:K29) -> 50000
C31: 발주 금액(EUR) | E31: =단가!D30 -> 196577.28 | F31: =단가!E30 -> 1711140 | G31: =단가!F30 -> 1054650 | H31: =단가!G30 -> 1059390 | I31: =단가!H30 -> 1147870 | J31: =단가!I30 -> 1062550 | K31: =단가!J30 -> 983550
C32: 발주 금액(KRW) | E32: =단가!D31 -> 2.8636985e+08 | F32: =단가!E31 -> 2.4927545e+09 | G32: =단가!F31 -> 1536393027 | H32: =단가!G31 -> 1.5432982e+09 | I32: =단가!H31 -> 1.6721941e+09 | J32: =단가!I31 -> 1547901589 | K32: =단가!J31 -> 1432815969
B34: 입고량 | K34: Jun. | L34: July. | M34: Aug. | N34: Sep. | O34: Oct. | P34: Nov. | Q34: Dec.
B35: Supply (arrival) | E35: Jun. | F35: July. | G35: Aug. | H35: Sep. | I35: Oct. | J35: Nov. | K35: Dec. | L35: Jan. | M35: Feb. | N35: Mar. | O35: Apr. | P35: May. | Q35: Jun.
C36: PN | D36: 1 | E36: 5776 | I36: 2880 | K36: =E24 -> 0 | L36: =F24 -> 16000 | M36: =G24 -> 8000 | N36: =H24 -> 10000 | O36: =I24 -> 8000 | P36: =J24 -> 9000 | Q36: =K24 -> 8000
D37: 2 | E37: 17012 | I37: 9792 | K37: =E25 -> 0 | L37: =F25 -> 14000 | M37: =G25 -> 8000 | N37: =H25 -> 9000 | O37: =I25 -> 9000 | P37: =J25 -> 6000 | Q37: =K25 -> 5000
D38: 3 | K38: =E26 -> 0 | L38: =F26 -> 0 | M38: =G26 -> 3500 | N38: =H26 -> 3500 | O38: =I26 -> 3000 | P38: =J26 -> 5000 | Q38: =K26 -> 2000
C39: PF | D39: 1 | E39: 36072 | F39: 10368 | G39: 1490 | H39: 31868 | K39: =E27 -> 3840 | L39: =F27 -> 26000 | M39: =G27 -> 15000 | N39: =H27 -> 12000 | O39: =I27 -> 15000 | P39: =J27 -> 12000 | Q39: =K27 -> 15000
D40: 2 | E40: 9508 | F40: 19968 | G40: 1364 | H40: 17664 | I40: 9216 | K40: =E28 -> 5376 | L40: =F28 -> 27000 | M40: =G28 -> 16000 | N40: =H28 -> 16000 | O40: =I28 -> 19000 | P40: =J28 -> 19000 | Q40: =K28 -> 18000
D41: 3 | E41: 3508 | F41: 9216 | G41: 6740 | H41: 5760 | K41: =E29 -> 0 | L41: =F29 -> 5000 | M41: =G29 -> 4000 | N41: =H29 -> 5000 | O41: =I29 -> 5000 | P41: =J29 -> 4000 | Q41: =K29 -> 2000
C42: Total | E42: =SUM(E36:E41) -> 71876 | F42: =SUM(F36:F41) -> 39552 | G42: =SUM(G36:G41) -> 9594 | H42: =SUM(H36:H41) -> 55292 | I42: =SUM(I36:I41) -> 21888 | J42: =SUM(J36:J41) -> 0 | K42: =SUM(K36:K41) -> 9216 | L42: =SUM(L36:L41) -> 88000 | ... Q42: =SUM(Q36:Q41) -> 50000
B44: 재고수준
B45: Stock Level(Month) | E45: Jun. | F45: July. | G45: Aug. | H45: Sep. | I45: Oct. | J45: Nov. | K45: Dec. | L45: Jan. | M45: Feb. | N45: Mar. | O45: Apr. | P45: May. | Q45: Jun.
...

Sheet 내수 판매량
E3: =1-(D5/E5) -> 0.025692996 | F3: =1-(E5/F5) -> 0.055514892 | G3: =1-(F5/G5) -> -0.064808153 | H3: =1-(G5/H5) -> 0.043468288 | I3: =1-(H5/I5) -> -0.13521255 | J3: =1-(I5/J5) -> -0.020935797 | K3: =1-(J5/K5) -> -0.068759767 | L3: =1-(K5/L5) -> -0.046458039 | ... AA3: =1-(Z5/AA5) -> 0.047624539 | AB3: 25년
A4: Sales | D4: 1 | E4: 2 | F4: 3 | G4: 4 | H4: 5 | I4: 6 | J4: 7 | K4: 8 | L4: 9 | M4: 10 | N4: 11 | O4: 12 | P4: 1 | Q4: 2 | R4: 3 | S4: 4 | T4: 5 | U4: Jun. | V4: July | W4: Aug. | X4: Sep. | Y4: Oct. | Z4: Nov. | AA4: Dec. | AB4: Jan. | AC4: Feb. | AD4: Mar. | AE4: Apr. | AF4: May. | AG4: Jun.
B5: PN | C5: 1 | D5: 16344 | E5: 16775 | F5: 17761 | G5: 16680 | H5: 17438 | I5: 15361 | J5: 15046 | K5: 14078 | L5: 13453 | M5: 12241 | N5: 11541 | O5: 11277 | P5: 9919 | Q5: 8492 | R5: 8462 | S5: 8396 | T5: 8562 | U5: 8839 | V5: 7757 | W5: 7424 | X5: 7808 | Y5: 8086 | Z5: 8259 | AA5: 8672 | AB5: =AA5+(AA5*$AB$28) -> 8456.762 | AC5: =AB5+(AB5*$AB28) -> 8246.8662 | AD5: =AC5+(AC5*$R28) -> 8217.6289 | AE5: =AD5+(AD5*$S28) -> 8153.031 | AF5: =AE5+(AE5*$T28) -> 8311.102 | AG5: =AF5+(AF5*$U28) -> 8571.5585
C6: 2 | D6: 16710 | E6: 14642 | F6: 16722 | G6: 17541 | H6: 18678 | I6: 16319 | J6: 17180 | K6: 17680 | L6: 16946 | M6: 15639 | N6: 15066 | O6: 14921 | P6: 13593 | Q6: 12085 | R6: 11805 | S6: 11381 | T6: 10605 | U6: 9769 | V6: 9878 | W6: 9386 | X6: 9667 | Y6: 9859 | Z6: 9958 | AA6: 10256 | AB6: =AA6+(AA6*AB29) -> 9917.5116 | AC6: =AB6+(AB6*$AB29) -> 9590.1947 | AD6: =AC6+(AC6*$R29) -> 9362.7272 | AE6: =AD6+(AD6*$S29) -> 9013.9181 | AF6: =AE6+(AE6*$T29) -> 8354.3424 | AG6: =AF6+(AF6*$U29) -> 7639.4043
C7: 3 | D7: 5210 | E7: 3827 | F7: 4687 | G7: 5118 | H7: 5329 | I7: 4805 | J7: 4741 | K7: 4795 | L7: 4636 | M7: 4295 | N7: 3742 | O7: 3948 | P7: 3902 | Q7: 3596 | R7: 3755 | S7: 3498 | T7: 3600 | U7: 3523 | V7: 3014 | W7: 2883 | X7: 3034 | Y7: 3142 | Z7: 3210 | AA7: 3370 | AB7: =AA7+(AA7*AB30) -> 3318.5943 | AC7: =AB7+(AB7*$AB30) -> 3267.9728 | AD7: =AC7+(AC7*$R30) -> 3406.3503 | AE7: =AD7+(AD7*$S30) -> 3156.0839 | AF7: =AE7+(AE7*$T30) -> 3245.5062 | AG7: =AF7+(AF7*$U30) -> 3174.5713
B8: PF | C8: 1 | D8: 7135 | E8: 9887 | F8: 11444 | G8: 14836 | H8: 13481 | I8: 10800 | J8: 11099 | K8: 11166 | L8: 11517 | M8: 11204 | N8: 11300 | O8: 12277 | P8: 12546 | Q8: 12398 | R8: 12378 | S8: 11967 | T8: 11714 | U8: 11979 | V8: 11038 | W8: 10485 | X8: 11214 | Y8: 11923 | Z8: 12932 | AA8: 13756 | AB8: =AA8+(AA8*AB31) -> 13868.882 | AC8: =AB8+(AB8*$AB31) -> 13982.69 | AD8: =AC8+(AC8*$R31) -> 13960.097 | AE8: =AD8+(AD8*$S31) -> 13480.645 | AF8: =AE8+(AE8*$T31) -> 13189.489 | AG8: =AF8+(AF8*$U31) -> 13481.268
C9: 2 | D9: 5823 | E9: 5716 | F9: 8611 | G9: 18795 | H9: 13523 | I9: 11340 | J9: 11483 | K9: 11747 | L9: 11506 | M9: 10390 | N9: 9877 | O9: 10453 | P9: 10462 | Q9: 10049 | R9: 10136 | S9: 10658 | T9: 10741 | U9: 11355 | V9: 10680 | W9: 10790 | X9: 11327 | Y9: 12042 | Z9: 13061 | AA9: 13895 | AB9: =AA9+(AA9*AB32) -> 14208.725 | AC9: =AB9+(AB9*$AB32) -> 14529.534 | AD9: =AC9+(AC9*$R32) -> 14654.245 | AE9: =AD9+(AD9*$S32) -> 15371.97 | AF9: =AE9+(AE9*$T32) -> 15490.756 | AG9: =AF9+(AF9*$U32) -> 16328.389
C10: 3 | D10: 2191 | E10: 2232 | F10: 2663 | G10: 4315 | H10: 4793 | I10: 4101 | J10: 4422 | K10: 4549 | L10: 4508 | M10: 4265 | N10: 4233 | O10: 4453 | P10: 4541 | Q10: 4043 | R10: 4407 | S10: 3907 | T10: 3939 | U10: 3866 | V10: 3458 | W10: 3354 | X10: 3588 | Y10: 3814 | Z10: 4139 | AA10: 4402 | AB10: =AA10+(AA10*AB33) -> 4385.0558 | AC10: =AB10+(AB10*$AB33) -> 4368.1769 | AD10: =AC10+(AC10*$R33) -> 4728.9702 | AE10: =AD10+(AD10*$S33) -> 4123.7782 | AF10: =AE10+(AE10*$T33) -> 4157.2794 | AG10: =AF10+(AF10*$U33) -> 4078.7792
B11: Total | D11: =SUM(D5:D10) -> 53413 | E11: =SUM(E5:E10) -> 53079 | F11: =SUM(F5:F10) -> 61888 | G11: =SUM(G5:G10) -> 77285 | H11: =SUM(H5:H10) -> 73242 | I11: =SUM(I5:I10) -> 62726 | J11: =SUM(J5:J10) -> 63971 | K11: =SUM(K5:K10) -> 64015 | ... AG11: =SUM(AG5:AG10) -> 53273.97
D13: 1 | E13: 2 | F13: 3 | G13: 4 | H13: 5 | I13: Jun. | J13: July | K13: Aug. | L13: Sep. | M13: Oct. | N13: Nov. | O13: Dec.
D14: 9919 | E14: 8492 | F14: 8462 | G14: 8396 | H14: 8562 | I14: 8839 | J14: 7757 | K14: 7424 | L14: 7808 | M14: 8086 | N14: 8259 | O14: 8672
D15: 13593 | E15: 12085 | F15: 11805 | G15: 11381 | H15: 10605 | I15: 9769 | J15: 9878 | K15: 9386 | L15: 9667 | M15: 9859 | N15: 9958 | O15: 10256
D16: 3902 | E16: 3596 | F16: 3755 | G16: 3498 | H16: 3600 | I16: 3523 | J16: 3014 | K16: 2883 | L16: 3034 | M16: 3142 | N16: 3210 | O16: 3370
D17: 12546 | E17: 12398 | F17: 12378 | G17: 11967 | H17: 11714 | I17: 11979 | J17: 11038 | K17: 10485 | L17: 11214 | M17: 11923 | N17: 12932 | O17: 13756
D18: 10462 | E18: 10049 | F18: 10136 | G18: 10658 | H18: 10741 | I18: 11355 | J18: 10680 | K18: 10790 | L18: 11327 | M18: 12042 | N18: 13061 | O18: 13895
D19: 4541 | E19: 4043 | F19: 4407 | G19: 3907 | H19: 3939 | I19: 3866 | J19: 3458 | K19: 3354 | L19: 3588 | M19: 3814 | N19: 4139 | O19: 4402
I20: =SUM(I14:I19) -> 49331 | J20: =SUM(J14:J19) -> 45825 | K20: =SUM(K14:K19) -> 44322 | L20: =SUM(L14:L19) -> 46638 | M20: =SUM(M14:M19) -> 48866 | N20: =SUM(N14:N19) -> 51559 | O20: =SUM(O14:O19) -> 54351
D23: =1-(D5/D14) -> -0.64774675 | E23: =1-(E5/E14) -> -0.9753886 | F23: =1-(F5/F14) -> -1.0989128 | G23: =1-(G5/G14) -> -0.98666031 | H23: =1-(H5/H14) -> -1.0366737 | I23: =1-(I5/I14) -> -0.73786627 | J23: =1-(J5/J14) -> -0.9396674 | K23: =1-(K5/K14) -> -0.89628233 | ... O23: =1-(O5/O14) -> -0.30039207
B26: *전월 대비 증감 | D26: 23년 | P26: 24년
A27: Sales | D27: 1 | E27: 2 | F27: 3 | G27: 4 | H27: 5 | I27: 6 | J27: 7 | K27: 8 | L27: 9 | M27: 10 | N27: 11 | O27: 12 | P27: 1 | Q27: 2 | R27: 3 | S27: 4 | T27: 5 | U27: Jun. | V27: July | W27: Aug. | X27: Sep. | Y27: Oct. | Z27: Nov. | AA27: Dec. | AB27: 평균
B28: PN | C28: 1 | E28: =1-(D5/E5) -> 0.025692996 | F28: =1-(E5/F5) -> 0.055514892 | G28: =1-(F5/G5) -> -0.064808153 | H28: =1-(G5/H5) -> 0.043468288 | I28: =1-(H5/I5) -> -0.13521255 | J28: =1-(I5/J5) -> -0.020935797 | K28: =1-(J5/K5) -> -0.068759767 | L28: =1-(K5/L5) -> -0.046458039 | ... AA28: =1-(Z5/AA5) -> 0.047624539 | AB28: =AVERAGE(P28:AA28) -> -0.02481988
C29: 2 | E29: =1-(D6/E6) -> -0.14123754 | F29: =1-(E6/F6) -> 0.12438704 | G29: =1-(F6/G6) -> 0.046690611 | H29: =1-(G6/H6) -> 0.060873755 | I29: =1-(H6/I6) -> -0.14455543 | J29: =1-(I6/J6) -> 0.050116414 | K29: =1-(J6/K6) -> 0.028280543 | L29: =1-(K6/L6) -> -0.043314056 | ... AA29: =1-(Z6/AA6) -> 0.029056162 | AB29: =AVERAGE(P29:AA29) -> -0.033003936
C30: 3 | E30: =1-(D7/E7) -> -0.36137967 | F30: =1-(E7/F7) -> 0.18348624 | G30: =1-(F7/G7) -> 0.084212583 | H30: =1-(G7/H7) -> 0.039594671 | I30: =1-(H7/I7) -> -0.10905307 | J30: =1-(I7/J7) -> -0.013499262 | K30: =1-(J7/K7) -> 0.011261731 | L30: =1-(K7/L7) -> -0.034296808 | ... AA30: =1-(Z7/AA7) -> 0.047477745 | AB30: =AVERAGE(P30:AA30) -> -0.015253911
B31: PF | C31: 1 | E31: =1-(D8/E8) -> 0.2783453 | F31: =1-(E8/F8) -> 0.13605383 | G31: =1-(F8/G8) -> 0.22863305 | H31: =1-(G8/H8) -> -0.10051183 | I31: =1-(H8/I8) -> -0.24824074 | J31: =1-(I8/J8) -> 0.026939364 | K31: =1-(J8/K8) -> 0.0060003582 | L31: =1-(K8/L8) -> 0.030476687 | ... AA31: =1-(Z8/AA8) -> 0.059901134 | AB31: =AVERAGE(P31:AA31) -> 0.0082060027
C32: 2 | E32: =1-(D9/E9) -> -0.018719384 | F32: =1-(E9/F9) -> 0.33619789 | G32: =1-(F9/G9) -> 0.54184624 | H32: =1-(G9/H9) -> -0.38985432 | I32: =1-(H9/I9) -> -0.19250441 | J32: =1-(I9/J9) -> 0.012453192 | K32: =1-(J9/K9) -> 0.022473823 | L32: =1-(K9/L9) -> -0.020945594 | ... AA32: =1-(Z9/AA9) -> 0.060021591 | AB32: =AVERAGE(P32:AA32) -> 0.022578296
C33: 3 | E33: =1-(D10/E10) -> 0.018369176 | F33: =1-(E10/F10) -> 0.16184754 | G33: =1-(F10/G10) -> 0.38285052 | H33: =1-(G10/H10) -> 0.099728771 | I33: =1-(H10/I10) -> -0.16873933 | J33: =1-(I10/J10) -> 0.072591588 | K33: =1-(J10/K10) -> 0.027918224 | L33: =1-(K10/L10) -> -0.0090949423 | ... AA33: =1-(Z10/AA10) -> 0.05974557 | AB33: =AVERAGE(P33:AA33) -> -0.0038492011
B34: Total | E34: =1-(D11/E11) -> -0.0062925074 | F34: =1-(E11/F11) -> 0.14233777 | G34: =1-(F11/G11) -> 0.19922365 | H34: =1-(G11/H11) -> -0.055200568 | I34: =1-(H11/I11) -> -0.16764978 | J34: =1-(I11/J11) -> 0.019461944 | K34: =1-(J11/K11) -> 0.0006873389 | L34: =1-(K11/L11) -> -0.023159544 | ... AA34: =1-(Z11/AA11) -> 0.0513698

Sheet Sheet1
B3: MONTH | C3: Domestic | D3: Jikgu
B4: 44927 | C4: 53413 | E4: =SUM(C4:D4) -> 53413
B5: 44958 | C5: 53079 | E5: =SUM(C5:D5) -> 53079
B6: 44986 | C6: 61888 | E6: =SUM(C6:D6) -> 61888
B7: 45017 | C7: 77285 | E7: =SUM(C7:D7) -> 77285
B8: 45047 | C8: 73242 | E8: =SUM(C8:D8) -> 73242
B9: 45078 | C9: 62726 | E9: =SUM(C9:D9) -> 62726
B10: 45108 | C10: 63971 | E10: =SUM(C10:D10) -> 63971
B11: 45139 | C11: 64015 | D11: 590 | E11: =SUM(C11:D11) -> 64605
B12: 45170 | C12: 62566 | D12: 3356 | E12: =SUM(C12:D12) -> 65922
B13: 45200 | C13: 58034 | D13: 4851 | E13: =SUM(C13:D13) -> 62885
B14: 45231 | C14: 55759 | D14: 8822 | E14: =SUM(C14:D14) -> 64581
B15: 45261 | C15: 57329 | D15: 13245 | E15: =SUM(C15:D15) -> 70574
B16: 45292 | C16: 54963 | D16: 16019 | E16: =SUM(C16:D16) -> 70982
B17: 45323 | C17: 50663 | D17: 15665 | E17: =SUM(C17:D17) -> 66328
B18: 45352 | C18: 50943 | D18: 23359 | E18: =SUM(C18:D18) -> 74302
B19: 45383 | C19: 49807 | D19: 26822 | E19: =SUM(C19:D19) -> 76629
B20: 45413 | C20: 49161 | D20: 27580 | E20: =SUM(C20:D20) -> 76741
B21: 45444 | C21: 49331 | D21: 22165 | E21: =SUM(C21:D21) -> 71496
B22: 45474 | C22: 45825 | D22: 26179 | E22: =SUM(C22:D22) -> 72004
... B33: 45809 | C33: 53273.97 | D33: 46684.514 | E33: =SUM(C33:D33) -> 99958.484

Sheet 크로네
B2: *판매량
B3: Sales | E3: Jun. | F3: July | G3: Aug. | H3: Sep. | I3: Oct. | J3: Nov. | K3: Dec. | L3: Jan. | M3: Feb. | N3: Mar. | O3: Apr. | P3: May. | Q3: Jun.
C4: PN | D4: Pre | E4: 711 | F4: 533.9 | G4: 550.05 | H4: 715.2 | I4: 736.16678 | J4: 758.26341 | K4: 776.95711 | L4: 800.26583 | M4: 824.2738 | N4: 849.00202 | O4: 882.9621 | P4: 909.45096 | Q4: 936.73449
D5: 1 | E5: 711 | F5: 587.1 | G5: 589.95 | H5: 752.4 | I5: 764.21162 | J5: 778.34188 | K5: 801.61069 | L5: 825.65901 | M5: 850.42878 | N5: 875.94165 | O5: 910.97931 | P5: 938.30869 | Q5: 966.45795
D6: 2 | E6: 1026 | F6: 1583.65 | G6: 1615.95 | H6: 2082 | I6: 2123.1695 | J6: 2184.8963 | K6: 2247.7543 | L6: 2315.1869 | M6: 2384.6425 | N6: 2503.8746 | O6: 2679.1459 | P6: 2947.0604 | Q6: 3300.7077
D7: 3 | E7: 86 | F7: 88.35 | G7: 91.2 | H7: 118.8 | I7: 122.29412 | J7: 125.78824 | K7: 129.28235 | L7: 133.16082 | M7: 137.15565 | N7: 146.75654 | O7: 161.4322 | P7: 171.11813 | Q7: 179.67404
C8: PF | D8: Pre | E8: 4541 | F8: 4922.9 | G8: 5071.1 | H8: 6597.6 | I8: 6789.831 | J8: 6987.7174 | K8: 7168.5951 | L8: 7383.653 | M8: 7605.1626 | N8: 7833.3175 | O8: 8303.3165 | P8: 8718.4823 | Q8: 8980.0368
D9: 1 | E9: 7701 | F9: 7876.45 | G9: 8113 | H9: 10555.2 | I9: 10862.769 | J9: 11179.386 | K9: 11468.79 | L9: 11812.854 | M9: 12167.239 | N9: 12532.256 | O9: 13284.192 | P9: 13948.401 | Q9: 14366.853
D10: 2 | E10: 6506 | F10: 8354.3 | G10: 8605.1 | H10: 11196 | I10: 11522.21 | J10: 11857.469 | K10: 12165.516 | L10: 12530.482 | M10: 12906.396 | N10: 13293.588 | O10: 13692.396 | P10: 14103.168 | Q10: 14526.263
D11: Kinder | E11: 446 | F11: 466.45 | G11: 513 | H11: 712.8 | I11: 727.056 | J11: 741.59712 | K11: 756.42906 | L11: 771.55764 | M11: 786.9888 | N11: 802.72857 | O11: 818.78314 | P11: 835.15881 | Q11: 851.86198
D12: AR | E12: 317 | F12: 331.55 | G12: 364.8 | H12: 506.4 | I12: 516.528 | J12: 526.85856 | K12: 537.39573 | L12: 548.14365 | M12: 559.10652 | N12: 570.28865 | O12: 581.69442 | P12: 593.32831 | Q12: 605.19488
D13: Comfort | E13: 120 | F13: 125.4 | G13: 137.75 | H13: 192 | I13: 195.84 | J13: 199.7568 | K13: 203.75194 | L13: 207.82697 | M13: 211.98351 | N13: 216.22318 | O13: 220.54765 | P13: 224.9586 | Q13: 229.45777
C14: Total | E14: =SUM(E4:E13) -> 22165 | F14: =SUM(F4:F13) -> 24870.05 | G14: =SUM(G4:G13) -> 25651.9 | H14: =SUM(H4:H13) -> 33428.4 | I14: =SUM(I4:I13) -> 34360.076 | J14: =SUM(J4:J13) -> 35340.075 | K14: =SUM(K4:K13) -> 36256.082 | L14: =SUM(L4:L13) -> 37328.789 | ... Q14: =SUM(Q4:Q13) -> 44943.242
B16: *재고
B17: Stock(CU) | E17: Jun. | F17: July | G17: Aug. | H17: Sep. | I17: Oct. | J17: Nov. | K17: Dec. | L17: Jan. | M17: Feb. | N17: Mar. | O17: Apr. | P17: May. | Q17: Jun.
C18: PN | D18: Pre | E18: 5247 | F18: =E18+F48-F4 -> 4713.1 | G18: =F18+G48-G4 -> 4163.05 | H18: 1600 | I18: =H18+I48-I4 -> 863.83322 | J18: =I18+J48-J4 -> 105.56982 | K18: =J18+K48-K4 -> 2028.6127 | L18: =K18+L48-L4 -> 2728.3469 | M18: =L18+M48-M4 -> 2904.0731 | N18: =M18+N48-N4 -> 3055.0711 | O18: =N18+O48-O4 -> 3172.109 | P18: =O18+P48-P4 -> 3262.658 | Q18: =P18+Q48-Q4 -> 3325.9235
D19: 1 | E19: 10420 | F19: =E19+F49-F5 -> 9832.9 | G19: =F19+G49-G5 -> 9242.95 | H19: =G19+H49-H5 -> 8490.55 | I19: =H19+I49-I5 -> 7726.3384 | J19: =I19+J49-J5 -> 6947.9965 | K19: =J19+K49-K5 -> 6146.3858 | L19: =K19+L49-L5 -> 5320.7268 | M19: =L19+M49-M5 -> 4470.298 | ... Q19: =P19+Q49-Q5 -> 3278.6104
D20: 2 | E20: 3711 | F20: =E20+F50-F6 -> 7257.35 | G20: =F20+G50-G6 -> 5641.4 | H20: =G20+H50-H6 -> 9499.4 | I20: =H20+I50-I6 -> 7376.2305 | J20: =I20+J50-J6 -> 5191.3342 | K20: =J20+K50-K6 -> 6183.5799 | L20: =K20+L50-L6 -> 7068.393 | M20: =L20+M50-M6 -> 7183.7505 | ... Q20: =P20+Q50-Q6 -> 9752.9619
D21: 3 | E21: 2032 | F21: =E21+F51-F7 -> 2753.65 | G21: =F21+G51-G7 -> 2662.45 | H21: =G21+H51-H7 -> 2543.65 | I21: =H21+I51-I7 -> 2421.3559 | J21: =I21+J51-J7 -> 2295.5676 | K21: =J21+K51-K7 -> 2166.2853 | L21: =K21+L51-L7 -> 2033.1245 | M21: =L21+M51-M7 -> 1895.9688 | ... Q21: =P21+Q51-Q7 -> 1236.9879
C22: PF | D22: Pre | E22: 20574 | F22: =E22+F52-F8 -> 32863.1 | G22: =F22+G52-G8 -> 35472 | H22: =G22+H52-H8 -> 36170.4 | I22: =H22+I52-I8 -> 29380.569 | J22: =I22+J52-J8 -> 22392.852 | K22: =J22+K52-K8 -> 15224.257 | L22: =K22+L52-L8 -> 22840.604 | M22: =L22+M52-M8 -> 24235.441 | ... Q22: =P22+Q52-Q8 -> 28400.288
D23: 1 | E23: 17559 | F23: =E23+F53-F9 -> 24858.55 | G23: =F23+G53-G9 -> 34409.55 | H23: =G23+H53-H9 -> 38830.35 | I23: =H23+I53-I9 -> 37951.581 | J23: =I23+J53-J9 -> 26772.195 | K23: =J23+K53-K9 -> 19911.405 | L23: =K23+L53-L9 -> 36098.552 | M23: =L23+M53-M9 -> 38931.313 | ... Q23: =P23+Q53-Q9 -> 42799.61
D24: 2 | E24: 49603 | F24: =E24+F54-F10 -> 41248.7 | G24: =F24+G54-G10 -> 32643.6 | H24: =G24+H54-H10 -> 32967.6 | I24: =H24+I54-I10 -> 42949.39 | J24: =I24+J54-J10 -> 31091.92 | K24: =J24+K54-K10 -> 22766.404 | L24: =K24+L54-L10 -> 37235.922 | M24: =L24+M54-M10 -> 38329.526 | ... Q24: =P24+Q54-Q10 -> 43714.112
D25: Kinder | E25: 2214 | F25: =E25+F55-F11 -> 2943.55 | G25: =F25+G55-G11 -> 2430.55 | H25: =G25+H55-H11 -> 1717.75 | I25: =H25+I55-I11 -> 3294.694 | J25: =I25+J55-J11 -> 2553.0969 | K25: =J25+K55-K11 -> 1796.6678 | L25: =K25+L55-L11 -> 3025.1102 | M25: =L25+M55-M11 -> 2238.1214 | ... Q25: =P25+Q55-Q11 -> 2929.5889
D26: AR | E26: 65 | F26: =E26+F56-F12 -> -266.55 | G26: =F26+G56-G12 -> -631.35 | H26: =G26+H56-H12 -> 1886.25 | I26: =H26+I56-I12 -> 1369.722 | J26: =I26+J56-J12 -> 842.86344 | K26: =J26+K56-K12 -> 2321.4677 | L26: =K26+L56-L12 -> 1773.3241 | M26: =L26+M56-M12 -> 3214.2175 | ... Q26: =P26+Q56-Q12 -> 1863.7113
D27: Comfort | E27: 678 | F27: =E27+F57-F13 -> 552.6 | G27: =F27+G57-G13 -> 414.85 | H27: =G27+H57-H13 -> 1230.85 | I27: =H27+I57-I13 -> 1035.01 | J27: =I27+J57-J13 -> 835.2532 | K27: =J27+K57-K13 -> 631.50126 | L27: =K27+L57-L13 -> 923.67429 | M27: =L27+M57-M13 -> 711.69078 | ... Q27: =P27+Q57-Q13 -> 820.50357
C28: Total | E28: =SUM(E18:E27) -> 112103 | F28: =SUM(F18:F27) -> 126756.95 | G28: =SUM(G18:G27) -> 126449.05 | H28: =SUM(H18:H27) -> 134936.8 | I28: =SUM(I18:I27) -> 134368.72 | J28: =SUM(J18:J27) -> 99028.649 | K28: =SUM(K18:K27) -> 79176.566 | L28: =SUM(L18:L27) -> 119047.78 | ... Q28: =SUM(Q18:Q27) -> 138122.3
B30: *발주 | F30: 3Q | I30: 4Q
B31: Supply (arrival) | E31: Jun. | F31: July. | G31: Aug. | H31: Sep. | I31: Oct. | J31: Nov. | K31: Dec.
C32: PN | D32: Pre | E32: 2700 | F32: 1500 | G32: 1000 | H32: 1000 | I32: 1000 | J32: 1000 | K32: 1000
D33: 1 | I33: 500 | J33: 1000 | K33: 1000
D34: 2 | E34: 3240 | F34: 3200 | G34: 2500 | H34: 3000 | I34: 3500 | J34: 3500 | K34: 4000
D35: 3
C36: PF | D36: Pre | F36: 15000 | G36: 9000 | H36: 8000 | I36: 9000 | J36: 11000 | K36: 10000
D37: 1 | E37: 4608 | F37: 28000 | G37: 15000 | H37: 11000 | I37: 16000 | J37: 17000 | K37: 14000
D38: 2 | E38: 3840 | F38: 27000 | G38: 14000 | H38: 15000 | I38: 15000 | J38: 15000 | K38: 16000
D39: Kinder | F39: 2000 | H39: 1000 | I39: 1000 | J39: 1000 | K39: 1000
D40: AR | E40: 2016 | G40: 2000 | J40: 1000
D41: Comfort | F41: 500 | H41: 1000
C42: Total | E42: =SUM(E32:E41) -> 16404 | F42: =SUM(F32:F41) -> 77200 | G42: =SUM(G32:G41) -> 43500 | H42: =SUM(H32:H41) -> 40000 | I42: =SUM(I32:I41) -> 46000 | J42: =SUM(J32:J41) -> 50500 | K42: =SUM(K32:K41) -> 47000
C43: 발주 금액(EUR) | E43: =단가!D47 -> 264580.08 | F43: =단가!E47 -> 1429385 | G43: =단가!F47 -> 799910 | H43: =단가!G47 -> 725160 | I43: =단가!H47 -> 847030 | J43: =단가!I47 -> 920310 | K43: =단가!J47 -> 861330
...

Sheet 직구 판매량
O2: 5%하락 | P2: 5%하락 | Q2: 20% 증가
A3: Sales | D3: Aug. | E3: Sep. | F3: Oct. | G3: Nov. | H3: Dec. | I3: Jan. | J3: Feb. | K3: Mar. | L3: Apr. | M3: May. | N3: Jun. | O3: July | P3: Aug. | Q3: Sep. | R3: Oct. | S3: Nov. | T3: Dec. | U3: Jan. | V3: Feb. | W3: Mar. | X3: Apr. | Y3: May. | Z3: Jun.
A4: Sales CU | B4: PN | C4: Pre | D4: 6 | E4: 88 | F4: 67 | G4: 150 | H4: 250 | I4: 377 | J4: 342 | K4: 302 | L4: 565 | M4: 470 | N4: 711 | O4: 533.9 | P4: 550.05 | Q4: 715.2 | R4: =Q4+(R19*Q4) -> 736.16678 | S4: =R4+(S19*R4) -> 758.26341 | T4: =S4+(T19*S4) -> 776.95711 | U4: =T4+(U19*T4) -> 800.26583 | V4: =U4+(V19*U4) -> 824.2738 | W4: =V4+(W19*V4) -> 849.00202 | X4: =W4+(X19*W4) -> 882.9621 | Y4: =X4+(Y19*X4) -> 909.45096 | Z4: =Y4+(Z19*Y4) -> 936.73449
C5: 1 | D5: 22 | E5: 138 | F5: 316 | G5: 832 | H5: 1229 | I5: 1014 | J5: 933 | K5: 743 | L5: 744 | M5: 700 | N5: 711 | O5: 587.1 | P5: 589.95 | Q5: 752.4 | R5: =Q5+(R20*Q5) -> 764.21162 | S5: =R5+(S20*R5) -> 778.34188 | T5: =S5+(T20*S5) -> 801.61069 | U5: =T5+(U20*T5) -> 825.65901 | V5: =U5+(V20*U5) -> 850.42878 | W5: =V5+(W20*V5) -> 875.94165 | X5: =W5+(X20*W5) -> 910.97931 | Y5: =X5+(Y20*X5) -> 938.30869 | Z5: =Y5+(Z20*Y5) -> 966.45795
C6: 2 | D6: 10 | E6: 68 | F6: 161 | G6: 275 | H6: 761 | I6: 743 | J6: 1467 | K6: 1179 | L6: 1336 | M6: 1178 | N6: 1026 | O6: 1583.65 | P6: 1615.95 | Q6: 2082 | R6: =Q6+(R21*Q6) -> 2123.1695 | S6: =R6+(S21*R6) -> 2184.8963 | T6: =S6+(T21*S6) -> 2247.7543 | U6: =T6+(U21*T6) -> 2315.1869 | V6: =U6+(V21*U6) -> 2384.6425 | W6: =V6+(W21*V6) -> 2503.8746 | X6: =W6+(X21*W6) -> 2679.1459 | Y6: =X6+(Y21*X6) -> 2947.0604 | Z6: =Y6+(Z21*Y6) -> 3300.7077
C7: 3 | D7: 0 | E7: 4 | F7: 8 | G7: 24 | H7: 232 | I7: 207 | J7: 358 | K7: 105 | L7: 86 | M7: 94 | N7: 86 | O7: 88.35 | P7: 91.2 | Q7: 118.8 | R7: =Q7+(R22*Q7) -> 122.29412 | S7: =R7+(S22*R7) -> 125.78824 | T7: =S7+(T22*S7) -> 129.28235 | U7: =T7+(U22*T7) -> 133.16082 | V7: =U7+(V22*U7) -> 137.15565 | W7: =V7+(W22*V7) -> 146.75654 | X7: =W7+(X22*W7) -> 161.4322 | Y7: =X7+(Y22*X7) -> 171.11813 | Z7: =Y7+(Z22*Y7) -> 179.67404
B8: PF | C8: Pre | D8: 184 | E8: 1248 | F8: 1712 | G8: 2254 | H8: 3248 | I8: 4757 | J8: 3703 | K8: 5085 | L8: 4611 | M8: 5026 | N8: 4541 | O8: 4922.9 | P8: 5071.1 | Q8: 6597.6 | R8: =Q8+(R23*Q8) -> 6789.831 | S8: =R8+(S23*R8) -> 6987.7174 | T8: =S8+(T23*S8) -> 7168.5951 | U8: =T8+(U23*T8) -> 7383.653 | V8: =U8+(V23*U8) -> 7605.1626 | W8: =V8+(W23*V8) -> 7833.3175 | X8: =W8+(X23*W8) -> 8303.3165 | Y8: =X8+(Y23*X8) -> 8718.4823 | Z8: =Y8+(Z23*Y8) -> 8980.0368
C9: 1 | D9: 258 | E9: 1350 | F9: 1896 | G9: 4155 | H9: 5197 | I9: 6023 | J9: 5139 | K9: 7077 | L9: 6977 | M9: 8068 | N9: 7701 | O9: 7876.45 | P9: 8113 | Q9: 10555.2 | R9: =Q9+(R24*Q9) -> 10862.769 | S9: =R9+(S24*R9) -> 11179.386 | T9: =S9+(T24*S9) -> 11468.79 | U9: =T9+(U24*T9) -> 11812.854 | V9: =U9+(V24*U9) -> 12167.239 | W9: =V9+(W24*V9) -> 12532.256 | X9: =W9+(X24*W9) -> 13284.192 | Y9: =X9+(Y24*X9) -> 13948.401 | Z9: =Y9+(Z24*Y9) -> 14366.853
C10: 2 | D10: 110 | E10: 460 | F10: 691 | G10: 1132 | H10: 2328 | I10: 2898 | J10: 3723 | K10: 8699 | L10: 11723 | M10: 11363 | N10: 6506 | O10: 8354.3 | P10: 8605.1 | Q10: 11196 | R10: =Q10+(R25*Q10) -> 11522.21 | S10: =R10+(S25*R10) -> 11857.469 | T10: =S10+(T25*S10) -> 12165.516 | U10: =T10+(U25*T10) -> 12530.482 | V10: =U10+(V25*U10) -> 12906.396 | W10: =V10+(W25*V10) -> 13293.588 | X10: =W10+(X25*W10) -> 13692.396 | Y10: =X10+(Y25*X10) -> 14103.168 | Z10: =Y10+(Z25*Y10) -> 14526.263
C11: Kinder | K11: 27 | L11: 400 | M11: 335 | N11: 446 | O11: 466.45 | P11: 513 | Q11: 712.8 | R11: =Q11+(R26*Q11) -> 727.056 | S11: =R11+(S26*R11) -> 741.59712 | T11: =S11+(T26*S11) -> 756.42906 | U11: =T11+(U26*T11) -> 771.55764 | V11: =U11+(V26*U11) -> 786.9888 | W11: =V11+(W26*V11) -> 802.72857 | X11: =W11+(X26*W11) -> 818.78314 | Y11: =X11+(Y26*X11) -> 835.15881 | Z11: =Y11+(Z26*Y11) -> 851.86198
C12: AR | K12: 116 | L12: 274 | M12: 260 | N12: 317 | O12: 331.55 | P12: 364.8 | Q12: 506.4 | R12: =Q12+(R27*Q12) -> 516.528 | S12: =R12+(S27*R12) -> 526.85856 | T12: =S12+(T27*S12) -> 537.39573 | U12: =T12+(U27*T12) -> 548.14365 | V12: =U12+(V27*U12) -> 559.10652 | W12: =V12+(W27*V12) -> 570.28865 | X12: =W12+(X27*W12) -> 581.69442 | Y12: =X12+(Y27*X12) -> 593.32831 | Z12: =Y12+(Z27*Y12) -> 605.19488
C13: Comfort | K13: 26 | L13: 106 | M13: 86 | N13: 120 | O13: 125.4 | P13: 137.75 | Q13: 192 | R13: =Q13+(R28*Q13) -> 195.84 | S13: =R13+(S28*R13) -> 199.7568 | T13: =S13+(T28*S13) -> 203.75194 | U13: =T13+(U28*T13) -> 207.82697 | V13: =U13+(V28*U13) -> 211.98351 | W13: =V13+(W28*V13) -> 216.22318 | X13: =W13+(X28*W13) -> 220.54765 | Y13: =X13+(Y28*X13) -> 224.9586 | Z13: =Y13+(Z28*Y13) -> 229.45777
B14: Total | D14: =SUM(D4:D13) -> 590 | E14: =SUM(E4:E13) -> 3356 | F14: =SUM(F4:F13) -> 4851 | G14: =SUM(G4:G13) -> 8822 | H14: =SUM(H4:H13) -> 13245 | I14: =SUM(I4:I13) -> 16019 | J14: =SUM(J4:J13) -> 15665 | K14: =SUM(K4:K13) -> 23359 | ... Z14: =SUM(Z4:Z13) -> 44943.242
L15: =L14*800/1000000 -> 21.4576 | M15: =M14*800/1000000 -> 22.064 | N15: =N14*800/1000000 -> 17.732 | O15: =O14*800/1000000 -> 19.89604 | P15: =P14*800/1000000 -> 20.52152 | Q15: =Q14*800/1000000 -> 26.74272 | R15: =R14*800/1000000 -> 27.488061 | S15: =S14*800/1000000 -> 28.27206 | T15: =T14*800/1000000 -> 29.004866
D16: 590 | E16: 3356 | F16: 4851 | G16: 8822 | H16: 13245 | I16: 16019 | J16: 15665 | K16: 23359 | L16: 26822 | M16: 27580 | N16: 22165 | O16: 26179 | P16: 27002 | Q16: 33428.4 | R16: 34498.8 | S16: 35634 | T16: 36717.6 | U16: 37950.588 | V16: 39233.712 | W16: 40623.081 | X16: 42757.106 | Y16: 44857.847 | Z16: 46684.514
A18: Sales | D18: Aug. | E18: Sep. | F18: Oct. | G18: Nov. | H18: Dec. | I18: Jan. | J18: Feb. | K18: Mar. | L18: Apr. | M18: May. | N18: Jun. | O18: July | P18: Aug. | Q18: Sep. | R18: Oct. | S18: Nov. | T18: Dec. | U18: Jan. | V18: Feb. | W18: Mar. | X18: Apr. | Y18: May. | Z18: Jun.
A19: Sales CU | B19: PN | C19: Pre | E19: =1-(D4/E4) -> 0.93181818 | F19: =1-(E4/F4) -> -0.31343284 | G19: =1-(F4/G4) -> 0.55333333 | H19: =1-(G4/H4) -> 0.4 | I19: =1-(H4/I4) -> 0.33687003 | J19: =1-(I4/J4) -> -0.10233918 | K19: =1-(J4/K4) -> -0.13245033 | L19: =1-(K4/L4) -> 0.46548673 | ... Q19: =1-(P4/Q4) -> 0.23091443 | R19: 0.029315961 | S19: 0.030015798 | T19: 0.024653313 | U19: 0.03 | V19: 0.03 | W19: 0.03 | X19: 0.04 | Y19: 0.03 | Z19: 0.03
C20: 1 | E20: =1-(D5/E5) -> 0.84057971 | F20: =1-(E5/F5) -> 0.56329114 | G20: =1-(F5/G5) -> 0.62019231 | H20: =1-(G5/H5) -> 0.32302685 | I20: =1-(H5/I5) -> -0.21203156 | J20: =1-(I5/J5) -> -0.08681672 | K20: =1-(J5/K5) -> -0.25572005 | L20: =1-(K5/L5) -> 0.001344086 | ... Q20: =1-(P5/Q5) -> 0.21590909 | R20: 0.015698587 | S20: 0.018489985 | T20: 0.029895366 | U20: 0.03 | V20: 0.03 | W20: 0.03 | X20: 0.04 | Y20: 0.03 | Z20: 0.03
C21: 2 | E21: =1-(D6/E6) -> 0.85294118 | F21: =1-(E6/F6) -> 0.57763975 | G21: =1-(F6/G6) -> 0.41454545 | H21: =1-(G6/H6) -> 0.63863338 | I21: =1-(H6/I6) -> -0.02422611 | J21: =1-(I6/J6) -> 0.4935242 | K21: =1-(J6/K6) -> -0.24427481 | L21: =1-(K6/L6) -> 0.11751497 | ... Q21: =1-(P6/Q6) -> 0.22384726 | R21: 0.019774011 | S21: 0.029072957 | T21: 0.028769313 | U21: 0.03 | V21: 0.03 | W21: 0.05 | X21: 0.07 | Y21: 0.1 | Z21: 0.12
C22: 3 | E22: =1-(D7/E7) -> 1 | F22: =1-(E7/F7) -> 0.5 | G22: =1-(F7/G7) -> 0.66666667 | H22: =1-(G7/H7) -> 0.89655172 | I22: =1-(H7/I7) -> -0.12077295 | J22: =1-(I7/J7) -> 0.42178771 | K22: =1-(J7/K7) -> -2.4095238 | L22: =1-(K7/L7) -> -0.22093023 | ... Q22: =1-(P7/Q7) -> 0.23232323 | R22: 0.029411765 | S22: 0.028571429 | T22: 0.027777778 | U22: 0.03 | V22: 0.03 | W22: 0.07 | X22: 0.1 | Y22: 0.06 | Z22: 0.05
B23: PF | C23: Pre | E23: =1-(D8/E8) -> 0.8525641 | F23: =1-(E8/F8) -> 0.27102804 | G23: =1-(F8/G8) -> 0.2404614 | H23: =1-(G8/H8) -> 0.30603448 | I23: =1-(H8/I8) -> 0.31721673 | J23: =1-(I8/J8) -> -0.28463408 | K23: =1-(J8/K8) -> 0.27177974 | L23: =1-(K8/L8) -> -0.10279766 | ... Q23: =1-(P8/Q8) -> 0.23137201 | R23: 0.0291365 | S23: 0.029144523 | T23: 0.025885104 | U23: 0.03 | V23: 0.03 | W23: 0.03 | X23: 0.06 | Y23: 0.05 | Z23: 0.03
C24: 1 | E24: =1-(D9/E9) -> 0.80888889 | F24: =1-(E9/F9) -> 0.28797468 | G24: =1-(F9/G9) -> 0.54368231 | H24: =1-(G9/H9) -> 0.20050029 | I24: =1-(H9/I9) -> 0.13714096 | J24: =1-(I9/J9) -> -0.1720179 | K24: =1-(J9/K9) -> 0.27384485 | L24: =1-(K9/L9) -> -0.014332808 | ... Q24: =1-(P9/Q9) -> 0.23137411 | R24: 0.029139073 | S24: 0.029147021 | T24: 0.025887265 | U24: 0.03 | V24: 0.03 | W24: 0.03 | X24: 0.06 | Y24: 0.05 | Z24: 0.03
C25: 2 | E25: =1-(D10/E10) -> 0.76086957 | F25: =1-(E10/F10) -> 0.33429812 | G25: =1-(F10/G10) -> 0.38957597 | H25: =1-(G10/H10) -> 0.5137457 | I25: =1-(H10/I10) -> 0.19668737 | J25: =1-(I10/J10) -> 0.22159549 | K25: =1-(J10/K10) -> 0.57201977 | L25: =1-(K10/L10) -> 0.25795445 | ... Q25: =1-(P10/Q10) -> 0.231413 | R25: 0.029136316 | S25: 0.029096787 | T25: 0.025979138 | U25: 0.03 | V25: 0.03 | W25: 0.03 | X25: 0.03 | Y25: 0.03 | Z25: 0.03
C26: Kinder | L26: =1-(K11/L11) -> 0.9325 | M26: =1-(L11/M11) -> -0.19402985 | N26: =1-(M11/N11) -> 0.24887892 | O26: =1-(N11/O11) -> 0.043841784 | P26: =1-(O11/P11) -> 0.090740741 | Q26: 0.03 | R26: 0.02 | S26: 0.02 | T26: 0.02 | U26: 0.02 | V26: 0.02 | W26: 0.02 | X26: 0.02 | Y26: 0.02 | Z26: 0.02
C27: AR | L27: =1-(K12/L12) -> 0.57664234 | M27: =1-(L12/M12) -> -0.053846154 | N27: =1-(M12/N12) -> 0.17981073 | O27: =1-(N12/O12) -> 0.043884784 | P27: =1-(O12/P12) -> 0.091145833 | Q27: =1-(P12/Q12) -> 0.27962085 | R27: 0.02 | S27: 0.02 | T27: 0.02 | U27: 0.02 | V27: 0.02 | W27: 0.02 | X27: 0.02 | Y27: 0.02 | Z27: 0.02
C28: Comfort | L28: =1-(K13/L13) -> 0.75471698 | M28: =1-(L13/M13) -> -0.23255814 | N28: =1-(M13/N13) -> 0.28333333 | O28: =1-(N13/O13) -> 0.043062201 | P28: =1-(O13/P13) -> 0.089655172 | Q28: =1-(P13/Q13) -> 0.28255208 | R28: 0.02 | S28: 0.02 | T28: 0.02 | U28: 0.02 | V28: 0.02 | W28: 0.02 | X28: 0.02 | Y28: 0.02 | Z28: 0.02
B29: Total
V31: 1 | W31: -0.0035452612 | X31: -0.0078608861 | Y31: 0.019387993 | Z31: 0.031338387
V32: 2 | W32: -0.023718763 | X32: -0.037255074 | Y32: -0.073173032 | Z32: -0.085576825
V33: 3 | W33: 0.042343542 | X33: -0.073470555 | Y33: 0.028333333 | Z33: -0.021856372
V34: 1 | W34: -0.0016157699 | X34: -0.034344447 | Y34: -0.021598088 | Z34: 0.022122047
V35: 2 | W35: 0.0085832676 | X35: 0.048977294 | Y35: 0.0077273997 | Z35: 0.054073096
V36: 3 | W36: 0.08259587 | X36: -0.12797543 | Y36: 0.0081238893 | Z36: -0.018882566

Sheet 단가
A1: 구분 | B1: 코드 | D1: 박스 금액 | E1: 캔당금액 | F1: 환율 | G1: 박스 금액 | H1: 캔당금액
A2: 내수 | B2: 676366 | C2: APTAMIL 1 KOR 4X800G | D2: 63.18 | E2: 15.8 | F2: 1456.78 | G2: 92039.36 | H2: 23009.84
A3: 내수 | B3: 676367 | C3: APTAMIL 2 KOR 4X800G | D3: 63.18 | E3: 15.8 | F3: 1456.78 | G3: 92039.36 | H3: 23009.84
A4: 내수 | B4: 676369 | C4: APTAMIL 3 KOR 4X800G | D4: 63.18 | E4: 15.8 | F4: 1456.78 | G4: 92039.36 | H4: 23009.84
A5: 내수 | B5: 677211 | C5: APTAMIL PROFUTURA 1 4X800G KOR | D5: 85.32 | E5: 21.33 | F5: 1456.78 | G5: 124292.47 | H5: 31073.12
A6: 내수 | B6: 677200 | C6: APTAMIL PROFUTURA 2 4X800G KOR | D6: 85.32 | E6: 21.33 | F6: 1456.78 | G6: 124292.47 | H6: 31073.12
A7: 내수 | B7: 677281 | C7: APTAMIL PROFUTURA 3 4X800G KOR | D7: 85.32 | E7: 21.33 | F7: 1456.78 | G7: 124292.47 | H7: 31073.12
A8: 직구 | B8: 673676 | C8: APTAMIL PRE 6X800G CR/SL | D8: 85.8 | E8: 14.3 | F8: 1456.78 | G8: 124991.72 | H8: 31247.93
A9: 직구 | B9: 673674 | C9: APTAMIL 1 6X800G CR/SL | D9: 85.8 | E9: 14.3 | F9: 1456.78 | G9: 124991.72 | H9: 31247.93
A10: 직구 | B10: 673672 | C10: APTAMIL 2 6X800G CR/SL | D10: 85.8 | E10: 14.3 | F10: 1456.78 | G10: 124991.72 | H10: 31247.93
A11: 직구 | B11: 673641 | C11: APTAMIL 3 6X800G CR/SL | D11: 85.8 | E11: 14.3 | F11: 1456.78 | G11: 124991.72 | H11: 31247.93
A12: 직구 | B12: 677044 | C12: APT PROFUTURA PRE, KOR 4X800G | D12: 77.2 | E12: 19.3 | F12: 1456.78 | G12: 112463.42 | H12: 28115.85
A13: 직구 | B13: 677045 | C13: APT PROFUTURA 1, KOR 4X800G | D13: 77.2 | E13: 19.3 | F13: 1456.78 | G13: 112463.42 | H13: 28115.85
A14: 직구 | B14: 677047 | C14: APT PROFUTURA 2, KOR 4X800G | D14: 77.2 | E14: 19.3 | F14: 1456.78 | G14: 112463.42 | H14: 28115.85
B15: 698408 | C15: 압타밀 프로푸트라 YCF | D15: 84.8 | E15: 3.53 | F15: 1456.78 | G15: 123534.94 | H15: 30883.74
B16: 653156 | C16: 압타밀 AR | D16: 197.57 | E16: 8.23 | F16: 1456.78 | G16: 287816.02 | H16: 11992.33
B17: 653299 | C17: 압타밀 COMFORT | D17: 197.57 | E17: 8.23 | F17: 1456.78 | G17: 287816.02 | H17: 11992.33
A21: 아이베 | J21: Jun.
A22: Supply (arrival) | D22: Jun. | E22: July. | F22: Aug. | G22: Sep. | H22: Oct. | I22: Nov. | J22: Dec.
B23: PN | C23: 1 | D23: =아이베!E24*$E2 -> 0 | E23: =아이베!F24*$E2 -> 252800 | F23: =아이베!G24*$E2 -> 126400 | G23: =아이베!H24*$E2 -> 158000 | H23: =아이베!I24*$E2 -> 126400 | I23: =아이베!J24*$E2 -> 142200 | J23: =아이베!K24*$E2 -> 126400
C24: 2 | D24: =아이베!E25*$E3 -> 0 | E24: =아이베!F25*$E3 -> 221200 | F24: =아이베!G25*$E3 -> 126400 | G24: =아이베!H25*$E3 -> 142200 | H24: =아이베!I25*$E3 -> 142200 | I24: =아이베!J25*$E3 -> 94800 | J24: =아이베!K25*$E3 -> 79000
C25: 3 | D25: =아이베!E26*$E4 -> 0 | E25: =아이베!F26*$E4 -> 0 | F25: =아이베!G26*$E4 -> 55300 | G25: =아이베!H26*$E4 -> 55300 | H25: =아이베!I26*$E4 -> 47400 | I25: =아이베!J26*$E4 -> 79000 | J25: =아이베!K26*$E4 -> 31600
B26: PF | C26: 1 | D26: =아이베!E27*$E5 -> 81907.2 | E26: =아이베!F27*$E5 -> 554580 | F26: =아이베!G27*$E5 -> 319950 | G26: =아이베!H27*$E5 -> 255960 | H26: =아이베!I27*$E5 -> 319950 | I26: =아이베!J27*$E5 -> 255960 | J26: =아이베!K27*$E5 -> 319950
C27: 2 | D27: =아이베!E28*$E6 -> 114670.08 | E27: =아이베!F28*$E6 -> 575910 | F27: =아이베!G28*$E6 -> 341280 | G27: =아이베!H28*$E6 -> 341280 | H27: =아이베!I28*$E6 -> 405270 | I27: =아이베!J28*$E6 -> 405270 | J27: =아이베!K28*$E6 -> 383940
C28: 3 | D28: =아이베!E29*$E7 -> 0 | E28: =아이베!F29*$E7 -> 106650 | F28: =아이베!G29*$E7 -> 85320 | G28: =아이베!H29*$E7 -> 106650 | H28: =아이베!I29*$E7 -> 106650 | I28: =아이베!J29*$E7 -> 85320 | J28: =아이베!K29*$E7 -> 42660
B29: Total | D29: =SUM(D23:D28) -> 196577.28 | E29: =SUM(E23:E28) -> 1711140 | F29: =SUM(F23:F28) -> 1054650 | G29: =SUM(G23:G28) -> 1059390 | H29: =SUM(H23:H28) -> 1147870 | I29: =SUM(I23:I28) -> 1062550 | J29: =SUM(J23:J28) -> 983550
B30: 발주 금액(EUR) | D30: =D29 -> 196577.28 | E30: =E29 -> 1711140 | F30: =F29 -> 1054650 | G30: =G29 -> 1059390 | H30: =H29 -> 1147870 | I30: =I29 -> 1062550 | J30: =J29 -> 983550
B31: 발주 금액(KRW) | D31: =D30*$F$2 -> 2.8636985e+08 | E31: =E30*$F$2 -> 2.4927545e+09 | F31: =F30*$F$2 -> 1536393027 | G31: =G30*$F$2 -> 1.5432982e+09 | H31: =H30*$F$2 -> 1.6721941e+09 | I31: =I30*$F$2 -> 1547901589 | J31: =J30*$F$2 -> 1432815969
A34: 크로네
A35: Supply (arrival) | D35: Jun. | E35: July. | F35: Aug. | G35: Sep. | H35: Oct. | I35: Nov. | J35: Dec.
B36: PN | C36: Pre | D36: =크로네!E32*단가!$E8 -> 38610 | E36: =크로네!F32*단가!$E8 -> 21450 | F36: =크로네!G32*단가!$E8 -> 14300 | G36: =크로네!H32*단가!$E8 -> 14300 | H36: =크로네!I32*단가!$E8 -> 14300 | I36: =크로네!J32*단가!$E8 -> 14300 | J36: =크로네!K32*단가!$E8 -> 14300
C37: 1 | D37: =크로네!E33*단가!$E9 -> 0 | E37: =크로네!F33*단가!$E9 -> 0 | F37: =크로네!G33*단가!$E9 -> 0 | G37: =크로네!H33*단가!$E9 -> 0 | H37: =크로네!I33*단가!$E9 -> 7150 | I37: =크로네!J33*단가!$E9 -> 14300 | J37: =크로네!K33*단가!$E9 -> 14300
C38: 2 | D38: =크로네!E34*단가!$E10 -> 46332 | E38: =크로네!F34*단가!$E10 -> 45760 | F38: =크로네!G34*단가!$E10 -> 35750 | G38: =크로네!H34*단가!$E10 -> 42900 | H38: =크로네!I34*단가!$E10 -> 50050 | I38: =크로네!J34*단가!$E10 -> 50050 | J38: =크로네!K34*단가!$E10 -> 57200
C39: 3 | D39: =크로네!E35*단가!$E11 -> 0 | E39: =크로네!F35*단가!$E11 -> 0 | F39: =크로네!G35*단가!$E11 -> 0 | G39: =크로네!H35*단가!$E11 -> 0 | H39: =크로네!I35*단가!$E11 -> 0 | I39: =크로네!J35*단가!$E11 -> 0 | J39: =크로네!K35*단가!$E11 -> 0
B40: PF | C40: Pre | D40: =크로네!E36*단가!$E12 -> 0 | E40: =크로네!F36*단가!$E12 -> 289500 | F40: =크로네!G36*단가!$E12 -> 173700 | G40: =크로네!H36*단가!$E12 -> 154400 | H40: =크로네!I36*단가!$E12 -> 173700 | I40: =크로네!J36*단가!$E12 -> 212300 | J40: =크로네!K36*단가!$E12 -> 193000
C41: 1 | D41: =크로네!E37*단가!$E13 -> 88934.4 | E41: =크로네!F37*단가!$E13 -> 540400 | F41: =크로네!G37*단가!$E13 -> 289500 | G41: =크로네!H37*단가!$E13 -> 212300 | H41: =크로네!I37*단가!$E13 -> 308800 | I41: =크로네!J37*단가!$E13 -> 328100 | J41: =크로네!K37*단가!$E13 -> 270200
C42: 2 | D42: =크로네!E38*단가!$E14 -> 74112 | E42: =크로네!F38*단가!$E14 -> 521100 | F42: =크로네!G38*단가!$E14 -> 270200 | G42: =크로네!H38*단가!$E14 -> 289500 | H42: =크로네!I38*단가!$E14 -> 289500 | I42: =크로네!J38*단가!$E14 -> 289500 | J42: =크로네!K38*단가!$E14 -> 308800
C43: Kinder | D43: =크로네!E39*단가!$E15 -> 0 | E43: =크로네!F39*단가!$E15 -> 7060 | F43: =크로네!G39*단가!$E15 -> 0 | G43: =크로네!H39*단가!$E15 -> 3530 | H43: =크로네!I39*단가!$E15 -> 3530 | I43: =크로네!J39*단가!$E15 -> 3530 | J43: =크로네!K39*단가!$E15 -> 3530
C44: AR | D44: =크로네!E40*단가!$E16 -> 16591.68 | E44: =크로네!F40*단가!$E16 -> 0 | F44: =크로네!G40*단가!$E16 -> 16460 | G44: =크로네!H40*단가!$E16 -> 0 | H44: =크로네!I40*단가!$E16 -> 0 | I44: =크로네!J40*단가!$E16 -> 8230 | J44: =크로네!K40*단가!$E16 -> 0
C45: Comfort | D45: =크로네!E41*단가!$E17 -> 0 | E45: =크로네!F41*단가!$E17 -> 4115 | F45: =크로네!G41*단가!$E17 -> 0 | G45: =크로네!H41*단가!$E17 -> 8230 | H45: =크로네!I41*단가!$E17 -> 0 | I45: =크로네!J41*단가!$E17 -> 0 | J45: =크로네!K41*단가!$E17 -> 0
...
