Workbook

Sheet 아이베
B3: *발주 | E3: 1Q | H3: 2Q | K3: 3Q | N3: 4Q
E4: Oct | F4: Nov | G4: Dec | H4: Jan | I4: Feb | J4: Mar | K4: Apr | L4: May | M4: Jun. | N4: July. | O4: Aug. | P4: Sep.
C5: PN | D5: 1 | G5: 2880 | L5: 2880 | M5: 16704 | N5: 2304 | O5: 5000 | P5: 9000
D6: 2 | E6: 9216 | F6: 5760 | G6: 9792 | L6: 9792 | M6: 8640 | N6: 14976 | O6: 8000 | P6: 7000
D7: 3 | E7: 16128 | F7: 6912 | G7: 0 | N7: 8064 | O7: 3000 | P7: 3000
C8: PF | D8: 1 | E8: 15360 | F8: 11520 | G8: 10752 | H8: 29184 | I8: 9984 | J8: 9216 | K8: 21888 | M8: 16128 | N8: 23040 | O8: 14000 | P8: 14000
D9: 2 | G9: 16800 | H9: 16896 | I9: 3072 | K9: 18432 | L9: 9216 | M9: 11520 | N9: 16512 | O9: 12000 | P9: 12000
D10: 3 | E10: 8064 | F10: 6912 | I10: 5376 | K10: 5760 | N10: 6528 | O10: 3000 | P10: 4000 | Q10: -723341.76 | R10: =Q10/2 -> -361670.88
C11: Total | E11: =SUM(E5:E10) -> 48768 | F11: =SUM(F5:F10) -> 31104 | G11: =SUM(G5:G10) -> 40224 | H11: =SUM(H5:H10) -> 46080 | I11: =SUM(I5:I10) -> 18432 | J11: =SUM(J5:J10) -> 9216 | K11: =SUM(K5:K10) -> 46080 | L11: =SUM(L5:L10) -> 21888 | ... P11: =SUM(P5:P10) -> 49000
C12: 발주 금액(EUR) | E12: =단가!D30 -> 899942.4 | F12: =단가!E30 -> 593308.8 | G12: =단가!F30 -> 787838.4 | H12: =단가!G30 -> 982886.4 | I12: =단가!H30 -> 393154.56 | J12: =단가!I30 -> 196577.28 | K12: =단가!J30 -> 982886.4 | L12: =단가!K30 -> 396731.52 | ... P12: =단가!O30 -> 940005
C13: 발주 금액(KRW) | E13: =단가!D31 -> 1.3110181e+09 | F13: =단가!E31 -> 8.6432039e+08 | G13: =단가!F31 -> 1.1477072e+09 | H13: =단가!G31 -> 1.4318492e+09 | I13: =단가!H31 -> 5.727397e+08 | J13: =단가!I31 -> 2.8636985e+08 | K13: =단가!J31 -> 1.4318492e+09 | L13: =단가!K31 -> 5.7795054e+08 | ... P13: =단가!O31 -> 1.3693805e+09
B15: *제조 | E15: 1Q | H15: 2Q | K15: 3Q | N15: 4Q
B16: 발주 월 | E16: Oct | F16: Nov | G16: Dec | H16: Jan | I16: Feb | J16: Mar | K16: Apr. | L16: May. | M16: Jun. | N16: July. | O16: Aug. | P16: Sep.
B17: 제조 월 | E17: Jan | F17: Feb | G17: Mar | H17: Apr | I17: May | J17: June | K17: July. | L17: Aug. | M17: Sep. | N17: Oct. | O17: Nov. | P17: Dec.
C18: PN | D18: 1 | E18: =E5 -> 0 | F18: =F5 -> 0 | G18: =G5 -> 2880 | H18: =H5 -> 0 | I18: =I5 -> 0 | J18: =J5 -> 0 | K18: =K5 -> 0 | L18: =L5 -> 2880 | ... P18: =P5 -> 9000
D19: 2 | E19: =E6 -> 9216 | F19: =F6 -> 5760 | G19: =G6 -> 9792 | H19: =H6 -> 0 | I19: =I6 -> 0 | J19: =J6 -> 0 | K19: =K6 -> 0 | L19: =L6 -> 9792 | ... P19: =P6 -> 7000
D20: 3 | E20: =E7 -> 16128 | F20: =F7 -> 6912 | G20: =G7 -> 0 | H20: =H7 -> 0 | I20: =I7 -> 0 | J20: =J7 -> 0 | K20: =K7 -> 0 | L20: =L7 -> 0 | ... P20: =P7 -> 3000
C21: PF | D21: 1 | E21: =E8 -> 15360 | F21: =F8 -> 11520 | G21: =G8 -> 10752 | H21: =H8 -> 29184 | I21: =I8 -> 9984 | J21: =J8 -> 9216 | K21: =K8 -> 21888 | L21: =L8 -> 0 | ... P21: =P8 -> 14000
D22: 2 | E22: =E9 -> 0 | F22: =F9 -> 0 | G22: =G9 -> 16800 | H22: =H9 -> 16896 | I22: =I9 -> 3072 | J22: =J9 -> 0 | K22: =K9 -> 18432 | L22: =L9 -> 9216 | ... P22: =P9 -> 12000
D23: 3 | E23: =E10 -> 8064 | F23: =F10 -> 6912 | G23: =G10 -> 0 | H23: =H10 -> 0 | I23: =I10 -> 5376 | J23: =J10 -> 0 | K23: =K10 -> 5760 | L23: =L10 -> 0 | ... P23: =P10 -> 4000
C24: Total | E24: =SUM(E18:E23) -> 48768 | F24: =SUM(F18:F23) -> 31104 | G24: =SUM(G18:G23) -> 40224 | H24: =SUM(H18:H23) -> 46080 | I24: =SUM(I18:I23) -> 18432 | J24: =SUM(J18:J23) -> 9216 | K24: =SUM(K18:K23) -> 46080 | L24: =SUM(L18:L23) -> 21888 | ... P24: =SUM(P18:P23) -> 49000
C25: 발주 금액(EUR) | E25: =단가!X30 -> 899942.4 | F25: =단가!Y30 -> 593308.8 | G25: =단가!Z30 -> 787838.4 | H25: =단가!AA30 -> 982886.4 | I25: =단가!AB30 -> 393154.56 | J25: =단가!AC30 -> 196577.28 | K25: =단가!AD30 -> 982886.4 | L25: =단가!AE30 -> 396731.52 | ... P25: =단가!AI30 -> 940005
C26: 발주 금액(KRW) | E26: =단가!X31 -> 1.3110181e+09 | F26: =단가!Y31 -> 8.6432039e+08 | G26: =단가!Z31 -> 1.1477072e+09 | H26: =단가!AA31 -> 1.4318492e+09 | I26: =단가!AB31 -> 5.727397e+08 | J26: =단가!AC31 -> 2.8636985e+08 | K26: =단가!AD31 -> 1.4318492e+09 | L26: =단가!AE31 -> 5.7795054e+08 | ... P26: =단가!AI31 -> 1.3693805e+09
O27: 871290 | P27: 940005
O28: =+-361670.88-O27 -> -1232960.9
B30: *발주 목표 | K30: 3093000 | N30: 3184000
B31: Supply (arrival) | E31: Oct | F31: Nov | G31: Dec | H31: Jan | I31: Feb | J31: Mar | K31: Apr. | L31: May. | M31: Jun. | N31: July. | O31: Aug. | P31: Sep.
C32: 발주 금액(EUR) | K32: =$K$30/3 -> 1031000 | L32: =$K$30/3 -> 1031000 | M32: =$K$30/3 -> 1031000 | N32: =$N$30/3 -> 1061333.3 | O32: =$N$30/3 -> 1061333.3 | P32: =$N$30/3 -> 1061333.3
C33: 발주 금액(KRW) | K33: =K32*단가!$F$2 -> 1501940180 | L33: =L32*단가!$F$2 -> 1501940180 | M33: =M32*단가!$F$2 -> 1501940180 | N33: =N32*단가!$F$2 -> 1.5461292e+09 | O33: =O32*단가!$F$2 -> 1.5461292e+09 | P33: =P32*단가!$F$2 -> 1.5461292e+09
B35: * 차이 | O35: (EUR)
C36: 발주 | D36: Oct | E36: Nov | F36: Dec | G36: Jan | H36: Feb | I36: Mar | J36: Apr. | K36: May. | L36: Jun. | M36: July. | N36: Aug. | O36: Sep.
C37: 제조 | D37: Jan | E37: Feb | F37: Mar | G37: Apr | H37: May | I37: June | J37: July. | K37: Aug. | L37: Sep. | M37: Oct. | N37: Nov. | O37: Dec.
B38: 발주 목표 | J38: =$K$30/3 -> 1031000 | K38: =$K$30/3 -> 1031000 | L38: =$K$30/3 -> 1031000 | M38: =+$N$30/3 -> 1061333.3 | N38: =+$N$30/3 -> 1061333.3 | O38: =+$N$30/3 -> 1061333.3
B39: 발주액 | D39: =E12 -> 899942.4 | E39: =F12 -> 593308.8 | F39: =G12 -> 787838.4 | G39: =H12 -> 982886.4 | H39: =I12 -> 393154.56 | I39: =J12 -> 196577.28 | J39: =K12 -> 982886.4 | K39: =L12 -> 396731.52 | ... O39: =P12 -> 940005
B40: 차이 | D40: =D39-D38 -> 899942.4 | E40: =E39-E38 -> 593308.8 | F40: =F39-F38 -> 787838.4 | G40: =G39-G38 -> 982886.4 | H40: =H39-H38 -> 393154.56 | I40: =I39-I38 -> 196577.28 | J40: =J39-J38 -> -48113.6 | K40: =K39-K38 -> -634268.48 | ... O40: =O39-O38 -> -121328.33
F42: (EUR)
C43: 1분기 누계 | D43: 2분기 누계 | E43: 3분기 누계 | F43: 4분기 누계
B44: 발주 목표 | C44: =I30 -> 0 | D44: =J30 -> 0 | E44: =K30 -> 3093000 | F44: =N30 -> 3184000
B45: 발주액 | C45: =+D39+E39+F39 -> 2281089.6 | D45: =+I39+H39+G39 -> 1572618.2 | E45: =+J39+K39+L39 -> 2369658.2 | F45: =+M39+N39+O39 -> 3194489.9
B46: 차이 | C46: =C45-C44 -> 2281089.6 | D46: =D45-D44 -> 1572618.2 | E46: =E45-E44 -> -723341.76 | F46: =F45-F44 -> 10489.88

Sheet 내수 판매량
E3: =1-(D5/E5) -> 0.025692996 | F3: =1-(E5/F5) -> 0.055514892 | G3: =1-(F5/G5) -> -0.064808153 | H3: =1-(G5/H5) -> 0.043468288 | I3: =1-(H5/I5) -> -0.13521255 | J3: =1-(I5/J5) -> -0.020935797 | K3: =1-(J5/K5) -> -0.068759767 | L3: =1-(K5/L5) -> -0.046458039 | ... AA3: =1-(Z5/AA5) -> 0.047624539 | AB3: 25년
A4: Sales | D4: 1 | E4: 2 | F4: 3 | G4: 4 | H4: 5 | I4: 6 | J4: 7 | K4: 8 | L4: 9 | M4: 10 | N4: 11 | O4: 12 | P4: 1 | Q4: 2 | R4: 3 | S4: 4 | T4: 5 | U4: Jun. | V4: July | W4: Aug. | X4: Sep. | Y4: Oct. | Z4: Nov. | AA4: Dec. | AB4: Jan. | AC4: Feb. | AD4: Mar. | AE4: Apr. | AF4: May. | AG4: Jun.
B5: PN | C5: 1 | D5: 16344 | E5: 16775 | F5: 17761 | G5: 16680 | H5: 17438 | I5: 15361 | J5: 15046 | K5: 14078 | L5: 13453 | M5: 12241 | N5: 11541 | O5: 11277 | P5: 9919 | Q5: 8492 | R5: 8462 | S5: 8396 | T5: 8562 | U5: 8839 | V5: 7757 | W5: 7424 | X5: 7808 | Y5: 8086 | Z5: 8259 | AA5: 8672 | AB5: =AA5+(AA5*$AB$28) -> 8456.762 | AC5: =AB5+(AB5*$AB28) -> 8246.8662 | AD5: =AC5+(AC5*$R28) -> 8217.6289 | AE5: =AD5+(AD5*$S28) -> 8153.031 | AF5: =AE5+(AE5*$T28) -> 8311.102 | AG5: =AF5+(AF5*$U28) -> 8571.5585
C6: 2 | D6: 16710 | E6: 14642 | F6: 16722 | G6: 17541 | H6: 18678 | I6: 16319 | J6: 17180 | K6: 17680 | L6: 16946 | M6: 15639 | N6: 15066 | O6: 14921 | P6: 13593 | Q6: 12085 | R6: 11805 | S6: 11381 | T6: 10605 | U6: 9769 | V6: 9878 | W6: 9386 | X6: 9667 | Y6: 9859 | Z6: 9958 | AA6: 10256 | AB6: =AA6+(AA6*AB29) -> 9917.5116 | AC6: =AB6+(AB6*$AB29) -> 9590.1947 | AD6: =AC6+(AC6*$R29) -> 9362.7272 | AE6: =AD6+(AD6*$S29) -> 9013.9181 | AF6: =AE6+(AE6*$T29) -> 8354.3424 | AG6: =AF6+(AF6*$U29) -> 7639.4043
C7: 3 | D7: 5210 | E7: 3827 | F7: 4687 | G7: 5118 | H7: 5329 | I7: 4805 | J7: 4741 | K7: 4795 | L7: 4636 | M7: 4295 | N7: 3742 | O7: 3948 | P7: 3902 | Q7: 3596 | R7: 3755 | S7: 3498 | T7: 3600 | U7: 3523 | V7: 3014 | W7: 2883 | X7: 3034 | Y7: 3142 | Z7: 3210 | AA7: 3370 | AB7: =AA7+(AA7*AB30) -> 3318.5943 | AC7: =AB7+(AB7*$AB30) -> 3267.9728 | AD7: =AC7+(AC7*$R30) -> 3406.3503 | AE7: =AD7+(AD7*$S30) -> 3156.0839 | AF7: =AE7+(AE7*$T30) -> 3245.5062 | AG7: =AF7+(AF7*$U30) -> 3174.5713
B8: PF | C8: 1 | D8: 7135 | E8: 9887 | F8: 11444 | G8: 14836 | H8: 13481 | I8: 10800 | J8: 11099 | K8: 11166 | L8: 11517 | M8: 11204 | N8: 11300 | O8: 12277 | P8: 12546 | Q8: 12398 | R8: 12378 | S8: 11967 | T8: 11714 | U8: 11979 | V8: 11038 | W8: 10485 | X8: 11214 | Y8: 11923 | Z8: 12932 | AA8: 13756 | AB8: =AA8+(AA8*AB31) -> 13868.882 | AC8: =AB8+(AB8*$AB31) -> 13982.69 | AD8: =AC8+(AC8*$R31) -> 13960.097 | AE8: =AD8+(AD8*$S31) -> 13480.645 | AF8: =AE8+(AE8*$T31) -> 13189.489 | AG8: =AF8+(AF8*$U31) -> 13481.268
C9: 2 | D9: 5823 | E9: 5716 | F9: 8611 | G9: 18795 | H9: 13523 | I9: 11340 | J9: 11483 | K9: 11747 | L9: 11506 | M9: 10390 | N9: 9877 | O9: 10453 | P9: 10462 | Q9: 10049 | R9: 10136 | S9: 10658 | T9: 10741 | U9: 11355 | V9: 10680 | W9: 10790 | X9: 11327 | Y9: 12042 | Z9: 13061 | AA9: 13895 | AB9: =AA9+(AA9*AB32) -> 14208.725 | AC9: =AB9+(AB9*$AB32) -> 14529.534 | AD9: =AC9+(AC9*$R32) -> 14654.245 | AE9: =AD9+(AD9*$S32) -> 15371.97 | AF9: =AE9+(AE9*$T32) -> 15490.756 | AG9: =AF9+(AF9*$U32) -> 16328.389
C10: 3 | D10: 2191 | E10: 2232 | F10: 2663 | G10: 4315 | H10: 4793 | I10: 4101 | J10: 4422 | K10: 4549 | L10: 4508 | M10: 4265 | N10: 4233 | O10: 4453 | P10: 4541 | Q10: 4043 | R10: 4407 | S10: 3907 | T10: 3939 | U10: 3866 | V10: 3458 | W10: 3354 | X10: 3588 | Y10: 3814 | Z10: 4139 | AA10: 4402 | AB10: =AA10+(AA10*AB33) -> 4385.0558 | AC10: =AB10+(AB10*$AB33) -> 4368.1769 | AD10: =AC10+(AC10*$R33) -> 4728.9702 | AE10: =AD10+(AD10*$S33) -> 4123.7782 | AF10: =AE10+(AE10*$T33) -> 4157.2794 | AG10: =AF10+(AF10*$U33) -> 4078.7792
B11: Total | D11: =SUM(D5:D10) -> 53413 | E11: =SUM(E5:E10) -> 53079 | F11: =SUM(F5:F10) -> 61888 | G11: =SUM(G5:G10) -> 77285 | H11: =SUM(H5:H10) -> 73242 | I11: =SUM(I5:I10) -> 62726 | J11: =SUM(J5:J10) -> 63971 | K11: =SUM(K5:K10) -> 64015 | ... AG11: =SUM(AG5:AG10) -> 53273.97
D13: 1 | E13: 2 | F13: 3 | G13: 4 | H13: 5 | I13: Jun. | J13: July | K13: Aug. | L13: Sep. | M13: Oct. | N13: Nov. | O13: Dec.
D14: 9919 | E14: 8492 | F14: 8462 | G14: 8396 | H14: 8562 | I14: 8839 | J14: 7757 | K14: 7424 | L14: 7808 | M14: 8086 | N14: 8259 | O14: 8672
D15: 13593 | E15: 12085 | F15: 11805 | G15: 11381 | H15: 10605 | I15: 9769 | J15: 9878 | K15: 9386 | L15: 9667 | M15: 9859 | N15: 9958 | O15: 10256
D16: 3902 | E16: 3596 | F16: 3755 | G16: 3498 | H16: 3600 | I16: 3523 | J16: 3014 | K16: 2883 | L16: 3034 | M16: 3142 | N16: 3210 | O16: 3370
D17: 12546 | E17: 12398 | F17: 12378 | G17: 11967 | H17: 11714 | I17: 11979 | J17: 11038 | K17: 10485 | L17: 11214 | M17: 11923 | N17: 12932 | O17: 13756
D18: 10462 | E18: 10049 | F18: 10136 | G18: 10658 | H18: 10741 | I18: 11355 | J18: 10680 | K18: 10790 | L18: 11327 | M18: 12042 | N18: 13061 | O18: 13895
D19: 4541 | E19: 4043 | F19: 4407 | G19: 3907 | H19: 3939 | I19: 3866 | J19: 3458 | K19: 3354 | L19: 3588 | M19: 3814 | N19: 4139 | O19: 4402
I20: =SUM(I14:I19) -> 49331 | J20: =SUM(J14:J19) -> 45825 | K20: =SUM(K14:K19) -> 44322 | L20: =SUM(L14:L19) -> 46638 | M20: =SUM(M14:M19) -> 48866 | N20: =SUM(N14:N19) -> 51559 | O20: =SUM(O14:O19) -> 54351
D23: =1-(D5/D14) -> -0.64774675 | E23: =1-(E5/E14) -> -0.9753886 | F23: =1-(F5/F14) -> -1.0989128 | G23: =1-(G5/G14) -> -0.98666031 | H23: =1-(H5/H14) -> -1.0366737 | I23: =1-(I5/I14) -> -0.73786627 | J23: =1-(J5/J14) -> -0.9396674 | K23: =1-(K5/K14) -> -0.89628233 | ... O23: =1-(O5/O14) -> -0.30039207
B26: *전월 대비 증감 | D26: 23년 | P26: 24년
A27: Sales | D27: 1 | E27: 2 | F27: 3 | G27: 4 | H27: 5 | I27: 6 | J27: 7 | K27: 8 | L27: 9 | M27: 10 | N27: 11 | O27: 12 | P27: 1 | Q27: 2 | R27: 3 | S27: 4 | T27: 5 | U27: Jun. | V27: July | W27: Aug. | X27: Sep. | Y27: Oct. | Z27: Nov. | AA27: Dec. | AB27: 평균
B28: PN | C28: 1 | E28: =1-(D5/E5) -> 0.025692996 | F28: =1-(E5/F5) -> 0.055514892 | G28: =1-(F5/G5) -> -0.064808153 | H28: =1-(G5/H5) -> 0.043468288 | I28: =1-(H5/I5) -> -0.13521255 | J28: =1-(I5/J5) -> -0.020935797 | K28: =1-(J5/K5) -> -0.068759767 | L28: =1-(K5/L5) -> -0.046458039 | ... AA28: =1-(Z5/AA5) -> 0.047624539 | AB28: =AVERAGE(P28:AA28) -> -0.02481988
C29: 2 | E29: =1-(D6/E6) -> -0.14123754 | F29: =1-(E6/F6) -> 0.12438704 | G29: =1-(F6/G6) -> 0.046690611 | H29: =1-(G6/H6) -> 0.060873755 | I29: =1-(H6/I6) -> -0.14455543 | J29: =1-(I6/J6) -> 0.050116414 | K29: =1-(J6/K6) -> 0.028280543 | L29: =1-(K6/L6) -> -0.043314056 | ... AA29: =1-(Z6/AA6) -> 0.029056162 | AB29: =AVERAGE(P29:AA29) -> -0.033003936
C30: 3 | E30: =1-(D7/E7) -> -0.36137967 | F30: =1-(E7/F7) -> 0.18348624 | G30: =1-(F7/G7) -> 0.084212583 | H30: =1-(G7/H7) -> 0.039594671 | I30: =1-(H7/I7) -> -0.10905307 | J30: =1-(I7/J7) -> -0.013499262 | K30: =1-(J7/K7) -> 0.011261731 | L30: =1-(K7/L7) -> -0.034296808 | ... AA30: =1-(Z7/AA7) -> 0.047477745 | AB30: =AVERAGE(P30:AA30) -> -0.015253911
B31: PF | C31: 1 | E31: =1-(D8/E8) -> 0.2783453 | F31: =1-(E8/F8) -> 0.13605383 | G31: =1-(F8/G8) -> 0.22863305 | H31: =1-(G8/H8) -> -0.10051183 | I31: =1-(H8/I8) -> -0.24824074 | J31: =1-(I8/J8) -> 0.026939364 | K31: =1-(J8/K8) -> 0.0060003582 | L31: =1-(K8/L8) -> 0.030476687 | ... AA31: =1-(Z8/AA8) -> 0.059901134 | AB31: =AVERAGE(P31:AA31) -> 0.0082060027
C32: 2 | E32: =1-(D9/E9) -> -0.018719384 | F32: =1-(E9/F9) -> 0.33619789 | G32: =1-(F9/G9) -> 0.54184624 | H32: =1-(G9/H9) -> -0.38985432 | I32: =1-(H9/I9) -> -0.19250441 | J32: =1-(I9/J9) -> 0.012453192 | K32: =1-(J9/K9) -> 0.022473823 | L32: =1-(K9/L9) -> -0.020945594 | ... AA32: =1-(Z9/AA9) -> 0.060021591 | AB32: =AVERAGE(P32:AA32) -> 0.022578296
C33: 3 | E33: =1-(D10/E10) -> 0.018369176 | F33: =1-(E10/F10) -> 0.16184754 | G33: =1-(F10/G10) -> 0.38285052 | H33: =1-(G10/H10) -> 0.099728771 | I33: =1-(H10/I10) -> -0.16873933 | J33: =1-(I10/J10) -> 0.072591588 | K33: =1-(J10/K10) -> 0.027918224 | L33: =1-(K10/L10) -> -0.0090949423 | ... AA33: =1-(Z10/AA10) -> 0.05974557 | AB33: =AVERAGE(P33:AA33) -> -0.0038492011
B34: Total | E34: =1-(D11/E11) -> -0.0062925074 | F34: =1-(E11/F11) -> 0.14233777 | G34: =1-(F11/G11) -> 0.19922365 | H34: =1-(G11/H11) -> -0.055200568 | I34: =1-(H11/I11) -> -0.16764978 | J34: =1-(I11/J11) -> 0.019461944 | K34: =1-(J11/K11) -> 0.0006873389 | L34: =1-(K11/L11) -> -0.023159544 | ... AA34: =1-(Z11/AA11) -> 0.0513698
A37: *판매량(영훈)
A38: Sales | D38: Jun. | E38: July | F38: Aug. | G38: Sep. | H38: Oct. | I38: Nov. | J38: Dec. | K38: Jan. | L38: Feb. | M38: Mar. | N38: Apr. | O38: May. | P38: Jun.
B39: PN | C39: 1 | D39: 8891.25 | E39: 8713.425 | F39: 8626.2908 | G39: 8540.0278 | H39: 8497.3277 | I39: 8582.301 | J39: 8753.947 | K39: 8841.4865 | L39: 8885.6939 | M39: 8796.837 | N39: 8664.8844 | O39: 8751.5333 | P39: 8839.0486
C40: 2 | D40: 9778.75 | E40: 9680.9625 | F40: 9535.7481 | G40: 9488.0693 | H40: 9535.5097 | I40: 9630.8648 | J40: 9823.4821 | K40: 9692.5023 | L40: 9627.8856 | M40: 9563.6997 | N40: 9531.8207 | O40: 9595.3662 | P40: 9723.3044
C41: 3 | D41: 3397.5 | E41: 3380.5125 | F41: 3346.7074 | G41: 3313.2403 | H41: 3329.8065 | I41: 3363.1046 | J41: 3396.7356 | K41: 3374.0907 | L41: 3340.3498 | M41: 3329.2153 | N41: 3340.3127 | O41: 3362.5814 | P41: 3407.4159
B42: PF | C42: 1 | D42: 11908.75 | E42: 11789.663 | F42: 11730.714 | G42: 11848.021 | H42: 11966.502 | I42: 12205.832 | J42: 12449.948 | K42: 12574.448 | L42: 12637.32 | M42: 12510.947 | N42: 12573.501 | O42: 12623.795 | P42: 12497.558
C43: 2 | D43: 10920 | E43: 11138.4 | F43: 11249.784 | G43: 11362.282 | H43: 11248.659 | I43: 11304.902 | J43: 11417.951 | K43: 11341.832 | L43: 11304.026 | M43: 11379.386 | N43: 11455.248 | O43: 11607.985 | P43: 11762.758
C44: 3 | D44: 3888.75 | E44: 3927.6375 | F44: 3947.2757 | G44: 3907.8029 | H44: 3868.7249 | I44: 3849.3813 | J44: 3900.7064 | K44: 3926.7111 | L44: 3952.8891 | M44: 3926.5365 | N44: 3939.625 | O44: 3965.8892 | P44: 3948.263
B45: Total | D45: =SUM(D39:D44) -> 48785 | E45: =SUM(E39:E44) -> 48630.6 | F45: =SUM(F39:F44) -> 48436.52 | G45: =SUM(G39:G44) -> 48459.444 | H45: =SUM(H39:H44) -> 48446.529 | I45: =SUM(I39:I44) -> 48936.385 | J45: =SUM(J39:J44) -> 49742.771 | K45: =SUM(K39:K44) -> 49751.07 | ... P45: =SUM(P39:P44) -> 50178.347

Sheet Sheet1
B3: MONTH | C3: Domestic | D3: Jikgu
B4: 44927 | C4: 53413 | E4: =SUM(C4:D4) -> 53413
B5: 44958 | C5: 53079 | E5: =SUM(C5:D5) -> 53079
B6: 44986 | C6: 61888 | E6: =SUM(C6:D6) -> 61888
B7: 45017 | C7: 77285 | E7: =SUM(C7:D7) -> 77285
B8: 45047 | C8: 73242 | E8: =SUM(C8:D8) -> 73242
B9: 45078 | C9: 62726 | E9: =SUM(C9:D9) -> 62726
B10: 45108 | C10: 63971 | E10: =SUM(C10:D10) -> 63971
B11: 45139 | C11: 64015 | D11: 590 | E11: =SUM(C11:D11) -> 64605
B12: 45170 | C12: 62566 | D12: 3356 | E12: =SUM(C12:D12) -> 65922
B13: 45200 | C13: 58034 | D13: 4851 | E13: =SUM(C13:D13) -> 62885
B14: 45231 | C14: 55759 | D14: 8822 | E14: =SUM(C14:D14) -> 64581
B15: 45261 | C15: 57329 | D15: 13245 | E15: =SUM(C15:D15) -> 70574
B16: 45292 | C16: 54963 | D16: 16019 | E16: =SUM(C16:D16) -> 70982
B17: 45323 | C17: 50663 | D17: 15665 | E17: =SUM(C17:D17) -> 66328
B18: 45352 | C18: 50943 | D18: 23359 | E18: =SUM(C18:D18) -> 74302
B19: 45383 | C19: 49807 | D19: 26822 | E19: =SUM(C19:D19) -> 76629
B20: 45413 | C20: 49161 | D20: 27580 | E20: =SUM(C20:D20) -> 76741
B21: 45444 | C21: 49331 | D21: 22165 | E21: =SUM(C21:D21) -> 71496
B22: 45474 | C22: 45825 | D22: 26179 | E22: =SUM(C22:D22) -> 72004
... B33: 45809 | C33: 53273.97 | D33: 46684.514 | E33: =SUM(C33:D33) -> 99958.484

Sheet 크로네
B3: *발주 | E3: 1Q | H3: 2Q | K3: 3Q | N3: 4Q
E4: Oct | F4: Nov | G4: Dec | H4: Jan | I4: Feb | J4: Mar | K4: Apr | L4: May | M4: Jun. | N4: July. | O4: Aug. | P4: Sep.
C5: PN | D5: Pre | M5: 2160 | N5: 4860 | O5: 4000
D6: 1 | F6: 5940 | G6: 5130 | L6: 9984 | N6: 1080
D7: 1 X 1200G | I7: 5130 | N7: 4992
D8: 2 | G8: 810 | I8: 810 | K8: 5940 | L8: 21504 | M8: 3780
D9: 2 X 1200G | H9: 10752 | I9: 10752 | J9: 11520 | N9: 4992
D10: 3 | F10: 16128 | H10: 13056 | I10: 14592 | J10: 13824
C11: PF | D11: Pre | K11: 3840 | M11: 2688 | N11: 1152 | O11: 8000 | P11: 8000
D12: 1 | F12: 384 | H12: 1536 | K12: 9984 | M12: 14592 | N12: 25344 | O12: 15000 | P12: 14000
D13: 2 | F13: 384 | K13: 11520 | M13: 13824 | N13: 20736 | O13: 11000 | P13: 15000
D14: Kinder 1 | L14: 2304 | M14: 1152 | N14: 3456 | O14: 2000 | P14: 1500
D15: Kinder 2 | M15: 1536
D16: AR | K16: 3024 | M16: 2016
D17: Comfort | K17: 1008
C18: Total | E18: =SUM(E5:E17) -> 0 | F18: =SUM(F5:F17) -> 22836 | G18: =SUM(G5:G17) -> 5940 | H18: =SUM(H5:H17) -> 25344 | I18: =SUM(I5:I17) -> 31284 | J18: =SUM(J5:J17) -> 25344 | K18: =SUM(K5:K17) -> 35316 | L18: =SUM(L5:L17) -> 33792 | ... P18: =SUM(P5:P17) -> 38500
C19: 발주 금액(EUR) | E19: =단가!D50 -> 0 | F19: =단가!E50 -> 330394.8 | G19: =단가!F50 -> 84942 | H19: =단가!G50 -> 423859.2 | I19: =단가!H50 -> 526771.2 | J19: =단가!I50 -> 420019.2 | K19: =단가!J50 -> 607272.96 | L19: =단가!K50 -> 499123.2 | ... P19: =단가!O50 -> 745900
C20: 발주 금액(KRW) | E20: =단가!D51 -> 0 | F20: =단가!E51 -> 4.8131254e+08 | G20: =단가!F51 -> 1.2374181e+08 | H20: =단가!G51 -> 6.1746961e+08 | I20: =단가!H51 -> 7.6738975e+08 | J20: =단가!I51 -> 6.1187557e+08 | K20: =단가!J51 -> 8.846631e+08 | L20: =단가!K51 -> 7.271127e+08 | ... P20: =단가!O51 -> 1086612202
B22: *제조 | E22: 1Q | H22: 2Q | K22: 3Q | N22: 4Q
B23: 발주 월 | E23: Oct | F23: Nov | G23: Dec | H23: Jan | I23: Feb | J23: Mar | K23: Apr. | L23: May. | M23: Jun. | N23: July. | O23: Aug. | P23: Sep.
B24: 제조 월 | E24: Jan | F24: Feb | G24: Mar | H24: Apr | I24: May | J24: June | K24: July. | L24: Aug. | M24: Sep. | N24: Oct. | O24: Nov. | P24: Dec.
C25: PN | D25: Pre | E25: =E5 -> 0 | F25: =F5 -> 0 | G25: =G5 -> 0 | H25: =H5 -> 0 | I25: =I5 -> 0 | J25: =J5 -> 0 | K25: =K5 -> 0 | L25: =L5 -> 0 | ... P25: =P5 -> 0
D26: 1 | E26: =E6 -> 0 | F26: =F6 -> 5940 | G26: =G6 -> 5130 | H26: =H6 -> 0 | I26: =I6 -> 0 | J26: =J6 -> 0 | K26: =K6 -> 0 | L26: =L6 -> 9984 | ... P26: =P6 -> 0
D27: 2 | E27: =E8 -> 0 | F27: =F8 -> 0 | G27: =G8 -> 810 | H27: =H8 -> 0 | I27: =I8 -> 810 | J27: =J8 -> 0 | K27: =K8 -> 5940 | L27: =L8 -> 21504 | ... P27: =P8 -> 0
D28: 3 | E28: =E10 -> 0 | F28: =F10 -> 16128 | G28: =G10 -> 0 | H28: =H10 -> 13056 | I28: =I10 -> 14592 | J28: =J10 -> 13824 | K28: =K10 -> 0 | L28: =L10 -> 0 | ... P28: =P10 -> 0
C29: PF | D29: Pre | E29: =E11 -> 0 | F29: =F11 -> 0 | G29: =G11 -> 0 | H29: =H11 -> 0 | I29: =I11 -> 0 | J29: =J11 -> 0 | K29: =K11 -> 3840 | L29: =L11 -> 0 | ... P29: =P11 -> 8000
D30: 1 | E30: =E12 -> 0 | F30: =F12 -> 384 | G30: =G12 -> 0 | H30: =H12 -> 1536 | I30: =I12 -> 0 | J30: =J12 -> 0 | K30: =K12 -> 9984 | L30: =L12 -> 0 | ... P30: =P12 -> 14000
D31: 2 | E31: =E13 -> 0 | F31: =F13 -> 384 | G31: =G13 -> 0 | H31: =H13 -> 0 | I31: =I13 -> 0 | J31: =J13 -> 0 | K31: =K13 -> 11520 | L31: =L13 -> 0 | ... P31: =P13 -> 15000
D32: Kinder | E32: =E14 -> 0 | F32: =F14 -> 0 | G32: =G14 -> 0 | H32: =H14 -> 0 | I32: =I14 -> 0 | J32: =J14 -> 0 | K32: =K14 -> 0 | L32: =L14 -> 2304 | ... P32: =P14 -> 1500
D33: Kinder 2 | E33: =E15 -> 0 | F33: =F15 -> 0 | G33: =G15 -> 0 | H33: =H15 -> 0 | I33: =I15 -> 0 | J33: =J15 -> 0 | K33: =K15 -> 0 | L33: =L15 -> 0 | ... P33: =P15 -> 0
D34: AR | E34: =E16 -> 0 | F34: =F16 -> 0 | G34: =G16 -> 0 | H34: =H16 -> 0 | I34: =I16 -> 0 | J34: =J16 -> 0 | K34: =K16 -> 3024 | L34: =L16 -> 0 | ... P34: =P16 -> 0
D35: Comfort | E35: =E17 -> 0 | F35: =F17 -> 0 | G35: =G17 -> 0 | H35: =H17 -> 0 | I35: =I17 -> 0 | J35: =J17 -> 0 | K35: =K17 -> 1008 | L35: =L17 -> 0 | ... P35: =P17 -> 0
C36: Total | E36: =SUM(E25:E35) -> 0 | F36: =SUM(F25:F35) -> 22836 | G36: =SUM(G25:G35) -> 5940 | H36: =SUM(H25:H35) -> 14592 | I36: =SUM(I25:I35) -> 15402 | J36: =SUM(J25:J35) -> 13824 | K36: =SUM(K25:K35) -> 35316 | L36: =SUM(L25:L35) -> 33792 | ... P36: =SUM(P25:P35) -> 38500
C37: 발주 금액(EUR) | E37: =단가!D50 -> 0 | F37: =단가!E50 -> 330394.8 | G37: =단가!F50 -> 84942 | H37: =단가!G50 -> 423859.2 | I37: =단가!H50 -> 526771.2 | J37: =단가!I50 -> 420019.2 | K37: =단가!J50 -> 607272.96 | L37: =단가!K50 -> 499123.2 | ... P37: =단가!O50 -> 745900
C38: 발주 금액(KRW) | E38: =단가!D51 -> 0 | F38: =단가!E51 -> 4.8131254e+08 | G38: =단가!F51 -> 1.2374181e+08 | H38: =단가!G51 -> 6.1746961e+08 | I38: =단가!H51 -> 7.6738975e+08 | J38: =단가!I51 -> 6.1187557e+08 | K38: =단가!J51 -> 8.846631e+08 | L38: =단가!K51 -> 7.271127e+08 | ... P38: =단가!O51 -> 1086612202
B42: *발주 목표 | E42: 0 | H42: 0 | K42: 2159000 | N42: 2160000
E43: Oct | F43: Nov | G43: Dec | H43: Jan | I43: Feb | J43: Mar | K43: Apr. | L43: May. | M43: Jun. | N43: July. | O43: Aug. | P43: Sep.
C44: 발주 금액(EUR) | K44: =$K$42/3 -> 719666.67 | L44: =$K$42/3 -> 719666.67 | M44: =$K$42/3 -> 719666.67 | N44: =$N$42/3 -> 720000 | O44: =$N$42/3 -> 720000 | P44: =$N$42/3 -> 720000
C45: 발주 금액(KRW) | K45: =K44*단가!$F$2 -> 1.048396e+09 | L45: =L44*단가!$F$2 -> 1.048396e+09 | M45: =M44*단가!$F$2 -> 1.048396e+09 | N45: =N44*단가!$F$2 -> 1048881600 | O45: =O44*단가!$F$2 -> 1048881600 | P45: =P44*단가!$F$2 -> 1048881600
B47: * 차이 | O47: (EUR)
...

Sheet 직구 판매량
A3: Sales | D3: Aug. | E3: Sep. | F3: Oct. | G3: Nov. | H3: Dec. | I3: Jan. | J3: Feb. | K3: Mar. | L3: Apr. | M3: May. | N3: Jun. | O3: July | P3: Aug. | Q3: Sep. | R3: Oct. | S3: Nov. | T3: Dec. | U3: Jan. | V3: Feb. | W3: Mar. | X3: Apr. | Y3: May. | Z3: Jun.
A4: Sales CU | B4: PN | C4: Pre | D4: 6 | E4: 88 | F4: 67 | G4: 150 | H4: 250 | I4: 377 | J4: 342 | K4: 302 | L4: 565 | M4: 470 | N4: 711 | O4: 533.9 | P4: 550.05 | Q4: 643.68 | R4: =Q4+(R18*Q4) -> 662.5501 | S4: =R4+(S18*R4) -> 682.43707 | T4: =S4+(T18*S4) -> 699.2614 | U4: =T4+(U18*T4) -> 720.23924 | V4: =U4+(V18*U4) -> 741.84642 | W4: =V4+(W18*V4) -> 764.10181 | X4: =W4+(X18*W4) -> 794.66589 | Y4: =X4+(Y18*X4) -> 818.50586 | Z4: =Y4+(Z18*Y4) -> 843.06104 | AA4: =Q4*0.1 -> 64.368 | AB4: =Q4-AA4 -> 579.312
C5: 1 | D5: 22 | E5: 138 | F5: 316 | G5: 832 | H5: 1229 | I5: 1014 | J5: 933 | K5: 743 | L5: 744 | M5: 700 | N5: 711 | O5: 587.1 | P5: 589.95 | Q5: 677.16 | R5: =Q5+(R19*Q5) -> 687.79046 | S5: =R5+(S19*R5) -> 700.50769 | T5: =S5+(T19*S5) -> 721.44962 | U5: =T5+(U19*T5) -> 743.09311 | V5: =U5+(V19*U5) -> 765.38591 | W5: =V5+(W19*V5) -> 788.34748 | X5: =W5+(X19*W5) -> 819.88138 | Y5: =X5+(Y19*X5) -> 844.47782 | Z5: =Y5+(Z19*Y5) -> 869.81216 | AA5: =Q5*0.1 -> 67.716 | AB5: =Q5-AA5 -> 609.444
C6: 2 | D6: 10 | E6: 68 | F6: 161 | G6: 275 | H6: 761 | I6: 743 | J6: 1467 | K6: 1179 | L6: 1336 | M6: 1178 | N6: 1026 | O6: 1583.65 | P6: 1615.95 | Q6: 1873.8 | R6: =Q6+(R20*Q6) -> 1910.8525 | S6: =R6+(S20*R6) -> 1966.4067 | T6: =S6+(T20*S6) -> 2022.9788 | U6: =T6+(U20*T6) -> 2083.6682 | V6: =U6+(V20*U6) -> 2146.1783 | W6: =V6+(W20*V6) -> 2253.4872 | X6: =W6+(X20*W6) -> 2411.2313 | Y6: =X6+(Y20*X6) -> 2652.3544 | Z6: =Y6+(Z20*Y6) -> 2970.6369 | AA6: =Q6*0.1 -> 187.38 | AB6: =Q6-AA6 -> 1686.42
C7: 3 | D7: 0 | E7: 4 | F7: 8 | G7: 24 | H7: 232 | I7: 207 | J7: 358 | K7: 105 | L7: 86 | M7: 94 | N7: 86 | O7: 88.35 | P7: 91.2 | Q7: 106.92 | R7: =Q7+(R21*Q7) -> 110.06471 | S7: =R7+(S21*R7) -> 113.20941 | T7: =S7+(T21*S7) -> 116.35412 | U7: =T7+(U21*T7) -> 119.84474 | V7: =U7+(V21*U7) -> 123.44008 | W7: =V7+(W21*V7) -> 132.08089 | X7: =W7+(X21*W7) -> 145.28898 | Y7: =X7+(Y21*X7) -> 154.00632 | Z7: =Y7+(Z21*Y7) -> 161.70663 | AA7: =Q7*0.1 -> 10.692 | AB7: =Q7-AA7 -> 96.228
B8: PF | C8: Pre | D8: 184 | E8: 1248 | F8: 1712 | G8: 2254 | H8: 3248 | I8: 4757 | J8: 3703 | K8: 5085 | L8: 4611 | M8: 5026 | N8: 4541 | O8: 4922.9 | P8: 5071.1 | Q8: 6597.6 | R8: =Q8+(R22*Q8) -> 6789.831 | S8: =R8+(S22*R8) -> 6987.7174 | T8: =S8+(T22*S8) -> 7168.5951 | U8: =T8+(U22*T8) -> 7383.653 | V8: =U8+(V22*U8) -> 7605.1626 | W8: =V8+(W22*V8) -> 7833.3175 | X8: =W8+(X22*W8) -> 8303.3165 | Y8: =X8+(Y22*X8) -> 8718.4823 | Z8: =Y8+(Z22*Y8) -> 8980.0368
C9: 1 | D9: 258 | E9: 1350 | F9: 1896 | G9: 4155 | H9: 5197 | I9: 6023 | J9: 5139 | K9: 7077 | L9: 6977 | M9: 8068 | N9: 7701 | O9: 7876.45 | P9: 8113 | Q9: 10555.2 | R9: =Q9+(R23*Q9) -> 10862.769 | S9: =R9+(S23*R9) -> 11179.386 | T9: =S9+(T23*S9) -> 11468.79 | U9: =T9+(U23*T9) -> 11812.854 | V9: =U9+(V23*U9) -> 12167.239 | W9: =V9+(W23*V9) -> 12532.256 | X9: =W9+(X23*W9) -> 13284.192 | Y9: =X9+(Y23*X9) -> 13948.401 | Z9: =Y9+(Z23*Y9) -> 14366.853
C10: 2 | D10: 110 | E10: 460 | F10: 691 | G10: 1132 | H10: 2328 | I10: 2898 | J10: 3723 | K10: 8699 | L10: 11723 | M10: 11363 | N10: 6506 | O10: 8354.3 | P10: 8605.1 | Q10: 11196 | R10: =Q10+(R24*Q10) -> 11522.21 | S10: =R10+(S24*R10) -> 11857.469 | T10: =S10+(T24*S10) -> 12165.516 | U10: =T10+(U24*T10) -> 12530.482 | V10: =U10+(V24*U10) -> 12906.396 | W10: =V10+(W24*V10) -> 13293.588 | X10: =W10+(X24*W10) -> 13692.396 | Y10: =X10+(Y24*X10) -> 14103.168 | Z10: =Y10+(Z24*Y10) -> 14526.263
C11: Kinder | K11: 27 | L11: 400 | M11: 335 | N11: 446 | O11: 466.45 | P11: 513 | Q11: 712.8 | R11: =Q11+(R25*Q11) -> 727.056 | S11: =R11+(S25*R11) -> 741.59712 | T11: =S11+(T25*S11) -> 756.42906 | U11: =T11+(U25*T11) -> 771.55764 | V11: =U11+(V25*U11) -> 786.9888 | W11: =V11+(W25*V11) -> 802.72857 | X11: =W11+(X25*W11) -> 818.78314 | Y11: =X11+(Y25*X11) -> 835.15881 | Z11: =Y11+(Z25*Y11) -> 851.86198
C12: AR | K12: 116 | L12: 274 | M12: 260 | N12: 317 | O12: 331.55 | P12: 364.8 | Q12: 506.4 | R12: =Q12+(R26*Q12) -> 516.528 | S12: =R12+(S26*R12) -> 526.85856 | T12: =S12+(T26*S12) -> 537.39573 | U12: =T12+(U26*T12) -> 548.14365 | V12: =U12+(V26*U12) -> 559.10652 | W12: =V12+(W26*V12) -> 570.28865 | X12: =W12+(X26*W12) -> 581.69442 | Y12: =X12+(Y26*X12) -> 593.32831 | Z12: =Y12+(Z26*Y12) -> 605.19488
C13: Comfort | K13: 26 | L13: 106 | M13: 86 | N13: 120 | O13: 125.4 | P13: 137.75 | Q13: 192 | R13: =Q13+(R27*Q13) -> 195.84 | S13: =R13+(S27*R13) -> 199.7568 | T13: =S13+(T27*S13) -> 203.75194 | U13: =T13+(U27*T13) -> 207.82697 | V13: =U13+(V27*U13) -> 211.98351 | W13: =V13+(W27*V13) -> 216.22318 | X13: =W13+(X27*W13) -> 220.54765 | Y13: =X13+(Y27*X13) -> 224.9586 | Z13: =Y13+(Z27*Y13) -> 229.45777
B14: Total | D14: =SUM(D4:D13) -> 590 | E14: =SUM(E4:E13) -> 3356 | F14: =SUM(F4:F13) -> 4851 | G14: =SUM(G4:G13) -> 8822 | H14: =SUM(H4:H13) -> 13245 | I14: =SUM(I4:I13) -> 16019 | J14: =SUM(J4:J13) -> 15665 | K14: =SUM(K4:K13) -> 23359 | ... Z14: =SUM(Z4:Z13) -> 44404.884
A17: Sales | D17: Aug. | E17: Sep. | F17: Oct. | G17: Nov. | H17: Dec. | I17: Jan. | J17: Feb. | K17: Mar. | L17: Apr. | M17: May. | N17: Jun. | O17: July | P17: Aug. | Q17: Sep. | R17: Oct. | S17: Nov. | T17: Dec. | U17: Jan. | V17: Feb. | W17: Mar. | X17: Apr. | Y17: May. | Z17: Jun.
A18: Sales CU | B18: PN | C18: Pre | E18: =1-(D4/E4) -> 0.93181818 | F18: =1-(E4/F4) -> -0.31343284 | G18: =1-(F4/G4) -> 0.55333333 | H18: =1-(G4/H4) -> 0.4 | I18: =1-(H4/I4) -> 0.33687003 | J18: =1-(I4/J4) -> -0.10233918 | K18: =1-(J4/K4) -> -0.13245033 | L18: =1-(K4/L4) -> 0.46548673 | ... Q18: =1-(P4/Q4) -> 0.14546048 | R18: 0.029315961 | S18: 0.030015798 | T18: 0.024653313 | U18: 0.03 | V18: 0.03 | W18: 0.03 | X18: 0.04 | Y18: 0.03 | Z18: 0.03
C19: 1 | E19: =1-(D5/E5) -> 0.84057971 | F19: =1-(E5/F5) -> 0.56329114 | G19: =1-(F5/G5) -> 0.62019231 | H19: =1-(G5/H5) -> 0.32302685 | I19: =1-(H5/I5) -> -0.21203156 | J19: =1-(I5/J5) -> -0.08681672 | K19: =1-(J5/K5) -> -0.25572005 | L19: =1-(K5/L5) -> 0.001344086 | ... Q19: =1-(P5/Q5) -> 0.12878788 | R19: 0.015698587 | S19: 0.018489985 | T19: 0.029895366 | U19: 0.03 | V19: 0.03 | W19: 0.03 | X19: 0.04 | Y19: 0.03 | Z19: 0.03
C20: 2 | E20: =1-(D6/E6) -> 0.85294118 | F20: =1-(E6/F6) -> 0.57763975 | G20: =1-(F6/G6) -> 0.41454545 | H20: =1-(G6/H6) -> 0.63863338 | I20: =1-(H6/I6) -> -0.02422611 | J20: =1-(I6/J6) -> 0.4935242 | K20: =1-(J6/K6) -> -0.24427481 | L20: =1-(K6/L6) -> 0.11751497 | ... Q20: =1-(P6/Q6) -> 0.13760807 | R20: 0.019774011 | S20: 0.029072957 | T20: 0.028769313 | U20: 0.03 | V20: 0.03 | W20: 0.05 | X20: 0.07 | Y20: 0.1 | Z20: 0.12
C21: 3 | E21: =1-(D7/E7) -> 1 | F21: =1-(E7/F7) -> 0.5 | G21: =1-(F7/G7) -> 0.66666667 | H21: =1-(G7/H7) -> 0.89655172 | I21: =1-(H7/I7) -> -0.12077295 | J21: =1-(I7/J7) -> 0.42178771 | K21: =1-(J7/K7) -> -2.4095238 | L21: =1-(K7/L7) -> -0.22093023 | ... Q21: =1-(P7/Q7) -> 0.14702581 | R21: 0.029411765 | S21: 0.028571429 | T21: 0.027777778 | U21: 0.03 | V21: 0.03 | W21: 0.07 | X21: 0.1 | Y21: 0.06 | Z21: 0.05
B22: PF | C22: Pre | E22: =1-(D8/E8) -> 0.8525641 | F22: =1-(E8/F8) -> 0.27102804 | G22: =1-(F8/G8) -> 0.2404614 | H22: =1-(G8/H8) -> 0.30603448 | I22: =1-(H8/I8) -> 0.31721673 | J22: =1-(I8/J8) -> -0.28463408 | K22: =1-(J8/K8) -> 0.27177974 | L22: =1-(K8/L8) -> -0.10279766 | ... Q22: =1-(P8/Q8) -> 0.23137201 | R22: 0.0291365 | S22: 0.029144523 | T22: 0.025885104 | U22: 0.03 | V22: 0.03 | W22: 0.03 | X22: 0.06 | Y22: 0.05 | Z22: 0.03
C23: 1 | E23: =1-(D9/E9) -> 0.80888889 | F23: =1-(E9/F9) -> 0.28797468 | G23: =1-(F9/G9) -> 0.54368231 | H23: =1-(G9/H9) -> 0.20050029 | I23: =1-(H9/I9) -> 0.13714096 | J23: =1-(I9/J9) -> -0.1720179 | K23: =1-(J9/K9) -> 0.27384485 | L23: =1-(K9/L9) -> -0.014332808 | ... Q23: =1-(P9/Q9) -> 0.23137411 | R23: 0.029139073 | S23: 0.029147021 | T23: 0.025887265 | U23: 0.03 | V23: 0.03 | W23: 0.03 | X23: 0.06 | Y23: 0.05 | Z23: 0.03
C24: 2 | E24: =1-(D10/E10) -> 0.76086957 | F24: =1-(E10/F10) -> 0.33429812 | G24: =1-(F10/G10) -> 0.38957597 | H24: =1-(G10/H10) -> 0.5137457 | I24: =1-(H10/I10) -> 0.19668737 | J24: =1-(I10/J10) -> 0.22159549 | K24: =1-(J10/K10) -> 0.57201977 | L24: =1-(K10/L10) -> 0.25795445 | ... Q24: =1-(P10/Q10) -> 0.231413 | R24: 0.029136316 | S24: 0.029096787 | T24: 0.025979138 | U24: 0.03 | V24: 0.03 | W24: 0.03 | X24: 0.03 | Y24: 0.03 | Z24: 0.03
C25: Kinder | L25: =1-(K11/L11) -> 0.9325 | M25: =1-(L11/M11) -> -0.19402985 | N25: =1-(M11/N11) -> 0.24887892 | O25: =1-(N11/O11) -> 0.043841784 | P25: =1-(O11/P11) -> 0.090740741 | Q25: 0.03 | R25: 0.02 | S25: 0.02 | T25: 0.02 | U25: 0.02 | V25: 0.02 | W25: 0.02 | X25: 0.02 | Y25: 0.02 | Z25: 0.02
C26: AR | L26: =1-(K12/L12) -> 0.57664234 | M26: =1-(L12/M12) -> -0.053846154 | N26: =1-(M12/N12) -> 0.17981073 | O26: =1-(N12/O12) -> 0.043884784 | P26: =1-(O12/P12) -> 0.091145833 | Q26: =1-(P12/Q12) -> 0.27962085 | R26: 0.02 | S26: 0.02 | T26: 0.02 | U26: 0.02 | V26: 0.02 | W26: 0.02 | X26: 0.02 | Y26: 0.02 | Z26: 0.02
C27: Comfort | L27: =1-(K13/L13) -> 0.75471698 | M27: =1-(L13/M13) -> -0.23255814 | N27: =1-(M13/N13) -> 0.28333333 | O27: =1-(N13/O13) -> 0.043062201 | P27: =1-(O13/P13) -> 0.089655172 | Q27: =1-(P13/Q13) -> 0.28255208 | R27: 0.02 | S27: 0.02 | T27: 0.02 | U27: 0.02 | V27: 0.02 | W27: 0.02 | X27: 0.02 | Y27: 0.02 | Z27: 0.02
B28: Total
V30: 1 | W30: -0.0035452612 | X30: -0.0078608861 | Y30: 0.019387993 | Z30: 0.031338387
V31: 2 | W31: -0.023718763 | X31: -0.037255074 | Y31: -0.073173032 | Z31: -0.085576825
V32: 3 | W32: 0.042343542 | X32: -0.073470555 | Y32: 0.028333333 | Z32: -0.021856372
V33: 1 | W33: -0.0016157699 | X33: -0.034344447 | Y33: -0.021598088 | Z33: 0.022122047
V34: 2 | W34: 0.0085832676 | X34: 0.048977294 | Y34: 0.0077273997 | Z34: 0.054073096
V35: 3 | W35: 0.08259587 | X35: -0.12797543 | Y35: 0.0081238893 | Z35: -0.018882566
A38: *판매량 | G38: 누트라 10, 푸트라20 업
A39: Sales | D39: Jun. | E39: July | F39: Aug. | G39: Sep. | H39: Oct. | I39: Nov. | J39: Dec. | K39: Jan. | L39: Feb. | M39: Mar. | N39: Apr. | O39: May. | P39: Jun.
B40: PN | C40: Pre | D40: 711 | E40: 533.9 | F40: 550.05 | G40: 643.68 | H40: 662.5501 | I40: 682.43707 | J40: 699.2614 | K40: 720.23924 | L40: 741.84642 | M40: 764.10181 | N40: 794.66589 | O40: 818.50586 | P40: 843.06104
C41: 1 | D41: 711 | E41: 587.1 | F41: 589.95 | G41: 677.16 | H41: 687.79046 | I41: 700.50769 | J41: 721.44962 | K41: 743.09311 | L41: 765.38591 | M41: 788.34748 | N41: 819.88138 | O41: 844.47782 | P41: 869.81216
C42: 2 | D42: 1026 | E42: 1583.65 | F42: 1615.95 | G42: 1873.8 | H42: 1910.8525 | I42: 1966.4067 | J42: 2022.9788 | K42: 2083.6682 | L42: 2146.1783 | M42: 2253.4872 | N42: 2411.2313 | O42: 2652.3544 | P42: 2970.6369
C43: 3 | D43: 86 | E43: 88.35 | F43: 91.2 | G43: 106.92 | H43: 110.06471 | I43: 113.20941 | J43: 116.35412 | K43: 119.84474 | L43: 123.44008 | M43: 132.08089 | N43: 145.28898 | O43: 154.00632 | P43: 161.70663
B44: PF | C44: Pre | D44: 4541 | E44: 4922.9 | F44: 5071.1 | G44: 6597.6 | H44: 6789.831 | I44: 6987.7174 | J44: 7168.5951 | K44: 7383.653 | L44: 7605.1626 | M44: 7833.3175 | N44: 8303.3165 | O44: 8718.4823 | P44: 8980.0368
C45: 1 | D45: 7701 | E45: 7876.45 | F45: 8113 | G45: 10555.2 | H45: 10862.769 | I45: 11179.386 | J45: 11468.79 | K45: 11812.854 | L45: 12167.239 | M45: 12532.256 | N45: 13284.192 | O45: 13948.401 | P45: 14366.853
C46: 2 | D46: 6506 | E46: 8354.3 | F46: 8605.1 | G46: 11196 | H46: 11522.21 | I46: 11857.469 | J46: 12165.516 | K46: 12530.482 | L46: 12906.396 | M46: 13293.588 | N46: 13692.396 | O46: 14103.168 | P46: 14526.263
C47: Kinder | D47: 446 | E47: 466.45 | F47: 513 | G47: 712.8 | H47: 727.056 | I47: 741.59712 | J47: 756.42906 | K47: 771.55764 | L47: 786.9888 | M47: 802.72857 | N47: 818.78314 | O47: 835.15881 | P47: 851.86198
...

Sheet 단가
A1: 구분 | B1: 코드 | D1: 박스 금액 | E1: 캔당금액 | F1: 환율 | G1: 박스 금액 | H1: 캔당금액
A2: 내수 | B2: 676366 | C2: APTAMIL 1 KOR 4X800G | D2: 63.18 | E2: =D2/4 -> 15.795 | F2: 1456.78 | G2: 92039.36 | H2: 23009.84
A3: 내수 | B3: 676367 | C3: APTAMIL 2 KOR 4X800G | D3: 63.18 | E3: =D3/4 -> 15.795 | F3: 1456.78 | G3: 92039.36 | H3: 23009.84
A4: 내수 | B4: 676369 | C4: APTAMIL 3 KOR 4X800G | D4: 63.18 | E4: =D4/4 -> 15.795 | F4: 1456.78 | G4: 92039.36 | H4: 23009.84
A5: 내수 | B5: 677211 | C5: APTAMIL PROFUTURA 1 4X800G KOR | D5: 85.32 | E5: =D5/4 -> 21.33 | F5: 1456.78 | G5: 124292.47 | H5: 31073.12
A6: 내수 | B6: 677200 | C6: APTAMIL PROFUTURA 2 4X800G KOR | D6: 85.32 | E6: =D6/4 -> 21.33 | F6: 1456.78 | G6: 124292.47 | H6: 31073.12
A7: 내수 | B7: 677281 | C7: APTAMIL PROFUTURA 3 4X800G KOR | D7: 85.32 | E7: =D7/4 -> 21.33 | F7: 1456.78 | G7: 124292.47 | H7: 31073.12
A8: 직구 | B8: 673676 | C8: APTAMIL PRE 6X800G CR/SL | D8: 85.8 | E8: =D8/6 -> 14.3 | F8: 1456.78 | G8: 124991.72 | H8: 31247.93
A9: 직구 | B9: 673674 | C9: APTAMIL 1 6X800G CR/SL | D9: 85.8 | E9: =D9/6 -> 14.3 | F9: 1456.78 | G9: 124991.72 | H9: 31247.93
A10: 직구 | B10: 673672 | C10: APTAMIL 2 6X800G CR/SL | D10: 85.8 | E10: =D10/6 -> 14.3 | F10: 1456.78 | G10: 124991.72 | H10: 31247.93
A11: 직구 | B11: 673641 | C11: APTAMIL 3 6X800G CR/SL | D11: 85.8 | E11: =D11/6 -> 14.3 | F11: 1456.78 | G11: 124991.72 | H11: 31247.93
A12: 직구 | B12: 677044 | C12: APT PROFUTURA PRE, KOR 4X800G | D12: 77.2 | E12: =D12/4 -> 19.3 | F12: 1456.78 | G12: 112463.42 | H12: 28115.85
A13: 직구 | B13: 677045 | C13: APT PROFUTURA 1, KOR 4X800G | D13: 77.2 | E13: =D13/4 -> 19.3 | F13: 1456.78 | G13: 112463.42 | H13: 28115.85
A14: 직구 | B14: 677047 | C14: APT PROFUTURA 2, KOR 4X800G | D14: 77.2 | E14: =D14/4 -> 19.3 | F14: 1456.78 | G14: 112463.42 | H14: 28115.85
B15: 698408 | C15: 압타밀 프로푸트라 YCF | D15: 84.8 | E15: 21.2 | F15: 1456.78 | G15: 123534.94 | H15: 30883.74
B16: 653156 | C16: 압타밀 AR | D16: 197.57 | E16: =D16/24 -> 8.2320833 | F16: 1456.78 | G16: 287816.02 | H16: 11992.33
B17: 653299 | C17: 압타밀 COMFORT | D17: 197.57 | E17: =D17/24 -> 8.2320833 | F17: 1456.78 | G17: 287816.02 | H17: 11992.33
C18: 1 X 1200G | E18: 19.3
A21: 아이베
A22: Supply (arrival) | D22: Oct | E22: Nov | F22: Dec | G22: Jan | H22: Feb | I22: Mar | J22: Apr | K22: May | L22: Jun. | M22: July. | N22: Aug. | O22: Sep. | P22: Oct. | Q22: Nov. | R22: Dec. | U22: Supply (arrival) | X22: Jan | Y22: Feb | Z22: Mar | AA22: Apr | AB22: May | AC22: June | AD22: July. | AE22: Aug. | AF22: Sep. | AG22: Oct. | AH22: Nov. | AI22: Dec.
B23: PN | C23: 1 | D23: =아이베!E5*단가!$E2 -> 0 | E23: =아이베!F5*단가!$E2 -> 0 | F23: =아이베!G5*단가!$E2 -> 45489.6 | G23: =아이베!H5*단가!$E2 -> 0 | H23: =아이베!I5*단가!$E2 -> 0 | I23: =아이베!J5*단가!$E2 -> 0 | J23: =아이베!K5*단가!$E2 -> 0 | K23: =아이베!L5*단가!$E2 -> 45489.6 | ... O23: =아이베!P5*단가!$E2 -> 142155 | P23: =아이베!#REF!*단가!$E2 -> #REF! | Q23: =아이베!#REF!*단가!$E2 -> #REF! | R23: =아이베!#REF!*단가!$E2 -> #REF! | V23: PN | W23: 1 | X23: =아이베!E18*$E$2 -> 0 | Y23: =아이베!F18*$E$2 -> 0 | Z23: =아이베!G18*$E$2 -> 45489.6 | AA23: =아이베!H18*$E$2 -> 0 | AB23: =아이베!I18*$E$2 -> 0 | AC23: =아이베!J18*$E$2 -> 0 | AD23: =아이베!K18*$E$2 -> 0 | AE23: =아이베!L18*$E$2 -> 45489.6 | ... AI23: =아이베!P18*$E$2 -> 142155
C24: 2 | D24: =아이베!E6*단가!$E3 -> 145566.72 | E24: =아이베!F6*단가!$E3 -> 90979.2 | F24: =아이베!G6*단가!$E3 -> 154664.64 | G24: =아이베!H6*단가!$E3 -> 0 | H24: =아이베!I6*단가!$E3 -> 0 | I24: =아이베!J6*단가!$E3 -> 0 | J24: =아이베!K6*단가!$E3 -> 0 | K24: =아이베!L6*단가!$E3 -> 154664.64 | ... O24: =아이베!P6*단가!$E3 -> 110565 | P24: =아이베!#REF!*단가!$E3 -> #REF! | Q24: =아이베!#REF!*단가!$E3 -> #REF! | R24: =아이베!#REF!*단가!$E3 -> #REF! | W24: 2 | X24: =아이베!E19*$E$3 -> 145566.72 | Y24: =아이베!F19*$E$3 -> 90979.2 | Z24: =아이베!G19*$E$3 -> 154664.64 | AA24: =아이베!H19*$E$3 -> 0 | AB24: =아이베!I19*$E$3 -> 0 | AC24: =아이베!J19*$E$3 -> 0 | AD24: =아이베!K19*$E$3 -> 0 | AE24: =아이베!L19*$E$3 -> 154664.64 | ... AI24: =아이베!P19*$E$3 -> 110565
C25: 3 | D25: =아이베!E7*단가!$E4 -> 254741.76 | E25: =아이베!F7*단가!$E4 -> 109175.04 | F25: =아이베!G7*단가!$E4 -> 0 | G25: =아이베!H7*단가!$E4 -> 0 | H25: =아이베!I7*단가!$E4 -> 0 | I25: =아이베!J7*단가!$E4 -> 0 | J25: =아이베!K7*단가!$E4 -> 0 | K25: =아이베!L7*단가!$E4 -> 0 | ... O25: =아이베!P7*단가!$E4 -> 47385 | P25: =아이베!#REF!*단가!$E4 -> #REF! | Q25: =아이베!#REF!*단가!$E4 -> #REF! | R25: =아이베!#REF!*단가!$E4 -> #REF! | W25: 3 | X25: =아이베!E20*$E$4 -> 254741.76 | Y25: =아이베!F20*$E$4 -> 109175.04 | Z25: =아이베!G20*$E$4 -> 0 | AA25: =아이베!H20*$E$4 -> 0 | AB25: =아이베!I20*$E$4 -> 0 | AC25: =아이베!J20*$E$4 -> 0 | AD25: =아이베!K20*$E$4 -> 0 | AE25: =아이베!L20*$E$4 -> 0 | ... AI25: =아이베!P20*$E$4 -> 47385
B26: PF | C26: 1 | D26: =아이베!E8*단가!$E5 -> 327628.8 | E26: =아이베!F8*단가!$E5 -> 245721.6 | F26: =아이베!G8*단가!$E5 -> 229340.16 | G26: =아이베!H8*단가!$E5 -> 622494.72 | H26: =아이베!I8*단가!$E5 -> 212958.72 | I26: =아이베!J8*단가!$E5 -> 196577.28 | J26: =아이베!K8*단가!$E5 -> 466871.04 | K26: =아이베!L8*단가!$E5 -> 0 | ... O26: =아이베!P8*단가!$E5 -> 298620 | P26: =아이베!#REF!*단가!$E5 -> #REF! | Q26: =아이베!#REF!*단가!$E5 -> #REF! | R26: =아이베!#REF!*단가!$E5 -> #REF! | V26: PF | W26: 1 | X26: =아이베!E21*$E$5 -> 327628.8 | Y26: =아이베!F21*$E$5 -> 245721.6 | Z26: =아이베!G21*$E$5 -> 229340.16 | AA26: =아이베!H21*$E$5 -> 622494.72 | AB26: =아이베!I21*$E$5 -> 212958.72 | AC26: =아이베!J21*$E$5 -> 196577.28 | AD26: =아이베!K21*$E$5 -> 466871.04 | AE26: =아이베!L21*$E$5 -> 0 | ... AI26: =아이베!P21*$E$5 -> 298620
C27: 2 | D27: =아이베!E9*단가!$E6 -> 0 | E27: =아이베!F9*단가!$E6 -> 0 | F27: =아이베!G9*단가!$E6 -> 358344 | G27: =아이베!H9*단가!$E6 -> 360391.68 | H27: =아이베!I9*단가!$E6 -> 65525.76 | I27: =아이베!J9*단가!$E6 -> 0 | J27: =아이베!K9*단가!$E6 -> 393154.56 | K27: =아이베!L9*단가!$E6 -> 196577.28 | ... O27: =아이베!P9*단가!$E6 -> 255960 | P27: =아이베!#REF!*단가!$E6 -> #REF! | Q27: =아이베!#REF!*단가!$E6 -> #REF! | R27: =아이베!#REF!*단가!$E6 -> #REF! | W27: 2 | X27: =아이베!E22*$E$6 -> 0 | Y27: =아이베!F22*$E$6 -> 0 | Z27: =아이베!G22*$E$6 -> 358344 | AA27: =아이베!H22*$E$6 -> 360391.68 | AB27: =아이베!I22*$E$6 -> 65525.76 | AC27: =아이베!J22*$E$6 -> 0 | AD27: =아이베!K22*$E$6 -> 393154.56 | AE27: =아이베!L22*$E$6 -> 196577.28 | ... AI27: =아이베!P22*$E$6 -> 255960
C28: 3 | D28: =아이베!E10*단가!$E7 -> 172005.12 | E28: =아이베!F10*단가!$E7 -> 147432.96 | F28: =아이베!G10*단가!$E7 -> 0 | G28: =아이베!H10*단가!$E7 -> 0 | H28: =아이베!I10*단가!$E7 -> 114670.08 | I28: =아이베!J10*단가!$E7 -> 0 | J28: =아이베!K10*단가!$E7 -> 122860.8 | K28: =아이베!L10*단가!$E7 -> 0 | ... O28: =아이베!P10*단가!$E7 -> 85320 | P28: =아이베!#REF!*단가!$E7 -> #REF! | Q28: =아이베!#REF!*단가!$E7 -> #REF! | R28: =아이베!#REF!*단가!$E7 -> #REF! | W28: 3 | X28: =아이베!E23*$E$7 -> 172005.12 | Y28: =아이베!F23*$E$7 -> 147432.96 | Z28: =아이베!G23*$E$7 -> 0 | AA28: =아이베!H23*$E$7 -> 0 | AB28: =아이베!I23*$E$7 -> 114670.08 | AC28: =아이베!J23*$E$7 -> 0 | AD28: =아이베!K23*$E$7 -> 122860.8 | AE28: =아이베!L23*$E$7 -> 0 | ... AI28: =아이베!P23*$E$7 -> 85320
B29: Total | D29: =SUM(D23:D28) -> 899942.4 | E29: =SUM(E23:E28) -> 593308.8 | F29: =SUM(F23:F28) -> 787838.4 | G29: =SUM(G23:G28) -> 982886.4 | H29: =SUM(H23:H28) -> 393154.56 | I29: =SUM(I23:I28) -> 196577.28 | J29: =SUM(J23:J28) -> 982886.4 | K29: =SUM(K23:K28) -> 396731.52 | ... R29: =SUM(R23:R28) -> #REF! | V29: Total | X29: =SUM(X23:X28) -> 899942.4 | Y29: =SUM(Y23:Y28) -> 593308.8 | Z29: =SUM(Z23:Z28) -> 787838.4 | AA29: =SUM(AA23:AA28) -> 982886.4 | AB29: =SUM(AB23:AB28) -> 393154.56 | AC29: =SUM(AC23:AC28) -> 196577.28 | AD29: =SUM(AD23:AD28) -> 982886.4 | AE29: =SUM(AE23:AE28) -> 396731.52 | ... AI29: =SUM(AI23:AI28) -> 940005
B30: 발주 금액(EUR) | D30: =D29 -> 899942.4 | E30: =E29 -> 593308.8 | F30: =F29 -> 787838.4 | G30: =G29 -> 982886.4 | H30: =H29 -> 393154.56 | I30: =I29 -> 196577.28 | J30: =J29 -> 982886.4 | K30: =K29 -> 396731.52 | ... R30: =R29 -> #REF! | V30: 발주 금액(EUR) | X30: =X29 -> 899942.4 | Y30: =Y29 -> 593308.8 | Z30: =Z29 -> 787838.4 | AA30: =AA29 -> 982886.4 | AB30: =AB29 -> 393154.56 | AC30: =AC29 -> 196577.28 | AD30: =AD29 -> 982886.4 | AE30: =AE29 -> 396731.52 | ... AI30: =AI29 -> 940005
B31: 발주 금액(KRW) | D31: =D30*$F$2 -> 1.3110181e+09 | E31: =E30*$F$2 -> 8.6432039e+08 | F31: =F30*$F$2 -> 1.1477072e+09 | G31: =G30*$F$2 -> 1.4318492e+09 | H31: =H30*$F$2 -> 5.727397e+08 | I31: =I30*$F$2 -> 2.8636985e+08 | J31: =J30*$F$2 -> 1.4318492e+09 | K31: =K30*$F$2 -> 5.7795054e+08 | ... R31: =R30*$F$2 -> #REF! | V31: 발주 금액(KRW) | X31: =X30*$F$2 -> 1.3110181e+09 | Y31: =Y30*$F$2 -> 8.6432039e+08 | Z31: =Z30*$F$2 -> 1.1477072e+09 | AA31: =AA30*$F$2 -> 1.4318492e+09 | AB31: =AB30*$F$2 -> 5.727397e+08 | AC31: =AC30*$F$2 -> 2.8636985e+08 | AD31: =AD30*$F$2 -> 1.4318492e+09 | AE31: =AE30*$F$2 -> 5.7795054e+08 | ... AI31: =AI30*$F$2 -> 1.3693805e+09
A34: 크로네
A35: Supply (arrival) | D35: Oct | E35: Nov | F35: Dec | G35: Jan | H35: Feb | I35: Mar | J35: Apr | K35: May | L35: Jun. | M35: July. | N35: Aug. | O35: Sep.
B36: PN | C36: Pre | D36: =크로네!E5*단가!$E8 -> 0 | E36: =크로네!F5*단가!$E8 -> 0 | F36: =크로네!G5*단가!$E8 -> 0 | G36: =크로네!H5*단가!$E8 -> 0 | H36: =크로네!I5*단가!$E8 -> 0 | I36: =크로네!J5*단가!$E8 -> 0 | J36: =크로네!K5*단가!$E8 -> 0 | K36: =크로네!L5*단가!$E8 -> 0 | ... O36: =크로네!P5*단가!$E8 -> 0 | P36: =크로네!#REF!*단가!$E8 -> #REF!
C37: 1 | D37: =크로네!E6*단가!$E9 -> 0 | E37: =크로네!F6*단가!$E9 -> 84942 | F37: =크로네!G6*단가!$E9 -> 73359 | G37: =크로네!H6*단가!$E9 -> 0 | H37: =크로네!I6*단가!$E9 -> 0 | I37: =크로네!J6*단가!$E9 -> 0 | J37: =크로네!K6*단가!$E9 -> 0 | K37: =크로네!L6*단가!$E9 -> 142771.2 | ... O37: =크로네!P6*단가!$E9 -> 0 | P37: =크로네!#REF!*단가!$E9 -> #REF!
C38: 1 X 1200G | D38: =크로네!E7*단가!$E18 -> 0 | E38: =크로네!F7*단가!$E18 -> 0 | F38: =크로네!G7*단가!$E18 -> 0 | G38: =크로네!H7*단가!$E18 -> 0 | H38: =크로네!I7*단가!$E18 -> 99009 | I38: =크로네!J7*단가!$E18 -> 0 | J38: =크로네!K7*단가!$E18 -> 0 | K38: =크로네!L7*단가!$E18 -> 0 | ... P38: =크로네!Q7*단가!$E18 -> 0
C39: 2 | D39: =크로네!E8*단가!$E10 -> 0 | E39: =크로네!F8*단가!$E10 -> 0 | F39: =크로네!G8*단가!$E10 -> 11583 | G39: =크로네!H8*단가!$E10 -> 0 | H39: =크로네!I8*단가!$E10 -> 11583 | I39: =크로네!J8*단가!$E10 -> 0 | J39: =크로네!K8*단가!$E10 -> 84942 | K39: =크로네!L8*단가!$E10 -> 307507.2 | ... O39: =크로네!P8*단가!$E10 -> 0 | P39: =크로네!#REF!*단가!$E10 -> #REF!
C40: 1 X 1200G | D40: =크로네!E9*단가!$E18 -> 0 | E40: =크로네!F9*단가!$E18 -> 0 | F40: =크로네!G9*단가!$E18 -> 0 | G40: =크로네!H9*단가!$E18 -> 207513.6 | H40: =크로네!I9*단가!$E18 -> 207513.6 | I40: =크로네!J9*단가!$E18 -> 222336 | J40: =크로네!K9*단가!$E18 -> 0 | K40: =크로네!L9*단가!$E18 -> 0 | ... P40: =크로네!Q9*단가!$E18 -> 0
C41: 3 | D41: =크로네!E10*단가!$E11 -> 0 | E41: =크로네!F10*단가!$E11 -> 230630.4 | F41: =크로네!G10*단가!$E11 -> 0 | G41: =크로네!H10*단가!$E11 -> 186700.8 | H41: =크로네!I10*단가!$E11 -> 208665.6 | I41: =크로네!J10*단가!$E11 -> 197683.2 | J41: =크로네!K10*단가!$E11 -> 0 | K41: =크로네!L10*단가!$E11 -> 0 | ... O41: =크로네!P10*단가!$E11 -> 0 | P41: =크로네!#REF!*단가!$E11 -> #REF!
B42: PF | C42: Pre | D42: =크로네!E11*단가!$E12 -> 0 | E42: =크로네!F11*단가!$E12 -> 0 | F42: =크로네!G11*단가!$E12 -> 0 | G42: =크로네!H11*단가!$E12 -> 0 | H42: =크로네!I11*단가!$E12 -> 0 | I42: =크로네!J11*단가!$E12 -> 0 | J42: =크로네!K11*단가!$E12 -> 74112 | K42: =크로네!L11*단가!$E12 -> 0 | ... O42: =크로네!P11*단가!$E12 -> 154400 | P42: =크로네!#REF!*단가!$E12 -> #REF!
C43: 1 | D43: =크로네!E12*단가!$E13 -> 0 | E43: =크로네!F12*단가!$E13 -> 7411.2 | F43: =크로네!G12*단가!$E13 -> 0 | G43: =크로네!H12*단가!$E13 -> 29644.8 | H43: =크로네!I12*단가!$E13 -> 0 | I43: =크로네!J12*단가!$E13 -> 0 | J43: =크로네!K12*단가!$E13 -> 192691.2 | K43: =크로네!L12*단가!$E13 -> 0 | ... O43: =크로네!P12*단가!$E13 -> 270200 | P43: =크로네!#REF!*단가!$E13 -> #REF!
C44: 2 | D44: =크로네!E13*단가!$E14 -> 0 | E44: =크로네!F13*단가!$E14 -> 7411.2 | F44: =크로네!G13*단가!$E14 -> 0 | G44: =크로네!H13*단가!$E14 -> 0 | H44: =크로네!I13*단가!$E14 -> 0 | I44: =크로네!J13*단가!$E14 -> 0 | J44: =크로네!K13*단가!$E14 -> 222336 | K44: =크로네!L13*단가!$E14 -> 0 | ... O44: =크로네!P13*단가!$E14 -> 289500 | P44: =크로네!#REF!*단가!$E14 -> #REF!
...
