Workbook

Sheet Domestic_2608 (27년 1월 증량 확정 > 세
J2: ※ Aptamil Domestic Stock Overview
E4: 뉴트리시아 코리아 소통 | J4: 1700 | Q4: 2026 | AA4: 12672
A5: SKU | C5: 파렛트 수량 조정 | D5: 파렛트 총합 | E5: 컨테이너 수 | F5: 월평균 출고량 | G5: MOQ (TU) | H5: TU | J5: Supply (arrival) | M5: Sep. | N5: Oct. | O5: Nov. | P5: Dec. | Q5: Jan. | R5: Feb. | S5: Mar. | T5: Apr. | U5: May. | V5: Jun. | W5: July. | X5: Aug. | Y5: Sept. | Z5: Oct. | AA5: Nov. | AB5: Dec. | AC5: Jan. | AD5: Feb. | AE5: Mar. | AF5: Apr. | AG5: May. | AH5: Jun.
A6: PN | B6: 1 | C6: 33 | D6: =SUM(C6:C8) -> 44 | E6: =D6/22 -> 2 | F6: =AVERAGE(T19:V19)/4 -> 1901 | G6: 1500 | H6: =AD6/4 -> 4752 | J6: Supply (arrival) | K6: 676366 | L6: PN 1 | M6: 12308 | O6: 6072 | P6: 7488 | Q6: 11520 | S6: 11948 | U6: 44008 | V6: 11572 | W6: 13320 | AA6: =12672-4600 -> 8072 | AC6: =6366+4600 -> 10966 | AD6: =C6*144*4 -> 19008
B7: 2 | C7: 11 | F7: =AVERAGE(T20:V20)/4 -> 718.58333 | G7: 1500 | H7: =AD7/4 -> 1584 | K7: 676367 | L7: PN 2 | M7: 5948 | N7: 6336 | O7: 432 | P7: 6252 | Q7: 1152 | S7: 7080 | T7: 6336 | U7: 8064 | W7: 17088 | X7: 6772 | AC7: 6336 | AD7: =C7*144*4 -> 6336
B8: 3 | C8: 0 | F8: =AVERAGE(T21:V21)/4 -> 340 | G8: 1500 | H8: =AD8/4 -> 0 | K8: 676369 | L8: PN 3 | N8: 6212 | U8: 6912 | W8: 332 | X8: 5760 | AD8: =C8*144*4 -> 0
A9: PF | B9: 1 | C9: 150 | D9: =SUM(C9:C11) -> 240 | E9: =D9/24 -> 10 | F9: =AVERAGE(T22:V22)/4 -> 6009.5 | G9: 2120 | H9: =AD9/4 -> 14400 | K9: 677211 | L9: PF 1 | M9: 9216 | N9: 16512 | O9: 24300 | Q9: 60572 | R9: 21560 | S9: 23808 | U9: 39428 | V9: 20880 | W9: 14968 | X9: 18432 | Y9: 79960 | Z9: 20352 | AA9: 48000 | AB9: 28416 | AC9: 76416 | AD9: =C9*96*4 -> 57600
B10: 2 | C10: 90 | F10: =AVERAGE(T23:V23)/4 -> 3391.3333 | G10: 2280 | H10: =AD10/4 -> 8640 | K10: 677200 | L10: PF 2 | O10: 12432 | Q10: 30336 | R10: 21584 | T10: 6528 | W10: 46080 | X10: 9216 | Y10: 26216 | Z10: 11520 | AA10: 24896 | AB10: 11136 | AC10: 26880 | AD10: =C10*96*4 -> 34560
B11: 3 | C11: 0 | F11: =AVERAGE(T24:V24)/4 -> 648.91667 | G11: 1880 | H11: =AD11/4 -> 0 | K11: 677281 | L11: PF 3 | O11: 8832 | Q11: 232 | R11: 10688 | W11: 4592 | Y11: 2424 | AA11: 7520 | AB11: 4224 | AC11: 7296 | AD11: =C11*96*4 -> 0
K12: 560277 | L12: VANILLA | P12: 6912 | R12: 5208 | U12: 11628 | V12: 11796
K13: Total | M13: =SUM(M6:M12) -> 27472 | N13: =SUM(N6:N12) -> 29060 | O13: =SUM(O6:O12) -> 52068 | P13: =SUM(P6:P12) -> 20652 | Q13: =SUM(Q6:Q12) -> 103812 | R13: =SUM(R6:R12) -> 59040 | S13: =SUM(S6:S12) -> 42836 | T13: =SUM(T6:T12) -> 12864 | ... AG13: =SUM(AG6:AG12) -> 0
K14: 발주 금액 | M14: =금액!E11 -> 4.457202e+08 | N14: =금액!F11 -> 3.0657648e+08 | O14: =금액!G11 -> 1.5969699e+08 | P14: =금액!H11 -> 3.3539444e+08 | Q14: =금액!I11 -> 3.1119442e+08 | R14: =금액!J11 -> 1208753.5 | S14: =금액!K11 -> 4.6487151e+08 | T14: =금액!L11 -> 1.5476444e+08 | ... V14: =금액!N11 -> 1.1184828e+09 | W14: =VLOOKUP($K6,단가!$B$2:$E$55,4,0)*SUM(W6:W8)+21.33*SUM(W9:W11)+VLOOKUP($K12,단가!$B$2:$E$55,4,0)*W12 -> 7.5158613e+08 | X14: =VLOOKUP($K6,단가!$B$2:$E$55,4,0)*SUM(X6:X8)+21.33*SUM(X9:X11)+VLOOKUP($K12,단가!$B$2:$E$55,4,0)*X12 -> 3.0642354e+08 | Y14: =VLOOKUP($K6,단가!$B$2:$E$55,4,0)*SUM(Y6:Y8)+21.69*SUM(Y9:Y11)+VLOOKUP($K12,단가!$B$2:$E$55,4,0)*Y12 -> 2355534 | Z14: =VLOOKUP($K6,단가!$B$2:$E$55,4,0)*SUM(Z6:Z8)+VLOOKUP($K9,단가!$B$2:$E$55,4,0)*SUM(Z9:Z11)+VLOOKUP($K12,단가!$B$2:$E$55,4,0)*Z12 -> 1.2760095e+09 | AA14: =VLOOKUP($K6,단가!$B$2:$E$55,4,0)*SUM(AA6:AA8)+VLOOKUP($K9,단가!$B$2:$E$55,4,0)*SUM(AA9:AA11)+VLOOKUP($K12,단가!$B$2:$E$55,4,0)*AA12 -> 3.4164809e+09 | AB14: =VLOOKUP($K6,단가!$B$2:$E$55,4,0)*SUM(AB6:AB8)+VLOOKUP($K9,단가!$B$2:$E$55,4,0)*SUM(AB9:AB11)+VLOOKUP($K12,단가!$B$2:$E$55,4,0)*AB12 -> 1.7525914e+09 | AC14: =VLOOKUP($K6,단가!$B$2:$E$55,4,0)*SUM(AC6:AC8)+VLOOKUP($K9,단가!$B$2:$E$55,4,0)*SUM(AC9:AC11)+VLOOKUP($K12,단가!$B$2:$E$55,4,0)*AC12 -> 4.8498414e+09 | AD14: =VLOOKUP($K6,단가!$B$2:$E$55,4,0)*SUM(AD6:AD8)+VLOOKUP($K9,단가!$B$2:$E$55,4,0)*SUM(AD9:AD11)+VLOOKUP($K12,단가!$B$2:$E$55,4,0)*AD12 -> 4.308167e+09 | AE14: =금액!W11 -> 0 | AF14: =금액!X11 -> 0 | AG14: =금액!Y11 -> 0
K15: 발주 금액(KRW) | M15: =M14*$J$4 -> 757724340272 | N15: =N14*$J$4 -> 5.2118001e+11 | O15: =O14*$J$4 -> 2.7148489e+11 | P15: =P14*$J$4 -> 5.7017054e+11 | Q15: =Q14*$J$4 -> 529030511892 | R15: =R14*$J$4 -> 2054880984 | S15: =S14*$J$4 -> 7.9028157e+11 | T15: =T14*$J$4 -> 2.6309955e+11 | ... Y15: =Y14*$J$4 -> 4004407800 | AE15: =AE14*$J$4 -> 0 | AF15: =AF14*$J$4 -> 0 | AG15: =AG14*$J$4 -> 0
M17: Actual | N17: Actual | O17: Actual | P17: Actual | Q17: Actual | R17: Actual | S17: Actual | T17: Actual | U17: Actual | V17: Actual | W17: Actual | X17: Actual | Y17: fcst | Z17: fcst | AA17: fcst | AB17: fcst | AC17: fcst | AD17: fcst | AE17: fcst | AF17: fcst | AG17: fcst | AH17: fcst
J18: Sales | M18: Sept. | N18: Oct. | O18: Nov. | P18: Dec. | Q18: Jan. | R18: Feb. | S18: Mar. | T18: Apr. | U18: May. | V18: Jun. | W18: July. | X18: Aug. | Y18: Sept. | Z18: Oct. | AA18: Nov. | AB18: Dec. | AC18: Jan. | AD18: Feb. | AE18: Mar. | AF18: Apr. | AG18: May. | AH18: Jun.
J19: Sales CU | K19: 676366 | L19: PN 1 | M19: 10091 | N19: 10170 | O19: 10429 | P19: 10538 | Q19: 10862 | R19: 7305 | S19: 8012 | T19: 6754 | U19: 7920 | V19: 8138 | W19: 8285 | X19: 10460 | Y19: 10170 | Z19: 10373 | AA19: 10788 | AB19: 11112 | AC19: 11445 | AD19: 11216 | AE19: 11441 | AF19: 11670 | AG19: 11786 | AH19: 11551
K20: 676367 | L20: PN 2 | M20: 6149 | N20: 6793 | O20: 6655 | P20: 6740 | Q20: 6647 | R20: 1972 | S20: 588 | T20: 2070 | U20: 2887 | V20: 3666 | W20: 3946 | X20: 4800 | Y20: 4590 | Z20: 4728 | AA20: 4822 | AB20: 4870 | AC20: 5017 | AD20: 4816 | AE20: 4912 | AF20: 5010 | AG20: 5111 | AH20: 5008
K21: 676369 | L21: PN 3 | M21: 1975 | N21: 2094 | O21: 2101 | P21: 1953 | Q21: 1892 | R21: 1785 | S21: 1922 | T21: 1407 | U21: 1512 | V21: 1161 | W21: 1086 | X21: 1109 | Y21: 1140 | Z21: 1163 | AA21: 1186 | AB21: 1222 | AC21: 1234 | AD21: 1209 | AE21: 1221 | AF21: 1233 | AG21: 1246 | AH21: 1208
K22: 677211 | L22: PF 1 | M22: 26395 | N22: 18036 | O22: 19567 | P22: 21775 | Q22: 24094 | R22: 20361 | S22: 21905 | T22: 22294 | U22: 24686 | V22: 25134 | W22: 30239 | X22: 35346 | Y22: 33300 | Z22: 34965 | AA22: 36014 | AB22: 37094 | AC22: 37836 | AD22: 37080 | AE22: 37821 | AF22: 38578 | AG22: 39349 | AH22: 40136
K23: 677200 | L23: PF 2 | M23: 9582 | N23: 11036 | O23: 10102 | P23: 10640 | Q23: 11504 | R23: 10237 | S23: 13952 | T23: 13606 | U23: 14459 | V23: 12631 | W23: 15942 | X23: 16880 | Y23: 16260 | Z23: 16910 | AA23: 17587 | AB23: 18114 | AC23: 18658 | AD23: 18844 | AE23: 19221 | AF23: 19606 | AG23: 19998 | AH23: 20198
K24: 677281 | L24: PF 3 | M24: 2881 | N24: 3060 | O24: 3108 | P24: 3172 | Q24: 3248 | R24: 2466 | S24: 2899 | T24: 2728 | U24: 2877 | V24: 2182 | W24: 3461 | X24: 3246 | Y24: 3060 | Z24: 3121 | AA24: 3184 | AB24: 3215 | AC24: 3248 | AD24: 3183 | AE24: 3214 | AF24: 3247 | AG24: 3279 | AH24: 3312
K25: 560277 | L25: VANILLA | Q25: 284 | R25: 129 | S25: 22 | T25: 298 | U25: 133 | V25: 287 | W25: 329 | X25: 199 | Y25: 330 | Z25: 337 | AA25: 340 | AB25: 347 | AC25: 357 | AD25: 368 | AE25: 364 | AF25: 371 | AG25: 383 | AH25: 375
K26: Total | M26: =SUM(M19:M24) -> 57073 | N26: =SUM(N19:N24) -> 51189 | O26: =SUM(O19:O24) -> 51962 | P26: =SUM(P19:P24) -> 54818 | Q26: =SUM(Q19:Q25) -> 58531 | R26: =SUM(R19:R25) -> 44255 | S26: =SUM(S19:S25) -> 49300 | T26: =SUM(T19:T25) -> 49157 | U26: =SUM(U19:U25) -> 54474 | V26: =SUM(V19:V25) -> 53199 | W26: =SUM(W19:W25) -> 63288 | X26: =SUM(X19:X25) -> 72040 | ... AH26: =SUM(AH19:AH25) -> 81788
V27: =SUM(V19:V24) -> 52912 | W27: =SUM(W19:W24) -> 62959 | X27: =SUM(X19:X24) -> 71841 | Y27: =SUM(Y19:Y24) -> 68520 | Z27: =SUM(Z19:Z24) -> 71260 | AA27: =SUM(AA19:AA24) -> 73581 | AB27: =SUM(AB19:AB24) -> 75627 | AC27: =SUM(AC19:AC24) -> 77438 | ... AH27: =SUM(AH19:AH24) -> 81413
A29: 용인 | B29: CJ | C29: 디앤비 | D29: 아르고 | E29: 품고 | F29: 8/20 기말재고 | G29: 예상 기말재고 | J29: Stock(CU) | M29: Sep. | N29: Oct. | O29: Nov. | P29: Dec. | Q29: Jan. | R29: Feb. | S29: Mar. | T29: Apr. | U29: May. | V29: Jun. | W29: July. | X29: Aug. | Y29: Sept. | Z29: Oct. | AA29: Nov. | AB29: Dec. | AC29: Jan. | AD29: Feb. | AE29: Mar. | AF29: Apr. | AG29: May. | AH29: Jun.
A30: 39459 | B30: 10 | C30: 1408 | D30: 1 | E30: 1219 | F30: =A30+B30+C30+D30+E30 -> 42097 | G30: =F30-(X19/31*11) -> 38385.387 | H30: =X30-G30 -> -485.3871 | J30: Stock(CU) | K30: 676366 | L30: PN 1 | M30: 30844 | N30: 20669 | O30: 17050 | P30: 13685 | Q30: 10623 | R30: 3902 | S30: 9601 | T30: 3607 | U30: 39061 | V30: 42442 | W30: 47469 | X30: 37900 | Y30: =X30+Y6-Y19 -> 27730 | Z30: =Y30+Z6-Z19 -> 17357 | AA30: =Z30+AA6-AA19 -> 14641 | AB30: =AA30+AB6-AB19 -> 3529 | AC30: =AB30+AC6-AC19 -> 3050 | AD30: =AC30+AD6-AD19 -> 10842 | AE30: =AD30+AE6-AE19 -> -599 | AF30: =AE30+AF6-AF19 -> -12269 | ... AH30: =AG30+AH6-AH19 -> -35606
A31: 24163 | B31: 136 | C31: 2452 | D31: 165 | E31: 432 | F31: =A31+B31+C31+D31+E31 -> 27348 | G31: =F31-(X20/31*11) -> 25644.774 | H31: =X31-G31 -> -234.77419 | K31: 676367 | L31: PN 2 | M31: 36898 | N31: 36258 | O31: 30555 | P31: 29714 | Q31: 20343 | R31: 0 | S31: 6194 | T31: 9670 | U31: 14884 | V31: 10629 | W31: 23526 | X31: 25410 | Y31: =X31+Y7-Y20 -> 20820 | Z31: =Y31+Z7-Z20 -> 16092 | AA31: =Z31+AA7-AA20 -> 11270 | AB31: =AA31+AB7-AB20 -> 6400 | AC31: =AB31+AC7-AC20 -> 7719 | AD31: =AC31+AD7-AD20 -> 9239 | AE31: =AD31+AE7-AE20 -> 4327 | AF31: =AE31+AF7-AF20 -> -683 | ... AH31: =AG31+AH7-AH20 -> -10802
A32: 8799 | B32: 286 | C32: 1020 | D32: 198 | E32: 0 | F32: =A32+B32+C32+D32+E32 -> 10303 | G32: =F32-(X21/31*11) -> 9909.4839 | H32: =X32-G32 -> 144.51613 | K32: 676369 | L32: PN 3 | M32: 9504 | N32: 13528 | O32: 11315 | P32: 9370 | Q32: 5587 | R32: 3807 | S32: 2641 | T32: 1780 | U32: 7358 | V32: 5628 | W32: 5062 | X32: 10054 | Y32: =X32+Y8-Y21 -> 8914 | Z32: =Y32+Z8-Z21 -> 7751 | AA32: =Z32+AA8-AA21 -> 6565 | AB32: =AA32+AB8-AB21 -> 5343 | AC32: =AB32+AC8-AC21 -> 4109 | AD32: =AC32+AD8-AD21 -> 2900 | AE32: =AD32+AE8-AE21 -> 1679 | AF32: =AE32+AF8-AF21 -> 446 | ... AH32: =AG32+AH8-AH21 -> -2008
A33: 17071 | B33: 0 | C33: 1760 | D33: 0 | E33: 1387 | F33: =A33+B33+C33+D33+E33 -> 20218 | G33: =F33-(X22/31*11) -> 7675.871 | H33: =X33-G33 -> 12182.129 | K33: 677211 | L33: PF 1 | M33: 30317 | N33: 28612 | O33: 34273 | P33: 12108 | Q33: 47968 | R33: 45113 | S33: 49297 | T33: 28221 | U33: 42865 | V33: 38482 | W33: 23218 | X33: 19858 | Y33: =X33+Y9-Y22 -> 66518 | Z33: =Y33+Z9-Z22 -> 51905 | AA33: =Z33+AA9-AA22 -> 63891 | AB33: =AA33+AB9-AB22 -> 55213 | AC33: =AB33+AC9-AC22 -> 93793 | AD33: =AC33+AD9-AD22 -> 114313 | AE33: =AD33+AE9-AE22 -> 76492 | AF33: =AE33+AF9-AF22 -> 37914 | ... AH33: =AG33+AH9-AH22 -> -41571
A34: 31105 | B34: 0 | C34: 2352 | D34: 5 | E34: 899 | F34: =A34+B34+C34+D34+E34 -> 34361 | G34: =F34-(X23/31*11) -> 28371.323 | H34: =X34-G34 -> 1973.6774 | K34: 677200 | L34: PF 2 | M34: 44579 | N34: 33292 | O34: 36167 | P34: 26193 | Q34: 43047 | R34: 51471 | S34: 39515 | T34: 33519 | U34: 18531 | V34: 6669 | W34: 37433 | X34: 30345 | Y34: =X34+Y10-Y23 -> 40301 | Z34: =Y34+Z10-Z23 -> 34911 | AA34: =Z34+AA10-AA23 -> 42220 | AB34: =AA34+AB10-AB23 -> 35242 | AC34: =AB34+AC10-AC23 -> 43464 | AD34: =AC34+AD10-AD23 -> 59180 | AE34: =AD34+AE10-AE23 -> 39959 | AF34: =AE34+AF10-AF23 -> 20353 | ... AH34: =AG34+AH10-AH23 -> -19843
A35: 6193 | B35: 115 | C35: 1788 | D35: 7 | E35: 0 | F35: =A35+B35+C35+D35+E35 -> 8103 | G35: =F35-(X24/31*11) -> 6951.1935 | H35: =X35-G35 -> 2790.8065 | K35: 677281 | L35: PF 3 | M35: 16866 | N35: 13727 | O35: 19729 | P35: 16406 | Q35: 12636 | R35: 18546 | S35: 16659 | T35: 14687 | U35: 11366 | V35: 8797 | W35: 10467 | X35: 9742 | Y35: =X35+Y11-Y24 -> 9106 | Z35: =Y35+Z11-Z24 -> 5985 | AA35: =Z35+AA11-AA24 -> 10321 | AB35: =AA35+AB11-AB24 -> 11330 | AC35: =AB35+AC11-AC24 -> 15378 | AD35: =AC35+AD11-AD24 -> 12195 | AE35: =AD35+AE11-AE24 -> 8981 | AF35: =AE35+AF11-AF24 -> 5734 | ... AH35: =AG35+AH11-AH24 -> -857
F36: =A36+B36+C36+D36+E36 -> 0 | G36: =F36-(X25/31*11) -> -70.612903 | H36: =X36-G36 -> 33739.613 | K36: 560277 | L36: VANILLA | P36: =O36+P12-P25 -> 6912 | Q36: 45869 | R36: 11717 | S36: 11671 | T36: 11347 | U36: 22844 | V36: 34353 | W36: 34023 | X36: 33669 | Y36: =X36+Y12-Y25 -> 33339 | Z36: =Y36+Z12-Z25 -> 33002 | AA36: =Z36+AA12-AA25 -> 32662 | AB36: =AA36+AB12-AB25 -> 32315 | AC36: =AB36+AC12-AC25 -> 31958 | AD36: =AC36+AD12-AD25 -> 31590 | AE36: =AD36+AE12-AE25 -> 31226 | AF36: =AE36+AF12-AF25 -> 30855 | ... AH36: =AG36+AH12-AH25 -> 30097
K37: Total | M37: =SUM(M30:M35) -> 169008 | N37: =SUM(N30:N35) -> 146086 | O37: =SUM(O30:O35) -> 149089 | P37: =SUM(P30:P35) -> 107476 | Q37: =SUM(Q30:Q36) -> 186073 | R37: =SUM(R30:R36) -> 134556 | S37: =SUM(S30:S36) -> 135578 | T37: =SUM(T30:T36) -> 102831 | U37: =SUM(U30:U36) -> 156909 | V37: =SUM(V30:V36) -> 147000 | W37: =SUM(W30:W36) -> 181198 | X37: =SUM(X30:X36) -> 166978 | ... AH37: =SUM(AH30:AH36) -> -80590
L38: 적정재고수준 | M38: 재고월수X 실제 재고량으로 확인 필요
J39: Stock Level(Month) | M39: Sep. | N39: Oct. | O39: Nov. | P39: Dec. | Q39: Jan. | R39: Feb. | S39: Mar. | T39: Apr. | U39: May. | V39: Jun. | W39: July. | X39: Aug. | Y39: Sept. | Z39: Oct. | AA39: Nov. | AB39: Dec. | AC39: Jan. | AD39: Feb. | AE39: Mar. | AF39: Apr. | AG39: May. | AH39: Jun.
J40: Stock month by SKU | K40: 676366 | L40: PN 1 | M40: =M30/M19 -> 3.0565851 | N40: =N30/N19 -> 2.03235 | O40: =O30/O19 -> 1.6348643 | P40: =P30/P19 -> 1.2986335 | Q40: =Q30/Q19 -> 0.97799669 | R40: =R30/R19 -> 0.53415469 | S40: =S30/S19 -> 1.1983275 | T40: =T30/T19 -> 0.53405389 | ... AH40: =AH30/AH19 -> -3.0825037
K41: 676367 | L41: PN 2 | M41: =M31/M20 -> 6.0006505 | N41: =N31/N20 -> 5.3375534 | O41: =O31/O20 -> 4.5912847 | P41: =P31/P20 -> 4.4086053 | Q41: =Q31/Q20 -> 3.0604784 | R41: =R31/R20 -> 0 | S41: =S31/S20 -> 10.534014 | T41: =T31/T20 -> 4.6714976 | ... AH41: =AH31/AH20 -> -2.1569489
K42: 676369 | L42: PN 3 | M42: =M32/M21 -> 4.8121519 | N42: =N32/N21 -> 6.4603629 | O42: =O32/O21 -> 5.3855307 | P42: =P32/P21 -> 4.7977471 | Q42: =Q32/Q21 -> 2.9529598 | R42: =R32/R21 -> 2.1327731 | S42: =S32/S21 -> 1.3740895 | T42: =T32/T21 -> 1.2651031 | ... AH42: =AH32/AH21 -> -1.6622517
K43: 677211 | L43: PF 1 | M43: =M33/M22 -> 1.1485887 | N43: =N33/N22 -> 1.5863828 | O43: =O33/O22 -> 1.7515715 | P43: =P33/P22 -> 0.55605052 | Q43: =Q33/Q22 -> 1.9908691 | R43: =R33/R22 -> 2.2156574 | S43: =S33/S22 -> 2.2504908 | T43: =T33/T22 -> 1.2658563 | ... AH43: =AH33/AH22 -> -1.0357534
K44: 677200 | L44: PF 2 | M44: =M34/M23 -> 4.652369 | N44: =N34/N23 -> 3.0166727 | O44: =O34/O23 -> 3.5801821 | P44: =P34/P23 -> 2.4617481 | Q44: =Q34/Q23 -> 3.7419159 | R44: =R34/R23 -> 5.0279379 | S44: =S34/S23 -> 2.8322104 | T44: =T34/T23 -> 2.4635455 | ... AH44: =AH34/AH23 -> -0.982424
...

Sheet Domestic_2608(Sales)
J2: ※ Aptamil Domestic Stock Overview
E4: 뉴트리시아 코리아 소통 | J4: 1700 | Q4: 2026
A5: SKU | C5: 파렛트 수량 조정 | D5: 파렛트 총합 | E5: 컨테이너 수 | F5: 월평균 출고량 | G5: MOQ (TU) | H5: TU | J5: Supply (arrival) | M5: Sep. | N5: Oct. | O5: Nov. | P5: Dec. | Q5: Jan. | R5: Feb. | S5: Mar. | T5: Apr. | U5: May. | V5: Jun. | W5: July. | X5: Aug. | Y5: Sept. | Z5: Oct. | AA5: Nov. | AB5: Dec. | AC5: Jan. | AD5: Feb. | AE5: Mar. | AF5: Apr. | AG5: May. | AH5: Jun.
A6: PN | B6: 1 | C6: 33 | D6: =SUM(C6:C8) -> 44 | E6: =D6/22 -> 2 | F6: =AVERAGE(T19:V19)/4 -> 1901 | G6: 1500 | H6: =AD6/4 -> 4752 | J6: Supply (arrival) | K6: 676366 | L6: PN 1 | M6: 12308 | O6: 6072 | P6: 7488 | Q6: 11520 | S6: 11948 | U6: 44008 | V6: 11572 | W6: 13320 | AA6: 12672 | AC6: 6336 | AD6: =C6*144*4 -> 19008
B7: 2 | C7: 11 | F7: =AVERAGE(T20:V20)/4 -> 718.58333 | G7: 1500 | H7: =AD7/4 -> 1584 | K7: 676367 | L7: PN 2 | M7: 5948 | N7: 6336 | O7: 432 | P7: 6252 | Q7: 1152 | S7: 7080 | T7: 6336 | U7: 8064 | W7: 17088 | X7: 6772 | AC7: 6336 | AD7: =C7*144*4 -> 6336 | AE7: 6336
B8: 3 | C8: 0 | F8: =AVERAGE(T21:V21)/4 -> 340 | G8: 1500 | H8: =AD8/4 -> 0 | K8: 676369 | L8: PN 3 | N8: 6212 | U8: 6912 | W8: 332 | X8: 5760 | AD8: =C8*144*4 -> 0
A9: PF | B9: 1 | C9: 150 | D9: =SUM(C9:C11) -> 240 | E9: =D9/24 -> 10 | F9: =AVERAGE(T22:V22)/4 -> 6009.5 | G9: 2120 | H9: =AD9/4 -> 14400 | K9: 677211 | L9: PF 1 | M9: 9216 | N9: 16512 | O9: 24300 | Q9: 60572 | R9: 21560 | S9: 23808 | U9: 39428 | V9: 20880 | W9: 14968 | X9: 18432 | Y9: 79960 | Z9: 20352 | AA9: 48000 | AB9: 28416 | AC9: 76416 | AD9: =C9*96*4 -> 57600
B10: 2 | C10: 90 | F10: =AVERAGE(T23:V23)/4 -> 3391.3333 | G10: 2280 | H10: =AD10/4 -> 8640 | K10: 677200 | L10: PF 2 | O10: 12432 | Q10: 30336 | R10: 21584 | T10: 6528 | W10: 46080 | X10: 9216 | Y10: 26216 | Z10: 11520 | AA10: 24896 | AB10: 11136 | AC10: 26880 | AD10: =C10*96*4 -> 34560
B11: 3 | C11: 0 | F11: =AVERAGE(T24:V24)/4 -> 648.91667 | G11: 1880 | H11: =AD11/4 -> 0 | K11: 677281 | L11: PF 3 | O11: 8832 | Q11: 232 | R11: 10688 | W11: 4592 | Y11: 2424 | AA11: 7520 | AB11: 4224 | AC11: 7296 | AD11: =C11*96*4 -> 0
K12: 560277 | L12: VANILLA | P12: 6912 | R12: 5208 | U12: 11628 | V12: 11796
K13: Total | M13: =SUM(M6:M12) -> 27472 | N13: =SUM(N6:N12) -> 29060 | O13: =SUM(O6:O12) -> 52068 | P13: =SUM(P6:P12) -> 20652 | Q13: =SUM(Q6:Q12) -> 103812 | R13: =SUM(R6:R12) -> 59040 | S13: =SUM(S6:S12) -> 42836 | T13: =SUM(T6:T12) -> 12864 | ... AG13: =SUM(AG6:AG12) -> 0
K14: 발주 금액 | M14: =금액!E11 -> 4.457202e+08 | N14: =금액!F11 -> 3.0657648e+08 | O14: =금액!G11 -> 1.5969699e+08 | P14: =금액!H11 -> 3.3539444e+08 | Q14: =금액!I11 -> 3.1119442e+08 | R14: =금액!J11 -> 1208753.5 | S14: =금액!K11 -> 4.6487151e+08 | T14: =금액!L11 -> 1.5476444e+08 | ... V14: =금액!N11 -> 1.1184828e+09 | W14: =VLOOKUP($K6,단가!$B$2:$E$55,4,0)*SUM(W6:W8)+21.33*SUM(W9:W11)+VLOOKUP($K12,단가!$B$2:$E$55,4,0)*W12 -> 7.5158613e+08 | X14: =VLOOKUP($K6,단가!$B$2:$E$55,4,0)*SUM(X6:X8)+21.33*SUM(X9:X11)+VLOOKUP($K12,단가!$B$2:$E$55,4,0)*X12 -> 3.0642354e+08 | Y14: =VLOOKUP($K6,단가!$B$2:$E$55,4,0)*SUM(Y6:Y8)+21.69*SUM(Y9:Y11)+VLOOKUP($K12,단가!$B$2:$E$55,4,0)*Y12 -> 2355534 | Z14: =VLOOKUP($K6,단가!$B$2:$E$55,4,0)*SUM(Z6:Z8)+VLOOKUP($K9,단가!$B$2:$E$55,4,0)*SUM(Z9:Z11)+VLOOKUP($K12,단가!$B$2:$E$55,4,0)*Z12 -> 1.2760095e+09 | AA14: =VLOOKUP($K6,단가!$B$2:$E$55,4,0)*SUM(AA6:AA8)+VLOOKUP($K9,단가!$B$2:$E$55,4,0)*SUM(AA9:AA11)+VLOOKUP($K12,단가!$B$2:$E$55,4,0)*AA12 -> 3.5287403e+09 | AB14: =VLOOKUP($K6,단가!$B$2:$E$55,4,0)*SUM(AB6:AB8)+VLOOKUP($K9,단가!$B$2:$E$55,4,0)*SUM(AB9:AB11)+VLOOKUP($K12,단가!$B$2:$E$55,4,0)*AB12 -> 1.7525914e+09 | AC14: =VLOOKUP($K6,단가!$B$2:$E$55,4,0)*SUM(AC6:AC8)+VLOOKUP($K9,단가!$B$2:$E$55,4,0)*SUM(AC9:AC11)+VLOOKUP($K12,단가!$B$2:$E$55,4,0)*AC12 -> 4.7368498e+09 | AD14: =VLOOKUP($K6,단가!$B$2:$E$55,4,0)*SUM(AD6:AD8)+VLOOKUP($K9,단가!$B$2:$E$55,4,0)*SUM(AD9:AD11)+VLOOKUP($K12,단가!$B$2:$E$55,4,0)*AD12 -> 4.308167e+09 | AE14: =금액!W11 -> 0 | AF14: =금액!X11 -> 0 | AG14: =금액!Y11 -> 0
K15: 발주 금액(KRW) | M15: =M14*$J$4 -> 757724340272 | N15: =N14*$J$4 -> 5.2118001e+11 | O15: =O14*$J$4 -> 2.7148489e+11 | P15: =P14*$J$4 -> 5.7017054e+11 | Q15: =Q14*$J$4 -> 529030511892 | R15: =R14*$J$4 -> 2054880984 | S15: =S14*$J$4 -> 7.9028157e+11 | T15: =T14*$J$4 -> 2.6309955e+11 | ... Y15: =Y14*$J$4 -> 4004407800 | AE15: =AE14*$J$4 -> 0 | AF15: =AF14*$J$4 -> 0 | AG15: =AG14*$J$4 -> 0
M17: Actual | N17: Actual | O17: Actual | P17: Actual | Q17: Actual | R17: Actual | S17: Actual | T17: Actual | U17: Actual | V17: Actual | W17: Actual | X17: fcst | Y17: fcst | Z17: fcst | AA17: fcst | AB17: fcst | AC17: fcst | AD17: fcst | AE17: fcst | AF17: fcst | AG17: fcst | AH17: fcst
J18: Sales | M18: Sept. | N18: Oct. | O18: Nov. | P18: Dec. | Q18: Jan. | R18: Feb. | S18: Mar. | T18: Apr. | U18: May. | V18: Jun. | W18: July. | X18: Aug. | Y18: Sept. | Z18: Oct. | AA18: Nov. | AB18: Dec. | AC18: Jan. | AD18: Feb. | AE18: Mar. | AF18: Apr. | AG18: May. | AH18: Jun.
J19: Sales CU | K19: 676366 | L19: PN 1 | M19: 10091 | N19: 10170 | O19: 10429 | P19: 10538 | Q19: 10862 | R19: 7305 | S19: 8012 | T19: 6754 | U19: 7920 | V19: 8138 | W19: 8285 | X19: 9860 | Y19: 9466 | Z19: 9655 | AA19: 9945 | AB19: 10143 | AC19: 10448 | AD19: 10134 | AE19: 10337 | AF19: 10544 | AG19: 10649 | AH19: 10436
K20: 676367 | L20: PN 2 | M20: 6149 | N20: 6793 | O20: 6655 | P20: 6740 | Q20: 6647 | R20: 1972 | S20: 588 | T20: 2070 | U20: 2887 | V20: 3666 | W20: 3946 | X20: 4992 | Y20: 4792 | Z20: 4888 | AA20: 4986 | AB20: 5036 | AC20: 5187 | AD20: 4979 | AE20: 5079 | AF20: 5181 | AG20: 5284 | AH20: 5178
K21: 676369 | L21: PN 3 | M21: 1975 | N21: 2094 | O21: 2101 | P21: 1953 | Q21: 1892 | R21: 1785 | S21: 1922 | T21: 1407 | U21: 1512 | V21: 1161 | W21: 1086 | X21: 1168 | Y21: 1133 | Z21: 1144 | AA21: 1156 | AB21: 1167 | AC21: 1179 | AD21: 1155 | AE21: 1167 | AF21: 1179 | AG21: 1190 | AH21: 1155
K22: 677211 | L22: PF 1 | M22: 26395 | N22: 18036 | O22: 19567 | P22: 21775 | Q22: 24094 | R22: 20361 | S22: 21905 | T22: 22294 | U22: 24686 | V22: 25134 | W22: 30239 | X22: 35414 | Y22: 34352 | Z22: 35039 | AA22: 36090 | AB22: 37172 | AC22: 38288 | AD22: 37522 | AE22: 38272 | AF22: 39038 | AG22: 39819 | AH22: 40615
K23: 677200 | L23: PF 2 | M23: 9582 | N23: 11036 | O23: 10102 | P23: 10640 | Q23: 11504 | R23: 10237 | S23: 13952 | T23: 13606 | U23: 14459 | V23: 12631 | W23: 15942 | X23: 18091 | Y23: 17910 | Z23: 18447 | AA23: 19185 | AB23: 19953 | AC23: 20551 | AD23: 20757 | AE23: 21172 | AF23: 21595 | AG23: 22027 | AH23: 22248
K24: 677281 | L24: PF 3 | M24: 2881 | N24: 3060 | O24: 3108 | P24: 3172 | Q24: 3248 | R24: 2466 | S24: 2899 | T24: 2728 | U24: 2877 | V24: 2182 | W24: 3461 | X24: 3331 | Y24: 3264 | Z24: 3297 | AA24: 3198 | AB24: 3230 | AC24: 3262 | AD24: 3197 | AE24: 3229 | AF24: 3261 | AG24: 3294 | AH24: 3327
K25: 560277 | L25: VANILLA | Q25: 284 | R25: 129 | S25: 22 | T25: 298 | U25: 133 | V25: 287 | W25: 329 | X25: 178 | Y25: 330 | Z25: 337 | AA25: 340 | AB25: 347 | AC25: 357 | AD25: 368 | AE25: 364 | AF25: 371 | AG25: 383 | AH25: 375
K26: Total | M26: =SUM(M19:M24) -> 57073 | N26: =SUM(N19:N24) -> 51189 | O26: =SUM(O19:O24) -> 51962 | P26: =SUM(P19:P24) -> 54818 | Q26: =SUM(Q19:Q25) -> 58531 | R26: =SUM(R19:R25) -> 44255 | S26: =SUM(S19:S25) -> 49300 | T26: =SUM(T19:T25) -> 49157 | U26: =SUM(U19:U25) -> 54474 | V26: =SUM(V19:V25) -> 53199 | W26: =SUM(W19:W25) -> 63288 | X26: =SUM(X19:X25) -> 73034 | ... AH26: =SUM(AH19:AH25) -> 83334
V27: =SUM(V19:V24) -> 52912 | W27: =SUM(W19:W24) -> 62959 | X27: =SUM(X19:X24) -> 72856 | Y27: =SUM(Y19:Y24) -> 70917 | Z27: =SUM(Z19:Z24) -> 72470 | AA27: =SUM(AA19:AA24) -> 74560 | AB27: =SUM(AB19:AB24) -> 76701 | AC27: =SUM(AC19:AC24) -> 78915 | ... AH27: =SUM(AH19:AH24) -> 82959
A29: 용인 | B29: CJ | C29: 디앤비 | D29: 아르고 | E29: 품고 | F29: 8/20 기말재고 | G29: 예상 기말재고 | J29: Stock(CU) | M29: Sep. | N29: Oct. | O29: Nov. | P29: Dec. | Q29: Jan. | R29: Feb. | S29: Mar. | T29: Apr. | U29: May. | V29: Jun. | W29: July. | X29: Aug. | Y29: Sept. | Z29: Oct. | AA29: Nov. | AB29: Dec. | AC29: Jan. | AD29: Feb. | AE29: Mar. | AF29: Apr. | AG29: May. | AH29: Jun.
A30: 39459 | B30: 10 | C30: 1408 | D30: 1 | E30: 1219 | F30: =A30+B30+C30+D30+E30 -> 42097 | G30: =F30-(X19/31*11) -> 38598.29 | H30: =X30-G30 -> -698.29032 | J30: Stock(CU) | K30: 676366 | L30: PN 1 | M30: 30844 | N30: 20669 | O30: 17050 | P30: 13685 | Q30: 10623 | R30: 3902 | S30: 9601 | T30: 3607 | U30: 39061 | V30: 42442 | W30: 47469 | X30: 37900 | Y30: =X30+Y6-Y19 -> 28434 | Z30: =Y30+Z6-Z19 -> 18779 | AA30: =Z30+AA6-AA19 -> 21506 | AB30: =AA30+AB6-AB19 -> 11363 | AC30: =AB30+AC6-AC19 -> 7251 | AD30: =AC30+AD6-AD19 -> 16125 | AE30: =AD30+AE6-AE19 -> 5788 | AF30: =AE30+AF6-AF19 -> -4756 | ... AH30: =AG30+AH6-AH19 -> -25841
A31: 24163 | B31: 136 | C31: 2452 | D31: 165 | E31: 432 | F31: =A31+B31+C31+D31+E31 -> 27348 | G31: =F31-(X20/31*11) -> 25576.645 | H31: =X31-G31 -> -166.64516 | K31: 676367 | L31: PN 2 | M31: 36898 | N31: 36258 | O31: 30555 | P31: 29714 | Q31: 20343 | R31: 0 | S31: 6194 | T31: 9670 | U31: 14884 | V31: 10629 | W31: 23526 | X31: 25410 | Y31: =X31+Y7-Y20 -> 20618 | Z31: =Y31+Z7-Z20 -> 15730 | AA31: =Z31+AA7-AA20 -> 10744 | AB31: =AA31+AB7-AB20 -> 5708 | AC31: =AB31+AC7-AC20 -> 6857 | AD31: =AC31+AD7-AD20 -> 8214 | AE31: =AD31+AE7-AE20 -> 9471 | AF31: =AE31+AF7-AF20 -> 4290 | ... AH31: =AG31+AH7-AH20 -> -6172
A32: 8799 | B32: 286 | C32: 1020 | D32: 198 | E32: 0 | F32: =A32+B32+C32+D32+E32 -> 10303 | G32: =F32-(X21/31*11) -> 9888.5484 | H32: =X32-G32 -> 165.45161 | K32: 676369 | L32: PN 3 | M32: 9504 | N32: 13528 | O32: 11315 | P32: 9370 | Q32: 5587 | R32: 3807 | S32: 2641 | T32: 1780 | U32: 7358 | V32: 5628 | W32: 5062 | X32: 10054 | Y32: =X32+Y8-Y21 -> 8921 | Z32: =Y32+Z8-Z21 -> 7777 | AA32: =Z32+AA8-AA21 -> 6621 | AB32: =AA32+AB8-AB21 -> 5454 | AC32: =AB32+AC8-AC21 -> 4275 | AD32: =AC32+AD8-AD21 -> 3120 | AE32: =AD32+AE8-AE21 -> 1953 | AF32: =AE32+AF8-AF21 -> 774 | ... AH32: =AG32+AH8-AH21 -> -1571
A33: 17071 | B33: 0 | C33: 1760 | D33: 0 | E33: 1387 | F33: =A33+B33+C33+D33+E33 -> 20218 | G33: =F33-(X22/31*11) -> 7651.7419 | H33: =X33-G33 -> 12206.258 | K33: 677211 | L33: PF 1 | M33: 30317 | N33: 28612 | O33: 34273 | P33: 12108 | Q33: 47968 | R33: 45113 | S33: 49297 | T33: 28221 | U33: 42865 | V33: 38482 | W33: 23218 | X33: 19858 | Y33: =X33+Y9-Y22 -> 65466 | Z33: =Y33+Z9-Z22 -> 50779 | AA33: =Z33+AA9-AA22 -> 62689 | AB33: =AA33+AB9-AB22 -> 53933 | AC33: =AB33+AC9-AC22 -> 92061 | AD33: =AC33+AD9-AD22 -> 112139 | AE33: =AD33+AE9-AE22 -> 73867 | AF33: =AE33+AF9-AF22 -> 34829 | ... AH33: =AG33+AH9-AH22 -> -45605
A34: 31105 | B34: 0 | C34: 2352 | D34: 5 | E34: 899 | F34: =A34+B34+C34+D34+E34 -> 34361 | G34: =F34-(X23/31*11) -> 27941.613 | H34: =X34-G34 -> 2403.3871 | K34: 677200 | L34: PF 2 | M34: 44579 | N34: 33292 | O34: 36167 | P34: 26193 | Q34: 43047 | R34: 51471 | S34: 39515 | T34: 33519 | U34: 18531 | V34: 6669 | W34: 37433 | X34: 30345 | Y34: =X34+Y10-Y23 -> 38651 | Z34: =Y34+Z10-Z23 -> 31724 | AA34: =Z34+AA10-AA23 -> 37435 | AB34: =AA34+AB10-AB23 -> 28618 | AC34: =AB34+AC10-AC23 -> 34947 | AD34: =AC34+AD10-AD23 -> 48750 | AE34: =AD34+AE10-AE23 -> 27578 | AF34: =AE34+AF10-AF23 -> 5983 | ... AH34: =AG34+AH10-AH23 -> -38292
A35: 6193 | B35: 115 | C35: 1788 | D35: 7 | E35: 0 | F35: =A35+B35+C35+D35+E35 -> 8103 | G35: =F35-(X24/31*11) -> 6921.0323 | H35: =X35-G35 -> 2820.9677 | K35: 677281 | L35: PF 3 | M35: 16866 | N35: 13727 | O35: 19729 | P35: 16406 | Q35: 12636 | R35: 18546 | S35: 16659 | T35: 14687 | U35: 11366 | V35: 8797 | W35: 10467 | X35: 9742 | Y35: =X35+Y11-Y24 -> 8902 | Z35: =Y35+Z11-Z24 -> 5605 | AA35: =Z35+AA11-AA24 -> 9927 | AB35: =AA35+AB11-AB24 -> 10921 | AC35: =AB35+AC11-AC24 -> 14955 | AD35: =AC35+AD11-AD24 -> 11758 | AE35: =AD35+AE11-AE24 -> 8529 | AF35: =AE35+AF11-AF24 -> 5268 | ... AH35: =AG35+AH11-AH24 -> -1353
F36: =A36+B36+C36+D36+E36 -> 0 | G36: =F36-(X25/31*11) -> -63.16129 | H36: =X36-G36 -> 33732.161 | K36: 560277 | L36: VANILLA | P36: =O36+P12-P25 -> 6912 | Q36: 45869 | R36: 11717 | S36: 11671 | T36: 11347 | U36: 22844 | V36: 34353 | W36: 34023 | X36: 33669 | Y36: =X36+Y12-Y25 -> 33339 | Z36: =Y36+Z12-Z25 -> 33002 | AA36: =Z36+AA12-AA25 -> 32662 | AB36: =AA36+AB12-AB25 -> 32315 | AC36: =AB36+AC12-AC25 -> 31958 | AD36: =AC36+AD12-AD25 -> 31590 | AE36: =AD36+AE12-AE25 -> 31226 | AF36: =AE36+AF12-AF25 -> 30855 | ... AH36: =AG36+AH12-AH25 -> 30097
K37: Total | M37: =SUM(M30:M35) -> 169008 | N37: =SUM(N30:N35) -> 146086 | O37: =SUM(O30:O35) -> 149089 | P37: =SUM(P30:P35) -> 107476 | Q37: =SUM(Q30:Q36) -> 186073 | R37: =SUM(R30:R36) -> 134556 | S37: =SUM(S30:S36) -> 135578 | T37: =SUM(T30:T36) -> 102831 | U37: =SUM(U30:U36) -> 156909 | V37: =SUM(V30:V36) -> 147000 | W37: =SUM(W30:W36) -> 181198 | X37: =SUM(X30:X36) -> 166978 | ... AH37: =SUM(AH30:AH36) -> -88737
L38: 적정재고수준 | M38: 재고월수X 실제 재고량으로 확인 필요
J39: Stock Level(Month) | M39: Sep. | N39: Oct. | O39: Nov. | P39: Dec. | Q39: Jan. | R39: Feb. | S39: Mar. | T39: Apr. | U39: May. | V39: Jun. | W39: July. | X39: Aug. | Y39: Sept. | Z39: Oct. | AA39: Nov. | AB39: Dec. | AC39: Jan. | AD39: Feb. | AE39: Mar. | AF39: Apr. | AG39: May. | AH39: Jun.
J40: Stock month by SKU | K40: 676366 | L40: PN 1 | M40: =M30/M19 -> 3.0565851 | N40: =N30/N19 -> 2.03235 | O40: =O30/O19 -> 1.6348643 | P40: =P30/P19 -> 1.2986335 | Q40: =Q30/Q19 -> 0.97799669 | R40: =R30/R19 -> 0.53415469 | S40: =S30/S19 -> 1.1983275 | T40: =T30/T19 -> 0.53405389 | ... AH40: =AH30/AH19 -> -2.4761403
K41: 676367 | L41: PN 2 | M41: =M31/M20 -> 6.0006505 | N41: =N31/N20 -> 5.3375534 | O41: =O31/O20 -> 4.5912847 | P41: =P31/P20 -> 4.4086053 | Q41: =Q31/Q20 -> 3.0604784 | R41: =R31/R20 -> 0 | S41: =S31/S20 -> 10.534014 | T41: =T31/T20 -> 4.6714976 | ... AH41: =AH31/AH20 -> -1.191966
K42: 676369 | L42: PN 3 | M42: =M32/M21 -> 4.8121519 | N42: =N32/N21 -> 6.4603629 | O42: =O32/O21 -> 5.3855307 | P42: =P32/P21 -> 4.7977471 | Q42: =Q32/Q21 -> 2.9529598 | R42: =R32/R21 -> 2.1327731 | S42: =S32/S21 -> 1.3740895 | T42: =T32/T21 -> 1.2651031 | ... AH42: =AH32/AH21 -> -1.3601732
K43: 677211 | L43: PF 1 | M43: =M33/M22 -> 1.1485887 | N43: =N33/N22 -> 1.5863828 | O43: =O33/O22 -> 1.7515715 | P43: =P33/P22 -> 0.55605052 | Q43: =Q33/Q22 -> 1.9908691 | R43: =R33/R22 -> 2.2156574 | S43: =S33/S22 -> 2.2504908 | T43: =T33/T22 -> 1.2658563 | ... AH43: =AH33/AH22 -> -1.122861
K44: 677200 | L44: PF 2 | M44: =M34/M23 -> 4.652369 | N44: =N34/N23 -> 3.0166727 | O44: =O34/O23 -> 3.5801821 | P44: =P34/P23 -> 2.4617481 | Q44: =Q34/Q23 -> 3.7419159 | R44: =R34/R23 -> 5.0279379 | S44: =S34/S23 -> 2.8322104 | T44: =T34/T23 -> 2.4635455 | ... AH44: =AH34/AH23 -> -1.7211435
...

Sheet Domestic_2608 (27년 1월 증량 확정)
J2: ※ Aptamil Domestic Stock Overview
A4: 계수 | E4: 뉴트리시아 코리아 소통 | J4: 1700 | Q4: 2026
A5: SKU | C5: 파렛트 수량 조정 | D5: 파렛트 총합 | E5: 컨테이너 수 | F5: 월평균 출고량 | G5: MOQ (TU) | H5: TU | J5: Supply (arrival) | M5: Sep. | N5: Oct. | O5: Nov. | P5: Dec. | Q5: Jan. | R5: Feb. | S5: Mar. | T5: Apr. | U5: May. | V5: Jun. | W5: July. | X5: Aug. | Y5: Sept. | Z5: Oct. | AA5: Nov. | AB5: Dec. | AC5: Jan. | AD5: Feb. | AE5: Mar. | AF5: Apr. | AG5: May. | AH5: Jun.
A6: PN | B6: 1 | C6: 33 | D6: =SUM(C6:C8) -> 44 | E6: =D6/22 -> 2 | F6: =AVERAGE(T19:V19)/4 -> 1901 | G6: 1500 | H6: =C6*144 -> 4752 | I6: =G6*4 -> 6000 | J6: Supply (arrival) | K6: PN | L6: 1 | M6: 12308 | O6: 6072 | P6: 7488 | Q6: 11520 | S6: 11948 | U6: 44008 | V6: 11572 | W6: 13320 | AA6: 12672 | AC6: 6336 | AD6: =C6*144*4 -> 19008
B7: 2 | C7: 11 | F7: =AVERAGE(T20:V20)/4 -> 718.58333 | G7: 1500 | H7: =C7*144 -> 1584 | I7: =G7*4 -> 6000 | L7: 2 | M7: 5948 | N7: 6336 | O7: 432 | P7: 6252 | Q7: 1152 | S7: 7080 | T7: 6336 | U7: 8064 | W7: 17088 | X7: 6772 | AC7: 6336 | AD7: =C7*144*4 -> 6336
B8: 3 | C8: 0 | F8: =AVERAGE(T21:V21)/4 -> 340 | G8: 1500 | H8: =C8*144 -> 0 | I8: =G8*4 -> 6000 | L8: 3 | N8: 6212 | U8: 6912 | W8: 332 | X8: 5760 | AD8: =C8*144*4 -> 0
A9: PF | B9: 1 | C9: 150 | D9: =SUM(C9:C11) -> 240 | E9: =D9/24 -> 10 | F9: =AVERAGE(T22:V22)/4 -> 6009.5 | G9: 2120 | H9: =C9*96 -> 14400 | I9: =G9*4 -> 8480 | K9: PF | L9: 1 | M9: 9216 | N9: 16512 | O9: 24300 | Q9: 60572 | R9: 21560 | S9: 23808 | U9: 39428 | V9: 20880 | W9: 14968 | X9: 18432 | Y9: 79960 | Z9: 20352 | AA9: 48000 | AB9: 28416 | AC9: 76416 | AD9: =C9*96*4 -> 57600
B10: 2 | C10: 90 | F10: =AVERAGE(T23:V23)/4 -> 3391.3333 | G10: 2280 | H10: =C10*96 -> 8640 | I10: =G10*4 -> 9120 | L10: 2 | O10: 12432 | Q10: 30336 | R10: 21584 | T10: 6528 | W10: 46080 | X10: 9216 | Y10: 26216 | Z10: 11520 | AA10: 24896 | AB10: 11136 | AC10: 26880 | AD10: =C10*96*4 -> 34560
B11: 3 | C11: 0 | F11: =AVERAGE(T24:V24)/4 -> 648.91667 | G11: 1880 | H11: =C11*96 -> 0 | I11: =G11*4 -> 7520 | L11: 3 | O11: 8832 | Q11: 232 | R11: 10688 | W11: 4592 | Y11: 2424 | AA11: 7520 | AB11: 4224 | AC11: 7296 | AD11: =C11*96*4 -> 0
K12: FORTIFIT | L12: VANILLA | P12: 6912 | R12: 5208 | U12: 11628 | V12: 11796
K13: Total | M13: =SUM(M6:M12) -> 27472 | N13: =SUM(N6:N12) -> 29060 | O13: =SUM(O6:O12) -> 52068 | P13: =SUM(P6:P12) -> 20652 | Q13: =SUM(Q6:Q12) -> 103812 | R13: =SUM(R6:R12) -> 59040 | S13: =SUM(S6:S12) -> 42836 | T13: =SUM(T6:T12) -> 12864 | ... AG13: =SUM(AG6:AG12) -> 0
K14: 발주 금액 | M14: =금액!E11 -> 4.457202e+08 | N14: =금액!F11 -> 3.0657648e+08 | O14: =금액!G11 -> 1.5969699e+08 | P14: =금액!H11 -> 3.3539444e+08 | Q14: =금액!I11 -> 3.1119442e+08 | R14: =금액!J11 -> 1208753.5 | S14: =금액!K11 -> 4.6487151e+08 | T14: =금액!L11 -> 1.5476444e+08 | ... AG14: =금액!Y11 -> 0
K15: 발주 금액(KRW) | M15: =M14*$J$4 -> 757724340272 | N15: =N14*$J$4 -> 5.2118001e+11 | O15: =O14*$J$4 -> 2.7148489e+11 | P15: =P14*$J$4 -> 5.7017054e+11 | Q15: =Q14*$J$4 -> 529030511892 | R15: =R14*$J$4 -> 2054880984 | S15: =S14*$J$4 -> 7.9028157e+11 | T15: =T14*$J$4 -> 2.6309955e+11 | ... AG15: =AG14*$J$4 -> 0
M17: Actual | N17: Actual | O17: Actual | P17: Actual | Q17: Actual | R17: Actual | S17: Actual | T17: Actual | U17: Actual | V17: Actual | W17: Actual | X17: fcst | Y17: fcst | Z17: fcst | AA17: fcst | AB17: fcst | AC17: fcst | AD17: fcst | AE17: fcst | AF17: fcst | AG17: fcst | AH17: fcst
J18: Sales | M18: Sept. | N18: Oct. | O18: Nov. | P18: Dec. | Q18: Jan. | R18: Feb. | S18: Mar. | T18: Apr. | U18: May. | V18: Jun. | W18: July. | X18: Aug. | Y18: Sept. | Z18: Oct. | AA18: Nov. | AB18: Dec. | AC18: Jan. | AD18: Feb. | AE18: Mar. | AF18: Apr. | AG18: May. | AH18: Jun.
J19: Sales CU | K19: PN | L19: 1 | M19: 10091 | N19: 10170 | O19: 10429 | P19: 10538 | Q19: 10862 | R19: 7305 | S19: 8012 | T19: 6754 | U19: 7920 | V19: 8138 | W19: 8285 | X19: 8534 | Y19: 8192 | Z19: 8356 | AA19: 8607 | AB19: 8779 | AC19: 9042 | AD19: 8771 | AE19: 8946 | AF19: 9125 | AG19: 9217 | AH19: 9032
L20: 2 | M20: 6149 | N20: 6793 | O20: 6655 | P20: 6740 | Q20: 6647 | R20: 1972 | S20: 588 | T20: 2070 | U20: 2887 | V20: 3666 | W20: 3946 | X20: 4222 | Y20: 4053 | Z20: 4134 | AA20: 4217 | AB20: 4259 | AC20: 4387 | AD20: 4212 | AE20: 4296 | AF20: 4382 | AG20: 4469 | AH20: 4380
L21: 3 | M21: 1975 | N21: 2094 | O21: 2101 | P21: 1953 | Q21: 1892 | R21: 1785 | S21: 1922 | T21: 1407 | U21: 1512 | V21: 1161 | W21: 1086 | X21: 1108 | Y21: 1074 | Z21: 1085 | AA21: 1096 | AB21: 1107 | AC21: 1118 | AD21: 1096 | AE21: 1107 | AF21: 1118 | AG21: 1129 | AH21: 1095
K22: PF | L22: 1 | M22: 26395 | N22: 18036 | O22: 19567 | P22: 21775 | Q22: 24094 | R22: 20361 | S22: 21905 | T22: 22294 | U22: 24686 | V22: 25134 | W22: 30239 | X22: 35682 | Y22: 34612 | Z22: 35304 | AA22: 36363 | AB22: 37454 | AC22: 38577 | AD22: 37806 | AE22: 38562 | AF22: 39333 | AG22: 40120 | AH22: 40922
L23: 2 | M23: 9582 | N23: 11036 | O23: 10102 | P23: 10640 | Q23: 11504 | R23: 10237 | S23: 13952 | T23: 13606 | U23: 14459 | V23: 12631 | W23: 15942 | X23: 17377 | Y23: 17203 | Z23: 17719 | AA23: 18428 | AB23: 19165 | AC23: 19740 | AD23: 19937 | AE23: 20336 | AF23: 20743 | AG23: 21158 | AH23: 21369
L24: 3 | M24: 2881 | N24: 3060 | O24: 3108 | P24: 3172 | Q24: 3248 | R24: 2466 | S24: 2899 | T24: 2728 | U24: 2877 | V24: 2182 | W24: 3461 | X24: 3738 | Y24: 3663 | Z24: 3700 | AA24: 3589 | AB24: 3625 | AC24: 3661 | AD24: 3588 | AE24: 3624 | AF24: 3660 | AG24: 3696 | AH24: 3733
K25: FORTIFIT | L25: VANILLA | Q25: 284 | R25: 129 | S25: 22 | T25: 298 | U25: 133 | V25: 287 | W25: 329 | X25: 352 | Y25: 380 | Z25: 388 | AA25: 392 | AB25: 400 | AC25: 411 | AD25: 424 | AE25: 420 | AF25: 428 | AG25: 441 | AH25: 432
K26: Total | M26: =SUM(M19:M24) -> 57073 | N26: =SUM(N19:N24) -> 51189 | O26: =SUM(O19:O24) -> 51962 | P26: =SUM(P19:P24) -> 54818 | Q26: =SUM(Q19:Q25) -> 58531 | R26: =SUM(R19:R25) -> 44255 | S26: =SUM(S19:S25) -> 49300 | T26: =SUM(T19:T25) -> 49157 | U26: =SUM(U19:U25) -> 54474 | V26: =SUM(V19:V25) -> 53199 | W26: =SUM(W19:W25) -> 63288 | X26: =SUM(X19:X25) -> 71013 | ... AH26: =SUM(AH19:AH25) -> 80963
V27: =SUM(V19:V24) -> 52912 | W27: =SUM(W19:W24) -> 62959 | X27: =SUM(X19:X24) -> 70661 | Y27: =SUM(Y19:Y24) -> 68797 | Z27: =SUM(Z19:Z24) -> 70298 | AA27: =SUM(AA19:AA24) -> 72300 | AB27: =SUM(AB19:AB24) -> 74389 | AC27: =SUM(AC19:AC24) -> 76525 | ... AH27: =SUM(AH19:AH24) -> 80531
A29: 용인 | B29: CJ | C29: 디앤비 | D29: 아르고 | E29: 품고 | F29: 8/20 기말재고 | G29: 예상 기말재고 | J29: Stock(CU) | M29: Sep. | N29: Oct. | O29: Nov. | P29: Dec. | Q29: Jan. | R29: Feb. | S29: Mar. | T29: Apr. | U29: May. | V29: Jun. | W29: July. | X29: Aug. | Y29: Sept. | Z29: Oct. | AA29: Nov. | AB29: Dec. | AC29: Jan. | AD29: Feb. | AE29: Mar. | AF29: Apr. | AG29: May. | AH29: Jun.
A30: 39459 | B30: 10 | C30: 1408 | D30: 1 | E30: 1219 | F30: =A30+B30+C30+D30+E30 -> 42097 | G30: =F30-(X19/31*11) -> 39068.806 | H30: =X30-G30 -> -133.80645 | J30: Stock(CU) | K30: PN | L30: 1 | M30: 30844 | N30: 20669 | O30: 17050 | P30: 13685 | Q30: 10623 | R30: 3902 | S30: 9601 | T30: 3607 | U30: 39061 | V30: 42442 | W30: 47469 | X30: =W30+X6-X19 -> 38935 | Y30: =X30+Y6-Y19 -> 30743 | Z30: =Y30+Z6-Z19 -> 22387 | AA30: =Z30+AA6-AA19 -> 26452 | AB30: =AA30+AB6-AB19 -> 17673 | AC30: =AB30+AC6-AC19 -> 14967 | AD30: =AC30+AD6-AD19 -> 25204 | AE30: =AD30+AE6-AE19 -> 16258 | ... AH30: =AG30+AH6-AH19 -> -11116
A31: 24163 | B31: 136 | C31: 2452 | D31: 165 | E31: 432 | F31: =A31+B31+C31+D31+E31 -> 27348 | G31: =F31-(X20/31*11) -> 25849.871 | H31: =X31-G31 -> 226.12903 | L31: 2 | M31: 36898 | N31: 36258 | O31: 30555 | P31: 29714 | Q31: 20343 | R31: 0 | S31: 6194 | T31: 9670 | U31: 14884 | V31: 10629 | W31: 23526 | X31: =W31+X7-X20 -> 26076 | Y31: =X31+Y7-Y20 -> 22023 | Z31: =Y31+Z7-Z20 -> 17889 | AA31: =Z31+AA7-AA20 -> 13672 | AB31: =AA31+AB7-AB20 -> 9413 | AC31: =AB31+AC7-AC20 -> 11362 | AD31: =AC31+AD7-AD20 -> 13486 | AE31: =AD31+AE7-AE20 -> 9190 | ... AH31: =AG31+AH7-AH20 -> -4041
A32: 8799 | B32: 286 | C32: 1020 | D32: 198 | E32: 0 | F32: =A32+B32+C32+D32+E32 -> 10303 | G32: =F32-(X21/31*11) -> 9909.8387 | H32: =X32-G32 -> -195.83871 | L32: 3 | M32: 9504 | N32: 13528 | O32: 11315 | P32: 9370 | Q32: 5587 | R32: 3807 | S32: 2641 | T32: 1780 | U32: 7358 | V32: 5628 | W32: 5062 | X32: =W32+X8-X21 -> 9714 | Y32: =X32+Y8-Y21 -> 8640 | Z32: =Y32+Z8-Z21 -> 7555 | AA32: =Z32+AA8-AA21 -> 6459 | AB32: =AA32+AB8-AB21 -> 5352 | AC32: =AB32+AC8-AC21 -> 4234 | AD32: =AC32+AD8-AD21 -> 3138 | AE32: =AD32+AE8-AE21 -> 2031 | ... AH32: =AG32+AH8-AH21 -> -1311
A33: 17071 | B33: 0 | C33: 1760 | D33: 0 | E33: 1387 | F33: =A33+B33+C33+D33+E33 -> 20218 | G33: =F33-(X22/31*11) -> 7556.6452 | H33: =X33-G33 -> -1588.6452 | K33: PF | L33: 1 | M33: 30317 | N33: 28612 | O33: 34273 | P33: 12108 | Q33: 47968 | R33: 45113 | S33: 49297 | T33: 28221 | U33: 42865 | V33: 38482 | W33: 23218 | X33: =W33+X9-X22 -> 5968 | Y33: =X33+Y9-Y22 -> 51316 | Z33: =Y33+Z9-Z22 -> 36364 | AA33: =Z33+AA9-AA22 -> 48001 | AB33: =AA33+AB9-AB22 -> 38963 | AC33: =AB33+AC9-AC22 -> 76802 | AD33: =AC33+AD9-AD22 -> 96596 | AE33: =AD33+AE9-AE22 -> 58034 | ... AH33: =AG33+AH9-AH22 -> -62341
A34: 31105 | B34: 0 | C34: 2352 | D34: 5 | E34: 899 | F34: =A34+B34+C34+D34+E34 -> 34361 | G34: =F34-(X23/31*11) -> 28194.968 | H34: =X34-G34 -> 1077.0323 | L34: 2 | M34: 44579 | N34: 33292 | O34: 36167 | P34: 26193 | Q34: 43047 | R34: 51471 | S34: 39515 | T34: 33519 | U34: 18531 | V34: 6669 | W34: 37433 | X34: =W34+X10-X23 -> 29272 | Y34: =X34+Y10-Y23 -> 38285 | Z34: =Y34+Z10-Z23 -> 32086 | AA34: =Z34+AA10-AA23 -> 38554 | AB34: =AA34+AB10-AB23 -> 30525 | AC34: =AB34+AC10-AC23 -> 37665 | AD34: =AC34+AD10-AD23 -> 52288 | AE34: =AD34+AE10-AE23 -> 31952 | ... AH34: =AG34+AH10-AH23 -> -31318
A35: 6193 | B35: 115 | C35: 1788 | D35: 7 | E35: 0 | F35: =A35+B35+C35+D35+E35 -> 8103 | G35: =F35-(X24/31*11) -> 6776.6129 | H35: =X35-G35 -> -47.612903 | L35: 3 | M35: 16866 | N35: 13727 | O35: 19729 | P35: 16406 | Q35: 12636 | R35: 18546 | S35: 16659 | T35: 14687 | U35: 11366 | V35: 8797 | W35: 10467 | X35: =W35+X11-X24 -> 6729 | Y35: =X35+Y11-Y24 -> 5490 | Z35: =Y35+Z11-Z24 -> 1790 | AA35: =Z35+AA11-AA24 -> 5721 | AB35: =AA35+AB11-AB24 -> 6320 | AC35: =AB35+AC11-AC24 -> 9955 | AD35: =AC35+AD11-AD24 -> 6367 | AE35: =AD35+AE11-AE24 -> 2743 | ... AH35: =AG35+AH11-AH24 -> -8346
F36: =A36+B36+C36+D36+E36 -> 0 | G36: =F36-(X25/31*11) -> -124.90323 | H36: =X36-G36 -> 33795.903 | K36: FORTIFIT | L36: VANILLA | P36: =O36+P12-P25 -> 6912 | Q36: 45869 | R36: 11717 | S36: 11671 | T36: 11347 | U36: 22844 | V36: 34353 | W36: 34023 | X36: =W36+X12-X25 -> 33671 | Y36: =X36+Y12-Y25 -> 33291 | Z36: =Y36+Z12-Z25 -> 32903 | AA36: =Z36+AA12-AA25 -> 32511 | AB36: =AA36+AB12-AB25 -> 32111 | AC36: =AB36+AC12-AC25 -> 31700 | AD36: =AC36+AD12-AD25 -> 31276 | AE36: =AD36+AE12-AE25 -> 30856 | ... AH36: =AG36+AH12-AH25 -> 29555
K37: Total | M37: =SUM(M30:M35) -> 169008 | N37: =SUM(N30:N35) -> 146086 | O37: =SUM(O30:O35) -> 149089 | P37: =SUM(P30:P35) -> 107476 | Q37: =SUM(Q30:Q36) -> 186073 | R37: =SUM(R30:R36) -> 134556 | S37: =SUM(S30:S36) -> 135578 | T37: =SUM(T30:T36) -> 102831 | U37: =SUM(U30:U36) -> 156909 | V37: =SUM(V30:V36) -> 147000 | W37: =SUM(W30:W36) -> 181198 | X37: =SUM(X30:X36) -> 150365 | ... AH37: =SUM(AH30:AH36) -> -88918
L38: 적정재고수준 | M38: 재고월수X 실제 재고량으로 확인 필요
J39: Stock Level(Month) | M39: Sep. | N39: Oct. | O39: Nov. | P39: Dec. | Q39: Jan. | R39: Feb. | S39: Mar. | T39: Apr. | U39: May. | V39: Jun. | W39: July. | X39: Aug. | Y39: Sept. | Z39: Oct. | AA39: Nov. | AB39: Dec. | AC39: Jan. | AD39: Feb. | AE39: Mar. | AF39: Apr. | AG39: May. | AH39: Jun.
J40: Stock month by SKU | K40: PN | L40: 1 | M40: =M30/M19 -> 3.0565851 | N40: =N30/N19 -> 2.03235 | O40: =O30/O19 -> 1.6348643 | P40: =P30/P19 -> 1.2986335 | Q40: =Q30/Q19 -> 0.97799669 | R40: =R30/R19 -> 0.53415469 | S40: =S30/S19 -> 1.1983275 | T40: =T30/T19 -> 0.53405389 | ... AH40: =AH30/AH19 -> -1.2307352
L41: 2 | M41: =M31/M20 -> 6.0006505 | N41: =N31/N20 -> 5.3375534 | O41: =O31/O20 -> 4.5912847 | P41: =P31/P20 -> 4.4086053 | Q41: =Q31/Q20 -> 3.0604784 | R41: =R31/R20 -> 0 | S41: =S31/S20 -> 10.534014 | T41: =T31/T20 -> 4.6714976 | ... AH41: =AH31/AH20 -> -0.92260274
L42: 3 | M42: =M32/M21 -> 4.8121519 | N42: =N32/N21 -> 6.4603629 | O42: =O32/O21 -> 5.3855307 | P42: =P32/P21 -> 4.7977471 | Q42: =Q32/Q21 -> 2.9529598 | R42: =R32/R21 -> 2.1327731 | S42: =S32/S21 -> 1.3740895 | T42: =T32/T21 -> 1.2651031 | ... AH42: =AH32/AH21 -> -1.1972603
K43: PF | L43: 1 | M43: =M33/M22 -> 1.1485887 | N43: =N33/N22 -> 1.5863828 | O43: =O33/O22 -> 1.7515715 | P43: =P33/P22 -> 0.55605052 | Q43: =Q33/Q22 -> 1.9908691 | R43: =R33/R22 -> 2.2156574 | S43: =S33/S22 -> 2.2504908 | T43: =T33/T22 -> 1.2658563 | ... AH43: =AH33/AH22 -> -1.5234104
L44: 2 | M44: =M34/M23 -> 4.652369 | N44: =N34/N23 -> 3.0166727 | O44: =O34/O23 -> 3.5801821 | P44: =P34/P23 -> 2.4617481 | Q44: =Q34/Q23 -> 3.7419159 | R44: =R34/R23 -> 5.0279379 | S44: =S34/S23 -> 2.8322104 | T44: =T34/T23 -> 2.4635455 | ... AH44: =AH34/AH23 -> -1.465581
...

Sheet Domestic_2607
I2: ※ Aptamil Domestic Stock Overview
E4: 뉴트리시아 코리아 소통 | I4: 1700 | P4: 2026
A5: SKU | C5: 파렛트 수량 조정 | D5: 파렛트 총합 | E5: 컨테이너 수 | F5: 월평균 출고량 | G5: MOQ (TU) | H5: TU | I5: Supply (arrival) | L5: Sep. | M5: Oct. | N5: Nov. | O5: Dec. | P5: Jan. | Q5: Feb. | R5: Mar. | S5: Apr. | T5: May. | U5: Jun. | V5: July. | W5: Aug. | X5: Sept. | Y5: Oct. | Z5: Nov. | AA5: Dec. | AB5: Jan. | AC5: Feb. | AD5: Mar. | AE5: Apr. | AF5: May.
A6: PN | B6: 1 | C6: 18 | D6: =SUM(C6:C8) -> 22 | E6: =D6/22 -> 1 | F6: =AVERAGE(S19:U19)/4 -> 1901 | G6: 1500 | H6: =AB6/4 -> 2592 | I6: Supply (arrival) | J6: PN | K6: 1 | L6: 12308 | N6: 6072 | O6: 7488 | P6: 11520 | R6: 11948 | T6: 44008 | U6: 11572 | V6: =13320 -> 13320 | Z6: 12672 | AB6: =144*4*C6 -> 10368 | AC6: 6336
B7: 2 | C7: 4 | F7: =AVERAGE(S20:U20)/4 -> 718.58333 | G7: 1500 | H7: =AB7/4 -> 576 | K7: 2 | L7: 5948 | M7: 6336 | N7: 432 | O7: 6252 | P7: 1152 | R7: 7080 | S7: 6336 | T7: 8064 | V7: 17088 | W7: 6772 | AB7: =144*4*C7 -> 2304
B8: 3 | C8: 0 | F8: =AVERAGE(S21:U21)/4 -> 340 | G8: 1500 | H8: =AB8/4 -> 0 | K8: 3 | M8: 6212 | T8: 6912 | V8: 332 | W8: 5760 | AB8: =144*4*C8 -> 0
A9: PF | B9: 1 | C9: 112 | D9: =SUM(C9:C11) -> 192 | E9: =D9/24 -> 8 | F9: =AVERAGE(S22:U22)/4 -> 6009.5 | G9: 2120 | H9: =AB9/4 -> 10752 | J9: PF | K9: 1 | L9: 9216 | M9: 16512 | N9: 24300 | P9: 60572 | Q9: 21560 | R9: 23808 | T9: 39428 | U9: 20880 | V9: 14968 | W9: =31192+19200 -> 50392 | X9: 38400 | Y9: =39552-19200 -> 20352 | Z9: =48000*2-38400 -> 57600 | AA9: 28416 | AB9: =96*4*C9 -> 43008
B10: 2 | C10: 61 | F10: =AVERAGE(S23:U23)/4 -> 3391.3333 | G10: 2280 | H10: =AB10/4 -> 5856 | K10: 2 | N10: 12432 | P10: 30336 | Q10: 21584 | S10: 6528 | V10: =27648 -> 27648 | W10: =21288+7680 -> 28968 | X10: 21120 | Y10: =19200-7680 -> 11520 | Z10: =24896*2-21120 -> 28672 | AA10: 11136 | AB10: =96*4*C10 -> 23424
B11: 3 | C11: 19 | F11: =AVERAGE(S24:U24)/4 -> 648.91667 | G11: 1880 | H11: =AB11/4 -> 1824 | K11: 3 | N11: 8832 | P11: 232 | Q11: 10688 | V11: 3072 | W11: =2424+1520 -> 3944 | Z11: 7520 | AA11: 4224 | AB11: =96*4*C11 -> 7296
J12: FORTIFIT | K12: VANILLA | O12: 6912 | Q12: 5208 | T12: 11628 | U12: 11796
J13: Total | L13: =SUM(L6:L12) -> 27472 | M13: =SUM(M6:M12) -> 29060 | N13: =SUM(N6:N12) -> 52068 | O13: =SUM(O6:O12) -> 20652 | P13: =SUM(P6:P12) -> 103812 | Q13: =SUM(Q6:Q12) -> 59040 | R13: =SUM(R6:R12) -> 42836 | S13: =SUM(S6:S12) -> 12864 | ... AF13: =SUM(AF6:AF12) -> 0
J14: 발주 금액 | L14: =금액!E11 -> 4.457202e+08 | M14: =금액!F11 -> 3.0657648e+08 | N14: =금액!G11 -> 1.5969699e+08 | O14: =금액!H11 -> 3.3539444e+08 | P14: =금액!I11 -> 3.1119442e+08 | Q14: =금액!J11 -> 1208753.5 | R14: =금액!K11 -> 4.6487151e+08 | S14: =금액!L11 -> 1.5476444e+08 | ... AF14: =금액!Y11 -> 0
J15: 발주 금액(KRW) | L15: =L14*$I$4 -> 757724340272 | M15: =M14*$I$4 -> 5.2118001e+11 | N15: =N14*$I$4 -> 2.7148489e+11 | O15: =O14*$I$4 -> 5.7017054e+11 | P15: =P14*$I$4 -> 529030511892 | Q15: =Q14*$I$4 -> 2054880984 | R15: =R14*$I$4 -> 7.9028157e+11 | S15: =S14*$I$4 -> 2.6309955e+11 | ... AF15: =AF14*$I$4 -> 0
L17: Actual | M17: Actual | N17: Actual | O17: Actual | P17: Actual | Q17: Actual | R17: Actual | S17: Actual | T17: Actual | U17: Actual | V17: fcst | W17: fcst | X17: fcst | Y17: fcst | Z17: fcst | AA17: fcst | AB17: fcst | AC17: fcst | AD17: fcst | AE17: fcst | AF17: fcst
I18: Sales | L18: Sept. | M18: Oct. | N18: Nov. | O18: Dec. | P18: Jan. | Q18: Feb. | R18: Mar. | S18: Apr. | T18: May. | U18: Jun. | V18: July. | W18: Aug. | X18: Sept. | Y18: Oct. | Z18: Nov. | AA18: Dec. | AB18: Jan. | AC18: Feb. | AD18: Mar. | AE18: Apr. | AF18: May.
I19: Sales CU | J19: PN | K19: 1 | L19: 10091 | M19: 10170 | N19: 10429 | O19: 10538 | P19: 10862 | Q19: 7305 | R19: 8012 | S19: 6754 | T19: 7920 | U19: 8138 | V19: 8152 | W19: 8397 | X19: 8229 | Y19: 8393 | Z19: 8729 | AA19: 9078 | AB19: 9350 | AC19: 9163 | AD19: 9347 | AE19: 9534 | AF19: 9629
K20: 2 | L20: 6149 | M20: 6793 | N20: 6655 | O20: 6740 | P20: 6647 | Q20: 1972 | R20: 588 | S20: 2070 | T20: 2887 | U20: 3666 | V20: 3876 | W20: 3954 | X20: 3835 | Y20: 3912 | Z20: 3990 | AA20: 4030 | AB20: 4151 | AC20: 3985 | AD20: 4064 | AE20: 4146 | AF20: 4229
K21: 3 | L21: 1975 | M21: 2094 | N21: 2101 | O21: 1953 | P21: 1892 | Q21: 1785 | R21: 1922 | S21: 1407 | T21: 1512 | U21: 1161 | V21: 1115 | W21: 1148 | X21: 1137 | Y21: 1148 | Z21: 1171 | AA21: 1195 | AB21: 1207 | AC21: 1219 | AD21: 1231 | AE21: 1243 | AF21: 1256
J22: PF | K22: 1 | L22: 26395 | M22: 18036 | N22: 19567 | O22: 21775 | P22: 24094 | Q22: 20361 | R22: 21905 | S22: 22294 | T22: 24686 | U22: 25134 | V22: 26860 | W22: 29277 | X22: 28692 | Y22: 29840 | Z22: 32525 | AA22: 35127 | AB22: 36532 | AC22: 35802 | AD22: 36518 | AE22: 37248 | AF22: 37993
K23: 2 | L23: 9582 | M23: 11036 | N23: 10102 | O23: 10640 | P23: 11504 | Q23: 10237 | R23: 13952 | S23: 13606 | T23: 14459 | U23: 12631 | V23: 14719 | W23: 16044 | X23: 16365 | Y23: 16856 | Z23: 17867 | AA23: 18760 | AB23: 19511 | AC23: 19706 | AD23: 20100 | AE23: 20502 | AF23: 20912
K24: 3 | L24: 2881 | M24: 3060 | N24: 3108 | O24: 3172 | P24: 3248 | Q24: 2466 | R24: 2899 | S24: 2728 | T24: 2877 | U24: 2182 | V24: 3191 | W24: 3223 | X24: 3255 | Y24: 3288 | Z24: 3353 | AA24: 3421 | AB24: 3455 | AC24: 3489 | AD24: 3524 | AE24: 3559 | AF24: 3595
J25: FORTIFIT | K25: VANILLA | P25: 284 | Q25: 129 | R25: 22 | S25: 298 | T25: 133 | U25: 287 | V25: 296 | W25: 313 | X25: 354 | Y25: 343 | Z25: 350 | AA25: 357 | AB25: 372 | AC25: 383 | AD25: 379 | AE25: 387 | AF25: 398
J26: Total | L26: =SUM(L19:L24) -> 57073 | M26: =SUM(M19:M24) -> 51189 | N26: =SUM(N19:N24) -> 51962 | O26: =SUM(O19:O24) -> 54818 | P26: =SUM(P19:P25) -> 58531 | Q26: =SUM(Q19:Q25) -> 44255 | R26: =SUM(R19:R25) -> 49300 | S26: =SUM(S19:S25) -> 49157 | T26: =SUM(T19:T25) -> 54474 | U26: =SUM(U19:U25) -> 53199 | V26: =SUM(V19:V25) -> 58209 | W26: =SUM(W19:W25) -> 62356 | ... AF26: =SUM(AF19:AF25) -> 78012
U27: =SUM(U19:U24) -> 52912 | V27: =SUM(V19:V24) -> 57913 | W27: =SUM(W19:W24) -> 62043 | X27: =SUM(X19:X24) -> 61513 | Y27: =SUM(Y19:Y24) -> 63437 | Z27: =SUM(Z19:Z24) -> 67635 | AA27: =SUM(AA19:AA24) -> 71611 | AB27: =SUM(AB19:AB24) -> 74206 | ... AF27: =SUM(AF19:AF24) -> 77614
A29: 용인 | B29: CJ | C29: 디앤비 | D29: 아르고 | E29: 7/22 기말재고 | F29: 예상 기말재고 | I29: Stock(CU) | L29: Sep. | M29: Oct. | N29: Nov. | O29: Dec. | P29: Jan. | Q29: Feb. | R29: Mar. | S29: Apr. | T29: May. | U29: Jun. | V29: July. | W29: Aug. | X29: Sept. | Y29: Oct. | Z29: Nov. | AA29: Dec. | AB29: Jan. | AC29: Feb. | AD29: Mar. | AE29: Apr. | AF29: May.
A30: 47282 | B30: 797 | C30: 2036 | D30: 190 | E30: =A30+B30+C30+D30 -> 50305 | F30: =E30-(V19/31*9) -> 47938.29 | G30: =V30-F30 -> 0 | I30: Stock(CU) | J30: PN | K30: 1 | L30: 30844 | M30: 20669 | N30: 17050 | O30: 13685 | P30: 10623 | Q30: 3902 | R30: 9601 | S30: 3607 | T30: 39061 | U30: 42442 | V30: 47938.29 | W30: =V30+W6-W19 -> 39541.29 | X30: =W30+X6-X19 -> 31312.29 | Y30: =X30+Y6-Y19 -> 22919.29 | Z30: =Y30+Z6-Z19 -> 26862.29 | AA30: =Z30+AA6-AA19 -> 17784.29 | AB30: =AA30+AB6-AB19 -> 18802.29 | AC30: =AB30+AC6-AC19 -> 15975.29 | AD30: =AC30+AD6-AD19 -> 6628.2903 | ... AF30: =AE30+AF6-AF19 -> -12534.71
A31: 20378 | B31: 751 | C31: 3212 | D31: 350 | E31: =A31+B31+C31+D31 -> 24691 | F31: =E31-(V20/31*9) -> 23565.71 | G31: =V31-F31 -> 0 | K31: 2 | L31: 36898 | M31: 36258 | N31: 30555 | O31: 29714 | P31: 20343 | Q31: 0 | R31: 6194 | S31: 9670 | T31: 14884 | U31: 10629 | V31: 23565.71 | W31: =V31+W7-W20 -> 26383.71 | X31: =W31+X7-X20 -> 22548.71 | Y31: =X31+Y7-Y20 -> 18636.71 | Z31: =Y31+Z7-Z20 -> 14646.71 | AA31: =Z31+AA7-AA20 -> 10616.71 | AB31: =AA31+AB7-AB20 -> 8769.7097 | AC31: =AB31+AC7-AC20 -> 4784.7097 | AD31: =AC31+AD7-AD20 -> 720.70968 | ... AF31: =AE31+AF7-AF20 -> -7654.2903
A32: 3593 | B32: 415 | C32: 1012 | D32: 252 | E32: =A32+B32+C32+D32 -> 5272 | F32: =E32-(V21/31*9) -> 4948.2903 | G32: =V32-F32 -> 0 | K32: 3 | L32: 9504 | M32: 13528 | N32: 11315 | O32: 9370 | P32: 5587 | Q32: 3807 | R32: 2641 | S32: 1780 | T32: 7358 | U32: 5628 | V32: 4948.2903 | W32: =V32+W8-W21 -> 9560.2903 | X32: =W32+X8-X21 -> 8423.2903 | Y32: =X32+Y8-Y21 -> 7275.2903 | Z32: =Y32+Z8-Z21 -> 6104.2903 | AA32: =Z32+AA8-AA21 -> 4909.2903 | AB32: =AA32+AB8-AB21 -> 3702.2903 | AC32: =AB32+AC8-AC21 -> 2483.2903 | AD32: =AC32+AD8-AD21 -> 1252.2903 | ... AF32: =AE32+AF8-AF21 -> -1246.7097
A33: 28740 | B33: 2335 | C33: 2960 | D33: 597 | E33: =A33+B33+C33+D33 -> 34632 | F33: =E33-(V22/31*9) -> 26833.935 | G33: =V33-F33 -> 0 | J33: PF | K33: 1 | L33: 30317 | M33: 28612 | N33: 34273 | O33: 12108 | P33: 47968 | Q33: 45113 | R33: 49297 | S33: 28221 | T33: 42865 | U33: 38482 | V33: 26833.935 | W33: =V33+W9-W22 -> 47948.935 | X33: =W33+X9-X22 -> 57656.935 | Y33: =X33+Y9-Y22 -> 48168.935 | Z33: =Y33+Z9-Z22 -> 73243.935 | AA33: =Z33+AA9-AA22 -> 66532.935 | AB33: =AA33+AB9-AB22 -> 73008.935 | AC33: =AB33+AC9-AC22 -> 37206.935 | AD33: =AC33+AD9-AD22 -> 688.93548 | ... AF33: =AE33+AF9-AF22 -> -74552.065
A34: 18843 | B34: 668 | C34: 4528 | D34: 493 | E34: =A34+B34+C34+D34 -> 24532 | F34: =E34-(V23/31*9) -> 20258.742 | G34: =V34-F34 -> 0 | K34: 2 | L34: 44579 | M34: 33292 | N34: 36167 | O34: 26193 | P34: 43047 | Q34: 51471 | R34: 39515 | S34: 33519 | T34: 18531 | U34: 6669 | V34: 20258.742 | W34: =V34+W10-W23 -> 33182.742 | X34: =W34+X10-X23 -> 37937.742 | Y34: =X34+Y10-Y23 -> 32601.742 | Z34: =Y34+Z10-Z23 -> 43406.742 | AA34: =Z34+AA10-AA23 -> 35782.742 | AB34: =AA34+AB10-AB23 -> 39695.742 | AC34: =AB34+AC10-AC23 -> 19989.742 | AD34: =AC34+AD10-AD23 -> -110.25806 | ... AF34: =AE34+AF10-AF23 -> -41524.258
A35: 7533 | B35: 342 | C35: 1628 | D35: 291 | E35: =A35+B35+C35+D35 -> 9794 | F35: =E35-(V24/31*9) -> 8867.5806 | G35: =V35-F35 -> 0 | K35: 3 | L35: 16866 | M35: 13727 | N35: 19729 | O35: 16406 | P35: 12636 | Q35: 18546 | R35: 16659 | S35: 14687 | T35: 11366 | U35: 8797 | V35: 8867.5806 | W35: =V35+W11-W24 -> 9588.5806 | X35: =W35+X11-X24 -> 6333.5806 | Y35: =X35+Y11-Y24 -> 3045.5806 | Z35: =Y35+Z11-Z24 -> 7212.5806 | AA35: =Z35+AA11-AA24 -> 8015.5806 | AB35: =AA35+AB11-AB24 -> 11856.581 | AC35: =AB35+AC11-AC24 -> 8367.5806 | AD35: =AC35+AD11-AD24 -> 4843.5806 | ... AF35: =AE35+AF11-AF24 -> -2310.4194
A36: 34043 | B36: 0 | C36: 0 | D36: 0 | E36: =A36+B36+C36+D36 -> 34043 | F36: =E36-(V25/31*9) -> 33957.065 | G36: =V36-F36 -> 0 | J36: FORTIFIT | K36: VANILLA | O36: =N36+O12-O25 -> 6912 | P36: 45869 | Q36: 11717 | R36: 11671 | S36: 11347 | T36: 22844 | U36: 34353 | V36: 33957.065 | W36: =V36+W12-W25 -> 33644.065 | X36: =W36+X12-X25 -> 33290.065 | Y36: =X36+Y12-Y25 -> 32947.065 | Z36: =Y36+Z12-Z25 -> 32597.065 | AA36: =Z36+AA12-AA25 -> 32240.065 | AB36: =AA36+AB12-AB25 -> 31868.065 | AC36: =AB36+AC12-AC25 -> 31485.065 | AD36: =AC36+AD12-AD25 -> 31106.065 | ... AF36: =AE36+AF12-AF25 -> 30321.065
J37: Total | L37: =SUM(L30:L35) -> 169008 | M37: =SUM(M30:M35) -> 146086 | N37: =SUM(N30:N35) -> 149089 | O37: =SUM(O30:O35) -> 107476 | P37: =SUM(P30:P36) -> 186073 | Q37: =SUM(Q30:Q36) -> 134556 | R37: =SUM(R30:R36) -> 135578 | S37: =SUM(S30:S36) -> 102831 | T37: =SUM(T30:T36) -> 156909 | U37: =SUM(U30:U36) -> 147000 | V37: =SUM(V30:V36) -> 166369.61 | W37: =SUM(W30:W36) -> 199849.61 | ... AF37: =SUM(AF30:AF36) -> -109501.39
K38: 적정재고수준 | L38: 재고월수X 실제 재고량으로 확인 필요
I39: Stock Level(Month) | L39: Sep. | M39: Oct. | N39: Nov. | O39: Dec. | P39: Jan. | Q39: Feb. | R39: Mar. | S39: Apr. | T39: May. | U39: Jun. | V39: July. | W39: Aug. | X39: Sept. | Y39: Oct. | Z39: Nov. | AA39: Dec. | AB39: Jan. | AC39: Feb. | AD39: Mar. | AE39: Apr. | AF39: May.
I40: Stock month by SKU | J40: PN | K40: 1 | L40: =L30/L19 -> 3.0565851 | M40: =M30/M19 -> 2.03235 | N40: =N30/N19 -> 1.6348643 | O40: =O30/O19 -> 1.2986335 | P40: =P30/P19 -> 0.97799669 | Q40: =Q30/Q19 -> 0.53415469 | R40: =R30/R19 -> 1.1983275 | S40: =S30/S19 -> 0.53405389 | ... AF40: =AF30/AF19 -> -1.3017665
K41: 2 | L41: =L31/L20 -> 6.0006505 | M41: =M31/M20 -> 5.3375534 | N41: =N31/N20 -> 4.5912847 | O41: =O31/O20 -> 4.4086053 | P41: =P31/P20 -> 3.0604784 | Q41: =Q31/Q20 -> 0 | R41: =R31/R20 -> 10.534014 | S41: =S31/S20 -> 4.6714976 | ... AF41: =AF31/AF20 -> -1.8099528
K42: 3 | L42: =L32/L21 -> 4.8121519 | M42: =M32/M21 -> 6.4603629 | N42: =N32/N21 -> 5.3855307 | O42: =O32/O21 -> 4.7977471 | P42: =P32/P21 -> 2.9529598 | Q42: =Q32/Q21 -> 2.1327731 | R42: =R32/R21 -> 1.3740895 | S42: =S32/S21 -> 1.2651031 | ... AF42: =AF32/AF21 -> -0.99260325
J43: PF | K43: 1 | L43: =L33/L22 -> 1.1485887 | M43: =M33/M22 -> 1.5863828 | N43: =N33/N22 -> 1.7515715 | O43: =O33/O22 -> 0.55605052 | P43: =P33/P22 -> 1.9908691 | Q43: =Q33/Q22 -> 2.2156574 | R43: =R33/R22 -> 2.2504908 | S43: =S33/S22 -> 1.2658563 | ... AF43: =AF33/AF22 -> -1.9622579
K44: 2 | L44: =L34/L23 -> 4.652369 | M44: =M34/M23 -> 3.0166727 | N44: =N34/N23 -> 3.5801821 | O44: =O34/O23 -> 2.4617481 | P44: =P34/P23 -> 3.7419159 | Q44: =Q34/Q23 -> 5.0279379 | R44: =R34/R23 -> 2.8322104 | S44: =S34/S23 -> 2.4635455 | ... AF44: =AF34/AF23 -> -1.9856665
...

Sheet Domestic_2606
I2: ※ Aptamil Domestic Stock Overview | V2: =7680/4 -> 1920 | W2: =4800*4 -> 19200 | Y2: 12848 | Z2: =24896/4 -> 6224
V3: =V2*4 -> 7680 | Y3: =Y2*4 -> 51392
E4: 뉴트리시아 코리아 소통 | I4: 1750 | P4: 2026
C5: 파렛트 수량 조정 | E5: 컨테이너 수 | F5: 월평균 출고량 | G5: moq | H5: TU | I5: Supply (arrival) | L5: Sep. | M5: Oct. | N5: Nov. | O5: Dec. | P5: Jan. | Q5: Feb. | R5: Mar. | S5: Apr. | T5: May. | U5: Jun. | V5: July. | W5: Aug. | X5: Sept. | Y5: Oct. | Z5: Nov. | AA5: Dec. | AB5: Jan. | AC5: Feb. | AD5: Mar. | AE5: Apr. | AF5: May.
A6: PN | B6: 1 | C6: 0 | D6: =SUM(C6:C8) -> 0 | E6: =D6/22 -> 0 | G6: 1500 | H6: =AA6/4 -> 0 | I6: Supply (arrival) | J6: PN | K6: 1 | L6: 12308 | N6: 6072 | O6: 7488 | P6: 11520 | R6: 11948 | T6: 44008 | U6: 11572 | V6: =13320 -> 13320 | Z6: 12672 | AA6: =144*4*C6 -> 0 | AB6: 18000 | AC6: 12000
B7: 2 | C7: 0 | G7: 1500 | H7: =AA7/4 -> 0 | K7: 2 | L7: 5948 | M7: 6336 | N7: 432 | O7: 6252 | P7: 1152 | R7: 7080 | S7: 6336 | T7: 8064 | V7: 17088 | W7: 6772 | AA7: =144*4*C7 -> 0
B8: 3 | C8: 0 | G8: 1500 | H8: =AA8/4 -> 0 | K8: 3 | M8: 6212 | T8: 6912 | V8: 332 | W8: 5760 | AA8: =144*4*C8 -> 0 | AB8: 6000
A9: PF | B9: 1 | C9: 74 | D9: =SUM(C9:C11) -> 114 | E9: =(D9-18)/24+1 -> 5 | G9: 2120 | H9: =AA9/4 -> 7104 | J9: PF | K9: 1 | L9: 9216 | M9: 16512 | N9: 24300 | P9: 60572 | Q9: 21560 | R9: 23808 | T9: 39428 | U9: 20880 | V9: 14968 | W9: =31192+19200 -> 50392 | X9: 38400 | Y9: =39552-19200 -> 20352 | Z9: =48000*2-38400 -> 57600 | AA9: =96*4*C9 -> 28416 | AB9: 26000
B10: 2 | C10: 29 | G10: 2280 | H10: =AA10/4 -> 2784 | K10: 2 | N10: 12432 | P10: 30336 | Q10: 21584 | S10: 6528 | V10: =27648 -> 27648 | W10: =7680+21288 -> 28968 | X10: 21120 | Y10: =19200-7680 -> 11520 | Z10: =24896*2-21120 -> 28672 | AA10: =96*4*C10 -> 11136 | AB10: 18000
B11: 3 | C11: 11 | G11: 1880 | H11: =AA11/4 -> 1056 | K11: 3 | N11: 8832 | P11: 232 | Q11: 10688 | V11: 3072 | W11: =2424+1520 -> 3944 | Z11: 7520 | AA11: =96*4*C11 -> 4224 | AB11: 3000
J12: FORTIFIT | K12: VANILLA | O12: 6912 | Q12: 5208 | T12: 11628 | U12: 11796
C13: AMN 4파렛트 배정 (ELN 18파렛트) + 24파렛트 기준 | J13: Total | L13: =SUM(L6:L12) -> 27472 | M13: =SUM(M6:M12) -> 29060 | N13: =SUM(N6:N12) -> 52068 | O13: =SUM(O6:O12) -> 20652 | P13: =SUM(P6:P12) -> 103812 | Q13: =SUM(Q6:Q12) -> 59040 | R13: =SUM(R6:R12) -> 42836 | S13: =SUM(S6:S12) -> 12864 | ... AF13: =SUM(AF6:AF12) -> 0
J14: 발주 금액 | L14: =금액!E11 -> 4.457202e+08 | M14: =금액!F11 -> 3.0657648e+08 | N14: =금액!G11 -> 1.5969699e+08 | O14: =금액!H11 -> 3.3539444e+08 | P14: =금액!I11 -> 3.1119442e+08 | Q14: =금액!J11 -> 1208753.5 | R14: =금액!K11 -> 4.6487151e+08 | S14: =금액!L11 -> 1.5476444e+08 | ... AF14: =금액!Y11 -> 0
J15: 발주 금액(KRW) | L15: =L14*$I$4 -> 780010350280 | M15: =M14*$I$4 -> 5.3650884e+11 | N15: =N14*$I$4 -> 2.7946974e+11 | O15: =O14*$I$4 -> 5.8694027e+11 | P15: =P14*$I$4 -> 544590232830 | Q15: =Q14*$I$4 -> 2115318660 | R15: =R14*$I$4 -> 8.1352515e+11 | S15: =S14*$I$4 -> 2.7083778e+11 | ... AF15: =AF14*$I$4 -> 0
L17: Actual | M17: Actual | N17: Actual | O17: Actual | P17: Actual | Q17: Actual | R17: Actual | S17: Actual | T17: Actual | U17: fcst | V17: fcst | W17: fcst | X17: fcst | Y17: fcst | Z17: fcst | AA17: fcst | AB17: fcst | AC17: fcst | AD17: fcst | AE17: fcst | AF17: fcst
I18: Sales | L18: Sept. | M18: Oct. | N18: Nov. | O18: Dec. | P18: Jan. | Q18: Feb. | R18: Mar. | S18: Apr. | T18: May. | U18: Jun. | V18: July. | W18: Aug. | X18: Sept. | Y18: Oct. | Z18: Nov. | AA18: Dec. | AB18: Jan. | AC18: Feb. | AD18: Mar. | AE18: Apr. | AF18: May.
I19: Sales CU | J19: PN | K19: 1 | L19: 10091 | M19: 10170 | N19: 10429 | O19: 10538 | P19: 10862 | Q19: 7305 | R19: 8012 | S19: 6754 | T19: 7920 | U19: 7623 | V19: 7928 | W19: 8086 | X19: 8248 | Y19: 8413 | Z19: 8581 | AA19: 8667 | AB19: 8927 | AC19: 9195 | AD19: 9379
K20: 2 | L20: 6149 | M20: 6793 | N20: 6655 | O20: 6740 | P20: 6647 | Q20: 1972 | R20: 588 | S20: 2070 | T20: 2887 | U20: 3129 | V20: 3223 | W20: 3287 | X20: 3353 | Y20: 3420 | Z20: 3523 | AA20: 3628 | AB20: 3701 | AC20: 3775 | AD20: 3851
K21: 3 | L21: 1975 | M21: 2094 | N21: 2101 | O21: 1953 | P21: 1892 | Q21: 1785 | R21: 1922 | S21: 1407 | T21: 1512 | U21: 1272 | V21: 1297 | W21: 1336 | X21: 1363 | Y21: 1377 | Z21: 1404 | AA21: 1432 | AB21: 1447 | AC21: 1461 | AD21: 1476
J22: PF | K22: 1 | L22: 26395 | M22: 18036 | N22: 19567 | O22: 21775 | P22: 24094 | Q22: 20361 | R22: 21905 | S22: 22294 | T22: 24686 | U22: 24960 | V22: 25958 | W22: 26737 | X22: 27005 | Y22: 27545 | Z22: 28646 | AA22: 29219 | AB22: 29804 | AC22: 30102 | AD22: 30704
K23: 2 | L23: 9582 | M23: 11036 | N23: 10102 | O23: 10640 | P23: 11504 | Q23: 10237 | R23: 13952 | S23: 13606 | T23: 14459 | U23: 12814 | V23: 13839 | W23: 14254 | X23: 14539 | Y23: 14830 | Z23: 15720 | AA23: 16192 | AB23: 16515 | AC23: 16681 | AD23: 16847
