Workbook

Sheet 시트29
D1: 남양주 | F1: 디앤비
A2: Sales | D2: 2월 마감재고 | E2: 3월 입고 재고 | F2: 롯마 출고 | G2: 이마출고 | H2: 풀필 출고 | I2: 일반 출고 | J2: 디앤비 회송 입고 | K2: 디앤비 파손 | L2: 유통기한 임박 폐기 | M2: 풀필 회송 | N2: 입고파손 | O2: 작업중 빈박스 | P2: 2월 재고 정정 | Q2: 이마트 점포 클레임 | R2: 영훈 파트장님 출고 | S2: 실장님 사용 | T2: 기부 | U2: 반품입고 | V2: 3월 마감 재고 | W2: 3월 마감 실재고 | X2: 차이
B3: PN | C3: 1 | D3: 15895 | F3: 112 | G3: 896 | H3: 4184 | I3: 4505 | L3: 32 | M3: =1215+12+3 -> 1230 | P3: -2 | R3: 4 | U3: 75 | V3: =D3+SUM(E3,J3,M3,P3,Q3)-SUM(F3:I3,K3:L3,N3:O3,R3:S3)+U3-T3 -> 7465 | W3: 7454 | X3: =V3-W3 -> 11
C4: 2 | D4: =36081-448 -> 35633 | F4: 336 | G4: 2240 | H4: 3712 | I4: 4404 | J4: 328 | K4: 328 | M4: =216+939 -> 1155 | N4: 1 | O4: 6 | U4: 58 | V4: =D4+SUM(E4,J4,M4,P4,Q4)-SUM(F4:I4,K4:L4,N4:O4,R4:S4)+U4-T4 -> 26147 | W4: 26136 | X4: =V4-W4 -> 11
C5: 3 | D5: 14523 | F5: 224 | G5: 896 | H5: 680 | I5: 1123 | J5: 324 | K5: 240 | M5: 180 | N5: 2 | P5: -2 | T5: =1300+2500 -> 3800 | U5: 21 | V5: =D5+SUM(E5,J5,M5,P5,Q5)-SUM(F5:I5,K5:L5,N5:O5,R5:S5)+U5-T5 -> 8081 | W5: 8091 | X5: =V5-W5 -> -10
B6: PF | C6: 1 | D6: 54780 | E6: 16896 | F6: 448 | G6: 1792 | H6: 6284 | I6: 7589 | M6: =6+1755+3 -> 1764 | R6: 4 | U6: 246 | V6: =D6+SUM(E6,J6,M6,P6,Q6)-SUM(F6:I6,K6:L6,N6:O6,R6:S6)+U6-T6 -> 57569 | W6: 57556 | X6: =V6-W6 -> 13
C7: 2 | D7: 57191 | E7: 15360 | F7: 448 | G7: 1792 | H7: 4164 | I7: 3979 | M7: 1368 | P7: =3 -> 3 | S7: 6 | U7: 58 | V7: =D7+SUM(E7,J7,M7,P7,Q7)-SUM(F7:I7,K7:L7,N7:O7,R7:S7)+U7-T7 -> 63591 | W7: 63591 | X7: =V7-W7 -> 0
C8: 3 | D8: 15223 | E8: 4608 | F8: 448 | G8: 896 | H8: 939 | I8: 1282 | M8: 456 | Q8: =4+4 -> 8 | U8: 9 | V8: =D8+SUM(E8,J8,M8,P8,Q8)-SUM(F8:I8,K8:L8,N8:O8,R8:S8)+U8-T8 -> 16739 | W8: 16738 | X8: =V8-W8 -> 1
B9: Total | D9: =SUM(D3:D8) -> 193245 | E9: =SUM(E3:E8) -> 36864 | F9: =SUM(F3:F8) -> 2016 | G9: =SUM(G3:G8) -> 8512 | H9: =SUM(H3:H8) -> 19963 | I9: =SUM(I3:I8) -> 22882 | J9: =SUM(J3:J8) -> 652 | K9: =SUM(K3:K8) -> 568 | ... X9: =SUM(X3:X8) -> 26
I10: 10702
D11: 풀필먼트 | U11: 73
A12: Sales | D12: 2월 마감재고 | E12: 3월 입고 재고 | F12: 출고 | G12: 반출 | H12: 비가용 재고 | I12: 3월 마감 재고 | J12: 3월 마감 실재고 | K12: 차이 | U12: 9
B13: PN | C13: 1 | D13: 767 | E13: 4184 | F13: 1472 | G13: 1011 | H13: 0 | I13: =D13+E13-F13-G13+H13 -> 2468 | J13: 2468 | K13: =I13-J13 -> 0 | U13: 164
C14: 2 | D14: 389 | E14: 3712 | F14: 1221 | G14: 1155 | H14: 2 | I14: =D14+E14-F14-G14+H14 -> 1727 | J14: 1727 | K14: =I14-J14 -> 0 | U14: 246
C15: 3 | D15: 146 | E15: 680 | F15: 227 | G15: 180 | H15: 4 | I15: =D15+E15-F15-G15+H15 -> 423 | J15: 423 | K15: =I15-J15 -> 0 | U15: =U6-U14 -> 0
B16: PF | C16: 1 | D16: 1911 | E16: 6284 | F16: 2422 | G16: 1977 | H16: 7 | I16: =D16+E16-F16-G16+H16 -> 3803 | J16: 3803 | K16: =I16-J16 -> 0
C17: 2 | D17: 1331 | E17: 4164 | F17: 1784 | G17: 1368 | H17: -210 | I17: =D17+E17-F17-G17+H17 -> 2133 | J17: 2133 | K17: =I17-J17 -> 0
C18: 3 | D18: 448 | E18: 939 | F18: 338 | G18: 456 | H18: -8 | I18: =D18+E18-F18-G18+H18 -> 585 | J18: 585 | K18: =I18-J18 -> 0
B19: Total | D19: =SUM(D13:D18) -> 4992 | E19: =SUM(E13:E18) -> 19963 | F19: =SUM(F13:F18) -> 7464 | G19: =SUM(G13:G18) -> 6147 | H19: =SUM(H13:H18) -> -205 | I19: =SUM(I13:I18) -> 11139 | J19: =SUM(J13:J18) -> 11139 | K19: =SUM(K13:K18) -> 0
D20: 디앤비
A21: Sales | D21: 2월 마감재고 | E21: 3월 입고 재고 | F21: 3월 출고 재고 | G21: 3월 마감 재고 | H21: 3월 마감 실재고 | I21: 차이
B22: PN | C22: 1 | D22: 1484 | E22: 1008 | F22: 1504 | G22: =D22+E22-F22 -> 988 | H22: 988 | I22: =G22-H22 -> 0
C23: 2 | D23: 1032 | E23: 2576 | F23: 2276 | G23: =D23+E23-F23 -> 1332 | H23: 1332 | I23: =G23-H23 -> 0
C24: 3 | D24: 1100 | E24: 1120 | F24: 1452 | G24: =D24+E24-F24 -> 768 | H24: 768 | I24: =G24-H24 -> 0
B25: PF | C25: 1 | D25: 1828 | E25: 2244 | F25: 2660 | G25: =D25+E25-F25 -> 1412 | H25: 1412 | I25: =G25-H25 -> 0
C26: 2 | D26: 1712 | E26: 2244 | F26: 2640 | G26: =D26+E26-F26 -> 1316 | H26: 1316 | I26: =G26-H26 -> 0
C27: 3 | D27: 1200 | E27: 1344 | F27: 1452 | G27: =D27+E27-F27 -> 1092 | H27: 1092 | I27: =G27-H27 -> 0
B28: Total | D28: =SUM(D22:D27) -> 8356 | E28: =SUM(E22:E27) -> 10536 | F28: =SUM(F22:F27) -> 11984 | G28: =SUM(G22:G27) -> 6908 | H28: =SUM(H22:H27) -> 6908 | I28: =SUM(I22:I27) -> 0

Sheet Domestic의 사본 발주예상용
F2: ※ Aptamil Domestic Stock Overview
AA4: 3
F5: Production | I5: Dec | J5: Jan | K5: Feb | L5: Mar | M5: April | N5: May | O5: Jun | P5: July | Q5: Aug | R5: 6월 발주 | S5: 7월 발주 | T5: 8월 발주 | U5: 9월 발주
F6: Supply (arrival) | I6: Mar. | J6: Apr. | K6: May. | L6: Jun. | M6: July. | N6: Aug. | O6: Sep. | P6: Oct. | Q6: Nov. | R6: Dec. | S6: Jan. | T6: Feb. | U6: Mar. | V6: Apr. | W6: May. | Y6: 품목명 | Z6: 재고
G7: PN | H7: 1 | I7: 12096 | J7: 19036 | L7: =2880+2896 -> 5776 | P7: 2880 | R7: =4176*4 -> 16704 | Y7: 누1 | Z7: =SUM(W7:Y7) -> 0 | AA7: 9919 | AB7: 8462 | AC7: 8562
H8: 2 | I8: 14976 | J8: 30252 | K8: =5760 -> 5760 | L8: =7640+9372 -> 17012 | P8: 9792 | R8: =2160*4 -> 8640 | Y8: 누2 | Z8: =SUM(W8:Y8) -> 0 | AA8: 13593 | AB8: 11805 | AC8: 10605
H9: 3 | I9: 4608 | J9: 25380 | K9: 6912 | Y9: 누3 | Z9: =SUM(W9:Y9) -> 0 | AA9: 3902 | AB9: 3755 | AC9: 3600
G10: PF | H10: 1 | J10: 28032 | K10: 1760 | L10: =10752+25320 -> 36072 | M10: =3072+7296 -> 10368 | N10: =338+1152 -> 1490 | O10: =1916+5760+1920+1152+384+20736 -> 31868 | R10: =4032*4 -> 16128 | Y10: 푸1 | Z10: =SUM(W10:Y10) -> 0 | AA10: 12546 | AB10: 12378 | AC10: 11714
H11: 2 | K11: =7296 -> 7296 | L11: =292+9216 -> 9508 | M11: =16896+3072 -> 19968 | N11: =212+384+768 -> 1364 | O11: 17664 | P11: 9216 | R11: =2880*4 -> 11520 | Y11: 푸2 | Z11: =SUM(W11:Y11) -> 0 | AA11: 10462 | AB11: 10136 | AC11: 10741
H12: 3 | J12: 8820 | L12: 3508 | M12: =5376+3840 -> 9216 | N12: =212+6528 -> 6740 | O12: 5760 | Y12: 푸3 | Z12: =SUM(W12:Y12) -> 0 | AA12: 4541 | AB12: 4407 | AC12: 3939
G13: Total | I13: =SUM(I7:I12) -> 31680 | J13: =SUM(J7:J12) -> 111520 | K13: =SUM(K7:K12) -> 21728 | L13: =SUM(L7:L12) -> 71876 | M13: =SUM(M7:M12) -> 39552 | N13: =SUM(N7:N12) -> 9594 | O13: =SUM(O7:O12) -> 55292 | P13: =SUM(P7:P12) -> 21888 | ... W13: =SUM(W7:W12) -> 0
G14: 발주 금액 | I14: =#REF! -> #REF! | J14: =#REF! -> #REF! | K14: =#REF! -> #REF! | L14: =#REF! -> #REF! | M14: =#REF! -> #REF! | N14: =#REF! -> #REF! | O14: =#REF! -> #REF! | P14: =#REF! -> #REF! | ... W14: =#REF! -> #REF! | AA14: =AA7*3 -> 29757 | AB14: =AB7*3 -> 25386 | AC14: =AC7*3 -> 25686
G15: 발주 금액(KRW) | I15: =I14* 1456.78 -> #REF! | J15: =J14* 1456.78 -> #REF! | K15: =K14* 1456.78 -> #REF! | L15: =L14* 1456.78 -> #REF! | M15: =M14* 1456.78 -> #REF! | N15: =N14* 1456.78 -> #REF! | O15: =O14* 1456.78 -> #REF! | P15: =P14* 1456.78 -> #REF! | ... W15: =W14* 1456.78 -> #REF! | AA15: =AA8*3 -> 40779 | AB15: =AB8*3 -> 35415 | AC15: =AC8*3 -> 31815
AA16: =AA9*3 -> 11706 | AB16: =AB9*3 -> 11265 | AC16: =AC9*3 -> 10800
I17: Actual | J17: Actual | K17: Actual | L17: fcst | M17: fcst | N17: fcst | O17: fcst | P17: fcst | Q17: fcst | R17: fcst | AA17: =AA10*3 -> 37638 | AB17: =AB10*3 -> 37134 | AC17: =AC10*3 -> 35142
F18: Sales | I18: Mar. | J18: Apr. | K18: May. | L18: Jun. | M18: July | N18: Aug. | O18: Sep. | P18: Oct. | Q18: Nov. | R18: Dec. | S18: Jan. | T18: Feb. | U18: Mar. | V18: Apr. | W18: May. | AA18: =AA11*3 -> 31386 | AB18: =AB11*3 -> 30408 | AC18: =AC11*3 -> 32223
G19: PN | H19: 1 | I19: 8462 | J19: 8396 | K19: 8562 | L19: 8839 | M19: 8713 | N19: 8626 | O19: 8540 | P19: 8497 | Q19: 8582 | R19: 8754 | S19: 8841 | T19: 8886 | U19: 8797 | V19: 8665 | W19: 8752 | AA19: =AA12*3 -> 13623 | AB19: =AB12*3 -> 13221 | AC19: =AC12*3 -> 11817
H20: 2 | I20: 11805 | J20: 11381 | K20: 10605 | L20: 9769 | M20: 9681 | N20: 9536 | O20: 9488 | P20: 9536 | Q20: 9631 | R20: 9823 | S20: 9693 | T20: 9628 | U20: 9564 | V20: 9532 | W20: 9595
H21: 3 | I21: 3755 | J21: 3498 | K21: 3600 | L21: 3523 | M21: 3381 | N21: 3347 | O21: 3313 | P21: 3330 | Q21: 3363 | R21: 3397 | S21: 3374 | T21: 3340 | U21: 3329 | V21: 3340 | W21: 3363
G22: PF | H22: 1 | I22: 12378 | J22: 11967 | K22: 11714 | L22: 11979 | M22: 11790 | N22: 11731 | O22: 11848 | P22: 11967 | Q22: 12206 | R22: 12450 | S22: 12574 | T22: 12637 | U22: 12511 | V22: 12574 | W22: 12624
H23: 2 | I23: 10136 | J23: 10658 | K23: 10741 | L23: 11355 | M23: 11138 | N23: 11250 | O23: 11362 | P23: 11249 | Q23: 11305 | R23: 11418 | S23: 11342 | T23: 11304 | U23: 11379 | V23: 11455 | W23: 11608
H24: 3 | I24: 4407 | J24: 3907 | K24: 3939 | L24: 3866 | M24: 3928 | N24: 3947 | O24: 3908 | P24: 3869 | Q24: 3849 | R24: 3901 | S24: 3927 | T24: 3953 | U24: 3927 | V24: 3940 | W24: 3966
G25: Total | I25: =SUM(I19:I24) -> 50943 | J25: =SUM(J19:J24) -> 49807 | K25: =SUM(K19:K24) -> 49161 | L25: =SUM(L19:L24) -> 49331 | M25: =SUM(M19:M24) -> 48631 | N25: =SUM(N19:N24) -> 48437 | O25: =SUM(O19:O24) -> 48459 | P25: =SUM(P19:P24) -> 48448 | ... W25: =SUM(W19:W24) -> 49908
B28: 재고 | C28: 판매량 | D28: 입고 | F28: Stock(CU) | I28: Mar. | J28: Apr. | K28: May. | L28: Jun. | M28: July | N28: Aug. | O28: Sep. | P28: Oct. | Q28: Nov. | R28: Dec. | S28: Jan. | T28: Feb. | U28: Mar. | V28: Apr. | W28: May.
A29: 66530 | B29: =SUMIF(#REF!,E29,#REF!) -> #REF! | C29: #N/A | D29: 5760 | E29: 01976-00 | G29: PN | H29: 1 | I29: 65764 | J29: 75367 | K29: 66530 | L29: =K29+L7-L19 -> 63467 | M29: =L29+M7-M19 -> 54754 | N29: =M29+N7-N19 -> 46128 | O29: =N29+O7-O19 -> 37588 | P29: =O29+P7-P19 -> 31971 | Q29: =P29+Q7-Q19 -> 23389 | R29: =Q29+R7-R19 -> 31339 | S29: =R29+S7-S19 -> 22498 | ... W29: =V29+W7-W19 -> -12602
A30: 69360 | B30: =SUMIF(#REF!,E30,#REF!) -> #REF! | C30: #N/A | D30: 14976 | E30: 01977-00 | H30: 2 | I30: 55465 | J30: 75543 | K30: 69360 | L30: =K30+L8-L20 -> 76603 | M30: =L30+M8-M20 -> 66922 | N30: =M30+N8-N20 -> 57386 | O30: =N30+O8-O20 -> 47898 | P30: =O30+P8-P20 -> 48154 | Q30: =P30+Q8-Q20 -> 38523 | R30: =Q30+R8-R20 -> 37340 | S30: =R30+S8-S20 -> 27647 | ... W30: =V30+W8-W20 -> -10672
A31: 35399 | B31: =SUMIF(#REF!,E31,#REF!) -> #REF! | C31: #N/A | D31: 4608 | E31: 01978-00 | H31: 3 | I31: 10635 | J31: 32258 | K31: 35399 | L31: =K31+L9-L21 -> 31876 | M31: =L31+M9-M21 -> 28495 | N31: =M31+N9-N21 -> 25148 | O31: =N31+O9-O21 -> 21835 | P31: =O31+P9-P21 -> 18505 | Q31: =P31+Q9-Q21 -> 15142 | R31: =Q31+R9-R21 -> 11745 | S31: =R31+S9-S21 -> 8371 | ... W31: =V31+W9-W21 -> -5001
A32: 30069 | B32: =SUMIF(#REF!,E32,#REF!) -> #REF! | C32: #N/A | E32: 02352-00 | G32: PF | H32: 1 | I32: 23691 | J32: 40883 | K32: 30069 | L32: =K32+L10-L22 -> 54162 | M32: =L32+M10-M22 -> 52740 | N32: =M32+N10-N22 -> 42499 | O32: =N32+O10-O22 -> 62519 | P32: =O32+P10-P22 -> 50552 | Q32: =P32+Q10-Q22 -> 38346 | R32: =Q32+R10-R22 -> 42024 | S32: =R32+S10-S22 -> 29450 | ... W32: =V32+W10-W22 -> -20896
A33: 49623 | B33: =SUMIF(#REF!,E33,#REF!) -> #REF! | C33: #N/A | E33: 02353-00 | H33: 2 | I33: 64523 | J33: 53429 | K33: 49623 | L33: =K33+L11-L23 -> 47776 | M33: =L33+M11-M23 -> 56606 | N33: =M33+N11-N23 -> 46720 | O33: =N33+O11-O23 -> 53022 | P33: =O33+P11-P23 -> 50989 | Q33: =P33+Q11-Q23 -> 39684 | R33: =Q33+R11-R23 -> 39786 | S33: =R33+S11-S23 -> 28444 | ... W33: =V33+W11-W23 -> -17302
A34: 14991 | B34: =SUMIF(#REF!,E34,#REF!) -> #REF! | C34: #N/A | E34: 02354-00 | H34: 3 | I34: 14504 | J34: 19092 | K34: 14991 | L34: =K34+L12-L24 -> 14633 | M34: =L34+M12-M24 -> 19921 | N34: =M34+N12-N24 -> 22714 | O34: =N34+O12-O24 -> 24566 | P34: =O34+P12-P24 -> 20697 | Q34: =P34+Q12-Q24 -> 16848 | R34: =Q34+R12-R24 -> 12947 | S34: =R34+S12-S24 -> 9020 | ... W34: =V34+W12-W24 -> -6766
A35: =SUM(A29:A34) -> 265972 | G35: Total | I35: =SUM(I29:I34) -> 234582 | J35: =SUM(J29:J34) -> 296572 | K35: =SUM(K29:K34) -> 265972 | L35: =SUM(L29:L34) -> 288517 | M35: =SUM(M29:M34) -> 279438 | N35: =SUM(N29:N34) -> 240595 | O35: =SUM(O29:O34) -> 247428 | P35: =SUM(P29:P34) -> 220868 | ... W35: =SUM(W29:W34) -> -73239
F38: Stock Level(Month) | I38: Mar. | J38: Apr. | K38: May. | L38: Jun. | M38: July. | N38: Aug. | O38: Sep. | P38: Oct. | Q38: Nov. | R38: Dec. | S38: Jan. | T38: Feb. | U38: Mar. | V38: Apr. | W38: May.
G39: PN | H39: 1 | I39: =I29/I19 -> 7.7716852 | J39: =J29/J19 -> 8.9765364 | K39: =K29/K19 -> 7.7703808 | L39: =L29/L19 -> 7.1803371 | M39: =M29/M19 -> 6.2841731 | N39: =N29/N19 -> 5.3475539 | O39: =O29/O19 -> 4.4014052 | P39: =P29/P19 -> 3.7626221 | ... W39: =W29/W19 -> -1.4398995
H40: 2 | I40: =I30/I20 -> 4.6984329 | J40: =J30/J20 -> 6.6376417 | K40: =K30/K20 -> 6.5403112 | L40: =L30/L20 -> 7.8414372 | M40: =M30/M20 -> 6.9127156 | N40: =N30/N20 -> 6.0178272 | O40: =O30/O20 -> 5.0482715 | P40: =P30/P20 -> 5.0497064 | ... W40: =W30/W20 -> -1.112246
H41: 3 | I41: =I31/I21 -> 2.8322237 | J41: =J31/J21 -> 9.2218411 | K41: =K31/K21 -> 9.8330556 | L41: =L31/L21 -> 9.0479705 | M41: =M31/M21 -> 8.4279799 | N41: =N31/N21 -> 7.5135943 | O41: =O31/O21 -> 6.5907033 | P41: =P31/P21 -> 5.5570571 | ... W41: =W31/W21 -> -1.4870651
G42: PF | H42: 1 | I42: =I32/I22 -> 1.9139603 | J42: =J32/J22 -> 3.4163115 | K42: =K32/K22 -> 2.5669285 | L42: =L32/L22 -> 4.5214125 | M42: =M32/M22 -> 4.4732824 | N42: =N32/N22 -> 3.6227943 | O42: =O32/O22 -> 5.2767556 | P42: =P32/P22 -> 4.2242834 | ... W42: =W32/W22 -> -1.6552598
H43: 2 | I43: =I33/I23 -> 6.3657261 | J43: =J33/J23 -> 5.0130418 | K43: =K33/K23 -> 4.6199609 | L43: =L33/L23 -> 4.2074857 | M43: =M33/M23 -> 5.082241 | N43: =N33/N23 -> 4.1528889 | O43: =O33/O23 -> 4.666608 | P43: =P33/P23 -> 4.5327585 | ... W43: =W33/W23 -> -1.4905238
H44: 3 | I44: =I34/I24 -> 3.2911278 | J44: =J34/J24 -> 4.8866138 | K44: =K34/K24 -> 3.8057883 | L44: =L34/L24 -> 3.7850491 | M44: =M34/M24 -> 5.0715377 | N44: =N34/N24 -> 5.7547504 | O44: =O34/O24 -> 6.2860798 | P44: =P34/P24 -> 5.3494443 | ... W44: =W34/W24 -> -1.706001
G45: Total | I45: =AVERAGE(I39:I44) -> 4.4788593 | J45: =AVERAGE(J39:J44) -> 6.3586644 | K45: =AVERAGE(K39:K44) -> 5.8560709 | L45: =AVERAGE(L39:L44) -> 6.097282 | M45: =AVERAGE(M39:M44) -> 6.0419883 | N45: =AVERAGE(N39:N44) -> 5.4015682 | O45: =AVERAGE(O39:O44) -> 5.3783039 | P45: =AVERAGE(P39:P44) -> 4.7459786 | ... W45: =AVERAGE(W39:W44) -> -1.4818325

Sheet Medical
A1: ※ Medical Stock Overview
A3: 1670 | I3: Suggested
A4: Supply (arrival) | D4: Dec. | E4: Jau. | F4: Feb. | G4: Mar. | H4: Apr. | I4: May. | N4: 금액
A5: Supply (arrival) | B5: =_xlfn.XLOOKUP(C5,'메디컬 SKU'!C:C,'메디컬 SKU'!A:A) -> 117547 | C5: Duocal | D5: 42.677419 | E5: 96 | F5: 324 | G5: 324 | H5: 360 | I5: 198 | K5: 12월 이전 물량 | L5: 12월 transfer | M5: 1월 결제 | N5: =D23 -> 4.7149024e+08
B6: =_xlfn.XLOOKUP(C6,'메디컬 SKU'!C:C,'메디컬 SKU'!A:A) -> 552897 | C6: Elemental Orange | D6: 6566 | E6: 0 | F6: 0 | G6: 0 | H6: 0 | I6: 0 | K6: 10월 생산 | L6: 11월 shipout | M6: 12월 결제 | N6: =E23 -> 8.288635e+08
B7: =_xlfn.XLOOKUP(C7,'메디컬 SKU'!C:C,'메디컬 SKU'!A:A) -> 117771 | C7: PK AID | D7: 220 | E7: 0 | F7: 60 | G7: 60 | H7: 120 | I7: 60 | K7: 11월 생산 | L7: 12월 shipout | M7: 1월 결제 | N7: =F23 -> 3.0087032e+08
B8: =_xlfn.XLOOKUP(C8,'메디컬 SKU'!C:C,'메디컬 SKU'!A:A) -> 646546 | C8: TYR Anamix | D8: 28.709677 | E8: 0 | F8: 68 | G8: 0 | H8: 0 | I8: 0 | K8: 12월 생산 | L8: 1월 shipout | M8: 2월 결제 | N8: =G23 -> 156893160
B9: =_xlfn.XLOOKUP(C9,'메디컬 SKU'!C:C,'메디컬 SKU'!A:A) -> 646567 | C9: NKH Anamix | D9: 61.258065 | E9: 68 | F9: 0 | G9: 0 | H9: 0 | I9: 0 | K9: 1월 생산 | L9: 2월 shipout | M9: 3월 결제 | N9: =H23 -> 63795670
B10: =_xlfn.XLOOKUP(C10,'메디컬 SKU'!C:C,'메디컬 SKU'!A:A) -> 691217 | C10: Lorenzo Oil | D10: 20 | E10: 48 | F10: 84 | G10: 0 | H10: 0 | I10: 84 | K10: 2월 생산 | L10: 3월 shipout | M10: 4월 결제 | N10: =I23 -> 619003202
B11: =_xlfn.XLOOKUP(C11,'메디컬 SKU'!C:C,'메디컬 SKU'!A:A) -> 611174 | C11: Infatrini | D11: 3472 | E11: 19008 | F11: 0 | G11: 0 | H11: 0 | I11: 12096 | N11: =SUM(N5:N10) -> 2.4409161e+09
B12: =_xlfn.XLOOKUP(C12,'메디컬 SKU'!C:C,'메디컬 SKU'!A:A) -> 701775 | C12: Neocate LCP | D12: 4116.3871 | E12: 0 | F12: 4536 | G12: 2592 | H12: 0 | I12: 1944
B13: =_xlfn.XLOOKUP(C13,'메디컬 SKU'!C:C,'메디컬 SKU'!A:A) -> 646548 | C13: GA1 Anamix Infant | D13: 38.419355 | E13: 168 | F13: 0 | G13: 0 | H13: 60 | I13: 0
B14: =_xlfn.XLOOKUP(C14,'메디컬 SKU'!C:C,'메디컬 SKU'!A:A) -> 589462 | C14: GA1 Anamix Junior | D14: 141 | E14: 96 | F14: 0 | G14: 65 | H14: 60 | I14: 0
B15: =_xlfn.XLOOKUP(C15,'메디컬 SKU'!C:C,'메디컬 SKU'!A:A) -> 589466 | C15: MSUD Anamix Junior | D15: 9.1290323 | E15: 259 | F15: 0 | G15: 0 | H15: 180 | I15: 132
B16: =_xlfn.XLOOKUP(C16,'메디컬 SKU'!C:C,'메디컬 SKU'!A:A) -> 116180 | C16: MSUD Maxamum | D16: 82 | E16: 420 | F16: 60 | G16: 60 | H16: 90 | I16: 600
B17: =_xlfn.XLOOKUP(C17,'메디컬 SKU'!C:C,'메디컬 SKU'!A:A) -> 695413 | C17: Locasol | D17: 25.516129 | E17: 238 | F17: 0 | G17: 0 | H17: 120 | I17: 0
B18: =_xlfn.XLOOKUP(C18,'메디컬 SKU'!C:C,'메디컬 SKU'!A:A) -> 699883 | C18: Basic F | D18: 72.83871 | E18: 86 | F18: 0 | G18: 0 | H18: 90 | I18: 0
B19: =_xlfn.XLOOKUP(C19,'메디컬 SKU'!C:C,'메디컬 SKU'!A:A) -> 645380 | C19: Aptamil Pepti Syneo | D19: 261.19355 | E19: 3454 | F19: 864 | G19: 0 | H19: 0 | I19: 1728
B20: =_xlfn.XLOOKUP(C20,'메디컬 SKU'!C:C,'메디컬 SKU'!A:A) -> 578785 | C20: Elemental 028 Banana | D20: 176.70968 | E20: 735 | F20: 0 | G20: 0 | H20: 0 | I20: 0
B21: Total | D21: =SUM(D5:D20) -> 15333.839 | E21: =SUM(E5:E20) -> 24676 | F21: =SUM(F5:F20) -> 5996 | G21: =SUM(G5:G20) -> 3101 | H21: =SUM(H5:H20) -> 1080 | I21: =SUM(I5:I20) -> 16842
B22: 발주 금액 | D22: =금액!H56 -> 282329.49 | E22: =금액!I56 -> 496325.45 | F22: =금액!J56 -> 180161.87 | G22: =금액!K56 -> 93948 | H22: =금액!L56 -> 38201 | I22: =금액!M56 -> 370660.6
B23: 발주 금액(KRW) | D23: =D22*$A$3 -> 4.7149024e+08 | E23: =E22*$A$3 -> 8.288635e+08 | F23: =F22*$A$3 -> 3.0087032e+08 | G23: =G22*$A$3 -> 156893160 | H23: =H22*$A$3 -> 63795670 | I23: =I22*$A$3 -> 619003202
E25: fcst | F25: fcst | G25: fcst | H25: fcst
A26: Sales | D26: Oct-Dec. | E26: Jau. | F26: Feb. | G26: Mar. | H26: Apr. | I26: May.
A27: Sales CU | B27: =_xlfn.XLOOKUP(C27,'메디컬 SKU'!C:C,'메디컬 SKU'!A:A) -> 117547 | C27: Duocal | E27: 187 | F27: 187 | G27: 187 | H27: 187 | I27: =AVERAGE(G27:H27) -> 187
B28: =_xlfn.XLOOKUP(C28,'메디컬 SKU'!C:C,'메디컬 SKU'!A:A) -> 552897 | C28: Elemental Orange | E28: 1453 | F28: 593 | G28: 593 | H28: 1453 | I28: =AVERAGE(G28:H28) -> 1023
B29: =_xlfn.XLOOKUP(C29,'메디컬 SKU'!C:C,'메디컬 SKU'!A:A) -> 117771 | C29: PK AID | E29: 121 | F29: 56 | G29: 56 | H29: 121 | I29: =AVERAGE(G29:H29) -> 88.5
B30: =_xlfn.XLOOKUP(C30,'메디컬 SKU'!C:C,'메디컬 SKU'!A:A) -> 646546 | C30: TYR Anamix | E30: 35 | F30: 35 | G30: 35 | H30: 35 | I30: =AVERAGE(G30:H30) -> 35
B31: =_xlfn.XLOOKUP(C31,'메디컬 SKU'!C:C,'메디컬 SKU'!A:A) -> 646567 | C31: NKH Anamix | E31: 55 | F31: 22 | G31: 22 | H31: 55 | I31: =AVERAGE(G31:H31) -> 38.5
B32: =_xlfn.XLOOKUP(C32,'메디컬 SKU'!C:C,'메디컬 SKU'!A:A) -> 691217 | C32: Lorenzo Oil | E32: 31 | F32: 31 | G32: 31 | H32: 31 | I32: =AVERAGE(G32:H32) -> 31
B33: =_xlfn.XLOOKUP(C33,'메디컬 SKU'!C:C,'메디컬 SKU'!A:A) -> 611174 | C33: Infatrini | E33: 2951 | F33: 3000 | G33: 3000 | H33: 2951 | I33: =AVERAGE(G33:H33) -> 2975.5
B34: =_xlfn.XLOOKUP(C34,'메디컬 SKU'!C:C,'메디컬 SKU'!A:A) -> 701775 | C34: Neocate LCP | E34: 2237 | F34: 1763 | G34: 1763 | H34: 2237 | I34: =AVERAGE(G34:H34) -> 2000
B35: =_xlfn.XLOOKUP(C35,'메디컬 SKU'!C:C,'메디컬 SKU'!A:A) -> 646548 | C35: GA1 Anamix Infant | E35: 70 | F35: 38 | G35: 38 | H35: 70 | I35: =AVERAGE(G35:H35) -> 54
B36: =_xlfn.XLOOKUP(C36,'메디컬 SKU'!C:C,'메디컬 SKU'!A:A) -> 589462 | C36: GA1 Anamix Junior | E36: 102 | F36: 30 | G36: 30 | H36: 102 | I36: =AVERAGE(G36:H36) -> 66
B37: =_xlfn.XLOOKUP(C37,'메디컬 SKU'!C:C,'메디컬 SKU'!A:A) -> 589466 | C37: MSUD Anamix Junior | E37: 136 | F37: 72 | G37: 72 | H37: 136 | I37: =AVERAGE(G37:H37) -> 104
B38: =_xlfn.XLOOKUP(C38,'메디컬 SKU'!C:C,'메디컬 SKU'!A:A) -> 116180 | C38: MSUD Maxamum | E38: 357 | F38: 30 | G38: 30 | H38: 357 | I38: =AVERAGE(G38:H38) -> 193.5
B39: =_xlfn.XLOOKUP(C39,'메디컬 SKU'!C:C,'메디컬 SKU'!A:A) -> 695413 | C39: Locasol | E39: 79 | F39: 49 | G39: 49 | H39: 79 | I39: =AVERAGE(G39:H39) -> 64
... B42: =_xlfn.XLOOKUP(C42,'메디컬 SKU'!C:C,'메디컬 SKU'!A:A) -> 578785 | C42: Elemental 028 Banana | E42: 345 | F42: 185 | G42: 185 | H42: 345 | I42: =AVERAGE(G42:H42) -> 265
B43: Total | D43: =SUM(D27:D42) -> 0 | E43: =SUM(E27:E42) -> 9154 | F43: =SUM(F27:F42) -> 7034 | G43: =SUM(G27:G42) -> 7034 | H43: =SUM(H27:H42) -> 9154 | I43: =SUM(I27:I42) -> 8094
D45: Stock Transfer
...

Sheet Jikgu의 사본 발주 예상용
F2: ※ Aptamil D2C Jikgu Stock Overview
H4: 입고완료 | I4: 발주량
F5: Production | I5: June | J5: July | K5: Aug | L5: Sep | M5: Oct | N5: Nov | O5: Dec | P5: Jan | Q5: Feb | R5: Mar | S5: April | T5: May | U5: June | V5: July | W5: Aug | X5: Sep | Y5: Oct
A6: 인보이스+오더오버뷰(생산계획) | F6: Supply (arrival) | I6: Aug. | J6: Sep. | K6: Oct. | L6: Nov. | M6: Dec. | N6: Jan. | O6: Feb. | P6: Mar. | Q6: Apr. | R6: May. | S6: Jun. | T6: July. | U6: Aug. | V6: Sep. | W6: Oct. | X6: Nov. | Y6: Dec. | Z6: Jan. | AA6: Feb. | AB6: Mar. | AC6: Apr. | AD6: May.
F7: Supply (arrival) | G7: PN | H7: Pre | I7: 3372 | J7: 3510 | N7: 1620 | Y7: 2160
H8: 1 | I8: 2604 | J8: 2700 | N8: 1350 | R8: 5670 | S8: 5130
H9: 2 | I9: 4404 | J9: 4320 | N9: 2430 | T9: 5130 | V9: 5940 | Y9: 3780
H10: 3 | I10: 810 | J10: 810 | N10: 540 | S10: 810 | T10: 810
G11: PF | H11: Pre | I11: 2688 | J11: 7296 | L11: 14592 | M11: 9216 | O11: 19200 | S11: 4992 | T11: =5760+1920+9532 -> 17212 | U11: =7680 -> 7680 | V11: =3456+3840 -> 7296 | Y11: 2688
H12: 1 | I12: 2688 | J12: 7296 | K12: 6912 | M12: 8448 | O12: 26496 | Q12: 16128 | S12: 3456 | T12: =9600+5576 -> 15176 | U12: =8832+8832 -> 17664 | V12: =4992+9984 -> 14976 | W12: 9984 | Y12: 15360
H13: 2 | I13: 3072 | J13: 9984 | K13: 18432 | L13: 19200 | M13: 16128 | O13: 31488 | V13: 11520 | W13: 21504 | Y13: 14592
H14: Kinder | I14: 2688 | J14: 7296 | K14: 6912 | M14: 8448 | P14: =1863+1536 -> 3399 | Q14: 1920 | T14: 1196 | W14: 2304 | Y14: 1152
H15: AR | P15: 1008 | V15: 3024 | Y15: 2016
H16: Comfort | P16: 1008 | V16: 1008
G17: Total | I17: =SUM(I7:I13) -> 19638 | J17: =SUM(J7:J13) -> 35916 | K17: =SUM(K7:K13) -> 25344 | L17: =SUM(L7:L13) -> 33792 | M17: =SUM(M7:M13) -> 33792 | N17: =SUM(N7:N14) -> 5940 | O17: =SUM(O7:O14) -> 77184 | P17: =SUM(P7:P16) -> 5415 | Q17: =SUM(Q7:Q16) -> 18048 | R17: =SUM(R7:R16) -> 5670 | S17: =SUM(S7:S16) -> 14388 | T17: =SUM(T7:T16) -> 39524 | U17: =SUM(U7:U16) -> 25344 | V17: =SUM(V7:V16) -> 43764 | W17: =SUM(W7:W16) -> 33792 | ... AD17: =SUM(AD7:AD16) -> 0
G18: 발주 금액 | Q18: =#REF! -> #REF! | R18: =#REF! -> #REF! | S18: =#REF! -> #REF! | T18: =#REF! -> #REF! | U18: =#REF! -> #REF! | V18: #REF! | W18: #REF! | X18: #REF! | Y18: #REF! | Z18: #REF! | AA18: #REF! | AB18: #REF! | AC18: #REF! | AD18: #REF!
G19: 발주 금액(KRW) | Q19: =Q18*1456.78 -> #REF! | R19: =R18*1456.78 -> #REF! | S19: =S18*1456.78 -> #REF! | T19: =T18*1456.78 -> #REF! | U19: =U18*1456.78 -> #REF! | V19: =V18*1456.78 -> #VALUE! | W19: =W18*1456.78 -> #VALUE! | X19: =X18*1456.78 -> #VALUE! | ... AD19: =AD18*1456.78 -> #VALUE!
I21: actual | J21: actual | K21: actual | L21: actual | M21: actual | N21: actual | O21: actual | P21: actual | Q21: actual | R21: actual | S21: fcst | T21: fcst | U21: fcst | V21: fcst | W21: fcst | X21: fcst | Y21: fcst | Z21: fcst
F22: Sales | I22: Aug. | J22: Sep. | K22: Oct. | L22: Nov. | M22: Dec. | N22: Jan. | O22: Feb. | P22: Mar. | Q22: Apr. | R22: May. | S22: Jun. | T22: July | U22: Aug. | V22: Sep. | W22: Oct. | X22: Nov. | Y22: Dec. | Z22: Jan. | AA22: Feb. | AB22: Mar. | AC22: Apr. | AD22: May.
F23: Sales CU | G23: PN | H23: Pre | I23: 6 | J23: 88 | K23: 67 | L23: 150 | M23: 250 | N23: 377 | O23: 342 | P23: 302 | Q23: 565 | R23: 470 | S23: 711 | T23: 534 | U23: 550 | V23: 644 | W23: 663 | X23: 682 | Y23: 699 | Z23: 720 | AA23: 742 | AB23: 764 | AC23: 795 | AD23: 819
H24: 1 | I24: 22 | J24: 138 | K24: 316 | L24: 832 | M24: 1229 | N24: 1014 | O24: 933 | P24: 743 | Q24: 744 | R24: 700 | S24: 711 | T24: 587 | U24: 590 | V24: 677 | W24: 688 | X24: 701 | Y24: 721 | Z24: 743 | AA24: 765 | AB24: 788 | AC24: 820 | AD24: 844
H25: 2 | I25: 10 | J25: 68 | K25: 161 | L25: 275 | M25: 761 | N25: 743 | O25: 1467 | P25: 1179 | Q25: 1336 | R25: 1178 | S25: 1026 | T25: 1584 | U25: 1616 | V25: 1874 | W25: 1911 | X25: 1966 | Y25: 2023 | Z25: 2084 | AA25: 2146 | AB25: 2253 | AC25: 2411 | AD25: 2652
H26: 3 | I26: 0 | J26: 4 | K26: 8 | L26: 24 | M26: 232 | N26: 207 | O26: 358 | P26: 105 | Q26: 86 | R26: 94 | S26: 86 | T26: 88 | U26: 91 | V26: 107 | W26: 110 | X26: 113 | Y26: 116 | Z26: 120 | AA26: 123 | AB26: 132 | AC26: 145 | AD26: 154
G27: PF | H27: Pre | I27: 184 | J27: 1248 | K27: 1712 | L27: 2254 | M27: 3248 | N27: 4757 | O27: 3703 | P27: 5085 | Q27: 4611 | R27: 5026 | S27: 4541 | T27: 4923 | U27: 5071 | V27: 6598 | W27: 6790 | X27: 6988 | Y27: 7169 | Z27: 7384 | AA27: 7605 | AB27: 7833 | AC27: 8303 | AD27: 8718
H28: 1 | I28: 258 | J28: 1350 | K28: 1896 | L28: 4155 | M28: 5197 | N28: 6023 | O28: 5139 | P28: 7077 | Q28: 6977 | R28: 8068 | S28: 7701 | T28: 7876 | U28: 8113 | V28: 10555 | W28: 10863 | X28: 11179 | Y28: 11469 | Z28: 11813 | AA28: 12167 | AB28: 12532 | AC28: 13284 | AD28: 13948
H29: 2 | I29: 110 | J29: 460 | K29: 691 | L29: 1132 | M29: 2328 | N29: 2898 | O29: 3723 | P29: 8699 | Q29: 11723 | R29: 11363 | S29: 6506 | T29: 8354 | U29: 8605 | V29: 11196 | W29: 11522 | X29: 11857 | Y29: 12166 | Z29: 12530 | AA29: 12906 | AB29: 13294 | AC29: 13692 | AD29: 14103
H30: Kinder | P30: 27 | Q30: 400 | R30: 335 | S30: 446 | T30: 466 | U30: 513 | V30: 713 | W30: 727 | X30: 742 | Y30: 756 | Z30: 772 | AA30: 787 | AB30: 803 | AC30: 819 | AD30: 835
H31: AR | P31: 116 | Q31: 274 | R31: 260 | S31: 317 | T31: 332 | U31: 365 | V31: 506 | W31: 517 | X31: 527 | Y31: 537 | Z31: 548 | AA31: 559 | AB31: 570 | AC31: 582 | AD31: 593
H32: Comfort | P32: 26 | Q32: 106 | R32: 86 | S32: 120 | T32: 125 | U32: 138 | V32: 192 | W32: 196 | X32: 200 | Y32: 204 | Z32: 208 | AA32: 212 | AB32: 216 | AC32: 221 | AD32: 225
G33: Total | I33: =SUM(I23:I29) -> 590 | J33: =SUM(J23:J29) -> 3356 | K33: =SUM(K23:K29) -> 4851 | L33: =SUM(L23:L29) -> 8822 | M33: =SUM(M23:M29) -> 13245 | N33: =SUM(N23:N29) -> 16019 | O33: =SUM(O23:O29) -> 15665 | P33: =SUM(P23:P32) -> 23359 | Q33: =SUM(Q23:Q32) -> 26822 | R33: =SUM(R23:R32) -> 27580 | S33: =SUM(S23:S32) -> 22165 | T33: =SUM(T23:T32) -> 24869 | U33: =SUM(U23:U32) -> 25652 | V33: =SUM(V23:V32) -> 33062 | W33: =SUM(W23:W32) -> 33987 | ... AD33: =SUM(AD23:AD32) -> 42891
A56: 재고 | B56: 전일까지 판매량 | C56: 3/27 재고 | D56: 입고 | F56: Stock | I56: Aug. | J56: Sep. | K56: Oct. | L56: Nov. | M56: Dec. | N56: Jan. | O56: Feb. | P56: Mar. | Q56: Apr. | R56: May. | S56: Jun. | T56: July | U56: Aug. | V56: Sep. | W56: Oct. | X56: Nov. | Y56: Dec. | Z56: Jan. | AA56: Feb. | AB56: Mar. | AC56: Apr. | AD56: May.
A57: =B57+C57-D57 -> #VALUE! | B57: #N/A | C57: =SUMIF(직구재고!B:B,E57,직구재고!J:J) -> 5344 | E57: 4056631001202 | F57: Stock | G57: PN | H57: Pre | I57: =I7-I23 -> 3366 | J57: =I57+J7-J23 -> 6788 | K57: =J57+K7-K23 -> 6721 | L57: =K57+L7-L23 -> 6571 | M57: =L57+M7-M23 -> 6321 | N57: =M57+N7-N23 -> 7564 | O57: =N57+O7-O23 -> 7222 | P57: 6997 | Q57: =P57+Q7-Q23 -> 6432 | R57: 5958 | S57: =R57+S7-S23 -> 5247 | T57: =S57+T7-T23 -> 4713 | U57: =T57+U7-U23 -> 4163 | V57: 1600 | W57: =V57+W7-W23 -> 937 | X57: =W57+X7-X23 -> 255 | Y57: =X57+Y7-Y23 -> 1716 | Z57: =Y57+Z7-Z23 -> 996 | AA57: =Z57+AA7-AA23 -> 254 | AB57: =AA57+AB7-AB23 -> -510 | AC57: =AB57+AC7-AC23 -> -1305 | AD57: =AC57+AD7-AD23 -> -2124
A58: =B58+C58-D58 -> #VALUE! | B58: #N/A | C58: =SUMIF(직구재고!B:B,E58,직구재고!J:J) -> 10474 | E58: 4056631001226 | H58: 1 | I58: =I8-I24 -> 2582 | J58: =I58+J8-J24 -> 5144 | K58: =J58+K8-K24 -> 4828 | L58: =K58+L8-L24 -> 3996 | M58: =L58+M8-M24 -> 2767 | N58: =M58+N8-N24 -> 3103 | O58: =N58+O8-O24 -> 2170 | P58: 1763 | Q58: =P58+Q8-Q24 -> 1019 | R58: 6001 | S58: =R58+S8-S24 -> 10420 | T58: =S58+T8-T24 -> 9833 | U58: =T58+U8-U24 -> 9243 | V58: =U58+V8-V24 -> 8566 | W58: =V58+W8-W24 -> 7878 | X58: =W58+X8-X24 -> 7177 | Y58: =X58+Y8-Y24 -> 6456 | Z58: =Y58+Z8-Z24 -> 5713 | ... AD58: =AC58+AD8-AD24 -> 2496
A59: =B59+C59-D59 -> #VALUE! | B59: #N/A | C59: =SUMIF(직구재고!B:B,E59,직구재고!J:J) -> 3709 | E59: 4056631001240 | H59: 2 | I59: =I9-I25 -> 4394 | J59: =I59+J9-J25 -> 8646 | K59: =J59+K9-K25 -> 8485 | L59: =K59+L9-L25 -> 8210 | M59: =L59+M9-M25 -> 7449 | N59: =M59+N9-N25 -> 9136 | O59: =N59+O9-O25 -> 7669 | P59: 7279 | Q59: =P59+Q9-Q25 -> 5943 | R59: 4737 | S59: =R59+S9-S25 -> 3711 | T59: =S59+T9-T25 -> 7257 | U59: =T59+U9-U25 -> 5641 | V59: =U59+V9-V25 -> 9707 | W59: =V59+W9-W25 -> 7796 | X59: =W59+X9-X25 -> 5830 | Y59: =X59+Y9-Y25 -> 7587 | Z59: =Y59+Z9-Z25 -> 5503 | ... AD59: =AC59+AD9-AD25 -> -3959
A60: =B60+C60-D60 -> #VALUE! | B60: #N/A | C60: =SUMIF(직구재고!B:B,E60,직구재고!J:J) -> 2808 | E60: 4056631001264 | H60: 3 | I60: =I10-I26 -> 810 | J60: =I60+J10-J26 -> 1616 | K60: =J60+K10-K26 -> 1608 | L60: =K60+L10-L26 -> 1584 | M60: =L60+M10-M26 -> 1352 | N60: =M60+N10-N26 -> 1685 | O60: =N60+O10-O26 -> 1327 | P60: 1488 | Q60: =P60+Q9-Q26 -> 1402 | R60: 1308 | S60: =R60+S10-S26 -> 2032 | T60: =S60+T10-T26 -> 2754 | U60: =T60+U10-U26 -> 2663 | V60: =U60+V10-V26 -> 2556 | W60: =V60+W10-W26 -> 2446 | X60: =W60+X10-X26 -> 2333 | Y60: =X60+Y10-Y26 -> 2217 | Z60: =Y60+Z10-Z26 -> 2097 | ... AD60: =AC60+AD10-AD26 -> 1543
A61: =B61+C61-D61 -> #VALUE! | B61: #N/A | C61: =SUMIF(직구재고!B:B,E61,직구재고!J:J) -> 15352 | E61: 4056631003435 | G61: PF | H61: Pre | I61: =I11-I27 -> 2504 | J61: =I61+J11-J27 -> 8552 | K61: =J61+K11-K27 -> 6840 | L61: =K61+L11-L27 -> 19178 | M61: =L61+M11-M27 -> 25146 | N61: =M61+N11-N27 -> 20389 | O61: =N61+O11-O27 -> 35886 | P61: 29847 | Q61: =P61+Q11-Q27 -> 25236 | R61: 20123 | S61: =R61+S11-S27 -> 20574 | T61: =S61+T11-T27 -> 32863 | U61: =T61+U11-U27 -> 35472 | V61: =U61+V11-V27 -> 36170 | W61: =V61+W11-W27 -> 29380 | X61: =W61+X11-X27 -> 22392 | Y61: =X61+Y11-Y27 -> 17911 | Z61: =Y61+Z11-Z27 -> 10527 | ... AD61: =AC61+AD11-AD27 -> -21932
A62: =B62+C62-D62 -> #VALUE! | B62: #N/A | C62: =SUMIF(직구재고!B:B,E62,직구재고!J:J) -> 14338 | E62: 4056631003459 | H62: 1 | I62: =I12-I28 -> 2430 | J62: =I62+J12-J28 -> 8376 | K62: =J62+K12-K28 -> 13392 | L62: =K62+L12-L28 -> 9237 | M62: =L62+M12-M28 -> 12488 | N62: =M62+N12-N28 -> 6465 | O62: =N62+O12-O28 -> 27822 | P62: 20729 | Q62: =P62+Q12-Q28 -> 29880 | R62: 21804 | S62: =R62+S12-S28 -> 17559 | T62: =S62+T12-T28 -> 24859 | U62: =T62+U12-U28 -> 34410 | V62: =U62+V12-V28 -> 38831 | W62: =V62+W12-W28 -> 37952 | X62: =W62+X12-X28 -> 26773 | Y62: =X62+Y12-Y28 -> 30664 | Z62: =Y62+Z12-Z28 -> 18851 | ... AD62: =AC62+AD12-AD28 -> -33080
A63: =B63+C63-D63 -> #VALUE! | B63: #N/A | C63: =SUMIF(직구재고!B:B,E63,직구재고!J:J) -> 49701 | E63: 4056631003473 | H63: 2 | I63: =I13-I29 -> 2962 | J63: =I63+J13-J29 -> 12486 | K63: =J63+K13-K29 -> 30227 | L63: =K63+L13-L29 -> 48295 | M63: =L63+M13-M29 -> 62095 | N63: =M63+N13-N29 -> 59197 | O63: =N63+O13-O29 -> 86962 | P63: 79250 | Q63: =P63+Q13-Q29 -> 67527 | R63: 56109 | S63: =R63+S13-S29 -> 49603 | T63: =S63+T13-T29 -> 41249 | U63: =T63+U13-U29 -> 32644 | V63: =U63+V13-V29 -> 32968 | W63: =V63+W13-W29 -> 42950 | X63: =W63+X13-X29 -> 31093 | Y63: =X63+Y13-Y29 -> 33519 | Z63: =Y63+Z13-Z29 -> 20989 | ... AD63: =AC63+AD13-AD29 -> -33006
H64: Kinder | N64: =M64+N14-N30 -> 0 | O64: =N64+O14-O30 -> 0 | P64: 1532 | Q64: =P64+Q14-Q30 -> 3052 | R64: 2660 | S64: =R64+S14-S30 -> 2214 | T64: =S64+T14-T30 -> 2944 | U64: =T64+U14-U30 -> 2431 | V64: =U64+V14-V30 -> 1718 | W64: =V64+W14-W30 -> 3295 | X64: =W64+X14-X30 -> 2553 | Y64: =X64+Y14-Y30 -> 2949 | Z64: =Y64+Z14-Z30 -> 2177 | ... AD64: =AC64+AD14-AD30 -> -1067
H65: AR | O65: =N65+O15-O31 -> 0 | P65: 916 | Q65: =P65+Q15-Q31 -> 642 | R65: 382 | S65: =R65+S15-S31 -> 65 | T65: =S65+T15-T31 -> -267 | U65: =T65+U15-U31 -> -632 | V65: =U65+V15-V31 -> 1886 | W65: =V65+W15-W31 -> 1369 | X65: =W65+X15-X31 -> 842 | Y65: =X65+Y15-Y31 -> 2321 | Z65: =Y65+Z15-Z31 -> 1773 | ... AD65: =AC65+AD15-AD31 -> -531
...

Sheet 직구재고
B1: Product SKU | C1: Channel SKU | D1: Other SKU | E1: Lot 1 | F1: Expiration Date | G1: Stock-In Date | H1: Item Description | I1: Inventory Type | J1: Qty | K1: Location | L1: Picking Location | M1: Action | N1: Action | P1: 45474 | Q1: 45504 | R1: 45537
B2: 8718117107834 | C2: Aptamil AR | D2: Aptamil AR | E2: 20250721 | F2: 45859 | G2: 45357 | H2: Aptamil AR 1 ENG | I2: Active | J2: 70 | K2: TM9F | L2: TM9F | O2: Aptamil AR | P2: =SUMIF(D:D,O2,J:J) -> 70 | Q2: 1972 | R2: 1616
B3: 8718117607846 | C3: Aptamil COMF | D3: Aptamil COMF | E3: 20250706 | F3: 45844 | G3: 45357 | H3: Aptamil COMF 1 ESC | I3: Active | J3: 698 | K3: TM9F | L3: TM9F | O3: Aptamil COMF | P3: =SUMIF(D:D,O3,J:J) -> 698 | Q3: 562 | R3: 432
B4: 9001375010237 | C4: Aptamil PF DUO YCF1+ | D4: Aptamil PF DUO YCF1+ | E4: 260130 | F4: 46052 | G4: 45407 | H4: Aptamil PF DUO YCF1+ | I4: Active | J4: 829 | K4: TM12F | L4: TM9F | O4: Aptamil PF DUO YCF1+ | P4: =SUMIF(D:D,O4,J:J) -> 2043 | Q4: 905 | R4: 782
B5: 9001375010237 | C5: Aptamil PF DUO YCF1+ | D5: Aptamil PF DUO YCF1+ | E5: 260219 | F5: 46072 | G5: 45376 | H5: Aptamil PF DUO YCF1+ | I5: Active | J5: 1214 | K5: TM9F | L5: TM9F | O5: Aptamil Pronutra Pre | P5: =SUMIF(D:D,O5,J:J) -> 5344 | Q5: 4387 | R5: 3450
B6: 4056631003435 | C6: Aptamil Profutura Pre | D6: Aptamil Profutura Pre | E6: 251016 | F6: 45946 | G6: 45344 | H6: Aptamil Profutura Pre | I6: Active | J6: 5760 | K6: TM12F-E | O6: Aptamil Pronutra Stage1 | P6: =SUMIF(D:D,O6,J:J) -> 10474 | Q6: 9546 | R6: 8634
B7: 4056631003435 | C7: Aptamil Profutura Pre | D7: Aptamil Profutura Pre | E7: 251016 | F7: 45946 | G7: 45344 | H7: Aptamil Profutura Pre | I7: Active | J7: 6520 | K7: TM12F | O7: Aptamil Pronutra Stage2 | P7: =SUMIF(D:D,O7,J:J) -> 3709 | Q7: 7428 | R7: 6103
B8: 4056631003435 | C8: Aptamil Profutura Pre | D8: Aptamil Profutura Pre | E8: 251016 | F8: 45946 | G8: 45345 | H8: Aptamil Profutura Pre | I8: Active | J8: 384 | K8: TM12F | O8: Aptamil Pronutra Stage3 | P8: =SUMIF(D:D,O8,J:J) -> 2808 | Q8: 2633 | R8: 2476
B9: 4056631003435 | C9: Aptamil Profutura Pre | D9: Aptamil Profutura Pre | E9: 251202 | F9: 45993 | G9: 45344 | H9: Aptamil Profutura Pre | I9: Active | J9: 2688 | K9: TM12F-E | O9: Aptamil Profutura Pre | P9: =SUMIF(D:D,O9,J:J) -> 15352 | Q9: 13626 | R9: 23312
B10: 4056631003459 | C10: Aptamil Profutura Stage 1 | D10: Aptamil Profutura Stage1 | E10: 250603 | F10: 45811 | G10: 45176 | H10: Aptamil Profutura Stage1 | I10: Hold | J10: 1 | K10: KR | O10: Aptamil Profutura Stage1 | P10: =SUMIF(D:D,O10,J:J) -> 14338 | Q10: 7078 | R10: 11527
B11: 4056631003459 | C11: Aptamil Profutura Stage 1 | D11: Aptamil Profutura Stage1 | E11: 250901 | F11: 45901 | G11: 45288 | H11: Aptamil Profutura Stage1 | I11: Damaged | J11: 4 | K11: LFS | O11: Aptamil Profutura Stage2 | P11: =SUMIF(D:D,O11,J:J) -> 49701 | Q11: 38336 | R11: 25448
B12: 4056631003459 | C12: Aptamil Profutura Stage 1 | D12: Aptamil Profutura Stage1 | E12: 260111 | F12: 46033 | G12: 45407 | H12: Aptamil Profutura Stage1 | I12: Active | J12: 1277 | K12: TM12F
B13: 4056631003459 | C13: Aptamil Profutura Stage 1 | D13: Aptamil Profutura Stage1 | E13: 260130 | F13: 46052 | G13: 45407 | H13: Aptamil Profutura Stage1 | I13: Active | J13: 11904 | K13: TM12F
B14: 4056631003459 | C14: Aptamil Profutura Stage 1 | D14: Aptamil Profutura Stage1 | E14: 260130 | F14: 46052 | G14: 45407 | H14: Aptamil Profutura Stage1 | I14: Active | J14: 1152 | K14: TM12F-E
B15: 4056631003473 | C15: Aptamil Profutura Stage 2 | D15: Aptamil Profutura Stage2 | E15: 250605 | F15: 45813 | G15: 45176 | H15: Aptamil Profutura Stage2 | I15: Hold | J15: 2 | K15: KR
B16: 4056631003473 | C16: Aptamil Profutura Stage 2 | D16: Aptamil Profutura Stage2 | E16: 250626 | F16: 45834 | G16: 45188 | H16: Aptamil Profutura Stage2 | I16: Hold | J16: 49 | K16: KR
B17: 4056631003473 | C17: Aptamil Profutura Stage 2 | D17: Aptamil Profutura Stage2 | E17: 250712 | F17: 45850 | G17: 45247 | H17: Aptamil Profutura Stage2 | I17: Active | J17: 2034 | K17: TM9F
B18: 4056631003473 | C18: Aptamil Profutura Stage 2 | D18: Aptamil Profutura Stage2 | E18: 250824 | F18: 45893 | G18: 45288 | H18: Aptamil Profutura Stage2 | I18: Active | J18: 10368 | K18: TM9F
B19: 4056631003473 | C19: Aptamil Profutura Stage 2 | D19: Aptamil Profutura Stage2 | E19: 251014 | F19: 45944 | G19: 45288 | H19: Aptamil Profutura Stage2 | I19: Active | J19: 5760 | K19: TM9F
B20: 4056631003473 | C20: Aptamil Profutura Stage 2 | D20: Aptamil Profutura Stage2 | E20: 251120 | F20: 45981 | G20: 45343 | H20: Aptamil Profutura Stage2 | I20: Active | J20: 240 | K20: TM9F
B21: 4056631003473 | C21: Aptamil Profutura Stage 2 | D21: Aptamil Profutura Stage2 | E21: 251120 | F21: 45981 | G21: 45343 | H21: Aptamil Profutura Stage2 | I21: Active | J21: 21648 | K21: TM12F-F
B22: 4056631003473 | C22: Aptamil Profutura Stage 2 | D22: Aptamil Profutura Stage2 | E22: 251120 | F22: 45981 | G22: 45344 | H22: Aptamil Profutura Stage2 | I22: Active | J22: 9600 | K22: TM12F-E
B23: 4056631001202 | C23: Aptamil Pronutra Pre | D23: Aptamil Pronutra Pre | E23: 241211 | F23: 45637 | G23: 45163 | H23: Aptamil Pronutra Pre | I23: Hold | J23: 10 | K23: KR
... B37: 4056631001264 | C37: Aptamil Pronutra Stage 3 | D37: Aptamil Pronutra Stage3 | E37: 250820 | F37: 45889 | G37: 45450 | H37: Aptamil Pronutra Stage3 | I37: Active | J37: 810 | K37: TM12F-F

Sheet Medical(2)
A1: ※ Medical Stock Overview
A2: 1670
A3: Supply (arrival) | D3: Dec. | E3: Jau. | F3: Feb. | G3: Mar. | H3: Apr. | I3: May. | J3: TU | K3: CU | L3: 1PT | M3: 1TU | N3: CU | R3: 금액
A4: Supply (arrival) | B4: =_xlfn.XLOOKUP(C4,'메디컬 SKU'!C:C,'메디컬 SKU'!A:A) -> 117547 | C4: Duocal | D4: 42.677419 | E4: 96 | F4: 324 | G4: 324 | H4: 360 | I4: =K4 -> 240 | J4: 40 | K4: =J4*M4 -> 240 | L4: 108 | M4: 6 | N4: =L4*M4 -> 648 | O4: 12월 이전 물량 | P4: 12월 transfer | Q4: 1월 결제 | R4: =D22 -> 4.7149024e+08
B5: =_xlfn.XLOOKUP(C5,'메디컬 SKU'!C:C,'메디컬 SKU'!A:A) -> 552897 | C5: Elemental Orange | D5: 6566 | E5: 0 | F5: 0 | G5: 0 | H5: 0 | I5: =K5 -> 0 | J5: 0 | K5: =J5*M5 -> 0 | L5: 245 | M5: 10 | N5: =L5*M5 -> 2450 | O5: 10월 생산 | P5: 11월 shipout | Q5: 12월 결제 | R5: =E22 -> 8.288635e+08
B6: =_xlfn.XLOOKUP(C6,'메디컬 SKU'!C:C,'메디컬 SKU'!A:A) -> 117771 | C6: PK AID | D6: 220 | E6: 0 | F6: 60 | G6: 60 | H6: 120 | I6: =K6 -> 204 | J6: 68 | K6: =J6*M6 -> 204 | L6: 200 | M6: 3 | N6: =L6*M6 -> 600 | O6: 11월 생산 | P6: 12월 shipout | Q6: 1월 결제 | R6: =F22 -> 3.0087032e+08
B7: =_xlfn.XLOOKUP(C7,'메디컬 SKU'!C:C,'메디컬 SKU'!A:A) -> 646546 | C7: TYR Anamix | D7: 28.709677 | E7: 0 | F7: 68 | G7: 0 | H7: 0 | I7: =K7 -> 165 | J7: 55 | K7: =J7*M7 -> 165 | L7: 225 | M7: 3 | N7: =L7*M7 -> 675 | O7: 12월 생산 | P7: 1월 shipout | Q7: 2월 결제 | R7: =G22 -> 156893160
B8: =_xlfn.XLOOKUP(C8,'메디컬 SKU'!C:C,'메디컬 SKU'!A:A) -> 646567 | C8: NKH Anamix | D8: 61.258065 | E8: 68 | F8: 0 | G8: 0 | H8: 0 | I8: =K8 -> 159 | J8: 53 | K8: =J8*M8 -> 159 | L8: 225 | M8: 3 | N8: =L8*M8 -> 675 | O8: 1월 생산 | P8: 2월 shipout | Q8: 3월 결제 | R8: =H22 -> 63795670
B9: =_xlfn.XLOOKUP(C9,'메디컬 SKU'!C:C,'메디컬 SKU'!A:A) -> 691217 | C9: Lorenzo Oil | D9: 20 | E9: 48 | F9: 84 | G9: 0 | H9: 0 | I9: =K9 -> 84 | J9: 7 | K9: =J9*M9 -> 84 | L9: 70 | M9: 12 | N9: =L9*M9 -> 840 | O9: 2월 생산 | P9: 3월 shipout | Q9: 4월 결제 | R9: =I22 -> 409132131
B10: =_xlfn.XLOOKUP(C10,'메디컬 SKU'!C:C,'메디컬 SKU'!A:A) -> 611174 | C10: Infatrini | D10: 3472 | E10: 19008 | F10: 0 | G10: 0 | H10: 0 | I10: =K10 -> 0 | J10: 0 | K10: =J10*M10 -> 0 | L10: 72 | M10: 12 | N10: =L10*M10 -> 864 | R10: =SUM(R4:R9) -> 2.231045e+09
B11: =_xlfn.XLOOKUP(C11,'메디컬 SKU'!C:C,'메디컬 SKU'!A:A) -> 701775 | C11: Neocate LCP | D11: 4116.3871 | E11: 0 | F11: 4536 | G11: 2592 | H11: 0 | I11: =K11 -> 1944 | J11: 324 | K11: =J11*M11 -> 1944 | L11: 108 | M11: 6 | N11: =L11*M11 -> 648
B12: =_xlfn.XLOOKUP(C12,'메디컬 SKU'!C:C,'메디컬 SKU'!A:A) -> 646548 | C12: GA1 Anamix Infant | D12: 38.419355 | E12: 168 | F12: 0 | G12: 0 | H12: 60 | I12: =K12 -> 138 | J12: 46 | K12: =J12*M12 -> 138 | L12: 225 | M12: 3 | N12: =L12*M12 -> 675
B13: =_xlfn.XLOOKUP(C13,'메디컬 SKU'!C:C,'메디컬 SKU'!A:A) -> 589462 | C13: GA1 Anamix Junior | D13: 141 | E13: 96 | F13: 0 | G13: 65 | H13: 60 | I13: =K13 -> 132 | J13: 22 | K13: =J13*M13 -> 132 | L13: 108 | M13: 6 | N13: =L13*M13 -> 648
B14: =_xlfn.XLOOKUP(C14,'메디컬 SKU'!C:C,'메디컬 SKU'!A:A) -> 589466 | C14: MSUD Anamix Junior | D14: 9.1290323 | E14: 259 | F14: 0 | G14: 0 | H14: 180 | I14: =K14 -> 330 | J14: 55 | K14: =J14*M14 -> 330 | L14: 108 | M14: 6 | N14: =L14*M14 -> 648
B15: =_xlfn.XLOOKUP(C15,'메디컬 SKU'!C:C,'메디컬 SKU'!A:A) -> 116180 | C15: MSUD Maxamum | D15: 82 | E15: 420 | F15: 60 | G15: 60 | H15: 90 | I15: =K15 -> 735 | J15: 245 | K15: =J15*M15 -> 735 | L15: 200 | M15: 3 | N15: =L15*M15 -> 600
B16: =_xlfn.XLOOKUP(C16,'메디컬 SKU'!C:C,'메디컬 SKU'!A:A) -> 695413 | C16: Locasol | D16: 25.516129 | E16: 238 | F16: 0 | G16: 0 | H16: 120 | I16: =K16 -> 96 | J16: 16 | K16: =J16*M16 -> 96 | L16: 132 | M16: 6 | N16: =L16*M16 -> 792
B17: =_xlfn.XLOOKUP(C17,'메디컬 SKU'!C:C,'메디컬 SKU'!A:A) -> 699883 | C17: Basic F | D17: 72.83871 | E17: 86 | F17: 0 | G17: 0 | H17: 90 | I17: =K17 -> 144 | J17: 24 | K17: =J17*M17 -> 144 | L17: 144 | M17: 6 | N17: =L17*M17 -> 864
B18: =_xlfn.XLOOKUP(C18,'메디컬 SKU'!C:C,'메디컬 SKU'!A:A) -> 645380 | C18: Aptamil Pepti Syneo | D18: 261.19355 | E18: 3454 | F18: 864 | G18: 0 | H18: 0 | I18: =K18 -> 2400 | J18: 200 | K18: =J18*M18 -> 2400 | L18: 72 | M18: 12 | N18: =L18*M18 -> 864
B19: =_xlfn.XLOOKUP(C19,'메디컬 SKU'!C:C,'메디컬 SKU'!A:A) -> 578785 | C19: Elemental 028 Banana | D19: 176.70968 | E19: 735 | F19: 0 | G19: 0 | H19: 0 | I19: =K19 -> 3310 | J19: 331 | K19: =J19*M19 -> 3310 | L19: 245 | M19: 10 | N19: =L19*M19 -> 2450
B20: Total | D20: =SUM(D4:D19) -> 15333.839 | E20: =SUM(E4:E19) -> 24676 | F20: =SUM(F4:F19) -> 5996 | G20: =SUM(G4:G19) -> 3101 | H20: =SUM(H4:H19) -> 1080 | I20: =SUM(I4:I19) -> 10081
B21: 발주 금액 | D21: =금액!H56 -> 282329.49 | E21: =금액!I56 -> 496325.45 | F21: =금액!J56 -> 180161.87 | G21: =금액!K56 -> 93948 | H21: =금액!L56 -> 38201 | I21: ='금액(2)'!M56 -> 244989.3
B22: 발주 금액(KRW) | D22: =D21*$A$2 -> 4.7149024e+08 | E22: =E21*$A$2 -> 8.288635e+08 | F22: =F21*$A$2 -> 3.0087032e+08 | G22: =G21*$A$2 -> 156893160 | H22: =H21*$A$2 -> 63795670 | I22: =I21*$A$2 -> 409132131 | L22: TU
K23: 엘리멘탈 | L23: 1500 | M23: =L23*M5 -> 15000
E24: fcst | F24: fcst | G24: fcst | H24: fcst
A25: Sales | D25: Oct-Dec. | E25: Jau. | F25: Feb. | G25: Mar. | H25: Apr. | I25: May.
A26: Sales CU | B26: =_xlfn.XLOOKUP(C26,'메디컬 SKU'!C:C,'메디컬 SKU'!A:A) -> 117547 | C26: Duocal | E26: 187 | F26: 187 | G26: 187 | H26: 187 | I26: =AVERAGE(G26:H26) -> 187
B27: =_xlfn.XLOOKUP(C27,'메디컬 SKU'!C:C,'메디컬 SKU'!A:A) -> 552897 | C27: Elemental Orange | E27: 1453 | F27: 593 | G27: 593 | H27: 1453 | I27: =AVERAGE(G27:H27) -> 1023
B28: =_xlfn.XLOOKUP(C28,'메디컬 SKU'!C:C,'메디컬 SKU'!A:A) -> 117771 | C28: PK AID | E28: 121 | F28: 56 | G28: 56 | H28: 121 | I28: =AVERAGE(G28:H28) -> 88.5
B29: =_xlfn.XLOOKUP(C29,'메디컬 SKU'!C:C,'메디컬 SKU'!A:A) -> 646546 | C29: TYR Anamix | E29: 35 | F29: 35 | G29: 35 | H29: 35 | I29: =AVERAGE(G29:H29) -> 35
B30: =_xlfn.XLOOKUP(C30,'메디컬 SKU'!C:C,'메디컬 SKU'!A:A) -> 646567 | C30: NKH Anamix | E30: 55 | F30: 22 | G30: 22 | H30: 55 | I30: =AVERAGE(G30:H30) -> 38.5
B31: =_xlfn.XLOOKUP(C31,'메디컬 SKU'!C:C,'메디컬 SKU'!A:A) -> 691217 | C31: Lorenzo Oil | E31: 31 | F31: 31 | G31: 31 | H31: 31 | I31: =AVERAGE(G31:H31) -> 31
B32: =_xlfn.XLOOKUP(C32,'메디컬 SKU'!C:C,'메디컬 SKU'!A:A) -> 611174 | C32: Infatrini | E32: 2951 | F32: 3000 | G32: 3000 | H32: 2951 | I32: =AVERAGE(G32:H32) -> 2975.5
B33: =_xlfn.XLOOKUP(C33,'메디컬 SKU'!C:C,'메디컬 SKU'!A:A) -> 701775 | C33: Neocate LCP | E33: 2237 | F33: 1763 | G33: 1763 | H33: 2237 | I33: =AVERAGE(G33:H33) -> 2000
B34: =_xlfn.XLOOKUP(C34,'메디컬 SKU'!C:C,'메디컬 SKU'!A:A) -> 646548 | C34: GA1 Anamix Infant | E34: 70 | F34: 38 | G34: 38 | H34: 70 | I34: =AVERAGE(G34:H34) -> 54
B35: =_xlfn.XLOOKUP(C35,'메디컬 SKU'!C:C,'메디컬 SKU'!A:A) -> 589462 | C35: GA1 Anamix Junior | E35: 102 | F35: 30 | G35: 30 | H35: 102 | I35: =AVERAGE(G35:H35) -> 66
B36: =_xlfn.XLOOKUP(C36,'메디컬 SKU'!C:C,'메디컬 SKU'!A:A) -> 589466 | C36: MSUD Anamix Junior | E36: 136 | F36: 72 | G36: 72 | H36: 136 | I36: =AVERAGE(G36:H36) -> 104
B37: =_xlfn.XLOOKUP(C37,'메디컬 SKU'!C:C,'메디컬 SKU'!A:A) -> 116180 | C37: MSUD Maxamum | E37: 357 | F37: 30 | G37: 30 | H37: 357 | I37: =AVERAGE(G37:H37) -> 193.5
B38: =_xlfn.XLOOKUP(C38,'메디컬 SKU'!C:C,'메디컬 SKU'!A:A) -> 695413 | C38: Locasol | E38: 79 | F38: 49 | G38: 49 | H38: 79 | I38: =AVERAGE(G38:H38) -> 64
... B41: =_xlfn.XLOOKUP(C41,'메디컬 SKU'!C:C,'메디컬 SKU'!A:A) -> 578785 | C41: Elemental 028 Banana | E41: 345 | F41: 185 | G41: 185 | H41: 345 | I41: =AVERAGE(G41:H41) -> 265
B42: Total | D42: =SUM(D26:D41) -> 0 | E42: =SUM(E26:E41) -> 9154 | F42: =SUM(F26:F41) -> 7034 | G42: =SUM(G26:G41) -> 7034 | H42: =SUM(H26:H41) -> 9154 | I42: =SUM(I26:I41) -> 8094
...

Sheet Medical_rev
A1: ※ Medical Stock Overview
A2: 1670
A3: Supply (arrival) | D3: Dec. | E3: Jau. | F3: Feb. | G3: Mar. | H3: Apr. | I3: May. | J3: June. | K3: TU | L3: CU | M3: 1PT | N3: 1TU | O3: CU | S3: 금액
A4: Supply (arrival) | B4: =_xlfn.XLOOKUP(C4,'메디컬 SKU'!C:C,'메디컬 SKU'!A:A) -> 117547 | C4: Duocal | E4: 96 | F4: 648 | G4: 0 | H4: 360 | I4: 240 | J4: =L4 -> 0 | L4: =K4*N4 -> 0 | M4: 108 | N4: 6 | O4: =M4*N4 -> 648 | P4: 12월 이전 물량 | Q4: 12월 transfer | R4: 1월 결제 | S4: =D22 -> 4.7149024e+08
B5: =_xlfn.XLOOKUP(C5,'메디컬 SKU'!C:C,'메디컬 SKU'!A:A) -> 552897 | C5: Elemental Orange | E5: 0 | F5: 0 | G5: 0 | H5: 0 | I5: 0 | J5: =L5 -> 0 | L5: =K5*N5 -> 0 | M5: 245 | N5: 10 | O5: =M5*N5 -> 2450 | P5: 10월 생산 | Q5: 11월 shipout | R5: 12월 결제 | S5: =E22 -> 8.288635e+08
B6: =_xlfn.XLOOKUP(C6,'메디컬 SKU'!C:C,'메디컬 SKU'!A:A) -> 117771 | C6: PK AID | E6: 0 | F6: 120 | G6: 0 | H6: 120 | I6: 204 | J6: =L6 -> 0 | L6: =K6*N6 -> 0 | M6: 200 | N6: 3 | O6: =M6*N6 -> 600 | P6: 11월 생산 | Q6: 12월 shipout | R6: 1월 결제 | S6: =F22 -> 3.0087032e+08
B7: =_xlfn.XLOOKUP(C7,'메디컬 SKU'!C:C,'메디컬 SKU'!A:A) -> 646546 | C7: TYR Anamix | E7: 0 | F7: 69 | G7: 0 | H7: 135 | I7: 165 | J7: =L7 -> 0 | L7: =K7*N7 -> 0 | M7: 225 | N7: 3 | O7: =M7*N7 -> 675 | P7: 12월 생산 | Q7: 1월 shipout | R7: 2월 결제 | S7: =G22 -> 156893160
B8: =_xlfn.XLOOKUP(C8,'메디컬 SKU'!C:C,'메디컬 SKU'!A:A) -> 646567 | C8: NKH Anamix | E8: 69 | F8: 0 | G8: 0 | H8: 69 | I8: 159 | J8: =L8 -> 0 | L8: =K8*N8 -> 0 | M8: 225 | N8: 3 | O8: =M8*N8 -> 675 | P8: 1월 생산 | Q8: 2월 shipout | R8: 3월 결제 | S8: =H22 -> 63795670
B9: =_xlfn.XLOOKUP(C9,'메디컬 SKU'!C:C,'메디컬 SKU'!A:A) -> 691217 | C9: Lorenzo Oil | E9: 0 | F9: 0 | G9: 48 | H9: 132 | I9: 84 | J9: =L9 -> 0 | L9: =K9*N9 -> 0 | M9: 70 | N9: 12 | O9: =M9*N9 -> 840 | P9: 2월 생산 | Q9: 3월 shipout | R9: 4월 결제 | S9: =J22 -> 409132131
B10: =_xlfn.XLOOKUP(C10,'메디컬 SKU'!C:C,'메디컬 SKU'!A:A) -> 611174 | C10: Infatrini | E10: 0 | F10: 0 | G10: 0 | H10: 0 | I10: 0 | J10: =L10 -> 0 | L10: =K10*N10 -> 0 | M10: 72 | N10: 12 | O10: =M10*N10 -> 864 | S10: =SUM(S4:S9) -> 2.231045e+09
B11: =_xlfn.XLOOKUP(C11,'메디컬 SKU'!C:C,'메디컬 SKU'!A:A) -> 701775 | C11: Neocate LCP | E11: 0 | F11: 4536 | G11: 2592 | H11: 2592 | I11: 1944 | J11: =L11 -> 0 | L11: =K11*N11 -> 0 | M11: 108 | N11: 6 | O11: =M11*N11 -> 648
B12: =_xlfn.XLOOKUP(C12,'메디컬 SKU'!C:C,'메디컬 SKU'!A:A) -> 646548 | C12: GA1 Anamix Infant | E12: 168 | F12: 0 | G12: 0 | H12: 60 | I12: 138 | J12: =L12 -> 0 | L12: =K12*N12 -> 0 | M12: 225 | N12: 3 | O12: =M12*N12 -> 675
B13: =_xlfn.XLOOKUP(C13,'메디컬 SKU'!C:C,'메디컬 SKU'!A:A) -> 589462 | C13: GA1 Anamix Junior | E13: 96 | F13: 66 | G13: 0 | H13: 60 | I13: 132 | J13: =L13 -> 0 | L13: =K13*N13 -> 0 | M13: 108 | N13: 6 | O13: =M13*N13 -> 648
B14: =_xlfn.XLOOKUP(C14,'메디컬 SKU'!C:C,'메디컬 SKU'!A:A) -> 589466 | C14: MSUD Anamix Junior | E14: 258 | F14: 0 | G14: 0 | H14: 180 | I14: 330 | J14: =L14 -> 0 | L14: =K14*N14 -> 0 | M14: 108 | N14: 6 | O14: =M14*N14 -> 648
B15: =_xlfn.XLOOKUP(C15,'메디컬 SKU'!C:C,'메디컬 SKU'!A:A) -> 116180 | C15: MSUD Maxamum | E15: 132 | F15: 408 | G15: 0 | H15: 90 | I15: 735 | J15: =L15 -> 0 | L15: =K15*N15 -> 0 | M15: 200 | N15: 3 | O15: =M15*N15 -> 600
B16: =_xlfn.XLOOKUP(C16,'메디컬 SKU'!C:C,'메디컬 SKU'!A:A) -> 695413 | C16: Locasol | E16: 240 | F16: 0 | G16: 0 | H16: 120 | I16: 96 | J16: =L16 -> 0 | L16: =K16*N16 -> 0 | M16: 132 | N16: 6 | O16: =M16*N16 -> 792
B17: =_xlfn.XLOOKUP(C17,'메디컬 SKU'!C:C,'메디컬 SKU'!A:A) -> 699883 | C17: Basic F | E17: =42+90 -> 132 | F17: 0 | G17: 0 | H17: 90 | I17: 144 | J17: =L17 -> 0 | L17: =K17*N17 -> 0 | M17: 144 | N17: 6 | O17: =M17*N17 -> 864
B18: =_xlfn.XLOOKUP(C18,'메디컬 SKU'!C:C,'메디컬 SKU'!A:A) -> 645380 | C18: Aptamil Pepti Syneo | E18: 3456 | F18: 864 | G18: 0 | H18: 1728 | I18: 2400 | J18: =L18 -> 0 | L18: =K18*N18 -> 0 | M18: 72 | N18: 12 | O18: =M18*N18 -> 864
B19: =_xlfn.XLOOKUP(C19,'메디컬 SKU'!C:C,'메디컬 SKU'!A:A) -> 578785 | C19: Elemental 028 Banana | E19: 661 | F19: 74 | G19: 0 | H19: 0 | I19: 331 | J19: =L19 -> 0 | L19: =K19*N19 -> 0 | M19: 245 | N19: 10 | O19: =M19*N19 -> 2450
B20: Total | D20: =SUM(D4:D19) -> 0 | E20: =SUM(E4:E19) -> 5308 | F20: =SUM(F4:F19) -> 6785 | G20: =SUM(G4:G19) -> 2640 | H20: =SUM(H4:H19) -> 5736 | I20: 10081 | J20: =SUM(J4:J19) -> 0
B21: 발주 금액 | D21: =금액!H56 -> 282329.49 | E21: =금액!I56 -> 496325.45 | F21: =금액!J56 -> 180161.87 | G21: =금액!K56 -> 93948 | H21: =금액!L56 -> 38201 | I21: 244989.3 | J21: ='금액(2)'!M56 -> 244989.3
B22: 발주 금액(KRW) | D22: =D21*$A$2 -> 4.7149024e+08 | E22: =E21*$A$2 -> 8.288635e+08 | F22: =F21*$A$2 -> 3.0087032e+08 | G22: =G21*$A$2 -> 156893160 | H22: =H21*$A$2 -> 63795670 | I22: 409132131 | J22: =J21*$A$2 -> 409132131 | M22: TU
L23: 엘리멘탈 | M23: 1500 | N23: =M23*N5 -> 15000
E24: fcst | F24: fcst | G24: fcst | H24: fcst | I24: fcst | J24: fcst
A25: Sales | D25: Oct-Dec. | E25: Jau. | F25: Feb. | G25: Mar. | H25: Apr. | I25: May. | J25: June.
A26: Sales CU | B26: =_xlfn.XLOOKUP(C26,'메디컬 SKU'!C:C,'메디컬 SKU'!A:A) -> 117547 | C26: Duocal | E26: 187 | F26: 187 | G26: 187 | H26: 187 | I26: 187 | J26: 187
B27: =_xlfn.XLOOKUP(C27,'메디컬 SKU'!C:C,'메디컬 SKU'!A:A) -> 552897 | C27: Elemental Orange | E27: 1453 | F27: 593 | G27: 593 | H27: 1453 | I27: 593 | J27: 593
B28: =_xlfn.XLOOKUP(C28,'메디컬 SKU'!C:C,'메디컬 SKU'!A:A) -> 117771 | C28: PK AID | E28: 121 | F28: 56 | G28: 56 | H28: 121 | I28: 56 | J28: 56
B29: =_xlfn.XLOOKUP(C29,'메디컬 SKU'!C:C,'메디컬 SKU'!A:A) -> 646546 | C29: TYR Anamix | E29: 35 | F29: 35 | G29: 35 | H29: 35 | I29: 35 | J29: 35
B30: =_xlfn.XLOOKUP(C30,'메디컬 SKU'!C:C,'메디컬 SKU'!A:A) -> 646567 | C30: NKH Anamix | E30: 55 | F30: 22 | G30: 22 | H30: 55 | I30: 22 | J30: 22
B31: =_xlfn.XLOOKUP(C31,'메디컬 SKU'!C:C,'메디컬 SKU'!A:A) -> 691217 | C31: Lorenzo Oil | E31: 31 | F31: 31 | G31: 31 | H31: 31 | I31: 31 | J31: 31
B32: =_xlfn.XLOOKUP(C32,'메디컬 SKU'!C:C,'메디컬 SKU'!A:A) -> 611174 | C32: Infatrini | E32: 2951 | F32: 3000 | G32: 3000 | H32: 2951 | I32: 3000 | J32: 3000
B33: =_xlfn.XLOOKUP(C33,'메디컬 SKU'!C:C,'메디컬 SKU'!A:A) -> 701775 | C33: Neocate LCP | E33: 2237 | F33: 1763 | G33: 1763 | H33: 2237 | I33: 1763 | J33: 1763
B34: =_xlfn.XLOOKUP(C34,'메디컬 SKU'!C:C,'메디컬 SKU'!A:A) -> 646548 | C34: GA1 Anamix Infant | E34: 70 | F34: 38 | G34: 38 | H34: 70 | I34: 38 | J34: 38
B35: =_xlfn.XLOOKUP(C35,'메디컬 SKU'!C:C,'메디컬 SKU'!A:A) -> 589462 | C35: GA1 Anamix Junior | E35: 102 | F35: 30 | G35: 30 | H35: 102 | I35: 30 | J35: 30
B36: =_xlfn.XLOOKUP(C36,'메디컬 SKU'!C:C,'메디컬 SKU'!A:A) -> 589466 | C36: MSUD Anamix Junior | E36: 136 | F36: 72 | G36: 72 | H36: 136 | I36: 72 | J36: 72
B37: =_xlfn.XLOOKUP(C37,'메디컬 SKU'!C:C,'메디컬 SKU'!A:A) -> 116180 | C37: MSUD Maxamum | E37: 357 | F37: 30 | G37: 30 | H37: 357 | I37: 30 | J37: 30
B38: =_xlfn.XLOOKUP(C38,'메디컬 SKU'!C:C,'메디컬 SKU'!A:A) -> 695413 | C38: Locasol | E38: 79 | F38: 49 | G38: 49 | H38: 79 | I38: 49 | J38: 49
... B41: =_xlfn.XLOOKUP(C41,'메디컬 SKU'!C:C,'메디컬 SKU'!A:A) -> 578785 | C41: Elemental 028 Banana | E41: 345 | F41: 185 | G41: 185 | H41: 345 | I41: 185 | J41: 185
B42: Total | D42: =SUM(D26:D41) -> 0 | E42: =SUM(E26:E41) -> 9154 | F42: =SUM(F26:F41) -> 7034 | G42: =SUM(G26:G41) -> 7034 | H42: =SUM(H26:H41) -> 9154 | I42: =SUM(I26:I41) -> 7034 | J42: =SUM(J26:J41) -> 7034
...

Sheet 메디컬 입고
A1: 인보이스 발행 날짜 | B1: 인보이스 넘버 | C1: 품목코드 | D1: 품목 | E1: 수량 | F1: 박스 수량 | G1: 입고 상세 | H1: 입고예정일 | M1: 품목코드 | N1: 품목명 | O1: 박스 당 입수
C2: 330851 | D2: 뉴트리시아 듀오칼/400G | E2: 630 | F2: =E2/VLOOKUP(C2, M:O, 3, FALSE) -> 105 | G2: 한독 입고완료 | H2: 45901 | K2: 리드타임 | L2: 3 month | M2: 343070 | N2: 뉴트리시아 인파트리니/400G | O2: 12
C3: 330854 | D3: 뉴트리시아 피케이 에이드4/500G | E3: 240 | F3: =E3/VLOOKUP(C3, M:O, 3, FALSE) -> 80 | G3: 한독 입고완료 | H3: 45901 | M3: 351434 | N3: 뉴트리시아 압타밀 펩티 시네오/400g | O3: 12
C4: 350473 | D4: 뉴트리시아 네오케이트 LCP/400G | E4: 3600 | F4: =E4/VLOOKUP(C4, M:O, 3, FALSE) -> 600 | G4: 한독 입고완료 | H4: 45931 | M4: 330851 | N4: 뉴트리시아 듀오칼/400G | O4: 6
C5: 351460 | D5: 뉴트리시아 엘리멘탈 Banana | E5: 662 | F5: =E5/VLOOKUP(C5, M:O, 3, FALSE) -> 66.2 | G5: 한독 입고완료 | H5: 45931 | M5: 330854 | N5: 뉴트리시아 피케이 에이드4/500G | O5: 3
C6: 351434 | D6: 뉴트리시아 압타밀 펩티 시네오/400g | E6: 1260 | F6: =E6/VLOOKUP(C6, M:O, 3, FALSE) -> 105 | G6: 한독 입고완료 | H6: 45931 | M6: 330853 | N6: 뉴트리시아 엘리멘탈 028 엑스트라/100GX10 | O6: 10
C7: 330856 | D7: 뉴트리시아 엔케이에이치 아나믹스/400G | E7: 72 | F7: =E7/VLOOKUP(C7, M:O, 3, FALSE) -> 24 | H7: 45992 | M7: 351460 | N7: 뉴트리시아 엘리멘탈 028 엑스트라 바나나향 | O7: 10
C8: 351364 | D8: 뉴트리시아 지에이1 아나믹스 주니어/400g | E8: 120 | F8: =E8/VLOOKUP(C8, M:O, 3, FALSE) -> 20 | H8: 45992 | M8: 350473 | N8: 뉴트리시아 네오케이트 LCP/400G | O8: 6
C9: 351366 | D9: 뉴트리시아 엠에스유디 맥사멈/500g | E9: 240 | F9: =E9/VLOOKUP(C9, M:O, 3, FALSE) -> 80 | H9: 45992 | M9: 330857 | N9: 뉴트리시아 로렌조 오일/500ML | O9: 12
C10: 351368 | D10: 뉴트리시아 베이직 에프/300g | E10: 42 | F10: =E10/VLOOKUP(C10, M:O, 3, FALSE) -> 7 | H10: 45992 | M10: 330855 | N10: 뉴트리시아 티와이알 아나믹스/400G | O10: 3
C11: 351434 | D11: 뉴트리시아 압타밀 펩티 시네오/400g | E11: 1500 | F11: =E11/VLOOKUP(C11, M:O, 3, FALSE) -> 125 | H11: 45992 | M11: 330856 | N11: 뉴트리시아 엔케이에이치 아나믹스/400G | O11: 3
C12: 350473 | D12: 뉴트리시아 네오케이트 LCP/400G | E12: 3600 | F12: =E12/VLOOKUP(C12, M:O, 3, FALSE) -> 600 | H12: 46023 | M12: 351368 | N12: 뉴트리시아 베이직 에프/300g | O12: 6
C13: 330857 | D13: 뉴트리시아 로렌조 오일/500ML | E13: 60 | F13: =E13/VLOOKUP(C13, M:O, 3, FALSE) -> 5 | H13: 46023 | M13: 351367 | N13: 뉴트리시아 로카솔/400g | O13: 6
M14: 351366 | N14: 뉴트리시아 엠에스유디 맥사멈/500g | O14: 3
M15: 351365 | N15: 뉴트리시아 엠에스유디 아나믹스 주니어 | O15: 6
M16: 351364 | N16: 뉴트리시아 지에이1 아나믹스 주니어 | O16: 6
M17: 351363 | N17: 뉴트리시아 지에이1 아나믹스 인펀트 | O17: 3

Sheet 메디컬 재고
C1: 45950
A2: SKU Code | B2: 제품명 | C2: 가용재고
A3: 330851 | B3: 뉴트리시아 듀오칼/400G | C3: 477
A4: 330853 | B4: 뉴트리시아 엘리멘탈 028 엑스트라/100GX10 | C4: 12868
A5: 330854 | B5: 뉴트리시아 피케이 에이드4/500G | C5: 332
A6: 330855 | B6: 뉴트리시아 티와이알 아나믹스/400G | C6: 110
A7: 330856 | B7: 뉴트리시아 엔케이에이치 아나믹스/400G | C7: 51
A8: 330857 | B8: 뉴트리시아 로렌조 오일/500ML | C8: 32
A9: 343070 | B9: 뉴트리시아 인파트리니/400G | C9: 10472
A10: 350473 | B10: 뉴트리시아 네오케이트 LCP/400G | C10: 4764
A11: 351363 | B11: 뉴트리시아 지에이1 아나믹스 인펀트/400g | C11: 137
A12: 351364 | B12: 뉴트리시아 지에이1 아나믹스 주니어/400g | C12: 42
A13: 351365 | B13: 뉴트리시아 엠에스유디 아나믹스 주니어/400g | C13: 197
A14: 351366 | B14: 뉴트리시아 엠에스유디 맥사멈/500g | C14: 2
... A18: 351460 | B18: 뉴트리시아 엘리멘탈 028 엑스트라 바나나/100GX10 | C18: 658

Sheet 메디컬 SKU
A2: 구매 코드 | B2: 상품 코드 | C2: 제품명(영문명) | D2: 제품명 | E2: 입수량 (CU/TU) | F2: 원산지 | G2: 캔당 유로가 | H2: 박스당 유로가
A3: 117547 | B3: 330851 | C3: Duocal | D3: 뉴트리시아 듀오칼/400G | E3: 6 | F3: UK | G3: 17.5 | H3: =G3*E3 -> 105
A4: 552897 | B4: 330853 | C4: Elemental Orange | D4: 뉴트리시아 엘리멘탈 028 엑스트라/100GX10 | E4: 10 | F4: UK | G4: 7.65 | H4: =G4*E4 -> 76.5
A5: 117771 | B5: 330854 | C5: PK AID | D5: 뉴트리시아 피케이 에이드4/500G | E5: 3 | F5: UK | G5: 57 | H5: =G5*E5 -> 171
A6: 646546 | B6: 330855 | C6: TYR Anamix | D6: 뉴트리시아 티와이알 아나믹스/400G | E6: 3 | F6: UK | G6: 47.833333 | H6: =G6*E6 -> 143.5
A7: 646567 | B7: 330856 | C7: NKH Anamix | D7: 뉴트리시아 엔케이에이치 아나믹스/400G | E7: 3 | F7: UK | G7: 52 | H7: =G7*E7 -> 156
A8: 691217 | B8: 330857 | C8: Lorenzo Oil | D8: 뉴트리시아 로렌조 오일/500ML | E8: 12 | F8: UK | G8: 102.5 | H8: =G8*E8 -> 1230
A9: 611174 | B9: 343070 | C9: Infatrini | D9: 뉴트리시아 인파트리니/400G | E9: 12 | F9: Germany | G9: 18.6 | H9: =G9*E9 -> 223.2
A10: 701775 | B10: 350473 | C10: Neocate LCP | D10: 뉴트리시아 네오케이트 LCP/400G | E10: 6 | F10: UK | G10: 30.5 | H10: =G10*E10 -> 183
A11: 646548 | B11: 351363 | C11: GA1 Anamix Infant | D11: 뉴트리시아 지에이1 아나믹스 인펀트/400g | E11: 3 | F11: UK | G11: 39.733333 | H11: =G11*E11 -> 119.2
A12: 589462 | B12: 351364 | C12: GA1 Anamix Junior | D12: 뉴트리시아 지에이1 아나믹스 주니어/400g | E12: 6 | F12: UK | G12: 44.8 | H12: =G12*E12 -> 268.8
A13: 589466 | B13: 351365 | C13: MSUD Anamix Junior | D13: 뉴트리시아 엠에스유디 아나믹스 주니어/400g | E13: 6 | F13: UK | G13: 45.8 | H13: =G13*E13 -> 274.8
A14: 116180 | B14: 351366 | C14: MSUD Maxamum | D14: 뉴트리시아 엠에스유디 맥사멈/500g | E14: 3 | F14: UK | G14: 48.166667 | H14: =G14*E14 -> 144.5
... A18: 578785 | B18: 351460 | C18: Elemental 028 Banana | D18: 뉴트리시아 엘리멘탈 028 엑스트라 바나나/100GX10 | E18: 10 | F18: UK | G18: 7.65 | H18: =G18*E18 -> 76.5

Sheet 금액
B2: ※ Aptamil Domestic Stock Overview
D3: CORPORATE CODE | E3: Sep. | F3: Oct. | G3: Nov. | H3: Dec. | I3: Jan. | J3: Feb. | K3: Mar. | L3: Apr. | M3: May. | N3: Jun. | O3: July. | P3: Aug. | Q3: Sept. | R3: Oct. | S3: Nov. | T3: Dec. | U3: Jan. | V3: Feb. | W3: Mar.
B4: PN | C4: 1 | D4: 676366 | E4: =#REF!*VLOOKUP($D4,단가!$B:$E,4,0) -> #REF! | F4: =#REF!*VLOOKUP($D4,단가!$B:$E,4,0) -> #REF! | G4: =#REF!*VLOOKUP($D4,단가!$B:$E,4,0) -> #REF! | H4: =#REF!*VLOOKUP($D4,단가!$B:$E,4,0) -> #REF! | I4: =#REF!*VLOOKUP($D4,단가!$B:$E,4,0) -> #REF! | J4: =#REF!*VLOOKUP($D4,단가!$B:$E,4,0) -> #REF! | K4: =#REF!*VLOOKUP($D4,단가!$B:$E,4,0) -> #REF! | L4: =#REF!*VLOOKUP($D4,단가!$B:$E,4,0) -> #REF! | ... W4: =#REF!*VLOOKUP($D4,단가!$B:$E,4,0) -> #REF!
C5: 2 | D5: 676367 | E5: =#REF!*VLOOKUP($D5,단가!$B:$E,4,0) -> #REF! | F5: =#REF!*VLOOKUP($D5,단가!$B:$E,4,0) -> #REF! | G5: =#REF!*VLOOKUP($D5,단가!$B:$E,4,0) -> #REF! | H5: =#REF!*VLOOKUP($D5,단가!$B:$E,4,0) -> #REF! | I5: =#REF!*VLOOKUP($D5,단가!$B:$E,4,0) -> #REF! | J5: =#REF!*VLOOKUP($D5,단가!$B:$E,4,0) -> #REF! | K5: =#REF!*VLOOKUP($D5,단가!$B:$E,4,0) -> #REF! | L5: =#REF!*VLOOKUP($D5,단가!$B:$E,4,0) -> #REF! | ... W5: =#REF!*VLOOKUP($D5,단가!$B:$E,4,0) -> #REF!
C6: 3 | D6: 676369 | E6: =#REF!*VLOOKUP($D6,단가!$B:$E,4,0) -> #REF! | F6: =#REF!*VLOOKUP($D6,단가!$B:$E,4,0) -> #REF! | G6: =#REF!*VLOOKUP($D6,단가!$B:$E,4,0) -> #REF! | H6: =#REF!*VLOOKUP($D6,단가!$B:$E,4,0) -> #REF! | I6: =#REF!*VLOOKUP($D6,단가!$B:$E,4,0) -> #REF! | J6: =#REF!*VLOOKUP($D6,단가!$B:$E,4,0) -> #REF! | K6: =#REF!*VLOOKUP($D6,단가!$B:$E,4,0) -> #REF! | L6: =#REF!*VLOOKUP($D6,단가!$B:$E,4,0) -> #REF! | ... W6: =#REF!*VLOOKUP($D6,단가!$B:$E,4,0) -> #REF!
B7: PF | C7: 1 | D7: 677211 | E7: =#REF!*VLOOKUP($D7,단가!$B:$E,4,0) -> #REF! | F7: =#REF!*VLOOKUP($D7,단가!$B:$E,4,0) -> #REF! | G7: =#REF!*VLOOKUP($D7,단가!$B:$E,4,0) -> #REF! | H7: =#REF!*VLOOKUP($D7,단가!$B:$E,4,0) -> #REF! | I7: =#REF!*VLOOKUP($D7,단가!$B:$E,4,0) -> #REF! | J7: =#REF!*VLOOKUP($D7,단가!$B:$E,4,0) -> #REF! | K7: =#REF!*VLOOKUP($D7,단가!$B:$E,4,0) -> #REF! | L7: =#REF!*VLOOKUP($D7,단가!$B:$E,4,0) -> #REF! | ... W7: =#REF!*VLOOKUP($D7,단가!$B:$E,4,0) -> #REF!
C8: 2 | D8: 677200 | E8: =#REF!*VLOOKUP($D8,단가!$B:$E,4,0) -> #REF! | F8: =#REF!*VLOOKUP($D8,단가!$B:$E,4,0) -> #REF! | G8: =#REF!*VLOOKUP($D8,단가!$B:$E,4,0) -> #REF! | H8: =#REF!*VLOOKUP($D8,단가!$B:$E,4,0) -> #REF! | I8: =#REF!*VLOOKUP($D8,단가!$B:$E,4,0) -> #REF! | J8: =#REF!*VLOOKUP($D8,단가!$B:$E,4,0) -> #REF! | K8: =#REF!*VLOOKUP($D8,단가!$B:$E,4,0) -> #REF! | L8: =#REF!*VLOOKUP($D8,단가!$B:$E,4,0) -> #REF! | ... W8: =#REF!*VLOOKUP($D8,단가!$B:$E,4,0) -> #REF!
C9: 3 | D9: 677281 | E9: =#REF!*VLOOKUP($D9,단가!$B:$E,4,0) -> #REF! | F9: =#REF!*VLOOKUP($D9,단가!$B:$E,4,0) -> #REF! | G9: =#REF!*VLOOKUP($D9,단가!$B:$E,4,0) -> #REF! | H9: =#REF!*VLOOKUP($D9,단가!$B:$E,4,0) -> #REF! | I9: =#REF!*VLOOKUP($D9,단가!$B:$E,4,0) -> #REF! | J9: =#REF!*VLOOKUP($D9,단가!$B:$E,4,0) -> #REF! | K9: =#REF!*VLOOKUP($D9,단가!$B:$E,4,0) -> #REF! | L9: =#REF!*VLOOKUP($D9,단가!$B:$E,4,0) -> #REF! | ... W9: =#REF!*VLOOKUP($D9,단가!$B:$E,4,0) -> #REF!
B10: Fortimel | C10: VANILLA | D10: 560277
B11: Total | E11: =SUM(E4:E10) -> #REF! | F11: =SUM(F4:F10) -> #REF! | G11: =SUM(G4:G10) -> #REF! | H11: =SUM(H4:H10) -> #REF! | I11: =SUM(I4:I10) -> #REF! | J11: =SUM(J4:J10) -> #REF! | K11: =SUM(K4:K10) -> #REF! | L11: =SUM(L4:L10) -> #REF! | ... W11: =SUM(W4:W10) -> #REF!
B13: ※ Aptamil D2C Jikgu Stock Overview
D14: CORPORATE CODE | E14: Sep. | F14: Oct. | G14: Nov. | H14: Dec. | I14: Dec. | J14: Jan. | K14: Feb. | L14: Mar. | M14: Apr. | N14: May. | O14: July. | P14: Aug. | Q14: Sep. | R14: Oct. | S14: Nov. | T14: Dec. | U14: Jan. | V14: Feb. | W14: Mar.
